File: data/r81.dat
[Header]
TITLE, default name
FILEOPENTIME,5973599.06,5/26/2021,4:42 PM
BYAPP, Resistivity, 2.1, 1.0
INFO, APPNAME, PPMS MultiVu Application, 1.5.11
INFO, , Sample1 Name
INFO, 1, Sample1 Cross Section
INFO, 1, Sample1 Length
INFO, Ohm-m, Sample1 Units
INFO, , Sample2 Name
INFO, 1, Sample2 Cross Section
INFO, 1, Sample2 Length
INFO, Ohm-m, Sample2 Units
INFO, , Sample3 Name
INFO, 1, Sample3 Cross Section
INFO, 1, Sample3 Length
INFO, Ohm-m, Sample3 Units
INFO, , Sample4 Name
INFO, 1, Sample4 Cross Section
INFO, 1, Sample4 Length
INFO, Ohm-m, Sample4 Units
FIELDGROUP, Resistivity,2,3,4,5,6,7,8,9,10,11,12,13,14,15,16,17,18,19,20,21,22,23,24,25,26,27,28,29,30,31,32,33,34,35,36,37,38,39,40,41
STARTUPGROUP, Resistivity
STARTUPAXIS, X, 2, LINEAR, AUTO
STARTUPAXIS, Y1, 7, LINEAR, AUTO
STARTUPAXIS, Y2, 9, LINEAR, AUTO
STARTUPAXIS, Y3, 11, LINEAR, AUTO
PLOT_APPEARANCE, ALL, HORZ_GRID_ON, VERT_GRID_ON, MARKERS_AND_LINES, ALL_LINES
DATATYPE, TIME, 2
DATATYPE, COMMENT, 1
[Data]
Comment,Time Stamp (sec),Status (code),Temperature (K),Magnetic Field (Oe),Sample Position (deg),Bridge 1 Resistivity (Ohm-m),Bridge 1 Excitation (uA),Bridge 2 Resistivity (Ohm-m),Bridge 2 Excitation (uA),Bridge 3 Resistivity (Ohm-m),Bridge 3 Excitation (uA),Bridge 4 Resistivity (Ohm-m),Bridge 4 Excitation (uA),Bridge 1 Std. Dev. (Ohm-m),Bridge 2 Std. Dev. (Ohm-m),Bridge 3 Std. Dev. (Ohm-m),Bridge 4 Std. Dev. (Ohm-m),Number of Readings,Bridge 1 Resistance (Ohms),Bridge 2 Resistance (Ohms),Bridge 3 Resistance (Ohms),Bridge 4 Resistance (Ohms),Signal 1 Vin (V),Signal 2 Vin (V),Digital Inputs (code),Drive 1 Iout (mA),Drive 1 Ipower (watts),Drive 2 Iout (mA),Drive 2 Ipower (watts),Pressure (),Map 20 (),Map 21 (),Map 22 (),Map 23 (),Map 24 (),Map 25 (),Map 26 (),Map 27 (),Map 28 (),Map 29 ()
,5973618.42,4422,5.08224987983704,-0.129914999380708,179.975601196289,-0.00447290186882019,0.999000012874603,-0.0133617603302002,0.999000012874603,-0.0176422882080078,0.999000012874603,,,0.000239661348017567,8.93398454712305e-005,0.000205905952508573,,20,-4.47290186882019,-13.3617603302002,-17.6422882080078,
,5973656.73,4422,5.08655023574829,149.371170043945,179.975601196289,-0.00396885271072388,0.999000012874603,-0.0131773742198944,0.999000012874603,-0.017331373500824,0.999000012874603,,,0.000208070589025576,0.000100325163648816,0.000154569168217729,,20,-3.96885271072388,-13.1773742198944,-17.331373500824,
,5973697.95,4422,5.09105014801025,299.375816345215,179.975601196289,-0.00361959487199783,0.999000012874603,-0.0129077431678772,0.999000012874603,-0.0169430299758911,0.999000012874603,,,0.000172207904927418,0.000106035803747004,0.000138796969423553,,20,-3.61959487199783,-12.9077431678772,-16.9430299758911,
,5973737.31,4422,5.09434986114502,449.824255371094,179.975601196289,-0.00336563509702683,0.999000012874603,-0.0125851380825043,0.999000012874603,-0.0166346504211426,0.999000012874603,,,0.000202524119858808,8.65959726718362e-005,0.000200884205448731,,20,-3.36563509702683,-12.5851380825043,-16.6346504211426,
,5973778.42,4422,5.09680008888245,599.363278198242,179.975601196289,-0.0029639001250267,0.999000012874603,-0.0123137959003448,0.999000012874603,-0.0161886444568634,0.999000012874603,,,0.000194760712495704,0.000107814845877839,0.00018737994316528,,20,-2.9639001250267,-12.3137959003448,-16.1886444568634,
,5973819.33,4422,5.0986499786377,749.2345703125,179.975601196289,-0.00275732336044311,0.999000012874603,-0.0121281936645508,0.999000012874603,-0.0159192980289459,0.999000012874603,,,0.000260686585510793,6.26709919714406e-005,0.000185336146945651,,20,-2.75732336044312,-12.1281936645508,-15.9192980289459,
,5973860.38,4422,5.0986499786377,899.266821289062,179.975601196289,-0.00192854647636414,0.999000012874603,-0.0117204863071442,0.999000012874603,-0.0150243811607361,0.999000012874603,,,0.000258075710449122,5.68802802730199e-005,0.000169408473699591,,20,-1.92854647636414,-11.7204863071442,-15.0243811607361,
,5973900.86,4422,5.09774994850159,1049.44391479492,179.975601196289,-0.00163544360399246,0.999000012874603,-0.0115055865764618,0.999000012874603,-0.0147352245807648,0.999000012874603,,,0.000237649076748776,0.000124897490019882,0.000210434206360877,,20,-1.63544360399246,-11.5055865764618,-14.7352245807648,
,5973943.09,4422,5.09635019302368,1199.57731933594,179.975601196289,-0.00123573518395424,0.999000012874603,-0.0112843438148499,0.999000012874603,-0.0144631627082825,0.999000012874603,,,0.000177089174121019,0.000104414148628322,0.000194631434537514,,20,-1.23573518395424,-11.2843438148499,-14.4631627082825,
,5973983.95,4422,5.09470009803772,1349.20489501953,179.975601196289,-0.000979400387406349,0.999000012874603,-0.0110153457641602,0.999000012874603,-0.0141374004364014,0.999000012874603,,,0.000255672444739525,0.000131857374213389,0.000220739811944638,,20,-0.979400387406349,-11.0153457641602,-14.1374004364014,
,5974022.73,4422,5.09270000457764,1499.36246948242,179.975601196289,-0.000697103677690029,0.999000012874603,-0.0107814246177673,0.999000012874603,-0.013855365562439,0.999000012874603,,,0.000228219871795296,0.000127220530949533,0.000162714481374483,,20,-0.697103677690029,-10.7814246177673,-13.855365562439,
,5974061.73,4422,5.09109997749329,1649.19579467773,179.975601196289,-0.000384942261502147,0.999000012874603,-0.0104620067119598,0.999000012874603,-0.0135060206413269,0.999000012874603,,,0.000178485592292741,9.83816671921661e-005,0.00017296805063539,,20,-0.384942261502147,-10.4620067119598,-13.5060206413269,
,5974103.81,4422,5.08809995651245,1799.30385742187,179.975601196289,-6.11172779346816e-005,0.999000012874603,-0.0101764402389526,0.999000012874603,-0.0133783319950104,0.999000012874603,,,0.00018006178634941,0.000134789486799429,0.000164554257382674,,20,-0.0611172779346816,-10.1764402389526,-13.3783319950104,
,5974143.69,4422,5.08550000190735,1949.29820556641,179.975601196289,0.000215649396926165,0.999000012874603,-0.00985531086921692,0.999000012874603,-0.0130125020980835,0.999000012874603,,,0.000215161424103045,0.000106016531210418,0.000236883514143436,,20,0.215649396926165,-9.85531086921692,-13.0125020980835,
,5974183.16,4422,5.08364987373352,2099.17869873047,179.975601196289,0.000399847238603979,0.999000012874603,-0.00976288084983826,0.999000012874603,-0.0125699286460876,0.999000012874603,,,0.000312819963341563,0.000127951224176895,0.000243816374239922,,20,0.399847238603979,-9.76288084983826,-12.5699286460876,
,5974225.39,4422,5.08154988288879,2249.59953613281,179.975601196289,0.000782541660964489,0.999000012874603,-0.00951629729270935,0.999000012874603,-0.012369619846344,0.999000012874603,,,0.000232641842730372,0.000110793503603,0.000171290811304028,,20,0.782541660964489,-9.51629729270935,-12.369619846344,
,5974268.63,4422,5.07969999313354,2399.58114013672,179.975601196289,0.00111162040531635,0.999000012874603,-0.0092302116394043,0.999000012874603,-0.0120328469753265,0.999000012874603,,,0.000218319003417352,9.88361332057069e-005,0.000234704982773737,,20,1.11162040531635,-9.2302116394043,-12.0328469753265,
,5974310.78,4422,5.07605004310608,2549.11682128906,179.975601196289,0.00142389260530472,0.999000012874603,-0.00905621299743653,0.999000012874603,-0.0117709857463837,0.999000012874603,,,0.000118814194484024,0.000120119360724543,0.00019191013882841,,20,1.42389260530472,-9.05621299743652,-11.7709857463837,
,5974350.94,4422,5.07350015640259,2699.22724609375,179.975601196289,0.00168681478500366,0.999000012874603,-0.0086727014541626,0.999000012874603,-0.0114491419792175,0.999000012874603,,,0.00020025397541686,0.000156145767360744,0.000202104305861696,,20,1.68681478500366,-8.6727014541626,-11.4491419792175,
,5974391.64,4422,5.07080006599426,2849.12720947266,179.975601196289,0.00198426336050034,0.999000012874603,-0.00833734350204468,0.999000012874603,-0.0112411667823791,0.999000012874603,,,0.00014089868116273,0.000126463425881185,0.000195537684958453,,20,1.98426336050034,-8.33734350204468,-11.2411667823792,
,5974432.73,4422,5.06815004348755,2999.51014404297,179.975601196289,0.00221292858123779,0.999000012874603,-0.00806655256748199,0.999000012874603,-0.0109993321418762,0.999000012874603,,,0.000261817150847708,0.000101989062501881,0.000145590042956847,,20,2.21292858123779,-8.066552567482,-10.9993321418762,
,5974474.97,4422,5.06414985656738,3149.28597412109,179.975601196289,0.00244480723142624,0.999000012874603,-0.00789809358119964,0.999000012874603,-0.0107566551685333,0.999000012874603,,,0.000189480089761398,0.000117271234259786,0.000117590847281966,,20,2.44480723142624,-7.89809358119965,-10.7566551685333,
,5974514.55,4422,5.06019997596741,3299.14923095703,179.975601196289,0.00264227864742279,0.999000012874603,-0.00773814945220947,0.999000012874603,-0.0103972341537476,0.999000012874603,,,0.000221939666437729,0.000153290400032833,0.000191927601966197,,20,2.64227864742279,-7.73814945220947,-10.3972341537476,
,5974556.89,4422,5.05580019950867,3449.49536132813,179.975601196289,0.00289320909976959,0.999000012874603,-0.00745579035282135,0.999000012874603,-0.0101084717273712,0.999000012874603,,,0.000336803568084283,0.000126993872377233,0.000185209946401449,,20,2.89320909976959,-7.45579035282135,-10.1084717273712,
,5974598.17,4422,5.05139994621277,3599.34010009766,179.975601196289,0.00323558365106583,0.999000012874603,-0.00713358151912689,0.999000012874603,-0.00981503658294678,0.999000012874603,,,0.000177679769041242,0.000148398947660017,0.000241583479470688,,20,3.23558365106583,-7.13358151912689,-9.81503658294678,
,5974640.00,4421,5.04754996299744,3749.50236816406,179.975601196289,0.00338884505033493,0.999000012874603,-0.00682333450317383,0.999000012874603,-0.00966158418655396,0.999000012874603,,,0.000337880520373781,0.000152507511541403,0.000192686873913786,,20,3.38884505033493,-6.82333450317383,-9.66158418655396,
,5974680.42,4421,5.04384994506836,3899.37133789063,179.975601196289,0.00374650286436081,0.999000012874603,-0.00665960073471069,0.999000012874603,-0.00934763736724854,0.999000012874603,,,0.000173366620092127,0.00013998397847264,0.000124599764662342,,20,3.74650286436081,-6.65960073471069,-9.34763736724853,
,5974721.33,4421,5.04015016555786,4049.37603759766,179.975601196289,0.00393435903787613,0.999000012874603,-0.00644818153381348,0.999000012874603,-0.0090891037940979,0.999000012874603,,,0.00021312817976313,0.000131968274439474,0.00019461680636434,,20,3.93435903787613,-6.44818153381348,-9.0891037940979,
,5974762.19,4421,5.03594994544983,4199.18410644531,179.975601196289,0.00421252675056457,0.999000012874603,-0.00620773320198059,0.999000012874603,-0.00890375413894653,0.999000012874603,,,0.000240532608507175,0.00013308753088315,0.000190589332380415,,20,4.21252675056458,-6.20773320198059,-8.90375413894653,
,5974804.31,4421,5.03154993057251,4349.32668457031,179.975601196289,0.00459845108985901,0.999000012874603,-0.00586255006790161,0.999000012874603,-0.00853390929698944,0.999000012874603,,,0.000142548975901784,0.000168235453927321,0.000212009655445354,,20,4.59845108985901,-5.86255006790161,-8.53390929698944,
,5974845.28,4417,5.02670001983643,4499.28647460937,179.975601196289,0.00472259917259216,0.999000012874603,-0.005566738986969,0.999000012874603,-0.00843251709938049,0.999000012874603,,,0.000237724896136036,0.000142090494337978,0.00014893210313542,,20,4.72259917259216,-5.56673898696899,-8.43251709938049,
,5974887.39,4417,5.02169990539551,4649.47634277344,179.975601196289,0.00485639042854309,0.999000012874603,-0.00539837024211884,0.999000012874603,-0.0079707417011261,0.999000012874603,,,0.000224110724006997,0.000136026326171859,0.000235313618387817,,20,4.85639042854309,-5.39837024211884,-7.9707417011261,
,5974928.92,4417,5.01760005950928,4799.61772460937,179.975601196289,0.00513343451023102,0.999000012874603,-0.00515205316543579,0.999000012874603,-0.00791612915992737,0.999000012874603,,,0.000206170346380711,0.000195811159768961,0.000174604694496383,,20,5.13343451023102,-5.15205316543579,-7.91612915992737,
,5974969.78,4417,5.01265001296997,4949.52685546875,179.975601196289,0.0053531022310257,0.999000012874603,-0.00490877664089203,0.999000012874603,-0.00765301725864411,0.999000012874603,,,0.000269100100010821,0.000180424622575359,0.000200819507889532,,20,5.3531022310257,-4.90877664089203,-7.6530172586441,
,5975008.44,4417,5.00819993019104,4950.40407714844,179.975601196289,0.00542642893791199,0.999000012874603,-0.00480007569789887,0.999000012874603,-0.00764722487926483,0.999000012874603,,,0.000237503786570818,0.000150627982163163,0.000134585066969915,,20,5.42642893791199,-4.80007569789886,-7.64722487926483,
,5975051.64,4417,5.00384998321533,4800.85024414063,179.975601196289,0.00510723028182983,0.999000012874603,-0.00502129340171814,0.999000012874603,-0.00778941640853882,0.999000012874603,,,0.000190198076987887,0.000180969838584564,0.000257620639104035,,20,5.10723028182983,-5.02129340171814,-7.78941640853882,
,5975093.42,4417,5.00005006790161,4650.38547363281,179.975601196289,0.00470006222724915,0.999000012874603,-0.00532114038467407,0.999000012874603,-0.00824201321601868,0.999000012874603,,,0.000336836592111384,0.00018613501660457,0.00021019985670531,,20,4.70006222724915,-5.32114038467407,-8.24201321601868,
,5975135.69,4417,4.9997501373291,4500.48093261719,179.975601196289,0.00459210152626038,0.999000012874603,-0.00556811654567718,0.999000012874603,-0.00842846457958221,0.999000012874603,,,0.000208491767173536,0.000182123128475935,0.000220598966471768,,20,4.59210152626038,-5.56811654567719,-8.42846457958222,
,5975177.08,4417,4.99995017051697,4350.51789550781,179.975601196289,0.00416988110542297,0.999000012874603,-0.0058975287437439,0.999000012874603,-0.00867872242927551,0.999000012874603,,,0.000256832493566899,0.000132997724160183,0.000181798094270021,,20,4.16988110542297,-5.8975287437439,-8.67872242927551,
,5975220.22,4417,5.00009989738464,4200.67299804688,179.975601196289,0.00398197462558746,0.999000012874603,-0.00619522225856781,0.999000012874603,-0.00897786922454834,0.999000012874603,,,0.000169560597869769,0.000149188592564263,0.000149249922443262,,20,3.98197462558746,-6.19522225856781,-8.97786922454834,
,5975264.47,4417,4.99980020523071,4050.82583007812,179.975601196289,0.00376464414596558,0.999000012874603,-0.00638478064537048,0.999000012874603,-0.00918852343559265,0.999000012874603,,,0.000184232100581106,0.000144216422239866,0.000186544279332656,,20,3.76464414596558,-6.38478064537048,-9.18852343559265,
,5975305.97,4417,5,3900.8314453125,179.975601196289,0.00345997037887573,0.999000012874603,-0.00661803600788116,0.999000012874603,-0.00948460412025452,0.999000012874603,,,0.000256253353233854,0.000133782581872731,0.000241534816037063,,20,3.45997037887573,-6.61803600788116,-9.48460412025452,
,5975348.56,4417,5.00005006790161,3750.65432128906,179.975601196289,0.00312006958723068,0.999000012874603,-0.00702213840484619,0.999000012874603,-0.00976457934379578,0.999000012874603,,,0.000188258342292562,0.000109920270398667,0.000143840765113278,,20,3.12006958723068,-7.02213840484619,-9.76457934379578,
,5975388.91,4417,5.00004982948303,3600.74393310547,179.975601196289,0.002730806016922,0.999000012874603,-0.00727368228435516,0.999000012874603,-0.0101440988540649,0.999000012874603,,,0.000219158898171481,0.00010872693902939,0.000116201065035833,,20,2.730806016922,-7.27368228435516,-10.1440988540649,
,5975431.02,4417,4.99985003471375,3450.40017089844,179.975601196289,0.00242373591661453,0.999000012874603,-0.00754454715251923,0.999000012874603,-0.0103488504886627,0.999000012874603,,,0.000292786516143342,0.000136627225548345,0.000157154494038265,,20,2.42373591661453,-7.54454715251923,-10.3488504886627,
,5975473.25,4417,5.00014996528625,3300.63004150391,179.975601196289,0.00241153779625893,0.999000012874603,-0.00772528493404388,0.999000012874603,-0.0105067120075226,0.999000012874603,,,0.000203529004067691,0.000138410450212211,0.000247277713196872,,20,2.41153779625893,-7.72528493404388,-10.5067120075226,
,5975515.08,4417,5.00005006790161,3150.49089355469,179.975601196289,0.00209458879828453,0.999000012874603,-0.00792937822341919,0.999000012874603,-0.0108840129375458,0.999000012874603,,,0.000211043092610383,0.000107790276952124,0.0001670939671611,,20,2.09458879828453,-7.92937822341919,-10.8840129375458,
,5975554.17,4417,4.99985003471375,3000.61619873047,179.975601196289,0.00175998006463051,0.999000012874603,-0.00832610788345337,0.999000012874603,-0.0111453186988831,0.999000012874603,,,0.000208044732685334,0.000139713387926075,0.000213454359456006,,20,1.75998006463051,-8.32610788345337,-11.1453186988831,
,5975595.17,4417,5.00005006790161,2850.61376953125,179.975601196289,0.00153726446330547,0.999000012874603,-0.00837271189689636,0.999000012874603,-0.0114305346012115,0.999000012874603,,,0.000235131389532692,9.46511242421822e-005,0.000184804676957831,,20,1.53726446330547,-8.37271189689636,-11.4305346012115,
,5975636.06,4417,4.99990010261536,2700.73450927734,179.975601196289,0.00110984842926264,0.999000012874603,-0.00882082152366638,0.999000012874603,-0.0116994371891022,0.999000012874603,,,0.000225084987924159,0.000127640604308217,0.000211294397909513,,20,1.10984842926264,-8.82082152366638,-11.6994371891022,
,5975678.13,4417,5,2550.64580078125,179.975601196289,0.000983851808309555,0.999000012874603,-0.00908118968009949,0.999000012874603,-0.0119667010307312,0.999000012874603,,,0.000176650473635187,9.91080302641274e-005,0.000185129329297059,,20,0.983851808309555,-9.08118968009949,-11.9667010307312,
,5975718.16,4417,4.99994993209839,2400.64819335938,179.975601196289,0.000545201063156128,0.999000012874603,-0.00928589124679565,0.999000012874603,-0.0122285446166992,0.999000012874603,,,0.000322708976203104,0.000113701340739255,0.000221985762252663,,20,0.545201063156128,-9.28589124679565,-12.2285446166992,
,5975761.58,4417,4.99990010261536,2250.76300048828,179.975601196289,0.000300926356390119,0.999000012874603,-0.00961063876152038,0.999000012874603,-0.012599560546875,0.999000012874603,,,0.000280846574201488,0.000111331236413524,0.000193843276652991,,20,0.300926356390119,-9.61063876152039,-12.599560546875,
,5975804.70,4417,5.00014996528625,2100.61009521484,179.975601196289,-1.12683626939543e-005,0.999000012874603,-0.00968228979110718,0.999000012874603,-0.0129344525337219,0.999000012874603,,,0.000302231402381561,0.00010864824065267,0.000181676908070181,,20,-0.0112683626939543,-9.68228979110718,-12.9344525337219,
,5975846.86,4417,5.00014996528625,1950.789453125,179.975601196289,-0.000252105660736561,0.999000012874603,-0.0100306535720825,0.999000012874603,-0.0131659311294556,0.999000012874603,,,0.00022851114929898,9.77831321527619e-005,0.000217646621798388,,20,-0.252105660736561,-10.0306535720825,-13.1659311294556,
,5975888.88,4417,5.00009989738464,1800.50303344727,179.975601196289,-0.000483014759421348,0.999000012874603,-0.0103833377361298,0.999000012874603,-0.0134467916488647,0.999000012874603,,,0.000169497225439188,9.88230176000126e-005,0.000184805702091259,,20,-0.483014759421349,-10.3833377361298,-13.4467916488647,
,5975931.05,4417,5.00014996528625,1650.70877685547,179.975601196289,-0.000664241532981396,0.999000012874603,-0.0105534868717194,0.999000012874603,-0.0137646084308624,0.999000012874603,,,0.000135088961090341,0.000112992721314079,0.000219993201284049,,20,-0.664241532981396,-10.5534868717194,-13.7646084308624,
,5975972.98,4417,4.99995017051697,1500.87427368164,179.975601196289,-0.0011532806634903,0.999000012874603,-0.010826840877533,0.999000012874603,-0.0140746260166168,0.999000012874603,,,0.000161937802993926,0.000116082903990507,0.000170423935159127,,20,-1.1532806634903,-10.826840877533,-14.0746260166168,
,5976013.59,4417,4.99979996681213,1350.58107910156,179.975601196289,-0.00151917959451675,0.999000012874603,-0.0111184006690979,0.999000012874603,-0.014290161895752,0.999000012874603,,,0.000202343995627572,0.000113795321148447,0.000226945547769196,,20,-1.51917959451675,-11.1184006690979,-14.290161895752,
,5976055.42,4417,4.99984979629517,1200.73276367188,179.975601196289,-0.00172902678251267,0.999000012874603,-0.0113759648799896,0.999000012874603,-0.0147599308013916,0.999000012874603,,,0.000215512009845204,9.35879831854839e-005,9.8961699631403e-005,,20,-1.72902678251266,-11.3759648799896,-14.7599308013916,
,5976096.66,4417,5,1050.87871704102,179.975601196289,-0.00218624240756035,0.999000012874603,-0.0116111732959747,0.999000012874603,-0.0150188861846924,0.999000012874603,,,0.000205577472731207,0.000103099355156952,0.000157397597306201,,20,-2.18624240756035,-11.6111732959747,-15.0188861846924,
,5976138.08,4417,5.00014996528625,900.706228637695,179.975601196289,-0.00239340469837189,0.999000012874603,-0.0119773343086243,0.999000012874603,-0.0153498113632202,0.999000012874603,,,0.000181829187103972,9.94848770069222e-005,0.000107939650215705,,20,-2.39340469837189,-11.9773343086243,-15.3498113632202,
,5976177.81,4417,4.99994993209839,750.732611083984,179.975601196289,-0.00267600004673004,0.999000012874603,-0.0122079730510712,0.999000012874603,-0.0156855695724487,0.999000012874603,,,0.000218776351332449,0.000109416164170545,0.000192610418912652,,20,-2.67600004673004,-12.2079730510712,-15.6855695724487,
,5976220.38,4417,4.99994993209839,600.824545288086,179.975601196289,-0.00303662139177322,0.999000012874603,-0.0125131770133972,0.999000012874603,-0.0159626127719879,0.999000012874603,,,0.000203639306656933,7.36503854680967e-005,0.000105671287198227,,20,-3.03662139177322,-12.5131770133972,-15.9626127719879,
,5976262.05,4417,5.00004982948303,450.704917907715,179.975601196289,-0.00346473302841187,0.999000012874603,-0.0127896583557129,0.999000012874603,-0.0162691895008087,0.999000012874603,,,0.000187069737597534,6.93240044774868e-005,0.000169141007250086,,20,-3.46473302841187,-12.7896583557129,-16.2691895008087,
,5976302.25,4417,4.99970006942749,300.779586791992,179.975601196289,-0.00367929552793503,0.999000012874603,-0.0130314514160156,0.999000012874603,-0.0165598856925964,0.999000012874603,,,0.000232706258313795,8.59920238632049e-005,0.000152424192065149,,20,-3.67929552793503,-13.0314514160156,-16.5598856925964,
,5976342.28,4417,5.00019979476929,150.5840965271,179.975601196289,-0.00395675246715546,0.999000012874603,-0.0132374742507935,0.999000012874603,-0.0168864003181458,0.999000012874603,,,0.000241444873362605,8.39869926165898e-005,0.000179079803780647,,20,-3.95675246715546,-13.2374742507935,-16.8864003181458,
,5976382.09,4417,5,0.763394156098366,179.975601196289,-0.0044222268819809,0.999000012874603,-0.0134465871334076,0.999000012874603,-0.0172163184165955,0.999000012874603,,,0.000339632950442925,9.69780298153174e-005,0.000227829611452287,,20,-4.4222268819809,-13.4465871334076,-17.2163184165955,
,5976422.23,4417,4.99990010261536,-149.657443237305,179.975601196289,-0.00461886599063873,0.999000012874603,-0.0137856604576111,0.999000012874603,-0.0175096442222595,0.999000012874603,,,0.000172912665843442,9.01279723570806e-005,0.000182324100284089,,20,-4.61886599063873,-13.7856604576111,-17.5096442222595,
,5976462.94,4417,4.99985003471375,-299.293040466309,179.975601196289,-0.00511249780654907,0.999000012874603,-0.0140981255531311,0.999000012874603,-0.0179338718414307,0.999000012874603,,,0.000194232537835535,8.58898799173667e-005,0.000187656792952369,,20,-5.11249780654907,-14.0981255531311,-17.9338718414307,
,5976504.58,4417,4.99985003471375,-449.181579589844,179.975601196289,-0.00520418200492859,0.999000012874603,-0.0143441063404083,0.999000012874603,-0.018261040687561,0.999000012874603,,,0.0001583111910779,7.24792668667188e-005,0.000171431284301568,,20,-5.20418200492859,-14.3441063404083,-18.261040687561,
,5976546.69,4417,5.00010013580322,-599.300048828125,179.975601196289,-0.00569767534732819,0.999000012874603,-0.0146380603790283,0.999000012874603,-0.0186363408088684,0.999000012874603,,,0.000265591252330674,7.65485164070677e-005,0.000168563190660466,,20,-5.69767534732819,-14.6380603790283,-18.6363408088684,
,5976587.94,4417,5.00014996528625,-749.548428344727,179.975601196289,-0.00604339551925659,0.999000012874603,-0.0149107542991638,0.999000012874603,-0.0189429954528809,0.999000012874603,,,0.000217436654228865,8.41501799933143e-005,0.000187242837881001,,20,-6.04339551925659,-14.9107542991638,-18.9429954528809,
,5976628.05,4417,5,-899.380624389648,179.975601196289,-0.00678582000732422,0.999000012874603,-0.0152031781196594,0.999000012874603,-0.0197901838302612,0.999000012874603,,,0.000225992464621104,9.82222339419388e-005,0.000120896312849058,,20,-6.78582000732422,-15.2031781196594,-19.7901838302612,
,5976669.14,4417,5,-1049.41517944336,179.975601196289,-0.00706649219989776,0.999000012874603,-0.0154657890796661,0.999000012874603,-0.020090922832489,0.999000012874603,,,0.000174913040528304,0.000126016671061317,0.000180005726493994,,20,-7.06649219989777,-15.4657890796661,-20.090922832489,
,5976710.17,4417,4.99995017051697,-1199.26346435547,179.975601196289,-0.00738995931148529,0.999000012874603,-0.0157021594524384,0.999000012874603,-0.0203696984291077,0.999000012874603,,,0.000179261274246036,0.000118097041128635,0.000174164954430704,,20,-7.38995931148529,-15.7021594524384,-20.3696984291077,
,5976751.81,4417,5.00005006790161,-1349.48080444336,179.975601196289,-0.00772232511043548,0.999000012874603,-0.0159761868953705,0.999000012874603,-0.0206738970756531,0.999000012874603,,,0.000195482378970876,0.000114040177850832,0.000226086251286042,,20,-7.72232511043549,-15.9761868953705,-20.6738970756531,
,5976793.56,4417,5,-1499.3291015625,179.975601196289,-0.00807935431003571,0.999000012874603,-0.0162785823822022,0.999000012874603,-0.0210588937759399,0.999000012874603,,,0.00024978984933447,0.000125689683442956,0.000174189646870027,,20,-8.07935431003571,-16.2785823822021,-21.0588937759399,
,5976835.55,4417,4.99979996681213,-1649.41539916992,179.975601196289,-0.0084121780872345,0.999000012874603,-0.0164478089332581,0.999000012874603,-0.0214074707984924,0.999000012874603,,,0.000184286925171195,0.000102690683447211,0.000170880550715877,,20,-8.4121780872345,-16.4478089332581,-21.4074707984924,
,5976875.16,4417,4.99995017051697,-1799.22690429688,179.975601196289,-0.00862680277824402,0.999000012874603,-0.0166675885200501,0.999000012874603,-0.0216359389305115,0.999000012874603,,,0.000203312507968743,0.000120553783749488,0.000165824196440298,,20,-8.62680277824402,-16.6675885200501,-21.6359389305115,
,5976916.19,4417,4.99974989891052,-1949.65346069336,179.975601196289,-0.0090059401512146,0.999000012874603,-0.0169800996780395,0.999000012874603,-0.0220612685203552,0.999000012874603,,,0.000122616393574785,6.87812959158795e-005,0.00017478217446238,,20,-9.0059401512146,-16.9800996780396,-22.0612685203552,
,5976954.66,4417,4.99985003471375,-2099.20745849609,179.975601196289,-0.00937058291435242,0.999000012874603,-0.0172962759017944,0.999000012874603,-0.0223282720565796,0.999000012874603,,,0.00023122126110692,9.679474591442e-005,0.000151753911158585,,20,-9.37058291435242,-17.2962759017944,-22.3282720565796,
,5976995.89,4417,4.99990010261536,-2249.30057373047,179.975601196289,-0.00969589323997498,0.999000012874603,-0.0175098381996155,0.999000012874603,-0.0225751676559448,0.999000012874603,,,0.000189981499120502,0.000135139326173865,0.000217210862255077,,20,-9.69589323997497,-17.5098381996155,-22.5751676559448,
,5977037.19,4417,4.99994993209839,-2399.26281738281,179.975601196289,-0.00994413776397705,0.999000012874603,-0.0177382761955261,0.999000012874603,-0.0229918557167053,0.999000012874603,,,0.000301062901843228,9.17064553277122e-005,0.000166593601317677,,20,-9.94413776397705,-17.7382761955261,-22.9918557167053,
,5977077.50,4417,4.99989986419678,-2549.41112060547,179.975601196289,-0.0102113152980804,0.999000012874603,-0.0180393405914307,0.999000012874603,-0.0232152780532837,0.999000012874603,,,0.000120603937456083,0.000110483411512206,0.00019760576499642,,20,-10.2113152980804,-18.0393405914307,-23.2152780532837,
,5977118.42,4417,5,-2699.29620361328,179.975601196289,-0.0106476006031036,0.999000012874603,-0.0181911673545837,0.999000012874603,-0.0234575309753418,0.999000012874603,,,0.000234745875264656,0.000110222395726202,0.000189959714490676,,20,-10.6476006031036,-18.1911673545837,-23.4575309753418,
,5977159.39,4417,4.99985003471375,-2849.22496337891,179.975601196289,-0.0109237911224365,0.999000012874603,-0.0184814566612244,0.999000012874603,-0.0237315541267395,0.999000012874603,,,0.000191897266461547,8.53738212159451e-005,0.000198912390295649,,20,-10.9237911224365,-18.4814566612244,-23.7315541267395,
,5977199.94,4417,4.99994993209839,-2999.32625732422,179.975601196289,-0.0113603559494019,0.999000012874603,-0.0187611004829407,0.999000012874603,-0.0241588864326477,0.999000012874603,,,0.000209620200053325,0.000168859544412182,0.000120325329777557,,20,-11.3603559494019,-18.7611004829407,-24.1588864326477,
,5977241.73,4417,4.99990010261536,-3149.42398681641,179.975601196289,-0.0116254184246063,0.999000012874603,-0.0190932888031006,0.999000012874603,-0.0243440286636353,0.999000012874603,,,0.000208283269100017,0.000139428249294742,0.000236204506852359,,20,-11.6254184246063,-19.0932888031006,-24.3440286636353,
,5977280.80,4417,4.99979996681213,-3299.2423828125,179.975601196289,-0.0118872344970703,0.999000012874603,-0.01929313621521,0.999000012874603,-0.0247342699050903,0.999000012874603,,,0.000273213317220747,0.000135432232108287,0.000131556940645964,,20,-11.8872344970703,-19.29313621521,-24.7342699050903,
,5977322.13,4417,4.99990010261536,-3449.53220214844,179.975601196289,-0.0122344882965088,0.999000012874603,-0.0195839469909668,0.999000012874603,-0.0249185476303101,0.999000012874603,,,0.00019319017383917,6.98462621276002e-005,0.000231066427514776,,20,-12.2344882965088,-19.5839469909668,-24.9185476303101,
,5977364.88,4417,5,-3599.31944580078,179.975601196289,-0.0125004141807556,0.999000012874603,-0.0199285276412964,0.999000012874603,-0.0253167345046997,0.999000012874603,,,0.000223913345918546,0.000142991341284846,0.000149010973139679,,20,-12.5004141807556,-19.9285276412964,-25.3167345046997,
,5977405.20,4417,5.00005006790161,-3749.19182128906,179.975601196289,-0.0128097160339355,0.999000012874603,-0.0201605032920837,0.999000012874603,-0.0255157392501831,0.999000012874603,,,0.00031087963924966,0.000121550506631439,0.000162860884565861,,20,-12.8097160339355,-20.1605032920837,-25.5157392501831,
,5977446.84,4417,5,-3899.54373779297,179.975601196289,-0.0130480298519135,0.999000012874603,-0.0203394242286682,0.999000012874603,-0.0258183323860168,0.999000012874603,,,0.000243221723997402,0.000122782180893237,0.000231470788046801,,20,-13.0480298519135,-20.3394242286682,-25.8183323860168,
,5977488.81,4417,5.00029993057251,-4049.47255859375,179.975601196289,-0.0133856127738953,0.999000012874603,-0.0206968022346497,0.999000012874603,-0.0261388583183289,0.999000012874603,,,0.000175450296200734,0.000156983894377722,0.00018014686447208,,20,-13.3856127738953,-20.6968022346497,-26.1388583183289,
,5977529.42,4417,5.00010013580322,-4199.33576660156,179.975601196289,-0.0136449336528778,0.999000012874603,-0.0209206648826599,0.999000012874603,-0.0263805678367615,0.999000012874603,,,0.000292097119967058,0.000170026322258232,0.000212687213516168,,20,-13.6449336528778,-20.9206648826599,-26.3805678367615,
,5977571.42,4417,5.00020003318787,-4349.57277832031,179.975601196289,-0.0140181045055389,0.999000012874603,-0.0211991690635681,0.999000012874603,-0.0266963950157166,0.999000012874603,,,0.000253782438415153,0.000162113224509519,0.000113459711465746,,20,-14.0181045055389,-21.1991690635681,-26.6963950157166,
,5977612.47,4417,4.99995017051697,-4499.19904785156,179.975601196289,-0.0141992694854736,0.999000012874603,-0.0214634811401367,0.999000012874603,-0.0269491920471191,0.999000012874603,,,0.000159823552965661,0.000177992299987625,0.000205015101521705,,20,-14.1992694854736,-21.4634811401367,-26.9491920471191,
,5977652.20,4417,5.0002498626709,-4649.256640625,179.975601196289,-0.0144951930046082,0.999000012874603,-0.0216166475296021,0.999000012874603,-0.0272228663444519,0.999000012874603,,,0.000215363109195257,0.000191402786985897,0.000148277256407876,,20,-14.4951930046082,-21.6166475296021,-27.2228663444519,
,5977692.77,4417,5,-4799.1025390625,179.975601196289,-0.0150156584739685,0.999000012874603,-0.0219340786933899,0.999000012874603,-0.0275168033599854,0.999000012874603,,,0.000256528229960637,0.000170709488932287,0.000179688653090866,,20,-15.0156584739685,-21.9340786933899,-27.5168033599854,
,5977733.83,4417,4.99995017051697,-4949.64196777344,179.975601196289,-0.0152706379890442,0.999000012874603,-0.0222640305519104,0.999000012874603,-0.0277824805259705,0.999000012874603,,,0.000254412967098682,0.000199943157353443,0.000201250342859877,,20,-15.2706379890442,-22.2640305519104,-27.7824805259705,
,5977773.61,4417,5.00009989738464,-4950.41796875,179.975601196289,-0.0152200249671936,0.999000012874603,-0.0221263246536255,0.999000012874603,-0.0276730417251587,0.999000012874603,,,0.00026488352225196,0.000179224331137919,0.000182188286162645,,20,-15.2200249671936,-22.1263246536255,-27.6730417251587,
,5977815.50,4417,4.99985003471375,-4800.45686035156,179.975601196289,-0.014954881477356,0.999000012874603,-0.0219279057502747,0.999000012874603,-0.0275820471763611,0.999000012874603,,,0.000333893663611417,0.000181601054117805,0.000151404349997632,,20,-14.954881477356,-21.9279057502747,-27.5820471763611,
,5977857.53,4417,5.00010013580322,-4650.35446777344,179.975601196289,-0.014566982460022,0.999000012874603,-0.0216788895606995,0.999000012874603,-0.0272398562431335,0.999000012874603,,,0.000201173916232178,0.000175310611236624,0.000170284785990553,,20,-14.566982460022,-21.6788895606995,-27.2398562431335,
,5977899.03,4417,5.00005006790161,-4500.85812988281,179.975601196289,-0.0142111149311066,0.999000012874603,-0.0213305653572083,0.999000012874603,-0.0269562705039978,0.999000012874603,,,0.000216692048816721,0.000179023877485014,0.000156705430819164,,20,-14.2111149311066,-21.3305653572083,-26.9562705039978,
,5977942.03,4417,4.99995017051697,-4350.39353027344,179.975601196289,-0.0139567639350891,0.999000012874603,-0.0210869216918945,0.999000012874603,-0.0266887239456177,0.999000012874603,,,0.000266858661161507,0.000136532387743539,0.000200069876626852,,20,-13.9567639350891,-21.0869216918945,-26.6887239456177,
,5977983.78,4417,5.00005006790161,-4200.40393066406,179.975601196289,-0.0137689807891846,0.999000012874603,-0.0209109913825989,0.999000012874603,-0.0263535470962524,0.999000012874603,,,0.000242174028306414,0.00015526802830758,0.000237829761634085,,20,-13.7689807891846,-20.9109913825989,-26.3535470962524,
,5978023.95,4417,5,-4050.90056152344,179.975601196289,-0.0133866868019104,0.999000012874603,-0.0206412943840027,0.999000012874603,-0.0261228150367737,0.999000012874603,,,0.00023074131121021,0.000147296879565,0.000205287780690855,,20,-13.3866868019104,-20.6412943840027,-26.1228150367737,
,5978066.19,4417,5,-3900.47501220703,179.975601196289,-0.0130690353393555,0.999000012874603,-0.0203306612968445,0.999000012874603,-0.0258314726829529,0.999000012874603,,,0.000220929104148295,0.000150922374025608,0.000196474200999622,,20,-13.0690353393555,-20.3306612968445,-25.8314726829529,
,5978109.59,4417,5.00009989738464,-3750.87391357422,179.975601196289,-0.0127322994709015,0.999000012874603,-0.020061315536499,0.999000012874603,-0.025452182674408,0.999000012874603,,,0.000152124470810126,0.000118964447089344,0.000625748917001449,,20,-12.7322994709015,-20.061315536499,-25.452182674408,
,5978152.11,4417,4.99990010261536,-3600.44616699219,179.975601196289,-0.0124566197395325,0.999000012874603,-0.0197418765068054,0.999000012874603,-0.0252707571029663,0.999000012874603,,,0.000221725015650661,0.00016513837467057,0.000149541720096477,,20,-12.4566197395325,-19.7418765068054,-25.2707571029663,
,5978195.23,4417,5.00020003318787,-3450.42429199219,179.975601196289,-0.0121696205615997,0.999000012874603,-0.0195505504608154,0.999000012874603,-0.0249493932723999,0.999000012874603,,,0.000232746063682624,0.000114737438366104,0.000174401336274098,,20,-12.1696205615997,-19.5505504608154,-24.9493932723999,
,5978234.81,4417,5.00020003318787,-3300.64161376953,179.975601196289,-0.0118989651203156,0.999000012874603,-0.0192944172859192,0.999000012874603,-0.024587916469574,0.999000012874603,,,0.000181217203790132,0.000159321634563177,0.000181460978025726,,20,-11.8989651203156,-19.2944172859192,-24.587916469574,
,5978273.55,4417,4.99979996681213,-3150.55749511719,179.975601196289,-0.0115811026573181,0.999000012874603,-0.0189735123634338,0.999000012874603,-0.0243527651786804,0.999000012874603,,,0.000220261093570185,0.000107166160830168,0.000154067916709179,,20,-11.5811026573181,-18.9735123634338,-24.3527651786804,
,5978312.58,4417,5.00009989738464,-3000.67478027344,179.975601196289,-0.0111612479686737,0.999000012874603,-0.0187492726325989,0.999000012874603,-0.024033521270752,0.999000012874603,,,0.000178048431145422,0.000118183670971889,0.000241363128434984,,20,-11.1612479686737,-18.7492726325989,-24.033521270752,
,5978351.52,4417,4.99995017051697,-2850.88513183594,179.975601196289,-0.0108087359428406,0.999000012874603,-0.0185325489044189,0.999000012874603,-0.023856702041626,0.999000012874603,,,0.000265999107386023,0.000149324768309046,9.52105695018831e-005,,20,-10.8087359428406,-18.5325489044189,-23.856702041626,
,5978392.84,4417,5.00005006790161,-2700.67469482422,179.975601196289,-0.0105811621189117,0.999000012874603,-0.018294894695282,0.999000012874603,-0.0234789328575134,0.999000012874603,,,0.00028470697785165,0.000120419137928404,0.000214439010235345,,20,-10.5811621189117,-18.294894695282,-23.4789328575134,
,5978435.42,4417,5.00019979476929,-2550.57797851563,179.975601196289,-0.0102019042015076,0.999000012874603,-0.0180443722724915,0.999000012874603,-0.0231426028251648,0.999000012874603,,,0.000231816753834417,0.000136339258937395,0.000196563240094384,,20,-10.2019042015076,-18.0443722724915,-23.1426028251648,
,5978477.64,4417,5.00005006790161,-2400.65853271484,179.975601196289,-0.00989915308952332,0.999000012874603,-0.0178331251144409,0.999000012874603,-0.0228005123138428,0.999000012874603,,,0.000186700481413353,0.000113956361162627,0.000197024247486462,,20,-9.89915308952332,-17.8331251144409,-22.8005123138428,
,5978518.02,4417,5,-2250.43083496094,179.975601196289,-0.00955849385261536,0.999000012874603,-0.0174738554954529,0.999000012874603,-0.0226018449783325,0.999000012874603,,,0.000173765838184409,0.000106148346219152,0.000148132134883859,,20,-9.55849385261536,-17.4738554954529,-22.6018449783325,
,5978559.98,4417,4.99985003471375,-2100.62387695313,179.975601196289,-0.00930615134239197,0.999000012874603,-0.0172104755401611,0.999000012874603,-0.0222210249900818,0.999000012874603,,,0.000285981442820268,0.000129750392911054,0.000187202796594632,,20,-9.30615134239197,-17.2104755401611,-22.2210249900818,
,5978602.42,4417,4.99990010261536,-1950.45252075195,179.975601196289,-0.0090378981590271,0.999000012874603,-0.017005891418457,0.999000012874603,-0.0219904714584351,0.999000012874603,,,0.000219463375631006,8.03670142429896e-005,0.000128117434330772,,20,-9.0378981590271,-17.005891418457,-21.9904714584351,
,5978643.83,4417,5.00009989738464,-1800.55942382813,179.975601196289,-0.00852513279914856,0.999000012874603,-0.0167218061447144,0.999000012874603,-0.0216296865463257,0.999000012874603,,,0.000160620203534603,0.000134688045183245,0.00020886140851542,,20,-8.52513279914856,-16.7218061447144,-21.6296865463257,
,5978683.61,4417,4.99989986419678,-1650.55935668945,179.975601196289,-0.00837919363975525,0.999000012874603,-0.0164521818161011,0.999000012874603,-0.0213288303375244,0.999000012874603,,,0.000239765112129327,0.000120980025913674,0.000180949380273752,,20,-8.37919363975525,-16.4521818161011,-21.3288303375244,
,5978726.70,4417,5.00014996528625,-1500.75814819336,179.975601196289,-0.00805565366744995,0.999000012874603,-0.0161536115169525,0.999000012874603,-0.0209626714706421,0.999000012874603,,,0.000230796807617107,0.000106288775639353,0.000212469267147112,,20,-8.05565366744995,-16.1536115169525,-20.9626714706421,
,5978768.39,4417,5.00005006790161,-1350.8512512207,179.975601196289,-0.00767786567211151,0.999000012874603,-0.015953072309494,0.999000012874603,-0.0206801390647888,0.999000012874603,,,0.0001795253647621,7.79125724699226e-005,0.000204952910664352,,20,-7.67786567211151,-15.953072309494,-20.6801390647888,
,5978810.58,4417,5.0002498626709,-1200.63275756836,179.975601196289,-0.00725652763843536,0.999000012874603,-0.0156404116630554,0.999000012874603,-0.0203638494491577,0.999000012874603,,,0.000233744112112341,0.000101550428675183,0.00022754360235246,,20,-7.25652763843536,-15.6404116630554,-20.3638494491577,
,5978852.11,4417,4.99970006942749,-1050.76259765625,179.975601196289,-0.00700644528865814,0.999000012874603,-0.0154030074596405,0.999000012874603,-0.0201274768829346,0.999000012874603,,,0.00021861735945783,0.000115246918406096,0.00015825379701982,,20,-7.00644528865814,-15.4030074596405,-20.1274768829346,
,5978892.91,4417,5,-900.676348876953,179.975601196289,-0.0067158421754837,0.999000012874603,-0.0150475047588348,0.999000012874603,-0.0197964227676392,0.999000012874603,,,0.000192504081101718,9.83674600357285e-005,0.000147567328188564,,20,-6.7158421754837,-15.0475047588348,-19.7964227676392,
,5978934.58,4417,4.99985003471375,-750.749862670898,179.975601196289,-0.00635256683826447,0.999000012874603,-0.0148174001693726,0.999000012874603,-0.0194367127418518,0.999000012874603,,,0.000146788492207811,8.37619341268408e-005,0.000154442754896782,,20,-6.35256683826447,-14.8174001693726,-19.4367127418518,
,5978973.59,4417,4.99979996681213,-600.624490356445,179.975601196289,-0.00610022709369659,0.999000012874603,-0.0145153803348541,0.999000012874603,-0.0191100033760071,0.999000012874603,,,0.000278055294367005,9.29579228161501e-005,0.000197527652465985,,20,-6.10022709369659,-14.5153803348541,-19.1100033760071,
,5979012.52,4417,5.00009989738464,-450.768157958984,179.975601196289,-0.00574125366210938,0.999000012874603,-0.0142407956123352,0.999000012874603,-0.0186938545227051,0.999000012874603,,,0.000215495446135418,8.91212626714692e-005,0.00025913897030724,,20,-5.74125366210937,-14.2407956123352,-18.6938545227051,
,5979051.36,4417,5,-300.614044189453,179.975601196289,-0.00547857308387756,0.999000012874603,-0.013999122095108,0.999000012874603,-0.018507753944397,0.999000012874603,,,0.00021192237324975,6.97436514374366e-005,0.000161574449979656,,20,-5.47857308387756,-13.999122095108,-18.507753944397,
,5979093.00,4417,5,-150.70595703125,179.975601196289,-0.00509500977993011,0.999000012874603,-0.013737849187851,0.999000012874603,-0.0181898477554321,0.999000012874603,,,0.000250379931334529,8.46891098005685e-005,0.000144117186373345,,20,-5.09500977993011,-13.737849187851,-18.1898477554321,
,5979135.41,4417,5.00014996528625,-0.533456048369408,179.975601196289,-0.00472637677192688,0.999000012874603,-0.013439058303833,0.999000012874603,-0.017881688117981,0.999000012874603,,,0.000202748438944167,8.88148691836994e-005,0.000178373795429291,,20,-4.72637677192688,-13.439058303833,-17.881688117981,