File: data/r82.dat
[Header]
TITLE, default name
FILEOPENTIME,5981732.06,5/26/2021,6:58 PM
BYAPP, Resistivity, 2.1, 1.0
INFO, APPNAME, PPMS MultiVu Application, 1.5.11
INFO, , Sample1 Name
INFO, 1, Sample1 Cross Section
INFO, 1, Sample1 Length
INFO, Ohm-m, Sample1 Units
INFO, , Sample2 Name
INFO, 1, Sample2 Cross Section
INFO, 1, Sample2 Length
INFO, Ohm-m, Sample2 Units
INFO, , Sample3 Name
INFO, 1, Sample3 Cross Section
INFO, 1, Sample3 Length
INFO, Ohm-m, Sample3 Units
INFO, , Sample4 Name
INFO, 1, Sample4 Cross Section
INFO, 1, Sample4 Length
INFO, Ohm-m, Sample4 Units
FIELDGROUP, Resistivity,2,3,4,5,6,7,8,9,10,11,12,13,14,15,16,17,18,19,20,21,22,23,24,25,26,27,28,29,30,31,32,33,34,35,36,37,38,39,40,41
STARTUPGROUP, Resistivity
STARTUPAXIS, X, 2, LINEAR, AUTO
STARTUPAXIS, Y1, 7, LINEAR, AUTO
STARTUPAXIS, Y2, 9, LINEAR, AUTO
STARTUPAXIS, Y3, 11, LINEAR, AUTO
PLOT_APPEARANCE, ALL, HORZ_GRID_ON, VERT_GRID_ON, MARKERS_AND_LINES, ALL_LINES
DATATYPE, TIME, 2
DATATYPE, COMMENT, 1
[Data]
Comment,Time Stamp (sec),Status (code),Temperature (K),Magnetic Field (Oe),Sample Position (deg),Bridge 1 Resistivity (Ohm-m),Bridge 1 Excitation (uA),Bridge 2 Resistivity (Ohm-m),Bridge 2 Excitation (uA),Bridge 3 Resistivity (Ohm-m),Bridge 3 Excitation (uA),Bridge 4 Resistivity (Ohm-m),Bridge 4 Excitation (uA),Bridge 1 Std. Dev. (Ohm-m),Bridge 2 Std. Dev. (Ohm-m),Bridge 3 Std. Dev. (Ohm-m),Bridge 4 Std. Dev. (Ohm-m),Number of Readings,Bridge 1 Resistance (Ohms),Bridge 2 Resistance (Ohms),Bridge 3 Resistance (Ohms),Bridge 4 Resistance (Ohms),Signal 1 Vin (V),Signal 2 Vin (V),Digital Inputs (code),Drive 1 Iout (mA),Drive 1 Ipower (watts),Drive 2 Iout (mA),Drive 2 Ipower (watts),Pressure (),Map 20 (),Map 21 (),Map 22 (),Map 23 (),Map 24 (),Map 25 (),Map 26 (),Map 27 (),Map 28 (),Map 29 ()
,5982010.11,4417,5,-0.482869803905487,179.975601196289,-0.00477552492618561,0.999000012874603,-0.0135193056106567,0.999000012874603,-0.0178666037559509,0.999000012874603,,,0.00022452425183255,0.000105358053920126,0.000131683822654521,,20,-4.77552492618561,-13.5193056106567,-17.8666037559509,
,5982036.66,4417,4.99990010261536,49.6689056396484,179.975601196289,-0.00460645310878754,0.999000012874603,-0.0134117276191711,0.999000012874603,-0.0177945515632629,0.999000012874603,,,0.000158772721414604,0.000106832846831599,0.000165902600403349,,20,-4.60645310878754,-13.4117276191711,-17.7945515632629,
,5982063.78,4417,4.99974989891052,99.3366630554199,179.975601196289,-0.00453541114330292,0.999000012874603,-0.0133739149570465,0.999000012874603,-0.0176115997314453,0.999000012874603,,,0.000206715857559327,0.000110228495403049,0.000173034254377166,,20,-4.53541114330292,-13.3739149570465,-17.6115997314453,
,5982090.70,4417,5.00020003318787,149.352774810791,179.975601196289,-0.00446155915260315,0.999000012874603,-0.0132835494041443,0.999000012874603,-0.0174740977287292,0.999000012874603,,,0.000212718546141915,7.19101373862176e-005,0.00023035951944135,,20,-4.46155915260315,-13.2835494041443,-17.4740977287292,
,5982117.56,4417,4.99989986419678,199.252767181396,179.975601196289,-0.00435422422885895,0.999000012874603,-0.0131656148910522,0.999000012874603,-0.0174426801681519,0.999000012874603,,,0.000237289207847605,0.000118709558034494,0.000178323742136809,,20,-4.35422422885895,-13.1656148910522,-17.4426801681519,
,5982144.61,4417,4.99955010414124,249.421789550781,179.975601196289,-0.00414208532571793,0.999000012874603,-0.0130636995315552,0.999000012874603,-0.0172975353240967,0.999000012874603,,,0.000181292488403703,0.000110778060416723,0.000150400226061144,,20,-4.14208532571793,-13.0636995315552,-17.2975353240967,
,5982172.67,4417,4.99994993209839,299.329827880859,179.975601196289,-0.00399446077346802,0.999000012874603,-0.0129525353431702,0.999000012874603,-0.0172003628730774,0.999000012874603,,,0.000121837504464972,9.04059542214327e-005,0.000147875819719974,,20,-3.99446077346802,-12.9525353431702,-17.2003628730774,
,5982200.88,4417,4.99979996681213,349.678221130371,179.975601196289,-0.00408983352184296,0.999000012874603,-0.0129183021068573,0.999000012874603,-0.0170315606117249,0.999000012874603,,,0.000254253708992712,9.88469894867608e-005,0.000210803162182228,,20,-4.08983352184296,-12.9183021068573,-17.0315606117249,
,5982226.73,4417,4.99994993209839,399.270083618164,179.975601196289,-0.00382945603132248,0.999000012874603,-0.012839789390564,0.999000012874603,-0.0168695085525513,0.999000012874603,,,0.000169605928775343,0.000125843309731457,0.00017062989323682,,20,-3.82945603132248,-12.839789390564,-16.8695085525513,
,5982253.48,4417,5.00020003318787,449.44140625,179.975601196289,-0.00381933296918869,0.999000012874603,-0.0126585303783417,0.999000012874603,-0.0167620710372925,0.999000012874603,,,0.000263261024944619,0.000119639064575413,0.000208895293232292,,20,-3.81933296918869,-12.6585303783417,-16.7620710372925,
,5982281.56,4417,4.99989986419678,499.615034484863,179.975601196289,-0.00366803233623505,0.999000012874603,-0.0125574627876282,0.999000012874603,-0.0167514636993408,0.999000012874603,,,0.000204134952030869,0.000128205786473225,0.000235465752204356,,20,-3.66803233623505,-12.5574627876282,-16.7514636993408,
,5982309.50,4417,4.99979996681213,549.68401184082,179.975601196289,-0.0035562114238739,0.999000012874603,-0.0124676049232483,0.999000012874603,-0.0166250329971314,0.999000012874603,,,0.000181235801742797,9.83780149260127e-005,0.00021812954598483,,20,-3.5562114238739,-12.4676049232483,-16.6250329971313,
,5982337.08,4417,4.99979996681213,599.561038208008,179.975601196289,-0.00339565191268921,0.999000012874603,-0.0123410458564758,0.999000012874603,-0.0165205156326294,0.999000012874603,,,0.000192388780239489,8.82178277900418e-005,0.000192536763711541,,20,-3.39565191268921,-12.3410458564758,-16.5205156326294,
,5982365.55,4417,5.00014996528625,649.459878540039,179.975601196289,-0.00337015808820724,0.999000012874603,-0.0122907263278961,0.999000012874603,-0.0164452755451202,0.999000012874603,,,0.000257663655872787,0.000107050996953982,0.000171860564576217,,20,-3.37015808820725,-12.2907263278961,-16.4452755451202,
,5982393.52,4417,5.00020003318787,699.618548583984,179.975601196289,-0.00316104023456573,0.999000012874603,-0.012212441778183,0.999000012874603,-0.0163290498733521,0.999000012874603,,,0.000198749592924436,0.000100750926525674,0.000171362704772548,,20,-3.16104023456573,-12.212441778183,-16.3290498733521,
,5982420.55,4417,5.00010013580322,749.123049926758,179.975601196289,-0.00319025427103043,0.999000012874603,-0.0121452302932739,0.999000012874603,-0.0161587299346924,0.999000012874603,,,0.000238006835540959,8.27795395487028e-005,0.00012120428663838,,20,-3.19025427103043,-12.1452302932739,-16.1587299346924,
,5982448.13,4417,4.99979996681213,799.604769897461,179.975601196289,-0.00270137885808945,0.999000012874603,-0.012128275680542,0.999000012874603,-0.0155728175640106,0.999000012874603,,,0.000326212962659852,8.84945268882055e-005,0.000150069953736078,,20,-2.70137885808945,-12.128275680542,-15.5728175640106,
,5982474.47,4417,5.00014996528625,849.236904907227,179.975601196289,-0.00251670998334885,0.999000012874603,-0.0120109238624573,0.999000012874603,-0.0153756401538849,0.999000012874603,,,0.000205339665890087,9.7887303951743e-005,0.000191756183074322,,20,-2.51670998334885,-12.0109238624573,-15.3756401538849,
,5982502.17,4417,5.00020003318787,899.120812988281,179.975601196289,-0.002438955950737,0.999000012874603,-0.011933938407898,0.999000012874603,-0.0153462051868439,0.999000012874603,,,0.00025480964480504,0.000111809882609721,0.000189835458365555,,20,-2.438955950737,-11.933938407898,-15.3462051868439,
,5982528.94,4417,5.00014996528625,949.199005126953,179.975601196289,-0.00228308733701706,0.999000012874603,-0.0117573599338531,0.999000012874603,-0.0152559423446655,0.999000012874603,,,0.000206839919910215,0.000145416871599736,0.00019634113137441,,20,-2.28308733701706,-11.7573599338531,-15.2559423446655,
,5982555.83,4417,5.0002498626709,999.671536254883,179.975601196289,-0.00203951087594032,0.999000012874603,-0.0117437059879303,0.999000012874603,-0.0151103312969208,0.999000012874603,,,0.000111341215353934,0.000102744331738581,0.000169961879044458,,20,-2.03951087594032,-11.7437059879303,-15.1103312969208,
,5982581.38,4417,4.99969983100891,1049.31167602539,179.975601196289,-0.00200145168304443,0.999000012874603,-0.0115794455528259,0.999000012874603,-0.0149721151351929,0.999000012874603,,,0.000105507004795848,0.000117709319415448,0.000153972760355532,,20,-2.00145168304443,-11.5794455528259,-14.9721151351929,
,5982607.14,4417,5.00009989738464,1099.16682739258,179.975601196289,-0.00201558538675308,0.999000012874603,-0.0115253935337067,0.999000012874603,-0.0149149118423462,0.999000012874603,,,0.000263916772703189,9.65589733411905e-005,0.000201791040077941,,20,-2.01558538675308,-11.5253935337067,-14.9149118423462,
,5982633.09,4417,5,1149.25538330078,179.975601196289,-0.00188641761541367,0.999000012874603,-0.0114225003242493,0.999000012874603,-0.0148791501045227,0.999000012874603,,,0.000211338265105402,9.71547501766559e-005,0.000157567669839876,,20,-1.88641761541367,-11.4225003242493,-14.8791501045227,
,5982660.33,4417,4.99994993209839,1199.13242797852,179.975601196289,-0.00177917622923851,0.999000012874603,-0.0113437165737152,0.999000012874603,-0.0146932203292847,0.999000012874603,,,0.000258617170372074,0.000114416862883323,0.000220867691441606,,20,-1.77917622923851,-11.3437165737152,-14.6932203292847,
,5982687.17,4417,5.00020003318787,1249.59460449219,179.975601196289,-0.00163984869718552,0.999000012874603,-0.0112275589942932,0.999000012874603,-0.0145673283576965,0.999000012874603,,,0.000173997418912592,9.55530081172442e-005,0.000172852174126818,,20,-1.63984869718552,-11.2275589942932,-14.5673283576965,
,5982716.56,4417,5.00020003318787,1299.46699829102,179.975601196289,-0.00160420514941216,0.999000012874603,-0.0111343355178833,0.999000012874603,-0.0144367961406708,0.999000012874603,,,0.000251626561500077,0.000110382966460801,0.000228003205841763,,20,-1.60420514941216,-11.1343355178833,-14.4367961406708,
,5982745.56,4417,5.00010013580322,1349.36121826172,179.975601196289,-0.00144846153259277,0.999000012874603,-0.0110138556003571,0.999000012874603,-0.0144689876556397,0.999000012874603,,,0.000236238870318868,0.000125003952234351,0.00016169241264007,,20,-1.44846153259277,-11.0138556003571,-14.4689876556396,
,5982772.72,4417,5.00020003318787,1399.53599853516,179.975601196289,-0.00135842316150665,0.999000012874603,-0.0109729077339172,0.999000012874603,-0.0143492458820343,0.999000012874603,,,0.000163189292071973,0.000119083964165064,0.000121497284045184,,20,-1.35842316150665,-10.9729077339172,-14.3492458820343,
,5982799.63,4417,4.99989986419678,1449.25895385742,179.975601196289,-0.00119426643252373,0.999000012874603,-0.0108754066467285,0.999000012874603,-0.0142524132728577,0.999000012874603,,,8.23281889294019e-005,0.000107051263934365,0.000124043089066087,,20,-1.19426643252373,-10.8754066467285,-14.2524132728577,
,5982826.70,4417,5.0002498626709,1499.62119140625,179.975601196289,-0.00120761602520943,0.999000012874603,-0.0107731531620026,0.999000012874603,-0.014176859998703,0.999000012874603,,,0.000154751862288883,9.57961911924639e-005,0.000102205889430312,,20,-1.20761602520943,-10.7731531620026,-14.176859998703,
,5982852.86,4417,5.00019979476929,1475.3948425293,179.975601196289,-0.00135619278550148,0.999000012874603,-0.0108160263538361,0.999000012874603,-0.0141795337677002,0.999000012874603,,,0.000266705071370139,8.50765947598919e-005,0.000147805517969878,,20,-1.35619278550148,-10.8160263538361,-14.1795337677002,
,5982880.03,4417,5.00020003318787,1425.76731567383,179.975601196289,-0.00134893580079079,0.999000012874603,-0.0108978583812714,0.999000012874603,-0.0141616776943207,0.999000012874603,,,0.000231212888318108,0.000120515070207586,0.000218479329587305,,20,-1.34893580079079,-10.8978583812714,-14.1616776943207,
,5982906.80,4417,5,1375.5879699707,179.975601196289,-0.001419213783741,0.999000012874603,-0.0111037271022797,0.999000012874603,-0.0143153151512146,0.999000012874603,,,0.000237641986035236,0.00011197286806521,0.000197512519802275,,20,-1.419213783741,-11.1037271022797,-14.3153151512146,
,5982934.17,4417,5,1325.80986328125,179.975601196289,-0.00146591804623604,0.999000012874603,-0.0110832304954529,0.999000012874603,-0.0144302174568176,0.999000012874603,,,0.000216313623398085,0.000122046749794846,0.000175499289718063,,20,-1.46591804623604,-11.0832304954529,-14.4302174568176,
,5982962.00,4417,5.00005006790161,1275.32349853516,179.975601196289,-0.00157362053990364,0.999000012874603,-0.0111731734275818,0.999000012874603,-0.0145020190238953,0.999000012874603,,,0.000202784381436534,0.000106166668579416,0.000246615585243638,,20,-1.57362053990364,-11.1731734275818,-14.5020190238953,
,5982988.89,4417,4.99989986419678,1225.43615112305,179.975601196289,-0.00175819660425186,0.999000012874603,-0.0112149811267853,0.999000012874603,-0.0146807363510132,0.999000012874603,,,0.000273757363675799,8.04284156518485e-005,0.00020842010744518,,20,-1.75819660425186,-11.2149811267853,-14.6807363510132,
,5983015.64,4417,5,1175.60283813477,179.975601196289,-0.00182959780693054,0.999000012874603,-0.0114131416320801,0.999000012874603,-0.0147477483272553,0.999000012874603,,,0.000203330003006755,9.58080183542042e-005,0.000160635952318522,,20,-1.82959780693054,-11.4131416320801,-14.7477483272552,
,5983044.61,4417,5.0002498626709,1125.46257324219,179.975601196289,-0.00192811994552612,0.999000012874603,-0.0114527156352997,0.999000012874603,-0.0148732064723969,0.999000012874603,,,0.000243015589946147,0.00011925981437967,0.000140234868270708,,20,-1.92811994552612,-11.4527156352997,-14.8732064723969,
,5983071.59,4417,4.99995017051697,1075.33723754883,179.975601196289,-0.00194085579514503,0.999000012874603,-0.0115422002792358,0.999000012874603,-0.0150382426261902,0.999000012874603,,,0.000150124577808077,9.70244436759985e-005,0.000141910195619649,,20,-1.94085579514503,-11.5422002792358,-15.0382426261902,
,5983098.61,4417,5.00004982948303,1025.43493041992,179.975601196289,-0.00216391191482544,0.999000012874603,-0.0116377823829651,0.999000012874603,-0.0149452386856079,0.999000012874603,,,0.000242406662000939,8.32592822789616e-005,0.00021481366347983,,20,-2.16391191482544,-11.6377823829651,-14.9452386856079,
,5983126.47,4417,4.99944996833801,975.516561889648,179.975601196289,-0.00226487167477608,0.999000012874603,-0.0117154595375061,0.999000012874603,-0.0151938325881958,0.999000012874603,,,0.000267462598035563,0.000113651177023794,0.000197090558916928,,20,-2.26487167477608,-11.7154595375061,-15.1938325881958,
,5983155.33,4417,5.00029993057251,925.473999023438,179.975601196289,-0.0024342596411705,0.999000012874603,-0.0118769222736359,0.999000012874603,-0.0152568515300751,0.999000012874603,,,0.00021439007956237,0.000101649864662718,0.000128613008891765,,20,-2.4342596411705,-11.8769222736359,-15.2568515300751,
,5983182.16,4417,4.99990010261536,875.897052001953,179.975601196289,-0.00248204460144043,0.999000012874603,-0.011977192735672,0.999000012874603,-0.0153466913223267,0.999000012874603,,,0.000226988951310495,8.2227743968758e-005,0.000213646393707359,,20,-2.48204460144043,-11.977192735672,-15.3466913223267,
,5983209.31,4417,4.99970006942749,825.063528442383,179.975601196289,-0.00255252900123596,0.999000012874603,-0.0119736590385437,0.999000012874603,-0.0154702779769897,0.999000012874603,,,0.000167125381576522,8.085270539105e-005,0.000168885384809519,,20,-2.55252900123596,-11.9736590385437,-15.4702779769897,
,5983236.17,4417,4.99974989891052,775.776306152344,179.975601196289,-0.0026433850646019,0.999000012874603,-0.0120828320503235,0.999000012874603,-0.0156068678855896,0.999000012874603,,,0.000199884932784206,8.41664032261505e-005,0.000178570653862587,,20,-2.6433850646019,-12.0828320503235,-15.6068678855896,
,5983265.17,4417,4.99989986419678,725.876306152344,179.975601196289,-0.00270039533376694,0.999000012874603,-0.0121597050666809,0.999000012874603,-0.0156642601013184,0.999000012874603,,,0.000180149380446544,0.000101281907026024,0.000146323380612905,,20,-2.70039533376694,-12.1597050666809,-15.6642601013184,
,5983292.17,4417,4.99989986419678,675.801556396484,179.975601196289,-0.00292262609004974,0.999000012874603,-0.0122735035419464,0.999000012874603,-0.0156761162757873,0.999000012874603,,,0.000294700052996502,0.000132586963025957,0.000205839887356735,,20,-2.92262609004974,-12.2735035419464,-15.6761162757874,
,5983318.05,4417,4.99989986419678,625.409506225586,179.975601196289,-0.00293110021352768,0.999000012874603,-0.0123833205223083,0.999000012874603,-0.0158813913822174,0.999000012874603,,,0.000135829860056406,0.000105134811392494,0.000170700851378058,,20,-2.93110021352768,-12.3833205223083,-15.8813913822174,
,5983344.34,4417,4.99994993209839,575.699197387695,179.975601196289,-0.00307546873092651,0.999000012874603,-0.0124153072357178,0.999000012874603,-0.0159376301288605,0.999000012874603,,,0.000201229352562238,9.41714362241081e-005,0.000202791950424806,,20,-3.07546873092651,-12.4153072357178,-15.9376301288605,
,5983370.09,4417,5.00005006790161,525.804962158203,179.975601196289,-0.00317616161108017,0.999000012874603,-0.0125375104904175,0.999000012874603,-0.0160946471691132,0.999000012874603,,,0.000182898759681302,9.801972669432e-005,0.000169192340198528,,20,-3.17616161108017,-12.5375104904175,-16.0946471691132,
,5983396.03,4417,5,475.723310852051,179.975601196289,-0.00330251659154892,0.999000012874603,-0.0126826798915863,0.999000012874603,-0.0161590181827545,0.999000012874603,,,0.000213260896106046,9.76523359608354e-005,0.000146524120298816,,20,-3.30251659154892,-12.6826798915863,-16.1590181827545,
,5983422.77,4417,5.00014996528625,425.534753417969,179.975601196289,-0.0034114478468895,0.999000012874603,-0.012689890909195,0.999000012874603,-0.0162757119655609,0.999000012874603,,,0.000219710294681708,9.17525413197808e-005,0.000154538014265069,,20,-3.4114478468895,-12.6898909091949,-16.2757119655609,
,5983450.39,4417,4.99985003471375,375.691105651855,179.975601196289,-0.00353463584184647,0.999000012874603,-0.0127744989871979,0.999000012874603,-0.0164511357307434,0.999000012874603,,,0.000181993796117176,6.65874714370553e-005,0.000150142462287731,,20,-3.53463584184647,-12.7744989871979,-16.4511357307434,
,5983476.41,4417,5.00020003318787,325.785354614258,179.975601196289,-0.00352734409570694,0.999000012874603,-0.0128966009140015,0.999000012874603,-0.0165106680870056,0.999000012874603,,,0.000174185641825818,7.89451108709343e-005,0.000162999172477533,,20,-3.52734409570694,-12.8966009140015,-16.5106680870056,
,5983504.55,4417,4.99949979782104,275.678405761719,179.975601196289,-0.00367404615879059,0.999000012874603,-0.0129455018520355,0.999000012874603,-0.0166211714744568,0.999000012874603,,,0.000126493141293833,8.85158280914875e-005,0.000224142959660725,,20,-3.67404615879059,-12.9455018520355,-16.6211714744568,
,5983531.14,4417,5.0002498626709,225.829000091553,179.975601196289,-0.00373616855144501,0.999000012874603,-0.0130820514678955,0.999000012874603,-0.0167618953704834,0.999000012874603,,,0.000145928434600503,0.000113647104622563,9.08617164083468e-005,,20,-3.73616855144501,-13.0820514678955,-16.7618953704834,
,5983559.00,4417,5.00019979476929,175.628939819336,179.975601196289,-0.00400679746866226,0.999000012874603,-0.0131337951183319,0.999000012874603,-0.0167925943374634,0.999000012874603,,,0.000269926390862197,8.57045017234147e-005,0.000212003564903252,,20,-4.00679746866226,-13.1337951183319,-16.7925943374634,
,5983584.45,4417,4.99965000152588,125.770333862305,179.975601196289,-0.00395801091194153,0.999000012874603,-0.0132760493755341,0.999000012874603,-0.0168703087806702,0.999000012874603,,,0.000152656278833395,0.000110221319279849,0.000220703600426021,,20,-3.95801091194153,-13.2760493755341,-16.8703087806702,
,5983612.53,4417,4.99965000152588,75.3495319366455,179.975601196289,-0.00421282850503922,0.999000012874603,-0.0133750953197479,0.999000012874603,-0.0170933811187744,0.999000012874603,,,0.000259380802508547,0.00010290528981695,0.000173727320283749,,20,-4.21282850503921,-13.3750953197479,-17.0933811187744,
,5983639.17,4417,4.99985003471375,25.5139201164246,179.975601196289,-0.00422676995992661,0.999000012874603,-0.0134652378082275,0.999000012874603,-0.0171717782974243,0.999000012874603,,,0.000188961825603032,0.000121387868867525,0.000205183697930347,,20,-4.2267699599266,-13.4652378082275,-17.1717782974243,
,5983666.17,4417,5.00010013580322,-24.52978515625,179.975601196289,-0.00439922497272491,0.999000012874603,-0.013499709892273,0.999000012874603,-0.0171891576766968,0.999000012874603,,,0.000230224380832799,8.90925975442257e-005,0.000169191432500447,,20,-4.39922497272491,-13.499709892273,-17.1891576766968,
,5983693.11,4417,4.99979996681213,-74.2630752563477,179.975601196289,-0.00447695381641388,0.999000012874603,-0.0136038895606995,0.999000012874603,-0.0174417285919189,0.999000012874603,,,0.000116750499622839,0.00011301856622464,0.000138450131260964,,20,-4.47695381641388,-13.6038895606995,-17.4417285919189,
,5983720.89,4417,5.00014996528625,-124.643642044067,179.975601196289,-0.00462012257575989,0.999000012874603,-0.0137078629493713,0.999000012874603,-0.0174488628387451,0.999000012874603,,,0.000256658092537605,0.00012834571552393,0.000161842497665709,,20,-4.62012257575989,-13.7078629493713,-17.4488628387451,
,5983747.59,4417,4.99990010261536,-174.19987411499,179.975601196289,-0.00481044325828552,0.999000012874603,-0.0138101373672485,0.999000012874603,-0.0176299199104309,0.999000012874603,,,0.000226649480998926,7.03692776000038e-005,0.00019989356877592,,20,-4.81044325828552,-13.8101373672485,-17.6299199104309,
,5983775.53,4417,5.00014996528625,-224.491920471191,179.975601196289,-0.00484179708957672,0.999000012874603,-0.0139121062278748,0.999000012874603,-0.0176752696990967,0.999000012874603,,,0.000218535663500896,8.30672094262912e-005,0.000223005129082889,,20,-4.84179708957672,-13.9121062278748,-17.6752696990967,
,5983803.86,4417,5.00014996528625,-274.356272888184,179.975601196289,-0.00492977809906006,0.999000012874603,-0.0139636629104614,0.999000012874603,-0.0178354772567749,0.999000012874603,,,0.000129565492001451,8.07434517719619e-005,0.00022579743040819,,20,-4.92977809906006,-13.9636629104614,-17.8354772567749,
,5983831.97,4417,4.99970006942749,-324.545986938477,179.975601196289,-0.00497272171974182,0.999000012874603,-0.0140713878154755,0.999000012874603,-0.0179512598991394,0.999000012874603,,,0.000163489760266698,0.000105131199839174,0.000171560938996348,,20,-4.97272171974182,-14.0713878154755,-17.9512598991394,
,5983860.80,4417,5,-374.327571105957,179.975601196289,-0.00513070962429047,0.999000012874603,-0.014160556268692,0.999000012874603,-0.0180239841461182,0.999000012874603,,,0.000236759912794263,0.000104948379433953,0.000212813868166329,,20,-5.13070962429047,-14.160556268692,-18.0239841461182,
,5983887.56,4417,4.99960017204285,-424.195362854004,179.975601196289,-0.00524022319316864,0.999000012874603,-0.0142448634147644,0.999000012874603,-0.0181694933891296,0.999000012874603,,,0.000196560360935343,0.000125803720799027,0.000187245066638391,,20,-5.24022319316864,-14.2448634147644,-18.1694933891296,
,5983913.97,4417,4.99995017051697,-474.126400756836,179.975601196289,-0.00544568073749542,0.999000012874603,-0.0143466881275177,0.999000012874603,-0.0182916771888733,0.999000012874603,,,0.000257522868536363,0.000104915237727021,0.000175416246465944,,20,-5.44568073749542,-14.3466881275177,-18.2916771888733,
,5983940.52,4417,5.00034999847412,-524.281628417969,179.975601196289,-0.00548913614749908,0.999000012874603,-0.0144743807315826,0.999000012874603,-0.0183797337532043,0.999000012874603,,,0.000230006716738991,9.64985392675408e-005,0.000176707077433469,,20,-5.48913614749908,-14.4743807315826,-18.3797337532043,
,5983968.59,4417,5.00014996528625,-574.665646362305,179.975601196289,-0.00557911579608917,0.999000012874603,-0.0145384634017944,0.999000012874603,-0.0185123293876648,0.999000012874603,,,0.000157679693831187,9.08348718391314e-005,0.000160679028535273,,20,-5.57911579608917,-14.5384634017944,-18.5123293876648,
,5983996.66,4417,5.00010013580322,-624.232214355469,179.975601196289,-0.00564483108520508,0.999000012874603,-0.014572944688797,0.999000012874603,-0.0186241790771484,0.999000012874603,,,0.000205503789322862,0.000107691579088596,0.000203216553717764,,20,-5.64483108520508,-14.572944688797,-18.6241790771484,
,5984024.34,4417,4.99979996681213,-674.108084106445,179.975601196289,-0.00574095981121063,0.999000012874603,-0.0147353432655334,0.999000012874603,-0.0187773860931396,0.999000012874603,,,0.000218787622954558,8.65269530870835e-005,0.000175973804156276,,20,-5.74095981121063,-14.7353432655334,-18.7773860931396,
,5984051.23,4417,4.99979996681213,-724.563375854492,179.975601196289,-0.00586760487556458,0.999000012874603,-0.0148047784328461,0.999000012874603,-0.0188459616661072,0.999000012874603,,,0.000204451060206879,0.000114605388765604,0.000244364174016233,,20,-5.86760487556458,-14.8047784328461,-18.8459616661072,
,5984077.28,4417,4.99990010261536,-774.654211425781,179.975601196289,-0.00597334146499634,0.999000012874603,-0.0149002262115479,0.999000012874603,-0.0190416642189026,0.999000012874603,,,0.000156895900407041,0.000102781492141007,0.000120192763750199,,20,-5.97334146499634,-14.9002262115479,-19.0416642189026,
,5984105.14,4417,5,-824.490975952148,179.975601196289,-0.00601730327606201,0.999000012874603,-0.0149357842445374,0.999000012874603,-0.0190905546188355,0.999000012874603,,,0.000229033501522607,9.42626764462136e-005,0.000168870247879433,,20,-6.01730327606201,-14.9357842445374,-19.0905546188354,
,5984132.41,4417,5.00009989738464,-874.124243164062,179.975601196289,-0.00668345313072205,0.999000012874603,-0.0150462296009064,0.999000012874603,-0.0196672965049744,0.999000012874603,,,0.000262687112309367,0.00011212225494936,0.000263110059557957,,20,-6.68345313072205,-15.0462296009064,-19.6672965049744,
,5984160.23,4417,5.00040006637573,-924.566891479492,179.975601196289,-0.00678863682746887,0.999000012874603,-0.0150757697582245,0.999000012874603,-0.0198341362953186,0.999000012874603,,,0.000261746407990327,7.39904142496903e-005,0.000161354231344216,,20,-6.78863682746887,-15.0757697582245,-19.8341362953186,
,5984188.70,4417,4.99994993209839,-974.660034179688,179.975601196289,-0.00693836228847503,0.999000012874603,-0.0152464067459106,0.999000012874603,-0.0199269506454468,0.999000012874603,,,0.000146597099324744,8.75275998300797e-005,0.000165074802320828,,20,-6.93836228847504,-15.2464067459106,-19.9269506454468,
,5984216.38,4417,5.00004982948303,-1024.5220703125,179.975601196289,-0.00703067681789398,0.999000012874603,-0.0153793551921845,0.999000012874603,-0.0201128901481628,0.999000012874603,,,0.000181895875558738,0.000101043941795193,0.000118963737116054,,20,-7.03067681789398,-15.3793551921844,-20.1128901481628,
,5984244.52,4417,4.9997501373291,-1074.10933837891,179.975601196289,-0.00710440855026245,0.999000012874603,-0.0154574799060822,0.999000012874603,-0.0200747820854187,0.999000012874603,,,0.000202305225460954,0.000111083191121519,0.000206260215015007,,20,-7.10440855026245,-15.4574799060822,-20.0747820854187,
,5984271.98,4417,4.99985003471375,-1124.60030517578,179.975601196289,-0.00722110805511474,0.999000012874603,-0.0154726979255676,0.999000012874603,-0.020247522354126,0.999000012874603,,,0.000203264764478925,0.000109479143223917,0.000151297451861105,,20,-7.22110805511475,-15.4726979255676,-20.247522354126,
,5984300.31,4417,5,-1174.34854736328,179.975601196289,-0.00726408059597015,0.999000012874603,-0.0155944536209106,0.999000012874603,-0.0203891402244568,0.999000012874603,,,0.000153804235318667,6.99627868558198e-005,0.000166743785269516,,20,-7.26408059597015,-15.5944536209106,-20.3891402244568,
,5984327.27,4417,5.00025010108948,-1224.54055175781,179.975601196289,-0.00746438131332398,0.999000012874603,-0.0157449390888214,0.999000012874603,-0.0204124339103699,0.999000012874603,,,0.000171122625019654,8.93873796101909e-005,0.000191229136936997,,20,-7.46438131332397,-15.7449390888214,-20.4124339103699,
,5984353.84,4417,4.99984979629517,-1274.10599975586,179.975601196289,-0.00754068017005921,0.999000012874603,-0.0157426473617554,0.999000012874603,-0.0205684688568115,0.999000012874603,,,0.00027400751339971,8.50952109043567e-005,0.000173837577514693,,20,-7.5406801700592,-15.7426473617554,-20.5684688568115,
,5984380.59,4417,4.99989986419678,-1324.61188354492,179.975601196289,-0.00771614940166473,0.999000012874603,-0.0158996864318848,0.999000012874603,-0.0206306644439697,0.999000012874603,,,0.000258488642083151,0.000122049626122534,0.000229231547684285,,20,-7.71614940166473,-15.8996864318848,-20.6306644439697,
,5984406.42,4417,4.9997501373291,-1374.1704284668,179.975601196289,-0.00776016700267792,0.999000012874603,-0.0159558304786682,0.999000012874603,-0.0207739840507507,0.999000012874603,,,0.000265232442897049,0.000107797386919768,0.000159105369243747,,20,-7.76016700267792,-15.9558304786682,-20.7739840507507,
,5984433.42,4417,5.00014996528625,-1424.59003295898,179.975601196289,-0.00781835927963257,0.999000012874603,-0.016125714969635,0.999000012874603,-0.0208573530197144,0.999000012874603,,,0.000237505833249966,9.42158745061461e-005,0.000180798975803594,,20,-7.81835927963257,-16.125714969635,-20.8573530197144,
,5984460.56,4417,5.00005006790161,-1474.14860839844,179.975601196289,-0.00789946632385254,0.999000012874603,-0.0161742162704468,0.999000012874603,-0.0210100176811218,0.999000012874603,,,0.000137019973247173,9.10334020506788e-005,0.000151771207799573,,20,-7.89946632385254,-16.1742162704468,-21.0100176811218,
,5984486.44,4417,5.00020003318787,-1499.53833618164,179.975601196289,-0.00792085661888122,0.999000012874603,-0.0162645517349243,0.999000012874603,-0.0211144864082336,0.999000012874603,,,0.000200658751760304,0.000115488674833552,0.00011812849191763,,20,-7.92085661888123,-16.2645517349243,-21.1144864082336,
,5984513.55,4417,5.00029993057251,-1450.85357055664,179.975601196289,-0.00788564548492432,0.999000012874603,-0.0161614483356476,0.999000012874603,-0.0210178849220276,0.999000012874603,,,0.000161091449773448,0.000102961273666783,0.000175260283547473,,20,-7.88564548492432,-16.1614483356476,-21.0178849220276,
,5984540.47,4417,5.00014996528625,-1400.73168945313,179.975601196289,-0.00779875302314758,0.999000012874603,-0.0161079758644104,0.999000012874603,-0.020775731086731,0.999000012874603,,,0.000173324079455258,0.00012083194214781,0.000229388412776738,,20,-7.79875302314758,-16.1079758644104,-20.775731086731,
,5984568.52,4417,4.99994993209839,-1350.49598999023,179.975601196289,-0.00767718381881714,0.999000012874603,-0.0159612118721008,0.999000012874603,-0.020751037311554,0.999000012874603,,,0.000194468159696431,7.58115196653894e-005,0.000198237986506056,,20,-7.67718381881714,-15.9612118721008,-20.751037311554,
,5984594.44,4417,4.99985003471375,-1300.72248535156,179.975601196289,-0.00759200594425201,0.999000012874603,-0.0158778483390808,0.999000012874603,-0.0206779864311218,0.999000012874603,,,0.000227096493973764,0.000116496382691189,0.000151129473725936,,20,-7.59200594425201,-15.8778483390808,-20.6779864311218,
,5984621.11,4417,4.99989986419678,-1250.79598999023,179.975601196289,-0.00743210256099701,0.999000012874603,-0.0157478107452393,0.999000012874603,-0.0206169080734253,0.999000012874603,,,0.000195700958748086,0.000106485334452647,0.000141395894400505,,20,-7.43210256099701,-15.7478107452393,-20.6169080734253,
,5984646.78,4417,5,-1200.32924194336,179.975601196289,-0.00737041187286377,0.999000012874603,-0.0156313279628754,0.999000012874603,-0.02032669506073,0.999000012874603,,,0.000168014986758563,0.000115460969793958,0.000221904165011228,,20,-7.37041187286377,-15.6313279628754,-20.32669506073,
,5984672.84,4417,5.00004982948303,-1150.85689086914,179.975601196289,-0.00729544725418091,0.999000012874603,-0.0155927473545074,0.999000012874603,-0.0203223021507263,0.999000012874603,,,0.000213703729757086,9.10945457203623e-005,0.000161453384493906,,20,-7.29544725418091,-15.5927473545074,-20.3223021507263,
,5984698.44,4417,4.99995017051697,-1100.38325805664,179.975601196289,-0.00720606915950775,0.999000012874603,-0.0155518638134003,0.999000012874603,-0.0202981091499329,0.999000012874603,,,0.0002452784892204,8.47680612399684e-005,7.99910598013153e-005,,20,-7.20606915950775,-15.5518638134003,-20.2981091499329,
,5984724.39,4417,4.99985003471375,-1050.78674316406,179.975601196289,-0.00701777017116547,0.999000012874603,-0.0153984169960022,0.999000012874603,-0.0200278825759888,0.999000012874603,,,0.000249619583094372,8.75467445197136e-005,0.000194151089752479,,20,-7.01777017116547,-15.3984169960022,-20.0278825759888,
,5984751.48,4417,4.9997501373291,-1000.34870605469,179.975601196289,-0.006932266497612,0.999000012874603,-0.0153028581142426,0.999000012874603,-0.0199654316902161,0.999000012874603,,,0.000145381456987086,0.000125019461546968,0.000221166916593015,,20,-6.932266497612,-15.3028581142426,-19.9654316902161,
,5984777.00,4417,4.99959993362427,-950.828115844727,179.975601196289,-0.00683753669261932,0.999000012874603,-0.0151880748748779,0.999000012874603,-0.0198601967811585,0.999000012874603,,,0.000212488176290217,9.53832618383885e-005,0.000121715819111474,,20,-6.83753669261932,-15.1880748748779,-19.8601967811584,
,5984802.89,4417,5.00030016899109,-900.352130126953,179.975601196289,-0.006652499127388,0.999000012874603,-0.015121869134903,0.999000012874603,-0.0196970438957214,0.999000012874603,,,0.00018188646578387,8.44495549997153e-005,0.000252540736769177,,20,-6.652499127388,-15.121869134903,-19.6970438957214,
,5984829.95,4417,5.00009989738464,-850.777499389648,179.975601196289,-0.00665135295391083,0.999000012874603,-0.015034955739975,0.999000012874603,-0.0196624693870544,0.999000012874603,,,0.000245721465730976,8.85002987214475e-005,0.000199274413617164,,20,-6.65135295391083,-15.034955739975,-19.6624693870544,
,5984857.73,4417,5.00005006790161,-800.517642211914,179.975601196289,-0.00648953754901886,0.999000012874603,-0.014926842880249,0.999000012874603,-0.0195151424407959,0.999000012874603,,,0.000273448985836769,7.97692325115846e-005,0.000208114033963718,,20,-6.48953754901886,-14.926842880249,-19.5151424407959,
,5984885.72,4417,4.99970006942749,-750.435995483398,179.975601196289,-0.00641835491657257,0.999000012874603,-0.014934023141861,0.999000012874603,-0.0194043007850647,0.999000012874603,,,0.000211353021193595,0.000102649669718264,0.000145962880370102,,20,-6.41835491657257,-14.934023141861,-19.4043007850647,
,5984914.42,4417,4.99985003471375,-700.360098266602,179.975601196289,-0.00630826661586762,0.999000012874603,-0.0147889889240265,0.999000012874603,-0.0192801763534546,0.999000012874603,,,0.000236296654012466,0.000115371340381261,0.00018472990981432,,20,-6.30826661586761,-14.7889889240265,-19.2801763534546,
,5984942.75,4417,4.99989986419678,-650.499203491211,179.975601196289,-0.00625302023887634,0.999000012874603,-0.0146996970653534,0.999000012874603,-0.019256334400177,0.999000012874603,,,0.000243135400762484,9.62407468273383e-005,0.00018908300959511,,20,-6.25302023887634,-14.6996970653534,-19.256334400177,
,5984969.45,4417,5.00010013580322,-600.882015991211,179.975601196289,-0.00606602928638458,0.999000012874603,-0.0146766813278198,0.999000012874603,-0.0191256889343262,0.999000012874603,,,0.000246232490789983,9.82097797356821e-005,0.000196529197673199,,20,-6.06602928638458,-14.6766813278198,-19.1256889343262,
,5984997.88,4417,5.00040006637573,-550.455477905273,179.975601196289,-0.00599119617938995,0.999000012874603,-0.0144605725765228,0.999000012874603,-0.0190967525482178,0.999000012874603,,,0.000161753180915536,0.000107682396005152,9.02198804271005e-005,,20,-5.99119617938995,-14.4605725765228,-19.0967525482178,
,5985025.55,4417,4.9997501373291,-500.350828552246,179.975601196289,-0.00578923268318176,0.999000012874603,-0.0144620051383972,0.999000012874603,-0.0189009955406189,0.999000012874603,,,0.000110499301048766,8.09514487933827e-005,0.000188088165141098,,20,-5.78923268318176,-14.4620051383972,-18.9009955406189,
,5985052.89,4417,4.99970006942749,-450.783100891113,179.975601196289,-0.00575646212100983,0.999000012874603,-0.0143613647460937,0.999000012874603,-0.0188188800811768,0.999000012874603,,,0.000125066165121034,0.000105947895168045,0.000200929107954299,,20,-5.75646212100983,-14.3613647460938,-18.8188800811768,
,5985078.48,4417,4.99979996681213,-400.827926635742,179.975601196289,-0.0056283243894577,0.999000012874603,-0.0142156580924988,0.999000012874603,-0.0185899125099182,0.999000012874603,,,0.000221307520044319,0.000113353304650487,0.000234796494497077,,20,-5.6283243894577,-14.2156580924988,-18.5899125099182,
,5985106.19,4417,5.00014996528625,-350.333525085449,179.975601196289,-0.00557867336273193,0.999000012874603,-0.0141216076374054,0.999000012874603,-0.0186168387413025,0.999000012874603,,,0.000205347031767837,5.21242966604901e-005,0.000170819517295356,,20,-5.57867336273193,-14.1216076374054,-18.6168387413025,
,5985131.70,4417,5.00014996528625,-300.884223937988,179.975601196289,-0.00542972023487091,0.999000012874603,-0.0140350050449371,0.999000012874603,-0.0184615838050842,0.999000012874603,,,0.000258187827121828,9.14752130709044e-005,0.000192589511558508,,20,-5.42972023487091,-14.0350050449371,-18.4615838050842,
,5985158.23,4417,4.99990010261536,-250.716349029541,179.975601196289,-0.00529254684448242,0.999000012874603,-0.0139928886890411,0.999000012874603,-0.0183603815078735,0.999000012874603,,,0.000152462802681381,6.34299859218879e-005,0.000196388647377169,,20,-5.29254684448242,-13.9928886890411,-18.3603815078735,
,5985186.42,4417,5.00005006790161,-200.802555084229,179.975601196289,-0.00527818653583527,0.999000012874603,-0.0138942266941071,0.999000012874603,-0.0183095871925354,0.999000012874603,,,0.000225499122414686,9.95612635640123e-005,0.000109651497419721,,20,-5.27818653583527,-13.8942266941071,-18.3095871925354,
,5985212.91,4417,4.99990010261536,-150.643881225586,179.975601196289,-0.0051336021900177,0.999000012874603,-0.0138307205677033,0.999000012874603,-0.0182779775619507,0.999000012874603,,,0.000203009149498884,0.00010671261384537,9.11504247275267e-005,,20,-5.1336021900177,-13.8307205677032,-18.2779775619507,
,5985240.42,4417,4.99970006942749,-100.854253387451,179.975601196289,-0.00502559351921082,0.999000012874603,-0.0137040194034576,0.999000012874603,-0.0180573183059692,0.999000012874603,,,0.000224870853749587,0.000102289444651874,0.000198238906981852,,20,-5.02559351921082,-13.7040194034576,-18.0573183059692,
,5985265.50,4417,4.9997501373291,-50.6840827941895,179.975601196289,-0.0048773829460144,0.999000012874603,-0.0135662184238434,0.999000012874603,-0.0179050011634827,0.999000012874603,,,0.000147989325813731,0.000117293594856204,0.000194402888630346,,20,-4.8773829460144,-13.5662184238434,-17.9050011634827,
,5985293.19,4417,5.00009989738464,-0.790986704826355,179.975601196289,-0.00487098937034607,0.999000012874603,-0.0134828116416931,0.999000012874603,-0.0178154127120972,0.999000012874603,,,0.000248682934288829,0.000113274727447398,0.000170598655469596,,20,-4.87098937034607,-13.4828116416931,-17.8154127120972,