File: data/r85.dat
[Header]
TITLE, default name
FILEOPENTIME,5994735.28,5/26/2021,10:34 PM
BYAPP, Resistivity, 2.1, 1.0
INFO, APPNAME, PPMS MultiVu Application, 1.5.11
INFO, , Sample1 Name
INFO, 1, Sample1 Cross Section
INFO, 1, Sample1 Length
INFO, Ohm-m, Sample1 Units
INFO, , Sample2 Name
INFO, 1, Sample2 Cross Section
INFO, 1, Sample2 Length
INFO, Ohm-m, Sample2 Units
INFO, , Sample3 Name
INFO, 1, Sample3 Cross Section
INFO, 1, Sample3 Length
INFO, Ohm-m, Sample3 Units
INFO, , Sample4 Name
INFO, 1, Sample4 Cross Section
INFO, 1, Sample4 Length
INFO, Ohm-m, Sample4 Units
FIELDGROUP, Resistivity,2,3,4,5,6,7,8,9,10,11,12,13,14,15,16,17,18,19,20,21,22,23,24,25,26,27,28,29,30,31,32,33,34,35,36,37,38,39,40,41
STARTUPGROUP, Resistivity
STARTUPAXIS, X, 2, LINEAR, AUTO
STARTUPAXIS, Y1, 7, LINEAR, AUTO
STARTUPAXIS, Y2, 9, LINEAR, AUTO
STARTUPAXIS, Y3, 11, LINEAR, AUTO
PLOT_APPEARANCE, ALL, HORZ_GRID_ON, VERT_GRID_ON, MARKERS_AND_LINES, ALL_LINES
DATATYPE, TIME, 2
DATATYPE, COMMENT, 1
[Data]
Comment,Time Stamp (sec),Status (code),Temperature (K),Magnetic Field (Oe),Sample Position (deg),Bridge 1 Resistivity (Ohm-m),Bridge 1 Excitation (uA),Bridge 2 Resistivity (Ohm-m),Bridge 2 Excitation (uA),Bridge 3 Resistivity (Ohm-m),Bridge 3 Excitation (uA),Bridge 4 Resistivity (Ohm-m),Bridge 4 Excitation (uA),Bridge 1 Std. Dev. (Ohm-m),Bridge 2 Std. Dev. (Ohm-m),Bridge 3 Std. Dev. (Ohm-m),Bridge 4 Std. Dev. (Ohm-m),Number of Readings,Bridge 1 Resistance (Ohms),Bridge 2 Resistance (Ohms),Bridge 3 Resistance (Ohms),Bridge 4 Resistance (Ohms),Signal 1 Vin (V),Signal 2 Vin (V),Digital Inputs (code),Drive 1 Iout (mA),Drive 1 Ipower (watts),Drive 2 Iout (mA),Drive 2 Ipower (watts),Pressure (),Map 20 (),Map 21 (),Map 22 (),Map 23 (),Map 24 (),Map 25 (),Map 26 (),Map 27 (),Map 28 (),Map 29 ()
,5994820.53,4421,5.00034999847412,-0.525408402085304,179.975601196289,-0.00505273084640503,0.999000012874603,-0.0136299090862274,0.999000012874603,-0.0178897846221924,0.999000012874603,,,0.000188685473690937,0.000122403867936488,0.000213924415698391,,20,-5.05273084640503,-13.6299090862274,-17.8897846221924,
,5994845.44,4421,5.00009989738464,29.3216933250427,179.975601196289,-0.00501771144866943,0.999000012874603,-0.0135434191703796,0.999000012874603,-0.0178400721549988,0.999000012874603,,,0.000206750680235976,0.000105893605163497,0.000223829636734008,,20,-5.01771144866943,-13.5434191703796,-17.8400721549988,
,5994870.48,4421,4.99984979629517,59.173394203186,179.975601196289,-0.00492671983242035,0.999000012874603,-0.013480880355835,0.999000012874603,-0.0177981568336487,0.999000012874603,,,0.000288365847786376,0.000103123554152186,0.00019181932026285,,20,-4.92671983242035,-13.480880355835,-17.7981568336487,
,5994896.44,4421,4.99995017051697,89.0664848327637,179.975601196289,-0.0049835303068161,0.999000012874603,-0.0134302112579346,0.999000012874603,-0.0176670140266418,0.999000012874603,,,0.000231950784230929,8.40085635642832e-005,0.000175475904381654,,20,-4.9835303068161,-13.4302112579346,-17.6670140266418,
,5994923.48,4421,5.00009989738464,118.871047592163,179.975601196289,-0.00484852550029755,0.999000012874603,-0.0133505831241608,0.999000012874603,-0.0177053002357483,0.999000012874603,,,0.000288522624890007,0.000102442214026245,0.000129064493111239,,20,-4.84852550029755,-13.3505831241608,-17.7053002357483,
,5994951.39,4421,4.99985003471375,148.419225311279,179.975601196289,-0.00473366992473602,0.999000012874603,-0.0134005396366119,0.999000012874603,-0.0175394682884216,0.999000012874603,,,0.000182452646607249,0.000115139232151514,0.000194211847875716,,20,-4.73366992473602,-13.4005396366119,-17.5394682884216,
,5994977.39,4417,4.99985003471375,178.269780731201,179.975601196289,-0.00471189363002777,0.999000012874603,-0.0132799106121063,0.999000012874603,-0.0175599074363708,0.999000012874603,,,0.000185730231387805,0.000122091503659651,0.000190666261706038,,20,-4.71189363002777,-13.2799106121063,-17.5599074363709,
,5995006.19,4417,4.99990010261536,208.468687438965,179.975601196289,-0.0046031191110611,0.999000012874603,-0.0131881561279297,0.999000012874603,-0.0175067042350769,0.999000012874603,,,0.000210451164896213,0.000114926668492962,0.00022768882104999,,20,-4.6031191110611,-13.1881561279297,-17.5067042350769,
,5995032.86,4417,5.00019979476929,238.36291809082,179.975601196289,-0.00462410826683044,0.999000012874603,-0.0132293718338013,0.999000012874603,-0.0174326730728149,0.999000012874603,,,0.000214015827389942,0.00014123132879686,0.000122692317529361,,20,-4.62410826683044,-13.2293718338013,-17.4326730728149,
,5995059.09,4417,5,267.942155456543,179.975601196289,-0.00445332238674164,0.999000012874603,-0.0130884662151337,0.999000012874603,-0.0173914322853088,0.999000012874603,,,0.00017156693428071,0.000111529660849759,0.000103190370789991,,20,-4.45332238674164,-13.0884662151337,-17.3914322853088,
,5995085.58,4417,5.00005006790161,297.786953735352,179.975601196289,-0.00443412988185883,0.999000012874603,-0.0131241767406464,0.999000012874603,-0.0172225092887878,0.999000012874603,,,0.000182556421776093,8.85843473634761e-005,0.000170145468853018,,20,-4.43412988185883,-13.1241767406464,-17.2225092887878,
,5995112.27,4417,5.00010013580322,327.890434265137,179.975601196289,-0.00435333230495453,0.999000012874603,-0.0131150082111359,0.999000012874603,-0.0172145827293396,0.999000012874603,,,0.000236474307856857,8.09149350108405e-005,0.00018058451109805,,20,-4.35333230495453,-13.1150082111359,-17.2145827293396,
,5995140.09,4417,5.00029993057251,357.71569519043,179.975601196289,-0.00437159829139709,0.999000012874603,-0.0129534212589264,0.999000012874603,-0.0170860145568848,0.999000012874603,,,0.000207908881691747,0.000116756697820683,0.000192414185541886,,20,-4.37159829139709,-12.9534212589264,-17.0860145568848,
,5995166.78,4417,4.99985003471375,387.290309143066,179.975601196289,-0.00420506837368011,0.999000012874603,-0.0129311725139618,0.999000012874603,-0.0171042531013489,0.999000012874603,,,0.000188531620443993,8.63161675588434e-005,0.000169727438436639,,20,-4.20506837368012,-12.9311725139618,-17.1042531013489,
,5995192.52,4417,4.99960017204285,417.122468566895,179.975601196289,-0.00411601244211197,0.999000012874603,-0.0129316325187683,0.999000012874603,-0.0170285451889038,0.999000012874603,,,0.000174526874312869,0.000114156531809584,0.000151800485220753,,20,-4.11601244211197,-12.9316325187683,-17.0285451889038,
,5995218.22,4417,4.99954986572266,446.979922485352,179.975601196289,-0.00409653060436249,0.999000012874603,-0.0128164605140686,0.999000012874603,-0.0170042880058289,0.999000012874603,,,0.000264751790782638,8.43593861575428e-005,0.000162925083786709,,20,-4.09653060436249,-12.8164605140686,-17.0042880058289,
,5995244.89,4417,5.00014996528625,477.181121826172,179.975601196289,-0.00397362706661224,0.999000012874603,-0.0127839085102081,0.999000012874603,-0.0169271773338318,0.999000012874603,,,0.000159977407669792,9.91054686150532e-005,0.000237237044620718,,20,-3.97362706661224,-12.7839085102081,-16.9271773338318,
,5995272.92,4417,5.00004982948303,506.751156616211,179.975601196289,-0.00397676075696945,0.999000012874603,-0.0127436603069305,0.999000012874603,-0.0167982350349426,0.999000012874603,,,0.000219228748857367,0.000116691717264209,0.000194194882999257,,20,-3.97676075696945,-12.7436603069305,-16.7982350349426,
,5995300.00,4417,4.99989986419678,536.505145263672,179.975601196289,-0.00378742752075195,0.999000012874603,-0.0126486596107483,0.999000012874603,-0.0167581344604492,0.999000012874603,,,0.000144289528077578,0.000122924928457095,0.000158855287823832,,20,-3.78742752075195,-12.6486596107483,-16.7581344604492,
,5995327.83,4417,5,566.382119750977,179.975601196289,-0.00377640058994293,0.999000012874603,-0.0125587209224701,0.999000012874603,-0.0166769457817078,0.999000012874603,,,0.00021423907585019,0.000109828953223768,0.00020259787931862,,20,-3.77640058994293,-12.5587209224701,-16.6769457817078,
,5995355.86,4417,4.99969983100891,596.238430786133,179.975601196289,-0.00386099742650986,0.999000012874603,-0.0126226935863495,0.999000012874603,-0.0165468044281006,0.999000012874603,,,0.000299365699759359,8.91657268019302e-005,0.000266559903641415,,20,-3.86099742650986,-12.6226935863495,-16.5468044281006,
,5995382.63,4417,4.99979996681213,626.157968139648,179.975601196289,-0.00367050520181656,0.999000012874603,-0.0125489855289459,0.999000012874603,-0.0166006834030151,0.999000012874603,,,0.000221008419933922,0.000101743237626415,0.000182791547168256,,20,-3.67050520181656,-12.5489855289459,-16.6006834030151,
,5995409.28,4417,5.00010013580322,656.034957885742,179.975601196289,-0.00355353101491928,0.999000012874603,-0.0124906416416168,0.999000012874603,-0.0165168437957764,0.999000012874603,,,0.000178199259760469,9.23382173511938e-005,0.000171895623627986,,20,-3.55353101491928,-12.4906416416168,-16.5168437957764,
,5995435.09,4417,4.99995017051697,685.905041503906,179.975601196289,-0.00366911467313766,0.999000012874603,-0.0123773401260376,0.999000012874603,-0.0164758685112,0.999000012874603,,,0.000251053511927485,0.000101012207948705,0.000176947282044198,,20,-3.66911467313766,-12.3773401260376,-16.4758685112,
,5995463.03,4417,4.99979996681213,715.748699951172,179.975601196289,-0.00353788378238678,0.999000012874603,-0.0123304449558258,0.999000012874603,-0.0163610655784607,0.999000012874603,,,0.000235455765586989,0.000117163117357006,0.000139805312653272,,20,-3.53788378238678,-12.3304449558258,-16.3610655784607,
,5995489.73,4417,4.99979996681213,745.521060180664,179.975601196289,-0.00342839164733887,0.999000012874603,-0.0123405915737152,0.999000012874603,-0.0163744663238525,0.999000012874603,,,0.000239176038870048,0.000106379457594804,0.000176460997105792,,20,-3.42839164733887,-12.3405915737152,-16.3744663238525,
,5995515.30,4417,4.99995017051697,775.373944091797,179.975601196289,-0.00339065943956375,0.999000012874603,-0.0123058937072754,0.999000012874603,-0.0162189793109894,0.999000012874603,,,0.000256278203056815,0.000112892374610411,0.000134884816814026,,20,-3.39065943956375,-12.3058937072754,-16.2189793109894,
,5995543.47,4417,4.99994993209839,805.237115478516,179.975601196289,-0.0030140061378479,0.999000012874603,-0.0122167346000671,0.999000012874603,-0.0156751388072968,0.999000012874603,,,0.000246971248603893,9.79407092487853e-005,0.000192170016192048,,20,-3.0140061378479,-12.2167346000671,-15.6751388072968,
,5995571.47,4417,4.99985003471375,835.215286254883,179.975601196289,-0.00292879523038864,0.999000012874603,-0.0121441670894623,0.999000012874603,-0.0155529453754425,0.999000012874603,,,0.000206433345863098,0.00012351002664962,0.000216164460945963,,20,-2.92879523038864,-12.1441670894623,-15.5529453754425,
,5995597.83,4417,5.00014996528625,865.05778503418,179.975601196289,-0.00273025062084198,0.999000012874603,-0.0120524868965149,0.999000012874603,-0.0155718545436859,0.999000012874603,,,0.000129942512984501,9.95084448974957e-005,0.000153265682057165,,20,-2.73025062084198,-12.0524868965149,-15.5718545436859,
,5995626.47,4417,4.99970006942749,894.903750610352,179.975601196289,-0.00280284147262573,0.999000012874603,-0.0120053848743439,0.999000012874603,-0.0154234097003937,0.999000012874603,,,0.000155220163565394,9.42038379348572e-005,0.000198888416090032,,20,-2.80284147262573,-12.0053848743439,-15.4234097003937,
,5995652.30,4417,5.00034999847412,924.772677612305,179.975601196289,-0.00273352230787277,0.999000012874603,-0.0119220300674438,0.999000012874603,-0.0154527222633362,0.999000012874603,,,0.000178671732783937,9.77742356262542e-005,0.000101582942691646,,20,-2.73352230787277,-11.9220300674438,-15.4527222633362,
,5995679.22,4417,4.99985003471375,954.580697631836,179.975601196289,-0.00273387137651444,0.999000012874603,-0.0119476624488831,0.999000012874603,-0.0153937252998352,0.999000012874603,,,0.000213231262363262,0.000140175251022288,0.000163788350795663,,20,-2.73387137651443,-11.9476624488831,-15.3937252998352,
,5995705.72,4417,5.00020003318787,984.436999511719,179.975601196289,-0.00256520700454712,0.999000012874603,-0.0118754598140717,0.999000012874603,-0.0153067188739777,0.999000012874603,,,0.000158483652331339,0.000109936036515684,0.000206660900296473,,20,-2.56520700454712,-11.8754598140717,-15.3067188739777,
,5995730.16,4417,5.00009989738464,999.38180847168,179.975601196289,-0.00246183376312256,0.999000012874603,-0.0119163919448853,0.999000012874603,-0.0153089397907257,0.999000012874603,,,0.000129071118085455,0.000117404743666532,0.000156145327513583,,20,-2.46183376312256,-11.9163919448853,-15.3089397907257,
,5995757.11,4417,4.99990010261536,970.709692382812,179.975601196289,-0.00257137120962143,0.999000012874603,-0.0119520879745483,0.999000012874603,-0.0152438555240631,0.999000012874603,,,0.00013840774123109,0.000141214114670535,0.000181092000244919,,20,-2.57137120962143,-11.9520879745483,-15.2438555240631,
,5995783.52,4417,4.99994993209839,940.534921264648,179.975601196289,-0.00260832204818726,0.999000012874603,-0.0120143408298492,0.999000012874603,-0.0153210990428925,0.999000012874603,,,0.000243732451220667,8.09331755147348e-005,0.00023673987172296,,20,-2.60832204818726,-12.0143408298492,-15.3210990428925,
,5995809.77,4417,4.99994993209839,910.482046508789,179.975601196289,-0.00279771214723587,0.999000012874603,-0.0120284150123596,0.999000012874603,-0.0153596795558929,0.999000012874603,,,0.000274595714309144,0.000109345129592364,0.000186352555315933,,20,-2.79771214723587,-12.0284150123596,-15.3596795558929,
,5995836.73,4417,5.00009989738464,880.325662231445,179.975601196289,-0.00273526705503464,0.999000012874603,-0.0119914633274078,0.999000012874603,-0.0154874339580536,0.999000012874603,,,0.000148969060718538,0.000119132175941621,0.000159499116698692,,20,-2.73526705503464,-11.9914633274078,-15.4874339580536,
,5995863.31,4417,4.99970006942749,850.154351806641,179.975601196289,-0.00272580586671829,0.999000012874603,-0.0120894441127777,0.999000012874603,-0.0155128132820129,0.999000012874603,,,0.000149574356947596,0.00013718065631415,0.00021585741469762,,20,-2.72580586671829,-12.0894441127777,-15.5128132820129,
,5995889.33,4417,4.99979996681213,820.17502746582,179.975601196289,-0.00286969141960144,0.999000012874603,-0.0121297359466553,0.999000012874603,-0.0155731555461884,0.999000012874603,,,0.000219571193652883,9.47010888172265e-005,0.000201527339827923,,20,-2.86969141960144,-12.1297359466553,-15.5731555461884,
,5995914.83,4417,5.00019979476929,790.301486206055,179.975601196289,-0.00291899440288544,0.999000012874603,-0.0121904876708984,0.999000012874603,-0.0157166189670563,0.999000012874603,,,0.000161051878396604,8.8843251597761e-005,0.000172943806595388,,20,-2.91899440288544,-12.1904876708984,-15.7166189670563,
,5995940.66,4417,5.0002498626709,759.882992553711,179.975601196289,-0.00306118171215057,0.999000012874603,-0.0122247689723969,0.999000012874603,-0.0157437383651733,0.999000012874603,,,0.000189061532185748,0.000105797665059996,0.000216952149196853,,20,-3.06118171215057,-12.2247689723969,-15.7437383651733,
,5995966.56,4417,5.00005006790161,729.753057861328,179.975601196289,-0.00299153180122375,0.999000012874603,-0.0122595688343048,0.999000012874603,-0.0156520869255066,0.999000012874603,,,0.000157844345137541,9.48744656807082e-005,0.000249801757282606,,20,-2.99153180122376,-12.2595688343048,-15.6520869255066,
,5995991.34,4417,4.99979996681213,699.687530517578,179.975601196289,-0.00313114047050476,0.999000012874603,-0.0123392370700836,0.999000012874603,-0.0158352981567383,0.999000012874603,,,0.000159082086213757,0.000115457724455011,0.000147139771680903,,20,-3.13114047050476,-12.3392370700836,-15.8352981567383,
,5996016.75,4417,4.99985003471375,669.815133666992,179.975601196289,-0.00317343772649765,0.999000012874603,-0.0125006924152374,0.999000012874603,-0.0158806506633759,0.999000012874603,,,0.000231461655995392,7.48768994262162e-005,0.00016333568767992,,20,-3.17343772649765,-12.5006924152374,-15.8806506633759,
,5996044.66,4417,5.00020003318787,639.987567138672,179.975601196289,-0.00327231948375702,0.999000012874603,-0.0125124613285065,0.999000012874603,-0.0160254951953888,0.999000012874603,,,0.000224356456546984,0.000101858025260218,0.000230610850346928,,20,-3.27231948375702,-12.5124613285065,-16.0254951953888,
,5996069.86,4417,5.0002498626709,609.462158203125,179.975601196289,-0.00340322753190994,0.999000012874603,-0.01260403008461,0.999000012874603,-0.0160873680114746,0.999000012874603,,,0.000300753632383033,9.57656801977002e-005,0.000119414309614927,,20,-3.40322753190994,-12.60403008461,-16.0873680114746,
,5996094.48,4417,4.99970006942749,579.216104125977,179.975601196289,-0.00335303716659546,0.999000012874603,-0.0126371074199677,0.999000012874603,-0.0160819159030914,0.999000012874603,,,0.000191766116497971,0.000118819310529276,0.000170299485382997,,20,-3.35303716659546,-12.6371074199677,-16.0819159030914,
,5996119.89,4417,4.99970006942749,549.451794433594,179.975601196289,-0.0033560929775238,0.999000012874603,-0.012695455121994,0.999000012874603,-0.0161697715759277,0.999000012874603,,,0.000151533742708793,0.000124593077653266,0.000149904390609185,,20,-3.3560929775238,-12.695455121994,-16.1697715759277,
,5996145.78,4417,4.99979996681213,519.304614257813,179.975601196289,-0.00343430384397507,0.999000012874603,-0.0126877199649811,0.999000012874603,-0.0161803717136383,0.999000012874603,,,0.000161281926419988,0.000137437739326767,0.000217372265802077,,20,-3.43430384397507,-12.6877199649811,-16.1803717136383,
,5996169.88,4417,4.9997501373291,489.513858032227,179.975601196289,-0.00362574708461761,0.999000012874603,-0.0127346598148346,0.999000012874603,-0.0162735139846802,0.999000012874603,,,0.000234731961322658,0.000113755332183438,0.000138092255964716,,20,-3.62574708461761,-12.7346598148346,-16.2735139846802,
,5996194.41,4417,4.99985003471375,459.343698120117,179.975601196289,-0.00362336002588272,0.999000012874603,-0.0129012850284576,0.999000012874603,-0.0163090349197388,0.999000012874603,,,0.00016967642989306,8.20536837220008e-005,0.000211835589460248,,20,-3.62336002588272,-12.9012850284576,-16.3090349197388,
,5996221.73,4417,5.00014996528625,429.186181640625,179.975601196289,-0.003732095682621,0.999000012874603,-0.0129483207702637,0.999000012874603,-0.0164224052429199,0.999000012874603,,,0.00025439742886243,0.00012604007362496,0.000193207934922111,,20,-3.732095682621,-12.9483207702637,-16.4224052429199,
,5996246.30,4417,4.99990010261536,399.089587402344,179.975601196289,-0.00381889522075653,0.999000012874603,-0.0129209155082703,0.999000012874603,-0.0164581179618835,0.999000012874603,,,0.000246781396447819,8.54260920892036e-005,0.000173221789960475,,20,-3.81889522075653,-12.9209155082703,-16.4581179618835,
,5996271.98,4417,4.99974989891052,369.180400085449,179.975601196289,-0.00388647176027298,0.999000012874603,-0.0129103327274323,0.999000012874603,-0.0166326282501221,0.999000012874603,,,0.000258487467069551,0.000106583839205719,0.000142963683830146,,20,-3.88647176027298,-12.9103327274323,-16.6326282501221,
,5996298.84,4417,5.00020003318787,338.706718444824,179.975601196289,-0.00393849433660507,0.999000012874603,-0.0130077913761139,0.999000012874603,-0.0165682954788208,0.999000012874603,,,0.00026537161227374,0.00010870980909431,0.000127805973618847,,20,-3.93849433660507,-13.0077913761139,-16.5682954788208,
,5996324.38,4417,5.00005006790161,308.860768127441,179.975601196289,-0.00393171548843384,0.999000012874603,-0.0130352886676788,0.999000012874603,-0.0167290771484375,0.999000012874603,,,0.000152655896714556,0.000116574089694087,0.000229700132828412,,20,-3.93171548843384,-13.0352886676788,-16.7290771484375,
,5996350.38,4417,4.99985003471375,278.791777038574,179.975601196289,-0.00400362926721573,0.999000012874603,-0.0130863855838776,0.999000012874603,-0.016718972492218,0.999000012874603,,,0.000208472834553442,0.000103405757710229,0.000191467072185153,,20,-4.00362926721573,-13.0863855838776,-16.718972492218,
,5996376.28,4417,4.99990010261536,248.928578948975,179.975601196289,-0.00409579292535782,0.999000012874603,-0.0131057735443115,0.999000012874603,-0.0167906976699829,0.999000012874603,,,0.000205455516871411,0.000105724391071255,0.000165254576480736,,20,-4.09579292535782,-13.1057735443115,-16.7906976699829,
,5996404.50,4417,4.99989986419678,218.469841003418,179.975601196289,-0.00412125848531723,0.999000012874603,-0.0131966392040253,0.999000012874603,-0.0168278986930847,0.999000012874603,,,0.000128253038506916,0.00011781326736959,0.000131316241127272,,20,-4.12125848531723,-13.1966392040253,-16.8278986930847,
,5996430.69,4417,4.99989986419678,188.536510467529,179.975601196289,-0.00425998952388764,0.999000012874603,-0.0132692986965179,0.999000012874603,-0.0168837538719177,0.999000012874603,,,0.000244139272082908,0.00011180349776978,0.000208030529660976,,20,-4.25998952388763,-13.2692986965179,-16.8837538719177,
,5996456.73,4417,5.00019979476929,158.365196990967,179.975601196289,-0.00431773241758347,0.999000012874603,-0.0133933356285095,0.999000012874603,-0.0169458632469177,0.999000012874603,,,0.000282239246915085,0.000107501834063662,0.000213501355893238,,20,-4.31773241758347,-13.3933356285095,-16.9458632469177,
,5996482.52,4417,4.99990010261536,128.508895111084,179.975601196289,-0.00438677570819855,0.999000012874603,-0.0134112889289856,0.999000012874603,-0.0170472796440125,0.999000012874603,,,0.000245397969084828,0.000142356230641505,0.000171792342707816,,20,-4.38677570819855,-13.4112889289856,-17.0472796440125,
,5996508.27,4417,5.00005006790161,98.4100116729736,179.975601196289,-0.00438553423881531,0.999000012874603,-0.0135048749923706,0.999000012874603,-0.0171356130599976,0.999000012874603,,,0.000257683962035998,0.00011462545734055,0.000134856400457317,,20,-4.38553423881531,-13.5048749923706,-17.1356130599976,
,5996535.14,4417,5.00025010108948,68.3111301422119,179.975601196289,-0.00445929806232452,0.999000012874603,-0.0135277153015137,0.999000012874603,-0.0172014320373535,0.999000012874603,,,0.000158710427544357,0.000122004668370686,0.000169941879625056,,20,-4.45929806232452,-13.5277153015137,-17.2014320373535,
,5996563.06,4417,4.99994993209839,38.1076248168945,179.975601196289,-0.00443074707984924,0.999000012874603,-0.013565719461441,0.999000012874603,-0.0172010503768921,0.999000012874603,,,0.000134862924943059,0.000147704325701504,0.000237198541713297,,20,-4.43074707984924,-13.565719461441,-17.2010503768921,
,5996588.98,4417,4.99970006942749,7.98344750404358,179.975601196289,-0.00460477821826935,0.999000012874603,-0.0135929950714111,0.999000012874603,-0.0172683957099915,0.999000012874603,,,0.000228974078879468,0.000130807000449993,0.000180691425264667,,20,-4.60477821826935,-13.5929950714111,-17.2683957099915,
,5996613.70,4417,5.00009989738464,-21.8992948532104,179.975601196289,-0.00467228770256042,0.999000012874603,-0.0136579264640808,0.999000012874603,-0.0172947499275207,0.999000012874603,,,0.000178080643975281,9.58990538322112e-005,0.000234285519065944,,20,-4.67228770256042,-13.6579264640808,-17.2947499275208,
,5996639.77,4417,5.00009989738464,-51.7636430740356,179.975601196289,-0.00482593011856079,0.999000012874603,-0.0137074139595032,0.999000012874603,-0.0174835770606995,0.999000012874603,,,0.000219361885568865,0.000106892212375874,0.000207896764426635,,20,-4.82593011856079,-13.7074139595032,-17.4835770606995,
,5996666.36,4417,5.00029993057251,-82.2235294342041,179.975601196289,-0.00475880393981934,0.999000012874603,-0.0137727258682251,0.999000012874603,-0.0174803304672241,0.999000012874603,,,0.000109830492121586,0.00010469721709331,0.000169347515648332,,20,-4.75880393981934,-13.7727258682251,-17.4803304672241,
,5996692.27,4417,4.99970006942749,-112.406339645386,179.975601196289,-0.00481795084476471,0.999000012874603,-0.0137783190727234,0.999000012874603,-0.0176311197280884,0.999000012874603,,,0.000180646945639353,0.000114578448702649,0.000178519196664639,,20,-4.81795084476471,-13.7783190727234,-17.6311197280884,
,5996718.47,4417,5,-142.161464691162,179.975601196289,-0.00494185266494751,0.999000012874603,-0.0139881986618042,0.999000012874603,-0.0176209250450134,0.999000012874603,,,0.000244974830880193,9.94817525427919e-005,0.000200302348398425,,20,-4.94185266494751,-13.9881986618042,-17.6209250450134,
,5996744.22,4417,4.99990010261536,-172.038459777832,179.975601196289,-0.00504525742530823,0.999000012874603,-0.0139944046974182,0.999000012874603,-0.0176524332046509,0.999000012874603,,,0.000256258267392976,0.00011855603819175,0.000165427970084444,,20,-5.04525742530823,-13.9944046974182,-17.6524332046509,
,5996771.08,4417,5,-202.210929107666,179.975601196289,-0.00505218648910522,0.999000012874603,-0.0140148591995239,0.999000012874603,-0.0177656825065613,0.999000012874603,,,0.000229135243810969,0.00012388933442536,0.00022321966204112,,20,-5.05218648910522,-14.0148591995239,-17.7656825065613,
,5996798.06,4417,5.00014996528625,-232.674261474609,179.975601196289,-0.00524899523258209,0.999000012874603,-0.0140283234596252,0.999000012874603,-0.0178559224128723,0.999000012874603,,,0.0002708694166208,0.00012783509692063,0.000188182686673529,,20,-5.24899523258209,-14.0283234596252,-17.8559224128723,
,5996824.88,4417,5.00029993057251,-262.26842956543,179.975601196289,-0.00520687508583069,0.999000012874603,-0.0141083787441254,0.999000012874603,-0.0179371682167053,0.999000012874603,,,0.000244222442143148,0.000130763021668188,9.52765481720501e-005,,20,-5.20687508583069,-14.1083787441254,-17.9371682167053,
,5996850.81,4417,5.00014996528625,-292.419049072266,179.975601196289,-0.00522282159328461,0.999000012874603,-0.0141026494503021,0.999000012874603,-0.0179421337127686,0.999000012874603,,,0.000141894975073684,0.000128235252970836,0.000226894134807031,,20,-5.22282159328461,-14.1026494503021,-17.9421337127686,
,5996877.86,4417,4.99994993209839,-322.555871582031,179.975601196289,-0.00528350698947907,0.999000012874603,-0.0143194630146027,0.999000012874603,-0.0180191387176514,0.999000012874603,,,0.0001553990413262,0.000137927610228125,0.000241650499285601,,20,-5.28350698947906,-14.3194630146027,-18.0191387176514,
,5996903.89,4417,4.99994993209839,-352.932981872559,179.975601196289,-0.00538572463989258,0.999000012874603,-0.0143248148918152,0.999000012874603,-0.0181144477844238,0.999000012874603,,,0.000194592308675772,0.00014483032427563,0.000150283762282813,,20,-5.38572463989258,-14.3248148918152,-18.1144477844238,
,5996930.89,4417,4.99995017051697,-383.087043762207,179.975601196289,-0.00542669427394867,0.999000012874603,-0.0144078998088837,0.999000012874603,-0.018206032371521,0.999000012874603,,,0.000159677146275682,0.000104359374932223,0.000187170859078416,,20,-5.42669427394867,-14.4078998088837,-18.206032371521,
,5996956.72,4417,5.00005006790161,-412.655928039551,179.975601196289,-0.00553729667663574,0.999000012874603,-0.0144162977218628,0.999000012874603,-0.0182219660758972,0.999000012874603,,,0.000160549041209123,9.99555553258261e-005,0.000155372330984494,,20,-5.53729667663574,-14.4162977218628,-18.2219660758972,
,5996982.31,4417,5.00005006790161,-442.904264831543,179.975601196289,-0.00562753055095673,0.999000012874603,-0.0145159847259521,0.999000012874603,-0.0183718783378601,0.999000012874603,,,0.00020301344803172,0.000127786936296279,0.000147574911282883,,20,-5.62753055095673,-14.5159847259521,-18.3718783378601,
,5997008.27,4417,5,-473.070989990234,179.975601196289,-0.00563094351291656,0.999000012874603,-0.0145519033432007,0.999000012874603,-0.018362486743927,0.999000012874603,,,0.00026810104437791,0.00013193476222661,0.000177076318703727,,20,-5.63094351291656,-14.5519033432007,-18.362486743927,
,5997034.13,4417,4.99980020523071,-502.910040283203,179.975601196289,-0.00569186096191406,0.999000012874603,-0.0145337617397308,0.999000012874603,-0.01840707654953,0.999000012874603,,,0.000254509711856241,0.000115030558646705,0.00018600638254379,,20,-5.69186096191406,-14.5337617397308,-18.40707654953,
,5997059.95,4417,4.99979996681213,-533.071005249023,179.975601196289,-0.00585706522464752,0.999000012874603,-0.0145960385322571,0.999000012874603,-0.0184939747810364,0.999000012874603,,,0.000277122248510096,0.000119635710260982,0.000224037312486406,,20,-5.85706522464752,-14.5960385322571,-18.4939747810364,
,5997087.88,4417,5.00014996528625,-563.138842773438,179.975601196289,-0.00585738978385925,0.999000012874603,-0.0146535968780518,0.999000012874603,-0.0186203073501587,0.999000012874603,,,0.000185411089142803,0.000119585100201469,0.000189839846125372,,20,-5.85738978385925,-14.6535968780518,-18.6203073501587,
,5997114.06,4417,5.00025010108948,-593.314764404297,179.975601196289,-0.00589478461742401,0.999000012874603,-0.0146590048313141,0.999000012874603,-0.0186382466316223,0.999000012874603,,,0.000150340868524842,0.000130124764277265,0.000180726930396993,,20,-5.89478461742401,-14.6590048313141,-18.6382466316223,
,5997141.08,4417,5,-623.175640869141,179.975601196289,-0.00596421363353729,0.999000012874603,-0.0147274492740631,0.999000012874603,-0.0187050874710083,0.999000012874603,,,0.000183721568361039,0.000110872513076713,0.000191975888378247,,20,-5.96421363353729,-14.7274492740631,-18.7050874710083,
,5997166.61,4417,4.99969983100891,-653.346978759766,179.975601196289,-0.00602446210384369,0.999000012874603,-0.0147504601955414,0.999000012874603,-0.0187132034301758,0.999000012874603,,,0.000135615931069695,0.000112531492940377,0.000183455140076254,,20,-6.02446210384369,-14.7504601955414,-18.7132034301758,
,5997203.14,4417,5.00005006790161,-698.426309204102,179.975601196289,-0.00618396909236908,0.999000012874603,-0.0149340167045593,0.999000012874603,-0.0188514562606812,0.999000012874603,,,0.000188330504589812,0.000124471622184824,0.000203740295124916,,20,-6.18396909236908,-14.9340167045593,-18.8514562606812,
,5997229.30,4417,5.00019979476929,-728.5861328125,179.975601196289,-0.00615350806713104,0.999000012874603,-0.0149123404979706,0.999000012874603,-0.0189398791313171,0.999000012874603,,,0.000154421944603253,0.000109990245906172,0.000136598306462925,,20,-6.15350806713104,-14.9123404979706,-18.9398791313171,
,5997256.02,4417,4.99980020523071,-758.686163330078,179.975601196289,-0.00625343804359436,0.999000012874603,-0.0150457448482513,0.999000012874603,-0.0189775763511658,0.999000012874603,,,0.000170065710812251,0.000125298337721071,0.000133360179339289,,20,-6.25343804359436,-15.0457448482513,-18.9775763511658,
,5997281.56,4417,5.00004982948303,-788.821853637695,179.975601196289,-0.00645456113815308,0.999000012874603,-0.0150892926216125,0.999000012874603,-0.0190998169898987,0.999000012874603,,,0.000236722395062314,7.23894834060892e-005,0.000153148483739616,,20,-6.45456113815308,-15.0892926216125,-19.0998169898987,
,5997307.59,4417,4.99995017051697,-818.982809448242,179.975601196289,-0.00639822399616241,0.999000012874603,-0.0150971695423126,0.999000012874603,-0.0192488195419312,0.999000012874603,,,0.000182032483699656,0.000145308318917297,0.0001412169037531,,20,-6.39822399616241,-15.0971695423126,-19.2488195419312,
,5997332.78,4417,4.99995017051697,-848.87473449707,179.975601196289,-0.00649906935691834,0.999000012874603,-0.0151587652683258,0.999000012874603,-0.0197954456329346,0.999000012874603,,,0.00018362613663751,0.000113090440212337,0.000125247024941644,,20,-6.49906935691834,-15.1587652683258,-19.7954456329346,
,5997358.89,4417,4.99990010261536,-879.313949584961,179.975601196289,-0.00699273266792298,0.999000012874603,-0.0152862679958344,0.999000012874603,-0.0198210314750671,0.999000012874603,,,0.00025967290617192,0.000100589600977077,0.000172683995548821,,20,-6.99273266792297,-15.2862679958344,-19.8210314750671,
,5997386.42,4417,5.00034999847412,-908.898916625977,179.975601196289,-0.00704793946743012,0.999000012874603,-0.0153107312202454,0.999000012874603,-0.0198544931411743,0.999000012874603,,,0.000202364785589168,0.00011362031689354,0.000202551661984931,,20,-7.04793946743011,-15.3107312202454,-19.8544931411743,
,5997414.64,4417,5.00014996528625,-939.05758972168,179.975601196289,-0.0071201201915741,0.999000012874603,-0.0153336454868317,0.999000012874603,-0.0199186542510986,0.999000012874603,,,0.000263182875985966,0.000127078753032961,0.000198021933692609,,20,-7.1201201915741,-15.3336454868317,-19.9186542510986,
,5997439.94,4417,5.00014996528625,-969.142672729492,179.975601196289,-0.00716779320240021,0.999000012874603,-0.0153637173652649,0.999000012874603,-0.0200416324615479,0.999000012874603,,,0.000193519088752852,0.000125778865551242,0.000209064207192845,,20,-7.16779320240021,-15.3637173652649,-20.0416324615479,
,5997466.25,4417,5.00020003318787,-999.57724609375,179.975601196289,-0.00721257767677307,0.999000012874603,-0.0154689463615417,0.999000012874603,-0.0200589160919189,0.999000012874603,,,0.000253109293009521,9.39998256761909e-005,0.000184694287345138,,20,-7.21257767677307,-15.4689463615417,-20.0589160919189,
,5997491.66,4417,4.99989986419678,-985.815454101563,179.975601196289,-0.00721020858287811,0.999000012874603,-0.0154159395694733,0.999000012874603,-0.0199950362205505,0.999000012874603,,,0.000151499289340991,0.000126915436785076,0.000185826599205852,,20,-7.21020858287811,-15.4159395694733,-19.9950362205505,
,5997518.59,4417,5,-956.069540405273,179.975601196289,-0.00713554680347443,0.999000012874603,-0.0154240548610687,0.999000012874603,-0.0199373690605164,0.999000012874603,,,0.000241557208234785,0.000112579557813354,0.000152335160251433,,20,-7.13554680347443,-15.4240548610687,-19.9373690605164,
,5997544.27,4417,4.99990010261536,-926.220138549805,179.975601196289,-0.00717395641803742,0.999000012874603,-0.0153388134002686,0.999000012874603,-0.019952067565918,0.999000012874603,,,0.000245727752605797,0.000110119595466648,0.000152088818824643,,20,-7.17395641803741,-15.3388134002686,-19.952067565918,
,5997570.69,4417,5,-896.310974121094,179.975601196289,-0.00697020018100739,0.999000012874603,-0.0153357581615448,0.999000012874603,-0.0199066188812256,0.999000012874603,,,0.000210874384231074,0.000142189953395186,0.00015851537620462,,20,-6.97020018100739,-15.3357581615448,-19.9066188812256,
,5997596.47,4417,5.00014996528625,-866.482229614258,179.975601196289,-0.00690221786499023,0.999000012874603,-0.0151767826080322,0.999000012874603,-0.0197506986618042,0.999000012874603,,,0.000212122679392799,0.000114582500116642,0.000197279655370565,,20,-6.90221786499023,-15.1767826080322,-19.7506986618042,
,5997624.45,4417,5,-836.633981323242,179.975601196289,-0.00684390919208527,0.999000012874603,-0.0150889871120453,0.999000012874603,-0.0196669653892517,0.999000012874603,,,0.00022796050559592,0.000107398691698908,0.000199800846475453,,20,-6.84390919208527,-15.0889871120453,-19.6669653892517,
,5997648.91,4417,4.99974989891052,-806.765054321289,179.975601196289,-0.00683779842853546,0.999000012874603,-0.0150338953018189,0.999000012874603,-0.0195987929344177,0.999000012874603,,,0.000237409267298134,0.000107090021974761,0.000183486223058912,,20,-6.83779842853546,-15.0338953018188,-19.5987929344177,
,5997676.83,4417,4.99969983100891,-776.619046020508,179.975601196289,-0.00682845091819763,0.999000012874603,-0.0150170924186707,0.999000012874603,-0.019561531162262,0.999000012874603,,,0.000248393148392658,0.000123578199463729,0.000129228967429283,,20,-6.82845091819763,-15.0170924186707,-19.561531162262,
,5997702.31,4417,4.99994993209839,-746.814483642578,179.975601196289,-0.00670642068386078,0.999000012874603,-0.0149603739261627,0.999000012874603,-0.019501375579834,0.999000012874603,,,0.000199835194934173,0.000101195344082961,0.000175413528933849,,20,-6.70642068386078,-14.9603739261627,-19.501375579834,
,5997728.19,4417,4.9997501373291,-716.673056030273,179.975601196289,-0.00661822190284729,0.999000012874603,-0.0149171636104584,0.999000012874603,-0.0194716554641724,0.999000012874603,,,0.000189857988494422,0.000115520716197896,0.000156438224106423,,20,-6.61822190284729,-14.9171636104584,-19.4716554641724,
,5997754.11,4417,5,-687.412271118164,179.975601196289,-0.00659081625938416,0.999000012874603,-0.0148352330207825,0.999000012874603,-0.0194138840675354,0.999000012874603,,,0.000286888367886637,0.000138564591775752,0.000158434617984545,,20,-6.59081625938416,-14.8352330207825,-19.4138840675354,
,5997782.20,4417,5.00014996528625,-657.244415283203,179.975601196289,-0.00653871853351593,0.999000012874603,-0.01488874335289,0.999000012874603,-0.0193374454498291,0.999000012874603,,,0.000158001340189216,0.000107490573503816,0.000227216340612406,,20,-6.53871853351593,-14.88874335289,-19.3374454498291,
,5997810.20,4417,4.99985003471375,-627.367416381836,179.975601196289,-0.00644611723423004,0.999000012874603,-0.0148663910865784,0.999000012874603,-0.0192554545402527,0.999000012874603,,,0.000239520252865464,9.65399136734402e-005,0.000136874376473157,,20,-6.44611723423004,-14.8663910865784,-19.2554545402527,
,5997837.31,4417,4.9997501373291,-597.489288330078,179.975601196289,-0.00641355040073395,0.999000012874603,-0.014750545167923,0.999000012874603,-0.019183731174469,0.999000012874603,,,0.000181969989563341,0.000101304986247696,0.000173454174057036,,20,-6.41355040073395,-14.750545167923,-19.183731174469,
,5997863.91,4417,5.00014996528625,-567.911199951172,179.975601196289,-0.00629576570987701,0.999000012874603,-0.0146547869205475,0.999000012874603,-0.0191111365318298,0.999000012874603,,,0.00014605664494262,0.000144628080050333,0.000194450081577613,,20,-6.29576570987701,-14.6547869205475,-19.1111365318298,
,5997892.08,4417,4.99994993209839,-538.151486206055,179.975601196289,-0.00618632895946503,0.999000012874603,-0.0145671229839325,0.999000012874603,-0.0191228826522827,0.999000012874603,,,0.000182226927899283,0.000121710745734321,0.000220584439439325,,20,-6.18632895946503,-14.5671229839325,-19.1228826522827,
,5997918.44,4417,4.99974989891052,-508.248054504395,179.975601196289,-0.00619595222473145,0.999000012874603,-0.0146038647651672,0.999000012874603,-0.0190599717140198,0.999000012874603,,,0.000222732783837576,8.53159880899058e-005,0.000202544637662737,,20,-6.19595222473145,-14.6038647651672,-19.0599717140198,
,5997944.08,4417,4.99970006942749,-478.414739990234,179.975601196289,-0.00611132874488831,0.999000012874603,-0.014486576128006,0.999000012874603,-0.0189784049987793,0.999000012874603,,,0.000194754198458973,7.08214838939186e-005,0.000165470225979642,,20,-6.11132874488831,-14.486576128006,-18.9784049987793,
,5997973.41,4417,4.99974989891052,-448.563053894043,179.975601196289,-0.00597341344356537,0.999000012874603,-0.0143937779903412,0.999000012874603,-0.0189307074546814,0.999000012874603,,,0.000190094320523812,0.000117819243207156,0.000196897598604117,,20,-5.97341344356537,-14.3937779903412,-18.9307074546814,
,5998001.42,4417,4.99985003471375,-418.622811889648,179.975601196289,-0.00602937545776367,0.999000012874603,-0.0144209951400757,0.999000012874603,-0.0187855496406555,0.999000012874603,,,0.000209008521570004,0.000125988816020683,0.000174803124859515,,20,-6.02937545776367,-14.4209951400757,-18.7855496406555,
,5998028.81,4417,4.99979996681213,-388.740075683594,179.975601196289,-0.00599555079936981,0.999000012874603,-0.0143172354698181,0.999000012874603,-0.0188126337051392,0.999000012874603,,,0.000257069284461801,6.04406721614276e-005,0.000141153562161879,,20,-5.99555079936981,-14.3172354698181,-18.8126337051392,
,5998055.34,4417,4.99994993209839,-358.899864196777,179.975601196289,-0.00589930880069733,0.999000012874603,-0.0142707378864288,0.999000012874603,-0.0186973917007446,0.999000012874603,,,0.00021921526507014,0.000146157203861125,0.000114813013502031,,20,-5.89930880069733,-14.2707378864288,-18.6973917007446,
,5998080.80,4417,5.00025010108948,-329.083807373047,179.975601196289,-0.00579970083236694,0.999000012874603,-0.0142233491420746,0.999000012874603,-0.0186889573097229,0.999000012874603,,,0.000231655429525,0.000100479162012512,0.000140208094033386,,20,-5.79970083236694,-14.2233491420746,-18.6889573097229,
,5998107.42,4417,4.99994993209839,-298.906750488281,179.975601196289,-0.00569643750190735,0.999000012874603,-0.0142157807826996,0.999000012874603,-0.0185838199615479,0.999000012874603,,,0.000187700932523861,0.000100220256027289,0.000155368623993379,,20,-5.69643750190735,-14.2157807826996,-18.5838199615479,
,5998134.28,4417,5.00009989738464,-269.336729431152,179.975601196289,-0.00559614140987396,0.999000012874603,-0.0142181687355042,0.999000012874603,-0.0185012907981873,0.999000012874603,,,0.000233813325963096,7.87805723522346e-005,0.000157146408174381,,20,-5.59614140987396,-14.2181687355042,-18.5012907981873,
,5998161.28,4417,5.00004982948303,-239.465476226807,179.975601196289,-0.0054706493139267,0.999000012874603,-0.0141253086090088,0.999000012874603,-0.0183829750061035,0.999000012874603,,,0.000159982983580596,0.000113883386916895,0.000155842602935331,,20,-5.4706493139267,-14.1253086090088,-18.3829750061035,
,5998189.84,4417,4.99994993209839,-209.574687194824,179.975601196289,-0.00550856103897095,0.999000012874603,-0.0140670566082001,0.999000012874603,-0.0183740938186646,0.999000012874603,,,0.000168266753157498,0.00011581376360576,0.000216450444338779,,20,-5.50856103897095,-14.0670566082001,-18.3740938186646,
,5998215.27,4417,5.0002498626709,-179.77472076416,179.975601196289,-0.00553019800186157,0.999000012874603,-0.0139038432598114,0.999000012874603,-0.0182991642951965,0.999000012874603,,,0.000202993453474831,0.000137362982829031,0.000171351980553826,,20,-5.53019800186157,-13.9038432598114,-18.2991642951965,
,5998242.28,4417,5.00029993057251,-149.918426513672,179.975601196289,-0.00539403185844421,0.999000012874603,-0.0139337308883667,0.999000012874603,-0.0182392932891846,0.999000012874603,,,0.000211571749939273,0.000123919344503015,0.000190097454743482,,20,-5.39403185844421,-13.9337308883667,-18.2392932891846,
,5998269.16,4417,5.00020003318787,-120.093164825439,179.975601196289,-0.00526293206214905,0.999000012874603,-0.0138562690734863,0.999000012874603,-0.0182020189285278,0.999000012874603,,,0.000184326870956829,0.000105562693701759,0.000171502876102527,,20,-5.26293206214905,-13.8562690734863,-18.2020189285278,
,5998296.16,4417,4.9997501373291,-90.3460872650146,179.975601196289,-0.00530427920818329,0.999000012874603,-0.0137621161937714,0.999000012874603,-0.0181562804222107,0.999000012874603,,,0.000250530866841242,0.000119958157499764,0.000164048400255338,,20,-5.30427920818329,-13.7621161937714,-18.1562804222107,
,5998322.58,4417,4.9997501373291,-60.4748424530029,179.975601196289,-0.00504939017295837,0.999000012874603,-0.0137962034702301,0.999000012874603,-0.0180164389610291,0.999000012874603,,,0.000145114392813484,9.63137980049665e-005,0.000164807645434693,,20,-5.04939017295837,-13.7962034702301,-18.0164389610291,
,5998351.19,4417,5.00020003318787,-30.5599095344543,179.975601196289,-0.00512881979942322,0.999000012874603,-0.0137324295043945,0.999000012874603,-0.0179788964271545,0.999000012874603,,,0.000243841055579783,8.93050668536005e-005,0.000208150345980669,,20,-5.12881979942322,-13.7324295043945,-17.9788964271545,
,5998377.61,4417,4.99985003471375,-0.661071738600731,179.975601196289,-0.00506340734958649,0.999000012874603,-0.0136267193317413,0.999000012874603,-0.0178486438751221,0.999000012874603,,,0.000251943530007493,0.000125985912130962,0.000184144616709143,,20,-5.06340734958649,-13.6267193317413,-17.8486438751221,