File: data/r91.dat
[Header]
TITLE, default name
FILEOPENTIME,6047827.64,5/27/2021,1:19 PM
BYAPP, Resistivity, 2.1, 1.0
INFO, APPNAME, PPMS MultiVu Application, 1.5.11
INFO, , Sample1 Name
INFO, 1, Sample1 Cross Section
INFO, 1, Sample1 Length
INFO, Ohm-m, Sample1 Units
INFO, , Sample2 Name
INFO, 1, Sample2 Cross Section
INFO, 1, Sample2 Length
INFO, Ohm-m, Sample2 Units
INFO, , Sample3 Name
INFO, 1, Sample3 Cross Section
INFO, 1, Sample3 Length
INFO, Ohm-m, Sample3 Units
INFO, , Sample4 Name
INFO, 1, Sample4 Cross Section
INFO, 1, Sample4 Length
INFO, Ohm-m, Sample4 Units
FIELDGROUP, Resistivity,2,3,4,5,6,7,8,9,10,11,12,13,14,15,16,17,18,19,20,21,22,23,24,25,26,27,28,29,30,31,32,33,34,35,36,37,38,39,40,41
STARTUPGROUP, Resistivity
STARTUPAXIS, X, 2, LINEAR, AUTO
STARTUPAXIS, Y1, 7, LINEAR, AUTO
STARTUPAXIS, Y2, 9, LINEAR, AUTO
STARTUPAXIS, Y3, 11, LINEAR, AUTO
PLOT_APPEARANCE, ALL, HORZ_GRID_ON, VERT_GRID_ON, MARKERS_AND_LINES, ALL_LINES
DATATYPE, TIME, 2
DATATYPE, COMMENT, 1
[Data]
Comment,Time Stamp (sec),Status (code),Temperature (K),Magnetic Field (Oe),Sample Position (deg),Bridge 1 Resistivity (Ohm-m),Bridge 1 Excitation (uA),Bridge 2 Resistivity (Ohm-m),Bridge 2 Excitation (uA),Bridge 3 Resistivity (Ohm-m),Bridge 3 Excitation (uA),Bridge 4 Resistivity (Ohm-m),Bridge 4 Excitation (uA),Bridge 1 Std. Dev. (Ohm-m),Bridge 2 Std. Dev. (Ohm-m),Bridge 3 Std. Dev. (Ohm-m),Bridge 4 Std. Dev. (Ohm-m),Number of Readings,Bridge 1 Resistance (Ohms),Bridge 2 Resistance (Ohms),Bridge 3 Resistance (Ohms),Bridge 4 Resistance (Ohms),Signal 1 Vin (V),Signal 2 Vin (V),Digital Inputs (code),Drive 1 Iout (mA),Drive 1 Ipower (watts),Drive 2 Iout (mA),Drive 2 Ipower (watts),Pressure (),Map 20 (),Map 21 (),Map 22 (),Map 23 (),Map 24 (),Map 25 (),Map 26 (),Map 27 (),Map 28 (),Map 29 ()
,6047936.17,4417,4.99994993209839,-0.280524399876595,179.975601196289,0.00273601317405701,0.999000012874603,-0.012727516412735,0.999000012874603,0.0021664121568203,0.999000012874603,,,0.000464917679543897,4.89454285020247e-005,0.000115003754939607,,20,2.73601317405701,-12.727516412735,2.1664121568203,
,6047974.84,4417,4.99954986572266,59.1768432617188,179.975601196289,0.00315284363031387,0.999000012874603,-0.0126064087867737,0.999000012874603,0.00239621846675873,0.999000012874603,,,0.000474871880296554,5.44766209260255e-005,0.000164394541680032,,20,3.15284363031387,-12.6064087867737,2.39621846675873,
,6048014.50,4417,4.9997501373291,119.39185333252,179.975601196289,0.00308962441682816,0.999000012874603,-0.0124373783111572,0.999000012874603,0.00260602600574493,0.999000012874603,,,0.000479083730824252,7.61922720639117e-005,0.000123374935250565,,20,3.08962441682816,-12.4373783111572,2.60602600574493,
,6048054.45,4417,4.99990010261536,179.442459869385,179.975601196289,0.00323307464122772,0.999000012874603,-0.0122162254333496,0.999000012874603,0.00284423460960388,0.999000012874603,,,0.000422450522505555,6.24971856555238e-005,0.000101455963838096,,20,3.23307464122772,-12.2162254333496,2.84423460960388,
,6048095.17,4417,5.00139999389648,239.220597839355,179.975601196289,0.00371652011871338,0.999000012874603,-0.0120316634654999,0.999000012874603,0.00300629254579544,0.999000012874603,,,0.000425984297301922,8.48006057396059e-005,0.000117303889724376,,20,3.71652011871338,-12.0316634654999,3.00629254579544,
,6048136.81,4417,5.00099992752075,299.23556060791,179.975601196289,0.00408672076463699,0.999000012874603,-0.01181118516922,0.999000012874603,0.00318599790334702,0.999000012874603,,,0.000504648616015463,5.59648857912269e-005,0.000129233792362956,,20,4.08672076463699,-11.81118516922,3.18599790334702,
,6048176.64,4417,5.00049996376038,359.462077331543,179.975601196289,0.00411479939222336,0.999000012874603,-0.0115571713447571,0.999000012874603,0.0034930579662323,0.999000012874603,,,0.000350031526280711,6.4563348058277e-005,0.000141500640885253,,20,4.11479939222336,-11.5571713447571,3.4930579662323,
,6048214.78,4417,5.00040006637573,419.171231079102,179.975601196289,0.00444721331596375,0.999000012874603,-0.0114189408302307,0.999000012874603,0.00366980789899826,0.999000012874603,,,0.000326076001909034,5.96800173673443e-005,0.000138434602773844,,20,4.44721331596375,-11.4189408302307,3.66980789899826,
,6048255.50,4417,5.00139999389648,479.203430175781,179.975601196289,0.00453114093542099,0.999000012874603,-0.0111451976776123,0.999000012874603,0.00388712239265442,0.999000012874603,,,0.000456911095353625,4.25087900591446e-005,9.95485697533536e-005,,20,4.53114093542099,-11.1451976776123,3.88712239265442,
,6048296.14,4417,5.00025010108948,539.732315063477,179.975601196289,0.00509669630527496,0.999000012874603,-0.0109904587745666,0.999000012874603,0.0040591542840004,0.999000012874603,,,0.000693901680426398,7.08321073772341e-005,0.000178627818821035,,20,5.09669630527496,-10.9904587745667,4.0591542840004,
,6048337.03,4417,5.00004982948303,599.221884155273,179.975601196289,0.00473820918798447,0.999000012874603,-0.0107994111537933,0.999000012874603,0.00423439836502075,0.999000012874603,,,0.000386895089608375,8.06956633785575e-005,0.000133372484016459,,20,4.73820918798447,-10.7994111537933,4.23439836502075,
,6048378.77,4417,5.00014996528625,659.588656616211,179.975601196289,0.00534316408634186,0.999000012874603,-0.0105746782302856,0.999000012874603,0.00440641038417816,0.999000012874603,,,0.000477833938004373,6.09268936705024e-005,0.000117812922540025,,20,5.34316408634186,-10.5746782302856,4.40641038417816,
,6048420.91,4417,5.00005006790161,719.600164794922,179.975601196289,0.00562770969867706,0.999000012874603,-0.0103764922142029,0.999000012874603,0.00479805233478546,0.999000012874603,,,0.000417570144748674,5.48120898069302e-005,0.000146921388888113,,20,5.62770969867706,-10.3764922142029,4.79805233478546,
,6048463.03,4417,4.99989986419678,779.550744628906,179.975601196289,0.00532370188236237,0.999000012874603,-0.0101866778850555,0.999000012874603,0.00516022765636444,0.999000012874603,,,0.000654721663422375,8.04305137971105e-005,0.000145235604635512,,20,5.32370188236237,-10.1866778850555,5.16022765636444,
,6048504.72,4417,5.00005006790161,839.387509155273,179.975601196289,0.00568645806312561,0.999000012874603,-0.00999118180274964,0.999000012874603,0.00539951877593994,0.999000012874603,,,0.000497084130309868,5.47058638326071e-005,0.000142881972513155,,20,5.68645806312561,-9.99118180274963,5.39951877593994,
,6048544.80,4417,4.99920010566711,899.39787902832,179.975601196289,0.00566901931762695,0.999000012874603,-0.00978751473426819,0.999000012874603,0.00562021920681,0.999000012874603,,,0.000441760795952448,6.79678791291722e-005,0.000121678677005357,,20,5.66901931762695,-9.78751473426819,5.62021920681,
,6048584.75,4417,5.00069999694824,959.318563842773,179.975601196289,0.0060037816286087,0.999000012874603,-0.00958212013244629,0.999000012874603,0.00578758399486542,0.999000012874603,,,0.000501515948942507,5.53444656311395e-005,0.000156921582233544,,20,6.0037816286087,-9.58212013244629,5.78758399486542,
,6048625.44,4417,4.99969983100891,1019.37377319336,179.975601196289,0.00623318169116974,0.999000012874603,-0.00940478811264038,0.999000012874603,0.00603615388870239,0.999000012874603,,,0.000470112850356233,7.09490542943384e-005,0.000123701008865511,,20,6.23318169116974,-9.40478811264038,6.03615388870239,
,6048663.78,4417,5.00469994544983,1079.44388427734,179.975601196289,0.00643071286678314,0.999000012874603,-0.00914900102615357,0.999000012874603,0.00617556600570679,0.999000012874603,,,0.000547451145346063,0.000117727499327426,0.000131852801115952,,20,6.43071286678314,-9.14900102615356,6.17556600570679,
,6048704.06,4421,4.99650001525879,1139.47496337891,179.975601196289,0.00654934706687927,0.999000012874603,-0.00891423516273499,0.999000012874603,0.00633889710903168,0.999000012874603,,,0.000538231240122695,9.02694656365735e-005,0.000125117424860482,,20,6.54934706687927,-8.91423516273499,6.33889710903168,
,6048743.19,4421,4.9974000453949,1199.39912719727,179.975601196289,0.00700481266975403,0.999000012874603,-0.00870311698913574,0.999000012874603,0.00649635269641876,0.999000012874603,,,0.000484439777971139,6.37426858734414e-005,0.000117621383992386,,20,7.00481266975403,-8.70311698913574,6.49635269641876,
,6048783.72,4421,4.99674987792969,1259.14389038086,179.975601196289,0.00715533952713013,0.999000012874603,-0.00852519602775574,0.999000012874603,0.006738796210289,0.999000012874603,,,0.000372136998939733,7.49487469068889e-005,0.000149697248246139,,20,7.15533952713013,-8.52519602775574,6.738796210289,
,6048823.58,4421,4.99825000762939,1319.14736938477,179.975601196289,0.00704000117778778,0.999000012874603,-0.00830767135620117,0.999000012874603,0.00691048340797424,0.999000012874603,,,0.000368218478272818,5.21823188411276e-005,0.000173858141729486,,20,7.04000117778778,-8.30767135620117,6.91048340797424,
,6048865.83,4421,4.99955010414124,1379.36817016602,179.975601196289,0.00746399059295654,0.999000012874603,-0.00813450345993042,0.999000012874603,0.00721412432193756,0.999000012874603,,,0.000464327564768214,7.30493238433335e-005,0.000102059410503007,,20,7.46399059295654,-8.13450345993042,7.21412432193756,
,6048905.84,4417,5.00184988975525,1439.20952148438,179.975601196289,0.00750386657714844,0.999000012874603,-0.00793128139972687,0.999000012874603,0.007359326338768,0.999000012874603,,,0.000356993883168235,0.000100666730915786,0.000116232681142318,,20,7.50386657714844,-7.93128139972687,7.35932633876801,
,6048947.73,4417,5.00149989128113,1499.60277099609,179.975601196289,0.00811218807697296,0.999000012874603,-0.00769742684364319,0.999000012874603,0.00751238842010498,0.999000012874603,,,0.000677002449029504,6.9558348444169e-005,0.000152832763385024,,20,8.11218807697296,-7.69742684364319,7.51238842010498,
,6048989.80,4417,5.00160002708435,1559.61312255859,179.975601196289,0.00814239416122437,0.999000012874603,-0.00750111951828003,0.999000012874603,0.00776597774028778,0.999000012874603,,,0.00045443808863513,6.97198642277864e-005,0.00013431393027024,,20,8.14239416122436,-7.50111951828003,7.76597774028778,
,6049032.11,4417,4.99955010414124,1619.57054443359,179.975601196289,0.00852391910552979,0.999000012874603,-0.00731471440792084,0.999000012874603,0.00802453956604004,0.999000012874603,,,0.000448851394506021,7.05629525092542e-005,9.40976965854235e-005,,20,8.52391910552979,-7.31471440792084,8.02453956604004,
,6049073.47,4417,5,1679.54653320312,179.975601196289,0.00864313895702362,0.999000012874603,-0.00716376869678498,0.999000012874603,0.00822366724014282,0.999000012874603,,,0.000340059900643728,6.89874657974961e-005,0.000131282384634965,,20,8.64313895702362,-7.16376869678497,8.22366724014282,
,6049115.77,4417,4.99985003471375,1739.60740356445,179.975601196289,0.00887339804172516,0.999000012874603,-0.00690274000167847,0.999000012874603,0.00846262226104736,0.999000012874603,,,0.000615634912528943,4.92571476309145e-005,0.000120694214000279,,20,8.87339804172516,-6.90274000167847,8.46262226104736,
,6049157.45,4417,5.00055003166199,1799.52924194336,179.975601196289,0.00888963143825531,0.999000012874603,-0.0067227611541748,0.999000012874603,0.0085144787311554,0.999000012874603,,,0.000720207731831698,0.000109262231558681,0.000127218638727575,,20,8.88963143825531,-6.7227611541748,8.5144787311554,
,6049199.98,4417,5.00099992752075,1859.54078369141,179.975601196289,0.00903247716426849,0.999000012874603,-0.0065983903169632,0.999000012874603,0.00878954591751099,0.999000012874603,,,0.000648927965351696,8.68870313094469e-005,9.90369104970367e-005,,20,9.03247716426849,-6.5983903169632,8.78954591751099,
,6049241.86,4417,5.00039982795715,1919.64196777344,179.975601196289,0.00954501657485962,0.999000012874603,-0.0063971777677536,0.999000012874603,0.00899894037246704,0.999000012874603,,,0.00073413186789021,9.14565169826813e-005,0.000142692464882162,,20,9.54501657485962,-6.3971777677536,8.99894037246704,
,6049283.91,4417,5.00004982948303,1979.6776184082,179.975601196289,0.00964642109870911,0.999000012874603,-0.00617269353866577,0.999000012874603,0.00922342457771301,0.999000012874603,,,0.000599597960253377,7.41125084073883e-005,0.000116887605928249,,20,9.64642109870911,-6.17269353866577,9.22342457771301,
,6049322.89,4417,5.00014996528625,1980.44216308594,179.975601196289,0.00936238446235657,0.999000012874603,-0.00614346823692322,0.999000012874603,0.00929593048095703,0.999000012874603,,,0.000402193332075433,8.09166523785185e-005,0.000155178748382749,,20,9.36238446235657,-6.14346823692322,9.29593048095703,
,6049362.22,4417,5.00100016593933,1920.49154663086,179.975601196289,0.00964045696258545,0.999000012874603,-0.00640265145301819,0.999000012874603,0.00903233575820923,0.999000012874603,,,0.000587888662222417,8.46662938165283e-005,0.000135883574750206,,20,9.64045696258545,-6.40265145301819,9.03233575820923,
,6049403.94,4417,5.00005006790161,1860.40192871094,179.975601196289,0.00909545888900757,0.999000012874603,-0.00654799702167511,0.999000012874603,0.00885251579284668,0.999000012874603,,,0.000326820527737989,7.901285164847e-005,0.00013282864687464,,20,9.09545888900757,-6.54799702167511,8.85251579284668,
,6049446.02,4417,4.99985003471375,1800.67200317383,179.975601196289,0.00892028465270996,0.999000012874603,-0.00677173883914948,0.999000012874603,0.0086123263835907,0.999000012874603,,,0.000441057226862564,0.000108555806991778,0.000138888070294228,,20,8.92028465270996,-6.77173883914948,8.6123263835907,
,6049484.55,4417,5.00019979476929,1740.44554443359,179.975601196289,0.00848555150032043,0.999000012874603,-0.00699029762744903,0.999000012874603,0.00841727304458618,0.999000012874603,,,0.000476379264740766,7.5401993851507e-005,0.000137628342278595,,20,8.48555150032043,-6.99029762744904,8.41727304458618,
,6049523.41,4417,4.99994993209839,1680.4213684082,179.975601196289,0.00841698644161224,0.999000012874603,-0.00720964863300323,0.999000012874603,0.00817108812332153,0.999000012874603,,,0.000568632050276663,7.7389423404327e-005,0.000153717392917923,,20,8.41698644161224,-7.20964863300324,8.17108812332153,
,6049563.00,4417,4.99994993209839,1620.71795654297,179.975601196289,0.00824347651004791,0.999000012874603,-0.00740607748031616,0.999000012874603,0.00798693878650665,0.999000012874603,,,0.000457916491059904,8.81886331155516e-005,0.000108308692280462,,20,8.24347651004791,-7.40607748031616,7.98693878650665,
,6049602.89,4417,4.99994993209839,1560.71334838867,179.975601196289,0.00781818690299988,0.999000012874603,-0.00755762202739716,0.999000012874603,0.00780415132045746,0.999000012874603,,,0.000377581161364848,8.55302403481767e-005,0.000154208427619615,,20,7.81818690299988,-7.55762202739716,7.80415132045746,
,6049643.09,4417,4.99994993209839,1500.77194824219,179.975601196289,0.00784215233325958,0.999000012874603,-0.00775392897129059,0.999000012874603,0.00758158736228943,0.999000012874603,,,0.000502207558134499,6.58839880170008e-005,0.000168794857294623,,20,7.84215233325958,-7.75392897129059,7.58158736228943,
,6049683.69,4417,5.00019979476929,1440.69377441406,179.975601196289,0.0073319079875946,0.999000012874603,-0.00800341801643372,0.999000012874603,0.00732350697517395,0.999000012874603,,,0.000585870502707356,9.12150983202924e-005,0.000161613301841595,,20,7.3319079875946,-8.00341801643372,7.32350697517395,
,6049723.25,4417,4.99979996681213,1380.65120849609,179.975601196289,0.00724198830127716,0.999000012874603,-0.00818828530311584,0.999000012874603,0.00714802703857422,0.999000012874603,,,0.000373786165795461,0.000102454832466596,0.00012693404936261,,20,7.24198830127716,-8.18828530311584,7.14802703857422,
,6049764.31,4417,4.99995017051697,1320.44425048828,179.975601196289,0.0070279972076416,0.999000012874603,-0.00838900308609009,0.999000012874603,0.00686824398040771,0.999000012874603,,,0.000421718966687472,0.000129236115600193,0.000180658015737643,,20,7.0279972076416,-8.38900308609009,6.86824398040771,
,6049804.02,4417,5,1260.69942016602,179.975601196289,0.00689967684745789,0.999000012874603,-0.00858054251670837,0.999000012874603,0.00670846748352051,0.999000012874603,,,0.000394422802399007,7.3471555374298e-005,0.000149173540494018,,20,6.89967684745789,-8.58054251670837,6.70846748352051,
,6049844.09,4417,5.00074982643127,1200.37177124023,179.975601196289,0.00640226168632507,0.999000012874603,-0.00876405053138733,0.999000012874603,0.00656900315284729,0.999000012874603,,,0.000370833884364618,8.07753008064702e-005,0.00011567165091216,,20,6.40226168632507,-8.76405053138733,6.56900315284729,
,6049885.95,4417,5,1140.38327636719,179.975601196289,0.00637112884521484,0.999000012874603,-0.00894397072792053,0.999000012874603,0.00632949120998383,0.999000012874603,,,0.000521510207653589,7.6126458352596e-005,0.000130793931996785,,20,6.37112884521484,-8.94397072792053,6.32949120998383,
,6049926.97,4417,5.00069999694824,1080.36595458984,179.975601196289,0.00637161395549774,0.999000012874603,-0.00920498080253601,0.999000012874603,0.00610377459526062,0.999000012874603,,,0.000393767732812729,0.000144008211010828,0.000131930550546306,,20,6.37161395549774,-9.20498080253601,6.10377459526062,
,6049966.72,4417,5.00049996376038,1020.79250183105,179.975601196289,0.00587278733253479,0.999000012874603,-0.00937892732620239,0.999000012874603,0.00591031522750855,0.999000012874603,,,0.000387290963071463,5.18292043034031e-005,0.000147471000844111,,20,5.87278733253479,-9.37892732620239,5.91031522750855,
,6050004.55,4417,5.00449991226196,960.889047241211,179.975601196289,0.00569020869731903,0.999000012874603,-0.0095685727596283,0.999000012874603,0.00569393286705017,0.999000012874603,,,0.000384078929037944,6.97244784986087e-005,0.000141819209563615,,20,5.69020869731903,-9.5685727596283,5.69393286705017,
,6050044.58,4421,4.99759984016418,900.661389160156,179.975601196289,0.00548689014911652,0.999000012874603,-0.00967581968307495,0.999000012874603,0.00529576349258423,0.999000012874603,,,0.00046594661091031,7.50863616502146e-005,0.000187893943869107,,20,5.48689014911652,-9.67581968307495,5.29576349258423,
,6050084.78,4421,4.99775004386902,840.609609985352,179.975601196289,0.00523155655860901,0.999000012874603,-0.00989276752471924,0.999000012874603,0.0052073028087616,0.999000012874603,,,0.000355727886620264,6.07624939225144e-005,0.000104595931032736,,20,5.23155655860901,-9.89276752471924,5.2073028087616,
,6050123.72,4421,4.99780011177063,780.516479492188,179.975601196289,0.00487815817594528,0.999000012874603,-0.0101156352519989,0.999000012874603,0.00506855986118317,0.999000012874603,,,0.000380755207031596,6.55388712194536e-005,0.000116607931751902,,20,4.87815817594528,-10.1156352519989,5.06855986118317,
,6050160.95,4421,4.99799990653992,720.441720581055,179.975601196289,0.00463238333463669,0.999000012874603,-0.0103452233314514,0.999000012874603,0.00484744329452515,0.999000012874603,,,0.000338797977707047,7.07414714005151e-005,0.000153058190043132,,20,4.63238333463669,-10.3452233314514,4.84744329452515,
,6050199.36,4421,4.99874997138977,660.541748046875,179.975601196289,0.00444492815732956,0.999000012874603,-0.0105664792060852,0.999000012874603,0.00450632467269897,0.999000012874603,,,0.000375859757245017,7.7935319804976e-005,0.000126230500784388,,20,4.44492815732956,-10.5664792060852,4.50632467269898,
,6050236.86,4421,5.00290012359619,600.438244628906,179.975601196289,0.00409040575027466,0.999000012874603,-0.0107650294780731,0.999000012874603,0.00445878853797913,0.999000012874603,,,0.000386894898941471,7.31619453139038e-005,9.33545093450933e-005,,20,4.09040575027466,-10.7650294780731,4.45878853797913,
,6050274.63,4417,5.0006000995636,540.395684814453,179.975601196289,0.00392567653656006,0.999000012874603,-0.0109255143642426,0.999000012874603,0.00420219445228577,0.999000012874603,,,0.000402677780114409,5.67511870216124e-005,0.000126887210460415,,20,3.92567653656006,-10.9255143642426,4.20219445228577,
,6050312.86,4417,5.00815010070801,480.487648010254,179.975601196289,0.0038720152258873,0.999000012874603,-0.0112316324234009,0.999000012874603,0.00411673743724823,0.999000012874603,,,0.00031795566293286,5.74468336540412e-005,0.000105356548845844,,20,3.8720152258873,-11.2316324234009,4.11673743724823,
,6050350.16,4417,4.99954986572266,420.453126525879,179.975601196289,0.00326227259635925,0.999000012874603,-0.0113615794658661,0.999000012874603,0.00382706738710403,0.999000012874603,,,0.000445229543534933,6.24351321404957e-005,0.000140716619221995,,20,3.26227259635925,-11.3615794658661,3.82706738710403,
,6050389.23,4417,4.99989986419678,360.749725341797,179.975601196289,0.00311489981412888,0.999000012874603,-0.0116018152236938,0.999000012874603,0.00361910232305527,0.999000012874603,,,0.000229638510382928,7.74626086061111e-005,0.000111458349674058,,20,3.11489981412888,-11.6018152236938,3.61910232305527,
,6050429.50,4417,5.00025010108948,300.687620544434,179.975601196289,0.00321700104475021,0.999000012874603,-0.0117888254642487,0.999000012874603,0.00345100299119949,0.999000012874603,,,0.000518785921912697,6.02990330432696e-005,0.000107508931226284,,20,3.21700104475021,-11.7888254642487,3.45100299119949,
,6050468.03,4417,5.00034999847412,240.769226837158,179.975601196289,0.00269120217561722,0.999000012874603,-0.0119319320678711,0.999000012874603,0.00311022833585739,0.999000012874603,,,0.000400896824649839,6.09113297996894e-005,0.000121195725834482,,20,2.69120217561722,-11.9319320678711,3.11022833585739,
,6050507.69,4417,4.99995017051697,180.697920227051,179.975601196289,0.00273462578654289,0.999000012874603,-0.0121397065162659,0.999000012874603,0.00292427431344986,0.999000012874603,,,0.000618105457216445,6.13512291107246e-005,0.000142933547345553,,20,2.73462578654289,-12.1397065162659,2.92427431344986,
,6050545.97,4417,5.00009989738464,120.620871734619,179.975601196289,0.00268286867141724,0.999000012874603,-0.0123543734550476,0.999000012874603,0.00270292211771011,0.999000012874603,,,0.00032988833954381,5.46393477116924e-005,0.000139431034781662,,20,2.68286867141724,-12.3543734550476,2.70292211771011,
,6050584.64,4417,5.00059986114502,60.7657148361206,179.975601196289,0.0023740258038044,0.999000012874603,-0.012553866147995,0.999000012874603,0.00252416328191757,0.999000012874603,,,0.000330864956643305,6.95135504803758e-005,0.000107637177493697,,20,2.3740258038044,-12.553866147995,2.52416328191757,
,6050624.64,4417,5.00010013580322,0.689813938736916,179.975601196289,0.0022604749917984,0.999000012874603,-0.012788069152832,0.999000012874603,0.00227439711093903,0.999000012874603,,,0.000497357023209125,5.93800784600458e-005,0.000102740447753337,,20,2.2604749917984,-12.788069152832,2.27439711093903,
,6050663.88,4417,5.00099992752075,-59.3274532318115,179.975601196289,0.00190591214895248,0.999000012874603,-0.0129578347682953,0.999000012874603,0.00206488935947418,0.999000012874603,,,0.000460462469699388,5.46488206586211e-005,9.72286088067599e-005,,20,1.90591214895248,-12.9578347682953,2.06488935947418,
,6050702.61,4417,5,-119.405652999878,179.975601196289,0.00155886200666428,0.999000012874603,-0.0131859117507935,0.999000012874603,0.00180716451406479,0.999000012874603,,,0.000416343513669943,7.74120388339929e-005,0.000136750266120206,,20,1.55886200666428,-13.1859117507935,1.80716451406479,
,6050743.59,4417,4.99994993209839,-179.325194549561,179.975601196289,0.00117121067345142,0.999000012874603,-0.0134124843597412,0.999000012874603,0.00160211243033409,0.999000012874603,,,0.000487189813035998,6.99253901660072e-005,0.000129716882466983,,20,1.17121067345142,-13.4124843597412,1.60211243033409,
,6050783.08,4417,5,-239.382696533203,179.975601196289,0.00125457206517458,0.999000012874603,-0.0136119684696198,0.999000012874603,0.00141672957539558,0.999000012874603,,,0.000467719325859294,8.50698900944381e-005,0.000107479368709012,,20,1.25457206517458,-13.6119684696198,1.41672957539558,
,6050824.27,4417,5.00014996528625,-299.409164428711,179.975601196289,0.00126084844693542,0.999000012874603,-0.0137708976745605,0.999000012874603,0.00114780555963516,0.999000012874603,,,0.000528018672029009,5.15315438276125e-005,0.000150118100227342,,20,1.26084844693542,-13.7708976745605,1.14780555963516,
,6050863.98,4417,5.00045013427734,-359.321807861328,179.975601196289,0.000447127053816803,0.999000012874603,-0.0140055002212524,0.999000012874603,0.000939498293399811,0.999000012874603,,,0.000404131543061719,4.84000033000352e-005,0.000122145049874365,,20,0.447127053816803,-14.0055002212524,0.939498293399811,
,6050903.45,4417,4.99955010414124,-419.344812011719,179.975601196289,0.000420240274816752,0.999000012874603,-0.0142193073272705,0.999000012874603,0.000715459084510803,0.999000012874603,,,0.000301277719640223,7.51928985107758e-005,0.000116725279006857,,20,0.420240274816751,-14.2193073272705,0.715459084510803,
,6050942.92,4417,4.99895000457764,-479.360935974121,179.975601196289,0.000376081283693202,0.999000012874603,-0.0143942029953003,0.999000012874603,0.000523019361123443,0.999000012874603,,,0.000629900293883814,8.09511750660686e-005,0.000155856329781221,,20,0.376081283693202,-14.3942029953003,0.523019361123443,
,6050982.17,4417,4.99974989891052,-539.525360107422,179.975601196289,8.34463130682707e-005,0.999000012874603,-0.0146517031669617,0.999000012874603,0.000285378768807277,0.999000012874603,,,0.000394215344090503,7.54647384164688e-005,0.000137886436365979,,20,0.0834463130682707,-14.6517031669617,0.285378768807277,
,6051020.34,4417,5.00029993057251,-599.375921630859,179.975601196289,-0.000370603747246787,0.999000012874603,-0.0148455341815949,0.999000012874603,3.933249944821e-005,0.999000012874603,,,0.000427084903131364,7.14784713448705e-005,0.000163282336187912,,20,-0.370603747246787,-14.8455341815948,0.03933249944821,
,6051061.50,4417,5.00004982948303,-659.421923828125,179.975601196289,-0.000404083838500082,0.999000012874603,-0.0149845285892487,0.999000012874603,-0.000112983019277453,0.999000012874603,,,0.000628614782179485,7.80258877656205e-005,0.000126606267971429,,20,-0.404083838500083,-14.9845285892487,-0.112983019277453,
,6051099.73,4417,4.9993999004364,-719.479446411133,179.975601196289,-0.000259966000542045,0.999000012874603,-0.0152412471294403,0.999000012874603,-0.000372566997632384,0.999000012874603,,,0.000560990942029042,6.6962539049423e-005,0.000143495543042415,,20,-0.259966000542045,-15.2412471294403,-0.372566997632384,
,6051139.06,4417,4.9993999004364,-779.395532226563,179.975601196289,-0.000655559276416898,0.999000012874603,-0.0154255979537964,0.999000012874603,-0.000609538359940052,0.999000012874603,,,0.00051619839461443,0.000101918870596245,0.000165139175271529,,20,-0.655559276416898,-15.4255979537964,-0.609538359940052,
,6051180.17,4417,5.00049996376038,-839.376007080078,179.975601196289,-0.00100249218791723,0.999000012874603,-0.0156254719734192,0.999000012874603,-0.00112089302539825,0.999000012874603,,,0.00039166564406662,6.82419005769e-005,0.000139469509552452,,20,-1.00249218791723,-15.6254719734192,-1.12089302539825,
,6051221.11,4417,4.99994993209839,-899.166806030273,179.975601196289,-0.000785646806284785,0.999000012874603,-0.0158215014457703,0.999000012874603,-0.00121580463647842,0.999000012874603,,,0.000569159436782436,6.52802326245449e-005,9.12490085017352e-005,,20,-0.785646806284785,-15.8215014457703,-1.21580463647842,
,6051259.23,4417,4.99875020980835,-959.179458618164,179.975601196289,-0.00114851315021515,0.999000012874603,-0.0159945750713348,0.999000012874603,-0.00144044005870819,0.999000012874603,,,0.000446719556273546,6.46954172458593e-005,0.000120490669770567,,20,-1.14851315021515,-15.9945750713348,-1.44044005870819,
,6051297.27,4417,4.99970006942749,-1019.39331665039,179.975601196289,-0.00145866558104753,0.999000012874603,-0.0162224627494812,0.999000012874603,-0.00169558534026146,0.999000012874603,,,0.000433405255297295,7.05233534764516e-005,0.000129569933723539,,20,-1.45866558104753,-16.2224627494812,-1.69558534026146,
,6051337.83,4417,4.99884986877441,-1079.41976928711,179.975601196289,-0.00136193050667644,0.999000012874603,-0.0163999852180481,0.999000012874603,-0.00185725612044334,0.999000012874603,,,0.000589882138908484,6.91110697488825e-005,9.67487761993681e-005,,20,-1.36193050667644,-16.3999852180481,-1.85725612044334,
,6051376.53,4417,5.00005006790161,-1139.4899230957,179.975601196289,-0.00161550946235657,0.999000012874603,-0.0166216213226318,0.999000012874603,-0.0020852831184864,0.999000012874603,,,0.000453130175841209,5.05201062543278e-005,0.00012811907151445,,20,-1.61550946235657,-16.6216213226318,-2.0852831184864,
,6051417.05,4417,5.00049996376038,-1199.38533935547,179.975601196289,-0.00208870006203651,0.999000012874603,-0.0168114763259888,0.999000012874603,-0.00227860793471336,0.999000012874603,,,0.000383109600356356,5.39868903266357e-005,0.000163307560452472,,20,-2.08870006203651,-16.8114763259888,-2.27860793471336,
,6051456.25,4417,4.99969983100891,-1259.42561035156,179.975601196289,-0.00192915451601148,0.999000012874603,-0.0170317461013794,0.999000012874603,-0.00250661191940308,0.999000012874603,,,0.000487335056012373,0.000114608512294124,0.000115748509166119,,20,-1.92915451601148,-17.0317461013794,-2.50661191940308,
,6051495.94,4417,5.00110006332397,-1319.46471557617,179.975601196289,-0.00241916089057922,0.999000012874603,-0.0172126949310303,0.999000012874603,-0.00260834285020828,0.999000012874603,,,0.000456091121460965,7.06079940656128e-005,0.00015694891592032,,20,-2.41916089057922,-17.2126949310303,-2.60834285020828,
,6051534.11,4417,5,-1379.20258789063,179.975601196289,-0.00256786050200462,0.999000012874603,-0.0174055018424988,0.999000012874603,-0.00288685003519058,0.999000012874603,,,0.000467338916879045,8.69712524676664e-005,9.10326582385444e-005,,20,-2.56786050200462,-17.4055018424988,-2.88685003519058,
,6051575.03,4417,5.00094985961914,-1439.1417175293,179.975601196289,-0.00279041802883148,0.999000012874603,-0.0175891045570374,0.999000012874603,-0.00311399034261704,0.999000012874603,,,0.000485244327493125,9.40866247366144e-005,0.000151039943096495,,20,-2.79041802883148,-17.5891045570374,-3.11399034261704,
,6051613.34,4421,4.9974000453949,-1499.4912109375,179.975601196289,-0.00275074483752251,0.999000012874603,-0.0177389044761658,0.999000012874603,-0.00331153098344803,0.999000012874603,,,0.000583288559229507,8.78868814055867e-005,0.00013849464666992,,20,-2.75074483752251,-17.7389044761658,-3.31153098344803,
,6051652.61,4421,4.99815011024475,-1559.51187133789,179.975601196289,-0.00306832920312881,0.999000012874603,-0.0179850608825684,0.999000012874603,-0.00351807076931,0.999000012874603,,,0.000323174244585131,6.15149966044892e-005,0.000145102218723927,,20,-3.06832920312881,-17.9850608825684,-3.51807076931,
,6051690.83,4421,4.99770021438599,-1619.4372253418,179.975601196289,-0.00324242757558823,0.999000012874603,-0.0182291546821594,0.999000012874603,-0.00364691941738129,0.999000012874603,,,0.00049192793709813,7.54190330096983e-005,0.000129855925385099,,20,-3.24242757558823,-18.2291546821594,-3.64691941738129,
,6051729.58,4421,4.99790000915527,-1679.46022949219,179.975601196289,-0.00362362710237503,0.999000012874603,-0.0184176294326782,0.999000012874603,-0.00391213814020157,0.999000012874603,,,0.000547061274005927,8.47580107660128e-005,9.29691702400809e-005,,20,-3.62362710237503,-18.4176294326782,-3.91213814020157,
,6051771.77,4421,4.99849987030029,-1739.63726806641,179.975601196289,-0.0037034375667572,0.999000012874603,-0.0186229361534119,0.999000012874603,-0.0040615318775177,0.999000012874603,,,0.000526803224273705,7.62862960974331e-005,0.000126174022268321,,20,-3.7034375667572,-18.6229361534119,-4.0615318775177,
,6051813.81,4421,4.99965000152588,-1799.37864990234,179.975601196289,-0.00397609139680862,0.999000012874603,-0.0188056073188782,0.999000012874603,-0.00428459601402283,0.999000012874603,,,0.000501917019388924,0.000106405843255248,0.000112276058485251,,20,-3.97609139680862,-18.8056073188782,-4.28459601402283,
,6051855.42,4417,5.00184988975525,-1859.61090087891,179.975601196289,-0.00397849454879761,0.999000012874603,-0.018997401714325,0.999000012874603,-0.0044894859790802,0.999000012874603,,,0.000486500292107409,8.45250820449053e-005,0.00013740508159784,,20,-3.97849454879761,-18.997401714325,-4.4894859790802,
,6051898.47,4417,5.0060498714447,-1919.69030151367,179.975601196289,-0.0042886340379715,0.999000012874603,-0.0192366846084595,0.999000012874603,-0.00463997187614441,0.999000012874603,,,0.000407364734208175,9.64141044827995e-005,0.000127150177698795,,20,-4.2886340379715,-19.2366846084595,-4.63997187614441,
,6051940.72,4417,5.00104999542236,-1979.67533569336,179.975601196289,-0.00428242665529251,0.999000012874603,-0.0194405724525452,0.999000012874603,-0.00486725766658783,0.999000012874603,,,0.000482931484895712,8.67794167514378e-005,0.000144430730956758,,20,-4.28242665529251,-19.4405724525452,-4.86725766658783,
,6051979.55,4417,5.0006000995636,-1980.56748046875,179.975601196289,-0.00436531909704208,0.999000012874603,-0.0194348423957825,0.999000012874603,-0.00487967252731323,0.999000012874603,,,0.000516896013993245,0.000103968496550136,0.000121957285059062,,20,-4.36531909704208,-19.4348423957825,-4.87967252731323,
,6052018.25,4417,5.00034999847412,-1920.58240356445,179.975601196289,-0.00402650618553162,0.999000012874603,-0.0191733121871948,0.999000012874603,-0.00467168297767639,0.999000012874603,,,0.00052355166664225,0.000102395306216222,0.000133550701671934,,20,-4.02650618553162,-19.1733121871948,-4.67168297767639,
,6052056.58,4417,5.0002498626709,-1860.48350219727,179.975601196289,-0.00390228325128555,0.999000012874603,-0.0189824412345886,0.999000012874603,-0.00454745986461639,0.999000012874603,,,0.00043183763004551,8.88858595784738e-005,0.000123605097782817,,20,-3.90228325128555,-18.9824412345886,-4.54745986461639,
,6052096.25,4417,5.00034999847412,-1800.55598144531,179.975601196289,-0.00383710604906082,0.999000012874603,-0.0187910401344299,0.999000012874603,-0.00434988491535187,0.999000012874603,,,0.000528911765152548,6.78487918766371e-005,0.00014844167967529,,20,-3.83710604906082,-18.7910401344299,-4.34988491535187,
,6052135.70,4417,5.00069999694824,-1740.53406982422,179.975601196289,-0.00369839171171188,0.999000012874603,-0.018585181427002,0.999000012874603,-0.00411956580877304,0.999000012874603,,,0.000304500048817485,6.05588324783434e-005,0.000131190314438655,,20,-3.69839171171188,-18.585181427002,-4.11956580877304,
,6052175.27,4417,5.00049996376038,-1680.35236816406,179.975601196289,-0.00335389903783798,0.999000012874603,-0.018376296043396,0.999000012874603,-0.00399665727615356,0.999000012874603,,,0.00048707083936893,8.62381471591765e-005,0.000137298595928373,,20,-3.35389903783798,-18.376296043396,-3.99665727615356,
,6052215.56,4417,5.00195002555847,-1620.8880859375,179.975601196289,-0.00330500787496567,0.999000012874603,-0.0182082403182983,0.999000012874603,-0.00374029693603516,0.999000012874603,,,0.000420338238688483,8.85490827589185e-005,0.000103228895841965,,20,-3.30500787496567,-18.2082403182983,-3.74029693603516,
,6052254.52,4417,4.99924993515015,-1560.39256591797,179.975601196289,-0.00283193960189819,0.999000012874603,-0.0179763095855713,0.999000012874603,-0.00354150334596634,0.999000012874603,,,0.000503392431075102,8.43886527095147e-005,0.000125293685387473,,20,-2.83193960189819,-17.9763095855713,-3.54150334596634,
,6052297.94,4417,5.00039982795715,-1500.33969726563,179.975601196289,-0.00306644117832184,0.999000012874603,-0.0177700422286987,0.999000012874603,-0.00335472283363342,0.999000012874603,,,0.00056870799692501,9.5947631834791e-005,0.000124023278821325,,20,-3.06644117832184,-17.7700422286987,-3.35472283363342,
,6052340.92,4417,5.00044989585876,-1440.50178222656,179.975601196289,-0.00277046319246292,0.999000012874603,-0.0175960747718811,0.999000012874603,-0.00321013596057892,0.999000012874603,,,0.000567339648489902,7.49277648947059e-005,0.000118702265819246,,20,-2.77046319246292,-17.5960747718811,-3.21013596057892,
,6052381.38,4417,5.00129985809326,-1380.37642211914,179.975601196289,-0.00266321646571159,0.999000012874603,-0.0173567427635193,0.999000012874603,-0.00295847158432007,0.999000012874603,,,0.000501915896308672,6.32600157911527e-005,0.000114893023609124,,20,-2.66321646571159,-17.3567427635193,-2.95847158432007,
,6052421.00,4417,4.99989986419678,-1320.35915527344,179.975601196289,-0.00242697418928146,0.999000012874603,-0.0171916404724121,0.999000012874603,-0.0027643404006958,0.999000012874603,,,0.000389499365052542,6.63987983787087e-005,0.000127987197555359,,20,-2.42697418928146,-17.1916404724121,-2.7643404006958,
,6052462.05,4417,4.99844980239868,-1260.90180664063,179.975601196289,-0.00235084596276283,0.999000012874603,-0.0169774826049805,0.999000012874603,-0.00256139937639236,0.999000012874603,,,0.000518266166532411,8.6946059361596e-005,0.000104830482259032,,20,-2.35084596276283,-16.9774826049805,-2.56139937639236,
,6052499.44,4417,5.00059986114502,-1200.85234985352,179.975601196289,-0.00223579296469688,0.999000012874603,-0.0167863279342651,0.999000012874603,-0.00235497179031372,0.999000012874603,,,0.000510783956029382,9.99779232089872e-005,0.000148148172775832,,20,-2.23579296469688,-16.7863279342651,-2.35497179031372,
,6052540.59,4417,4.99935007095337,-1140.3418762207,179.975601196289,-0.00211003214120865,0.999000012874603,-0.016571280670166,0.999000012874603,-0.00214125439524651,0.999000012874603,,,0.000466245034948459,7.21381553772186e-005,0.000117033423184988,,20,-2.11003214120865,-16.571280670166,-2.14125439524651,
,6052580.91,4417,5.00194978713989,-1080.91094360352,179.975601196289,-0.00181926718950272,0.999000012874603,-0.0163756017684937,0.999000012874603,-0.00188182265758514,0.999000012874603,,,0.000471799495469549,6.66555373948e-005,0.000155549482778397,,20,-1.81926718950272,-16.3756017684937,-1.88182265758514,
,6052619.63,4417,4.99860000610352,-1020.8580291748,179.975601196289,-0.00151903074979782,0.999000012874603,-0.0161527037620544,0.999000012874603,-0.00176360194683075,0.999000012874603,,,0.000482701639165558,7.17146466268861e-005,0.000153063609459727,,20,-1.51903074979782,-16.1527037620544,-1.76360194683075,
,6052659.66,4417,5.00045013427734,-960.321081542969,179.975601196289,-0.00147520629763603,0.999000012874603,-0.0159733144283295,0.999000012874603,-0.00149965615868568,0.999000012874603,,,0.000483106324010266,0.000100464207209124,0.000138725681050791,,20,-1.47520629763603,-15.9733144283295,-1.49965615868568,
,6052697.78,4417,4.99930000305176,-900.7453125,179.975601196289,-0.00131968456506729,0.999000012874603,-0.015769180059433,0.999000012874603,-0.00135644859671593,0.999000012874603,,,0.000632485057535947,6.02420472791048e-005,0.00012498283494993,,20,-1.31968456506729,-15.769180059433,-1.35644859671593,
,6052735.73,4417,5.00049996376038,-840.872897338867,179.975601196289,-0.00117119252085686,0.999000012874603,-0.0155773326396942,0.999000012874603,-0.00107160675525665,0.999000012874603,,,0.000362540533219028,7.25405574075259e-005,0.000100358733224897,,20,-1.17119252085686,-15.5773326396942,-1.07160675525665,
,6052774.64,4417,4.99934983253479,-780.81311340332,179.975601196289,-0.000897553420811892,0.999000012874603,-0.0153997400760651,0.999000012874603,-0.000904524526000023,0.999000012874603,,,0.000499222163167067,6.83579183052028e-005,0.000161299803915904,,20,-0.897553420811892,-15.3997400760651,-0.904524526000023,
,6052814.47,4417,5.00049996376038,-720.599252319336,179.975601196289,-0.000952062679640949,0.999000012874603,-0.0151697863578796,0.999000012874603,-0.000751432406902313,0.999000012874603,,,0.000478829422439095,7.00862854608801e-005,0.000113372784032664,,20,-0.952062679640949,-15.1697863578796,-0.751432406902313,
,6052853.92,4417,5.00185012817383,-660.890103149414,179.975601196289,-0.000761459137871861,0.999000012874603,-0.0149927433013916,0.999000012874603,-0.000476604281365871,0.999000012874603,,,0.000483219386779806,7.38168457467716e-005,0.000132689521913203,,20,-0.761459137871861,-14.9927433013916,-0.476604281365871,
,6052892.52,4417,4.99935007095337,-600.838339233398,179.975601196289,-0.000561226916965097,0.999000012874603,-0.0147847048282623,0.999000012874603,-0.000282380126602948,0.999000012874603,,,0.000527025793770902,4.6699155566952e-005,0.000137084779129361,,20,-0.561226916965097,-14.7847048282623,-0.282380126602948,
,6052932.52,4417,5.00025010108948,-540.892337036133,179.975601196289,-0.000344086822471581,0.999000012874603,-0.0145548539161682,0.999000012874603,-0.00012478398764506,0.999000012874603,,,0.000493323629135586,5.92228531308756e-005,0.00014815861968979,,20,-0.344086822471581,-14.5548539161682,-0.12478398764506,
,6052973.70,4417,5.00095009803772,-480.848648071289,179.975601196289,-7.99114061985165e-005,0.999000012874603,-0.0143531177043915,0.999000012874603,9.43279168801382e-005,0.999000012874603,,,0.0004865907074699,6.39448690052283e-005,0.00013243175302333,,20,-0.0799114061985165,-14.3531177043915,0.0943279168801382,
,6053014.61,4417,4.99895000457764,-420.776184082031,179.975601196289,8.12681969255209e-005,0.999000012874603,-0.014129017829895,0.999000012874603,0.000400133727490902,0.999000012874603,,,0.000656973323924389,5.73472117864435e-005,0.000118417465754276,,20,0.0812681969255209,-14.129017829895,0.400133727490902,
,6053053.33,4417,5.00009989738464,-360.77042388916,179.975601196289,0.000273326326161623,0.999000012874603,-0.0139753603935242,0.999000012874603,0.000535192419588566,0.999000012874603,,,0.000593926046207295,4.60736836923938e-005,0.000108869763809427,,20,0.273326326161623,-13.9753603935242,0.535192419588566,
,6053092.89,4417,5.00174999237061,-300.841680908203,179.975601196289,0.000398911280662287,0.999000012874603,-0.0137643008708954,0.999000012874603,0.000734695807099342,0.999000012874603,,,0.00035950954132133,6.78348841316671e-005,0.000103961614538499,,20,0.398911280662287,-13.7643008708954,0.734695807099342,
,6053133.80,4417,5.00080013275146,-240.796816253662,179.975601196289,0.000420550919231027,0.999000012874603,-0.0135294563293457,0.999000012874603,0.000997268226742745,0.999000012874603,,,0.000625775004692534,4.8577095965359e-005,0.000152882456767424,,20,0.420550919231027,-13.5294563293457,0.997268226742744,
,6053172.69,4417,4.9985499382019,-180.77035369873,179.975601196289,0.00119729207456112,0.999000012874603,-0.0133496297359467,0.999000012874603,0.00118058212697506,0.999000012874603,,,0.000354067197811847,6.051196748395e-005,0.000119543227837975,,20,1.19729207456112,-13.3496297359467,1.18058212697506,
,6053212.02,4417,4.99945020675659,-120.725497055054,179.975601196289,0.00106103432234377,0.999000012874603,-0.0131316366672516,0.999000012874603,0.00135092816352844,0.999000012874603,,,0.000603982838913412,8.46193181328925e-005,0.000137431922933201,,20,1.06103432234377,-13.1316366672516,1.35092816352844,
,6053253.83,4417,5,-60.7760625839233,179.975601196289,0.00102484767958522,0.999000012874603,-0.0129169768333435,0.999000012874603,0.00156009473800659,0.999000012874603,,,0.000513532235288924,5.16224383865745e-005,0.000142386565866913,,20,1.02484767958522,-12.9169768333435,1.56009473800659,
,6053293.92,4417,5.00239992141724,-0.779489904642105,179.975601196289,0.00152888389527798,0.999000012874603,-0.0127548941612244,0.999000012874603,0.00180301740765572,0.999000012874603,,,0.000394929992690771,8.32732703204697e-005,0.000128790791797643,,20,1.52888389527798,-12.7548941612244,1.80301740765572,