File: data/r92.dat
[Header]
TITLE, default name
FILEOPENTIME,6053459.75,5/27/2021,2:53 PM
BYAPP, Resistivity, 2.1, 1.0
INFO, APPNAME, PPMS MultiVu Application, 1.5.11
INFO, , Sample1 Name
INFO, 1, Sample1 Cross Section
INFO, 1, Sample1 Length
INFO, Ohm-m, Sample1 Units
INFO, , Sample2 Name
INFO, 1, Sample2 Cross Section
INFO, 1, Sample2 Length
INFO, Ohm-m, Sample2 Units
INFO, , Sample3 Name
INFO, 1, Sample3 Cross Section
INFO, 1, Sample3 Length
INFO, Ohm-m, Sample3 Units
INFO, , Sample4 Name
INFO, 1, Sample4 Cross Section
INFO, 1, Sample4 Length
INFO, Ohm-m, Sample4 Units
FIELDGROUP, Resistivity,2,3,4,5,6,7,8,9,10,11,12,13,14,15,16,17,18,19,20,21,22,23,24,25,26,27,28,29,30,31,32,33,34,35,36,37,38,39,40,41
STARTUPGROUP, Resistivity
STARTUPAXIS, X, 2, LINEAR, AUTO
STARTUPAXIS, Y1, 7, LINEAR, AUTO
STARTUPAXIS, Y2, 9, LINEAR, AUTO
STARTUPAXIS, Y3, 11, LINEAR, AUTO
PLOT_APPEARANCE, ALL, HORZ_GRID_ON, VERT_GRID_ON, MARKERS_AND_LINES, ALL_LINES
DATATYPE, TIME, 2
DATATYPE, COMMENT, 1
[Data]
Comment,Time Stamp (sec),Status (code),Temperature (K),Magnetic Field (Oe),Sample Position (deg),Bridge 1 Resistivity (Ohm-m),Bridge 1 Excitation (uA),Bridge 2 Resistivity (Ohm-m),Bridge 2 Excitation (uA),Bridge 3 Resistivity (Ohm-m),Bridge 3 Excitation (uA),Bridge 4 Resistivity (Ohm-m),Bridge 4 Excitation (uA),Bridge 1 Std. Dev. (Ohm-m),Bridge 2 Std. Dev. (Ohm-m),Bridge 3 Std. Dev. (Ohm-m),Bridge 4 Std. Dev. (Ohm-m),Number of Readings,Bridge 1 Resistance (Ohms),Bridge 2 Resistance (Ohms),Bridge 3 Resistance (Ohms),Bridge 4 Resistance (Ohms),Signal 1 Vin (V),Signal 2 Vin (V),Digital Inputs (code),Drive 1 Iout (mA),Drive 1 Ipower (watts),Drive 2 Iout (mA),Drive 2 Ipower (watts),Pressure (),Map 20 (),Map 21 (),Map 22 (),Map 23 (),Map 24 (),Map 25 (),Map 26 (),Map 27 (),Map 28 (),Map 29 ()
,6053709.09,4417,5.00185012817383,-0.761094757914543,179.975601196289,0.00142527054920793,0.999000012874603,-0.0127133330345154,0.999000012874603,0.00176108961701393,0.999000012874603,,,0.000463995035037737,5.78796035820403e-005,7.79625451850919e-005,,20,1.42527054920793,-12.7133330345154,1.76108961701393,
,6053733.50,4417,5.00184988975525,39.1837348937988,179.975601196289,0.00190449830889702,0.999000012874603,-0.0125726871490479,0.999000012874603,0.00191509689688683,0.999000012874603,,,0.000490145866235008,6.43609808908489e-005,0.00011999755212735,,20,1.90449830889702,-12.5726871490479,1.91509689688683,
,6053759.94,4417,5.00445008277893,79.2550281524658,179.975601196289,0.00178142107725143,0.999000012874603,-0.0124508510112762,0.999000012874603,0.00204094312787056,0.999000012874603,,,0.000484326634058278,6.76231815224233e-005,0.000152114354000615,,20,1.78142107725143,-12.4508510112762,2.04094312787056,
,6053788.22,4417,5.00009989738464,119.171113204956,179.975601196289,0.00205030518174171,0.999000012874603,-0.0123464256286621,0.999000012874603,0.00215849743485451,0.999000012874603,,,0.000472205540494002,6.69677344855531e-005,0.000156229579133164,,20,2.05030518174171,-12.3464256286621,2.15849743485451,
,6053814.83,4417,5.00040006637573,159.21481628418,179.975601196289,0.0020229945063591,0.999000012874603,-0.0121440786838532,0.999000012874603,0.00230173513889313,0.999000012874603,,,0.000388675375465816,7.35648631244826e-005,0.000158598793311362,,20,2.0229945063591,-12.1440786838531,2.30173513889313,
,6053840.36,4417,5,199.253919219971,179.975601196289,0.00246328667998314,0.999000012874603,-0.0121110483169556,0.999000012874603,0.00251322458982468,0.999000012874603,,,0.000462164797174619,6.94461300381682e-005,0.000138293084678479,,20,2.46328667998314,-12.1110483169556,2.51322458982468,
,6053866.27,4417,4.9997501373291,239.27003326416,179.975601196289,0.00246462345719337,0.999000012874603,-0.0119249503135681,0.999000012874603,0.00268203965425491,0.999000012874603,,,0.00051658193144103,4.73334904482656e-005,0.000112481941723228,,20,2.46462345719337,-11.9249503135681,2.68203965425491,
,6053892.69,4417,5.00029993057251,279.303378295898,179.975601196289,0.00274973258972168,0.999000012874603,-0.0118203260421753,0.999000012874603,0.00285707471370697,0.999000012874603,,,0.000418034239615478,5.79496270352676e-005,0.000106859867185156,,20,2.74973258972168,-11.8203260421753,2.85707471370697,
,6053919.88,4417,5.00049996376038,319.253964233398,179.975601196289,0.0029376767039299,0.999000012874603,-0.0116645660400391,0.999000012874603,0.00299831925630569,0.999000012874603,,,0.000540596164743366,6.71925473867125e-005,0.000141541998495539,,20,2.9376767039299,-11.6645660400391,2.99831925630569,
,6053946.50,4417,4.99989986419678,359.283863830566,179.975601196289,0.00289742141962051,0.999000012874603,-0.011531717300415,0.999000012874603,0.0031046670794487,0.999000012874603,,,0.000523674707640141,6.28944464109024e-005,0.000120621599599168,,20,2.89742141962051,-11.531717300415,3.1046670794487,
,6053974.58,4417,5.00005006790161,399.295373535156,179.975601196289,0.00322182440757752,0.999000012874603,-0.0113851733207703,0.999000012874603,0.00322545229196548,0.999000012874603,,,0.0004851561997816,6.29640441987717e-005,0.000112184131935359,,20,3.22182440757751,-11.3851733207703,3.22545229196548,
,6054002.39,4417,5.00090003013611,439.597772216797,179.975601196289,0.00297436631321907,0.999000012874603,-0.0112730918884277,0.999000012874603,0.00338985154628754,0.999000012874603,,,0.000582577923290032,7.13486048633131e-005,0.000117494398037464,,20,2.97436631321907,-11.2730918884277,3.38985154628754,
,6054030.14,4417,5.00164985656738,479.615019226074,179.975601196289,0.00343553967475891,0.999000012874603,-0.0111199077129364,0.999000012874603,0.00353628165721893,0.999000012874603,,,0.000516604624189655,6.04398909656953e-005,0.000156472354372721,,20,3.43553967475891,-11.1199077129364,3.53628165721893,
,6054058.02,4417,4.99714994430542,519.558703613281,179.975601196289,0.00342007033824921,0.999000012874603,-0.0109814469337463,0.999000012874603,0.00365803146362305,0.999000012874603,,,0.000503894443068684,6.21888475484962e-005,0.000121344306643713,,20,3.42007033824921,-10.9814469337463,3.65803146362305,
,6054086.28,4417,5.00174999237061,559.608139038086,179.975601196289,0.00355689269304276,0.999000012874603,-0.0108591896533966,0.999000012874603,0.00380327578783035,0.999000012874603,,,0.000448795470839688,7.51302092919e-005,0.000115505358002369,,20,3.55689269304276,-10.8591896533966,3.80327578783035,
,6054112.94,4417,5.00015020370483,599.574841308594,179.975601196289,0.00367148952484131,0.999000012874603,-0.0106938841342926,0.999000012874603,0.00400038228034973,0.999000012874603,,,0.000401179705395374,6.24099616380517e-005,0.000154768745939082,,20,3.67148952484131,-10.6938841342926,4.00038228034973,
,6054139.59,4417,4.99834990501404,639.623114013672,179.975601196289,0.00377572360038757,0.999000012874603,-0.0105906285762787,0.999000012874603,0.00412570788860321,0.999000012874603,,,0.000576516163807829,7.76419313993374e-005,0.000106663695304885,,20,3.77572360038757,-10.5906285762787,4.12570788860321,
,6054166.47,4417,5.00125002861023,679.585202026367,179.975601196289,0.00406545134782791,0.999000012874603,-0.0104067073345184,0.999000012874603,0.00426245484352112,0.999000012874603,,,0.000621853980134887,7.55738102978038e-005,0.000129242928399103,,20,4.06545134782791,-10.4067073345184,4.26245484352112,
,6054192.84,4417,5.00094985961914,719.132238769531,179.975601196289,0.00417647076845169,0.999000012874603,-0.0103665966510773,0.999000012874603,0.00443506505489349,0.999000012874603,,,0.000514612424194718,6.84583080809376e-005,0.000109242332142133,,20,4.17647076845169,-10.3665966510773,4.43506505489349,
,6054219.48,4417,5.0008499622345,759.373684692383,179.975601196289,0.00407505742311478,0.999000012874603,-0.0102018719673157,0.999000012874603,0.00481436223983765,0.999000012874603,,,0.000666341300136235,7.91288995413513e-005,9.34710132138653e-005,,20,4.07505742311478,-10.2018719673157,4.81436223983765,
,6054246.52,4417,5.00025010108948,799.689855957031,179.975601196289,0.00462850776910782,0.999000012874603,-0.0100745264053345,0.999000012874603,0.00494587483406067,0.999000012874603,,,0.000376908250519457,5.98388439454536e-005,0.000164571410585755,,20,4.62850776910782,-10.0745264053345,4.94587483406067,
,6054273.59,4417,4.99930000305176,839.184027099609,179.975601196289,0.00442103167772293,0.999000012874603,-0.00991989545822144,0.999000012874603,0.00507857713699341,0.999000012874603,,,0.000498058206849685,6.25862318256799e-005,0.000139113178432577,,20,4.42103167772293,-9.91989545822144,5.07857713699341,
,6054300.13,4417,4.99980020523071,879.192092895508,179.975601196289,0.00477133432626724,0.999000012874603,-0.00977925896644592,0.999000012874603,0.00515323970317841,0.999000012874603,,,0.000566161318701648,9.15499820102954e-005,0.000141111373823655,,20,4.77133432626724,-9.77925896644592,5.15323970317841,
,6054327.48,4417,5.00040006637573,919.215072631836,179.975601196289,0.00490193450450897,0.999000012874603,-0.00966636757850647,0.999000012874603,0.00535941407680512,0.999000012874603,,,0.000453648179623955,9.71896538713956e-005,0.000118689220219145,,20,4.90193450450897,-9.66636757850647,5.35941407680511,
,6054355.13,4417,4.99885010719299,959.447332763672,179.975601196289,0.00486946887969971,0.999000012874603,-0.00950948195457458,0.999000012874603,0.00549777507781983,0.999000012874603,,,0.000523906448599772,9.57154178537708e-005,0.000135633020886472,,20,4.86946887969971,-9.50948195457459,5.49777507781982,
,6054382.53,4417,5.00139999389648,999.211663818359,179.975601196289,0.00485969077348709,0.999000012874603,-0.00942539553642273,0.999000012874603,0.00563996047973633,0.999000012874603,,,0.000563208166674602,6.68607976436628e-005,0.000111257928773123,,20,4.85969077348709,-9.42539553642273,5.63996047973633,
,6054409.06,4417,4.9989001750946,1039.24271240234,179.975601196289,0.00549425675868988,0.999000012874603,-0.0092720537185669,0.999000012874603,0.00573859233856201,0.999000012874603,,,0.00052486294912654,9.32481605961913e-005,0.000144415423762756,,20,5.49425675868988,-9.27205371856689,5.73859233856201,
,6054435.86,4417,5.00099992752075,1079.25538330078,179.975601196289,0.00564988207817078,0.999000012874603,-0.00915220737457275,0.999000012874603,0.00590227196216583,0.999000012874603,,,0.000707597282451751,0.000151582522497657,0.000188847073372954,,20,5.64988207817078,-9.15220737457275,5.90227196216583,
,6054461.75,4417,4.99965000152588,1119.2668762207,179.975601196289,0.00569304528236389,0.999000012874603,-0.00899416513442993,0.999000012874603,0.00604579880237579,0.999000012874603,,,0.000464242679484007,7.76290316198835e-005,0.000119041196895757,,20,5.69304528236389,-8.99416513442993,6.04579880237579,
,6054489.77,4417,4.99780011177063,1159.51755371094,179.975601196289,0.00572686002254486,0.999000012874603,-0.00886339716911316,0.999000012874603,0.00606614394187927,0.999000012874603,,,0.000549923887342224,8.68681741468378e-005,9.95569783350754e-005,,20,5.72686002254486,-8.86339716911316,6.06614394187927,
,6054515.09,4417,5.00214982032776,1199.51177978516,179.975601196289,0.00617720365524292,0.999000012874603,-0.00876602993011475,0.999000012874603,0.00629111881256104,0.999000012874603,,,0.000757146203783154,8.82504231310575e-005,0.000150029544340577,,20,6.17720365524292,-8.76602993011475,6.29111881256104,
,6054540.94,4417,4.99989986419678,1180.40510864258,179.975601196289,0.0057746331691742,0.999000012874603,-0.00877987546920776,0.999000012874603,0.00621921768188477,0.999000012874603,,,0.000435306603771369,6.76173538987916e-005,0.000133860040241424,,20,5.77463316917419,-8.77987546920776,6.21921768188477,
,6054570.06,4417,5.00020003318787,1140.38553466797,179.975601196289,0.00572592313289642,0.999000012874603,-0.00892040357589722,0.999000012874603,0.00608451550006866,0.999000012874603,,,0.00065153704027946,6.53649647024839e-005,0.00016134129783539,,20,5.72592313289642,-8.92040357589722,6.08451550006866,
,6054597.92,4417,5.00324988365173,1100.43614501953,179.975601196289,0.00532855882644654,0.999000012874603,-0.0090349048614502,0.999000012874603,0.00598452985286713,0.999000012874603,,,0.000614141749364063,8.03054836116598e-005,0.000121917326394209,,20,5.32855882644653,-9.0349048614502,5.98452985286713,
,6054625.88,4417,4.99994993209839,1060.39585571289,179.975601196289,0.00526269040107727,0.999000012874603,-0.00919760494232178,0.999000012874603,0.00577546677589416,0.999000012874603,,,0.000519117310773706,9.27423259414237e-005,0.000150717031029929,,20,5.26269040107727,-9.19760494232178,5.77546677589416,
,6054652.45,4417,5.00005006790161,1020.35676269531,179.975601196289,0.00530384607315063,0.999000012874603,-0.00930111484527588,0.999000012874603,0.00565199937820435,0.999000012874603,,,0.000408380736870629,8.80425343642611e-005,0.000127894747967584,,20,5.30384607315063,-9.30111484527588,5.65199937820435,
,6054680.27,4417,5.00159978866577,980.33030090332,179.975601196289,0.00506124887466431,0.999000012874603,-0.00945071964263916,0.999000012874603,0.00558112242221832,0.999000012874603,,,0.000532279358598625,8.36278045306599e-005,8.37502511904539e-005,,20,5.06124887466431,-9.45071964263916,5.58112242221832,
,6054706.28,4417,4.99880003929138,940.448696899414,179.975601196289,0.00495116347074509,0.999000012874603,-0.00953999094963074,0.999000012874603,0.00536753976345062,0.999000012874603,,,0.000670496192132694,7.00871085177255e-005,0.000136926377156755,,20,4.95116347074509,-9.53999094963074,5.36753976345062,
,6054732.81,4417,5.00139999389648,900.399258422852,179.975601196289,0.00483296267986298,0.999000012874603,-0.00974673156738281,0.999000012874603,0.00529386484622955,0.999000012874603,,,0.000586287017873411,7.88459486779204e-005,0.000163333490064829,,20,4.83296267986298,-9.74673156738281,5.29386484622955,
,6054760.88,4417,5.00150012969971,860.371618652344,179.975601196289,0.00482265110015869,0.999000012874603,-0.00981248307228088,0.999000012874603,0.005122927069664,0.999000012874603,,,0.000491408850149932,7.16988423424444e-005,0.000124517294731667,,20,4.82265110015869,-9.81248307228088,5.122927069664,
,6054786.59,4417,4.99860000610352,820.572833251953,179.975601196289,0.00417531542778015,0.999000012874603,-0.0100371409416199,0.999000012874603,0.0049591835975647,0.999000012874603,,,0.000440857421802391,7.59657434860441e-005,0.000167774439192014,,20,4.17531542778015,-10.0371409416199,4.9591835975647,
,6054812.34,4417,4.9997501373291,780.539468383789,179.975601196289,0.00408260282278061,0.999000012874603,-0.0101595346450806,0.999000012874603,0.00486366481781006,0.999000012874603,,,0.000404885198245812,9.72589559640518e-005,0.000136346665419533,,20,4.08260282278061,-10.1595346450806,4.86366481781006,
,6054836.66,4417,4.99869990348816,740.509567260742,179.975601196289,0.00416996031999588,0.999000012874603,-0.0102653181552887,0.999000012874603,0.00470775799751282,0.999000012874603,,,0.000657579707515357,7.06224027387306e-005,0.000154970149974892,,20,4.16996031999588,-10.2653181552887,4.70775799751282,
,6054862.63,4417,4.99950003623962,700.569338989258,179.975601196289,0.00396276323795319,0.999000012874603,-0.0103854486942291,0.999000012874603,0.0045445170879364,0.999000012874603,,,0.000452661655629943,6.75985482674643e-005,0.000136657615356251,,20,3.96276323795319,-10.3854486942291,4.5445170879364,
,6054888.05,4417,5.00209999084473,660.575088500977,179.975601196289,0.00384494198560715,0.999000012874603,-0.0105132954120636,0.999000012874603,0.00446202318668366,0.999000012874603,,,0.000345577465792783,6.61597360622398e-005,0.000148475689846825,,20,3.84494198560715,-10.5132954120636,4.46202318668365,
,6054915.00,4417,4.99809980392456,620.537109375,179.975601196289,0.00362171595096588,0.999000012874603,-0.0106802439689636,0.999000012874603,0.00428698642253876,0.999000012874603,,,0.000556002439761318,8.55404079137475e-005,8.93493872774585e-005,,20,3.62171595096588,-10.6802439689636,4.28698642253876,
,6054940.55,4417,5.00020003318787,580.807287597656,179.975601196289,0.00334492079019547,0.999000012874603,-0.0108144319534302,0.999000012874603,0.00414636487960815,0.999000012874603,,,0.000533379704454845,7.08445856736585e-005,0.000110590411064115,,20,3.34492079019547,-10.8144319534302,4.14636487960815,
,6054967.38,4417,5,540.748651123047,179.975601196289,0.0031258416056633,0.999000012874603,-0.0109224434375763,0.999000012874603,0.00401648334264755,0.999000012874603,,,0.000415568773550439,7.6205922726507e-005,8.9159725584529e-005,,20,3.1258416056633,-10.9224434375763,4.01648334264755,
,6054992.86,4417,5.00040006637573,500.846354675293,179.975601196289,0.00307288308143616,0.999000012874603,-0.0110507478237152,0.999000012874603,0.00390780804157257,0.999000012874603,,,0.00039993223366626,6.51690101096784e-005,0.000123735396343712,,20,3.07288308143616,-11.0507478237152,3.90780804157257,
,6055020.86,4417,5.00059986114502,460.242741394043,179.975601196289,0.00283356910347939,0.999000012874603,-0.0112214951038361,0.999000012874603,0.0037066927075386,0.999000012874603,,,0.000459672646734118,8.0124272410407e-005,0.000168735241161905,,20,2.83356910347939,-11.2214951038361,3.7066927075386,
,6055048.06,4417,5.00139999389648,420.806079101562,179.975601196289,0.00318216114044189,0.999000012874603,-0.011296485710144,0.999000012874603,0.0036204017162323,0.999000012874603,,,0.000540670224651136,5.88763322682678e-005,0.000109302851938898,,20,3.18216114044189,-11.296485710144,3.6204017162323,
,6055074.94,4417,4.99845004081726,380.777337646484,179.975601196289,0.00281600586175919,0.999000012874603,-0.0114448571681976,0.999000012874603,0.00344329136610031,0.999000012874603,,,0.000407410682419016,7.05487611097061e-005,0.00013950474899788,,20,2.81600586175919,-11.4448571681976,3.44329136610031,
,6055099.58,4417,4.99899983406067,340.791108703613,179.975601196289,0.00248858486413956,0.999000012874603,-0.0116982211589813,0.999000012874603,0.00333435219526291,0.999000012874603,,,0.00059706226203828,6.32034901597264e-005,0.000158675374805886,,20,2.48858486413956,-11.6982211589813,3.33435219526291,
,6055125.14,4417,4.99880003929138,300.743949890137,179.975601196289,0.00276149624586105,0.999000012874603,-0.0117357619285583,0.999000012874603,0.00316260050535202,0.999000012874603,,,0.000580418084531556,8.43474816220797e-005,0.000138413082505338,,20,2.76149624586105,-11.7357619285584,3.16260050535202,
,6055151.20,4417,5.00124979019165,260.847410583496,179.975601196289,0.00208480595946312,0.999000012874603,-0.0118847787857056,0.999000012874603,0.00303010902404785,0.999000012874603,,,0.000410516554494368,5.85654725702251e-005,0.000137270624287375,,20,2.08480595946312,-11.8847787857056,3.03010902404785,
,6055175.34,4417,4.99785017967224,220.772659301758,179.975601196289,0.00258158170580864,0.999000012874603,-0.0120081941127777,0.999000012874603,0.0029163125038147,0.999000012874603,,,0.000408354494644639,8.2191951553464e-005,0.000155907454580914,,20,2.58158170580864,-12.0081941127777,2.9163125038147,
,6055202.23,4417,5.00005006790161,180.710566711426,179.975601196289,0.00197877964377403,0.999000012874603,-0.0121375978469849,0.999000012874603,0.00279579025506973,0.999000012874603,,,0.000563964921632509,5.56437950048608e-005,0.000150738973408108,,20,1.97877964377403,-12.1375978469849,2.79579025506973,
,6055228.98,4417,5.00080013275146,140.711705780029,179.975601196289,0.0016939734429121,0.999000012874603,-0.0122844103813171,0.999000012874603,0.00264245344400406,0.999000012874603,,,0.000511292047522798,6.89080716983095e-005,0.000123514377295094,,20,1.6939734429121,-12.2844103813171,2.64245344400406,
,6055256.13,4417,5.00125002861023,100.690995407105,179.975601196289,0.00201220215260983,0.999000012874603,-0.0123639436244965,0.999000012874603,0.00251527655124664,0.999000012874603,,,0.000826811960113765,6.58755667584918e-005,0.000128249005020735,,20,2.01220215260983,-12.3639436244965,2.51527655124664,
,6055282.42,4417,5.00069999694824,60.7381223678589,179.975601196289,0.00137406183592975,0.999000012874603,-0.0125792070388794,0.999000012874603,0.00240188680887222,0.999000012874603,,,0.000499274644585259,9.15508064248845e-005,0.000120025833532893,,20,1.37406183592975,-12.5792070388794,2.40188680887222,
,6055308.14,4417,5.00039982795715,20.736958026886,179.975601196289,0.00120476290285587,0.999000012874603,-0.0126334436893463,0.999000012874603,0.00221492273807526,0.999000012874603,,,0.000541375391295681,5.53887528904335e-005,0.000156218588292874,,20,1.20476290285587,-12.6334436893463,2.21492273807526,
,6055332.59,4417,5.00090003013611,-19.3297372817993,179.975601196289,0.000747569833882153,0.999000012874603,-0.0127879417419434,0.999000012874603,0.00199157800674438,0.999000012874603,,,0.000435637367797723,7.74029469207878e-005,0.000116192380514486,,20,0.747569833882153,-12.7879417419434,1.99157800674438,
,6055360.06,4421,5.00079989433289,-59.3332012176514,179.975601196289,0.00140168807059526,0.999000012874603,-0.0127453269004822,0.999000012874603,0.0017750960111618,0.999000012874603,,,0.000444311402147382,0.000222381029643382,0.000207398146982584,,20,1.40168807059526,-12.7453269004822,1.7750960111618,
,6055385.84,4421,4.9976499080658,-99.2975749969482,179.975601196289,0.000769157332181931,0.999000012874603,-0.0129995804786682,0.999000012874603,0.00166214753985405,0.999000012874603,,,0.000553256028837623,8.89333951519226e-005,0.000118483773142924,,20,0.769157332181931,-12.9995804786682,1.66214753985405,
,6055413.05,4421,4.99790000915527,-139.272291564941,179.975601196289,0.000928673803806305,0.999000012874603,-0.0131766454696655,0.999000012874603,0.00160106949210167,0.999000012874603,,,0.000484974171930353,8.96335487960475e-005,0.000145222293893427,,20,0.928673803806305,-13.1766454696655,1.60106949210167,
,6055440.91,4421,4.99814987182617,-179.314846801758,179.975601196289,0.000752220027893782,0.999000012874603,-0.0133336203098297,0.999000012874603,0.00139616163372993,0.999000012874603,,,0.000358341245313764,7.3290926746956e-005,0.000139846065351458,,20,0.752220027893782,-13.3336203098297,1.39616163372993,
,6055468.20,4421,4.99825000762939,-219.28381729126,179.975601196289,0.00064874305780977,0.999000012874603,-0.0134844993591309,0.999000012874603,0.00130025485157967,0.999000012874603,,,0.000650452211661036,8.00225607380026e-005,0.000118457244490459,,20,0.64874305780977,-13.4844993591309,1.30025485157967,
,6055494.88,4421,4.99825000762939,-259.350520324707,179.975601196289,0.000201926654903218,0.999000012874603,-0.0135886613845825,0.999000012874603,0.00117241572737694,0.999000012874603,,,0.000451074426959223,7.26138597019398e-005,0.000112167448082328,,20,0.201926654903218,-13.5886613845825,1.17241572737694,
,6055520.42,4421,4.99825000762939,-299.381565856934,179.975601196289,0.000464470408111811,0.999000012874603,-0.0137393225669861,0.999000012874603,0.000959409269690514,0.999000012874603,,,0.000356830706793721,5.89502166789195e-005,0.000125306819230562,,20,0.464470408111811,-13.7393225669861,0.959409269690514,
,6055546.20,4421,4.99865007400513,-339.288465881348,179.975601196289,0.000165016181394458,0.999000012874603,-0.01385687084198,0.999000012874603,0.000856021445989609,0.999000012874603,,,0.000536641542986815,8.66306782325087e-005,0.000140774200356616,,20,0.165016181394458,-13.85687084198,0.856021445989609,
,6055572.94,4421,4.99945020675659,-379.251686096191,179.975601196289,-5.9207177720964e-006,0.999000012874603,-0.0140570296764374,0.999000012874603,0.000712587231397629,0.999000012874603,,,0.000428409299284607,7.33451841977264e-005,0.000137392622670277,,20,-0.0059207177720964,-14.0570296764374,0.712587231397629,
,6055598.58,4417,4.99969983100891,-419.270092773438,179.975601196289,-0.000427862161770463,0.999000012874603,-0.0141310043811798,0.999000012874603,0.000678029260039329,0.999000012874603,,,0.000718336881254308,7.80773887658128e-005,9.1262525350845e-005,,20,-0.427862161770463,-14.1310043811798,0.67802926003933,
,6055624.19,4417,5.00185012817383,-459.35288848877,179.975601196289,-0.000269645761756692,0.999000012874603,-0.0143089857578278,0.999000012874603,0.000483720069378614,0.999000012874603,,,0.000434497554688804,8.93634624974039e-005,0.00011053705258684,,20,-0.269645761756692,-14.3089857578278,0.483720069378614,
,6055649.73,4417,5.00675010681152,-499.410374450684,179.975601196289,-0.000814531936240382,0.999000012874603,-0.0144562945842743,0.999000012874603,0.000353463507443666,0.999000012874603,,,0.00050247231105965,6.20907470884072e-005,0.00010678110486883,,20,-0.814531936240382,-14.4562945842743,0.353463507443666,
,6055675.30,4417,5,-539.39775390625,179.975601196289,-0.000846135504543781,0.999000012874603,-0.0145330597877502,0.999000012874603,0.000203083976916969,0.999000012874603,,,0.000543511564969371,8.92929745331186e-005,0.00011044129192511,,20,-0.846135504543781,-14.5330597877502,0.203083976916969,
,6055701.05,4417,4.99979996681213,-579.319577026367,179.975601196289,-0.000889252758771181,0.999000012874603,-0.0147391595363617,0.999000012874603,4.97532845125534e-005,0.999000012874603,,,0.000452725198476153,6.03219198692089e-005,0.000124738298529651,,20,-0.889252758771181,-14.7391595363617,0.0497532845125534,
,6055729.23,4417,5.00094985961914,-619.397772216797,179.975601196289,-0.00105356649756432,0.999000012874603,-0.0148168765544891,0.999000012874603,-0.000155857550574001,0.999000012874603,,,0.000371368997033391,7.95161928435377e-005,9.85492109053484e-005,,20,-1.05356649756432,-14.8168765544891,-0.155857550574001,
,6055755.50,4417,5.00005006790161,-659.369039916992,179.975601196289,-0.00112452369183302,0.999000012874603,-0.0149125685691834,0.999000012874603,-0.000364622631296515,0.999000012874603,,,0.000539386756352673,7.44310056040272e-005,0.000155662319402438,,20,-1.12452369183302,-14.9125685691834,-0.364622631296515,
,6055781.05,4417,4.99979996681213,-699.403552246094,179.975601196289,-0.000889548959583044,0.999000012874603,-0.0150449801445007,0.999000012874603,-0.000427059887349606,0.999000012874603,,,0.000350408466558185,6.36777160335557e-005,0.000166744897553273,,20,-0.889548959583044,-15.0449801445007,-0.427059887349606,
,6055806.67,4417,5.00115013122559,-739.407006835938,179.975601196289,-0.00132214760631323,0.999000012874603,-0.0151893703937531,0.999000012874603,-0.00057985412478447,0.999000012874603,,,0.000447378680606782,5.96077015653165e-005,0.00011232647515462,,20,-1.32214760631323,-15.1893703937531,-0.57985412478447,
,6055832.34,4417,5.00130009651184,-779.344964599609,179.975601196289,-0.0011949337258935,0.999000012874603,-0.0153247617721558,0.999000012874603,-0.000722595790028572,0.999000012874603,,,0.000570498180721704,0.000105144416443282,0.000155726858657148,,20,-1.1949337258935,-15.3247617721558,-0.722595790028572,
,6055857.78,4417,5.00159978866577,-819.364501953125,179.975601196289,-0.00160107744634151,0.999000012874603,-0.0154439689159393,0.999000012874603,-0.0010673212736845,0.999000012874603,,,0.000478248075662152,8.7398452717231e-005,0.000135046911512296,,20,-1.60107744634151,-15.4439689159393,-1.0673212736845,
,6055887.33,4417,5.00014996528625,-859.682983398438,179.975601196289,-0.00144113264977932,0.999000012874603,-0.0156058578968048,0.999000012874603,-0.00130651873350143,0.999000012874603,,,0.000385160657317628,7.85877906139956e-005,0.000154547095602128,,20,-1.44113264977932,-15.6058578968048,-1.30651873350143,
,6055915.05,4417,5.00155019760132,-899.417425537109,179.975601196289,-0.00158643928170204,0.999000012874603,-0.0156926407337189,0.999000012874603,-0.00135797753334045,0.999000012874603,,,0.000377867466142264,7.52015290142378e-005,0.000180103269493212,,20,-1.58643928170204,-15.6926407337189,-1.35797753334045,
,6055940.84,4417,4.99810004234314,-939.413998413086,179.975601196289,-0.00196984935998917,0.999000012874603,-0.0158780912876129,0.999000012874603,-0.00161286786794663,0.999000012874603,,,0.000377925883070126,8.4207390374536e-005,0.000155354493320632,,20,-1.96984935998917,-15.8780912876129,-1.61286786794662,
,6055968.61,4417,5.00049996376038,-979.680737304687,179.975601196289,-0.00204178689718246,0.999000012874603,-0.0159914825439453,0.999000012874603,-0.0016538073182106,0.999000012874603,,,0.00041123448204964,8.04168194518231e-005,0.000137461120588345,,20,-2.04178689718246,-15.9914825439453,-1.6538073182106,
,6055997.75,4417,5.00100016593933,-1019.66809997559,179.975601196289,-0.00213259881138802,0.999000012874603,-0.0161480883598328,0.999000012874603,-0.00182712333798409,0.999000012874603,,,0.000319817481632631,6.74392880423936e-005,0.00012153574536957,,20,-2.13259881138802,-16.1480883598328,-1.82712333798409,
,6056024.48,4417,4.99930000305176,-1059.37725219727,179.975601196289,-0.00205609620213509,0.999000012874603,-0.0162591094970703,0.999000012874603,-0.00192841386795044,0.999000012874603,,,0.000476027100975936,5.6804316464122e-005,0.000140441874837532,,20,-2.05609620213509,-16.2591094970703,-1.92841386795044,
,6056050.36,4417,5.00130009651184,-1099.40827026367,179.975601196289,-0.00246177651882172,0.999000012874603,-0.0164070372581482,0.999000012874603,-0.00205332677960396,0.999000012874603,,,0.000345049789192207,6.08180478107285e-005,0.000123313665959888,,20,-2.46177651882172,-16.4070372581482,-2.05332677960396,
,6056076.94,4417,4.99959993362427,-1139.12666015625,179.975601196289,-0.00220011471360922,0.999000012874603,-0.0165156589508057,0.999000012874603,-0.00218674830198288,0.999000012874603,,,0.000575202547067709,6.67333569133255e-005,8.46436390524968e-005,,20,-2.20011471360922,-16.5156589508057,-2.18674830198288,
,6056103.86,4417,4.99700021743774,-1179.38303833008,179.975601196289,-0.00235745670199394,0.999000012874603,-0.0166527605056763,0.999000012874603,-0.00235631102323532,0.999000012874603,,,0.000448323093522396,8.17659878440725e-005,0.000145585337554178,,20,-2.35745670199394,-16.6527605056763,-2.35631102323532,
,6056128.47,4417,5.0006000995636,-1199.37268676758,179.975601196289,-0.00247983112335205,0.999000012874603,-0.0167360431671143,0.999000012874603,-0.00245749027729034,0.999000012874603,,,0.00051084210506315,8.4283002056405e-005,0.000157572480669577,,20,-2.47983112335205,-16.7360431671143,-2.45749027729034,
,6056156.11,4417,5.00114989280701,-1160.3809753418,179.975601196289,-0.0025906759262085,0.999000012874603,-0.0165904459953308,0.999000012874603,-0.00231876712441444,0.999000012874603,,,0.000387442553886887,7.37573072689038e-005,0.000125002994657236,,20,-2.5906759262085,-16.5904459953308,-2.31876712441444,
,6056184.14,4417,5.00114989280701,-1120.31427612305,179.975601196289,-0.00246842033863068,0.999000012874603,-0.0164781428337097,0.999000012874603,-0.00210138901472092,0.999000012874603,,,0.000489786235826373,6.75741933638026e-005,0.000129235023328879,,20,-2.46842033863068,-16.4781428337097,-2.10138901472092,
,6056212.80,4417,4.99885010719299,-1080.7189453125,179.975601196289,-0.00218587954044342,0.999000012874603,-0.0163208015441895,0.999000012874603,-0.00201340815424919,0.999000012874603,,,0.00042570397036268,7.42146358827749e-005,0.000111803804046017,,20,-2.18587954044342,-16.3208015441895,-2.01340815424919,
,6056241.14,4417,4.99889993667603,-1040.87759399414,179.975601196289,-0.00244008338451386,0.999000012874603,-0.0162105893135071,0.999000012874603,-0.00192126634716988,0.999000012874603,,,0.000542878833117433,9.08854761980032e-005,0.000152873340501273,,20,-2.44008338451386,-16.2105893135071,-1.92126634716988,
,6056268.44,4417,4.99895000457764,-1000.85686645508,179.975601196289,-0.0018835377573967,0.999000012874603,-0.0160454386711121,0.999000012874603,-0.00177318503260613,0.999000012874603,,,0.000388501221754288,8.23043970357043e-005,0.000125640210406352,,20,-1.8835377573967,-16.0454386711121,-1.77318503260612,
,6056296.50,4417,4.99830007553101,-960.344085693359,179.975601196289,-0.00191580357551575,0.999000012874603,-0.0159468273639679,0.999000012874603,-0.00159629608392715,0.999000012874603,,,0.000483834314646085,6.99368419436894e-005,0.000140240901546941,,20,-1.91580357551575,-15.9468273639679,-1.59629608392715,
,6056323.58,4417,5.00069999694824,-920.308441162109,179.975601196289,-0.00200454516410828,0.999000012874603,-0.0157827493190765,0.999000012874603,-0.00151403174996376,0.999000012874603,,,0.000449018355632286,6.88781726838088e-005,0.000106324994784869,,20,-2.00454516410828,-15.7827493190765,-1.51403174996376,
,6056351.58,4417,5,-880.303823852539,179.975601196289,-0.00167970055341721,0.999000012874603,-0.0156919421195984,0.999000012874603,-0.00136946538090706,0.999000012874603,,,0.000333048692903023,0.000101040875625517,0.000143853167173139,,20,-1.67970055341721,-15.6919421195984,-1.36946538090706,
,6056377.13,4417,4.99810004234314,-840.877496337891,179.975601196289,-0.00146037052869797,0.999000012874603,-0.015569710111618,0.999000012874603,-0.00121419025361538,0.999000012874603,,,0.000561481500780479,6.19601596031015e-005,0.000154871301596997,,20,-1.46037052869797,-15.569710111618,-1.21419025361538,
,6056402.75,4417,4.99944996833801,-800.578567504883,179.975601196289,-0.00156589004397392,0.999000012874603,-0.0153833083152771,0.999000012874603,-0.00107782661616802,0.999000012874603,,,0.000458466607520137,8.0631589595053e-005,9.8247657889581e-005,,20,-1.56589004397392,-15.3833083152771,-1.07782661616802,
,6056429.80,4417,5.00020003318787,-760.869430541992,179.975601196289,-0.00114401925504208,0.999000012874603,-0.0152528261184692,0.999000012874603,-0.000926042628288269,0.999000012874603,,,0.000444534213219931,7.84488628310436e-005,0.000147801285973856,,20,-1.14401925504208,-15.2528261184692,-0.926042628288269,
,6056457.80,4417,4.99924993515015,-720.343997192383,179.975601196289,-0.00121524599194527,0.999000012874603,-0.0151156242847443,0.999000012874603,-0.00080927287042141,0.999000012874603,,,0.000481953999333717,7.64273516976151e-005,0.000106132209538781,,20,-1.21524599194527,-15.1156242847443,-0.80927287042141,
,6056484.67,4417,4.99930000305176,-680.623373413086,179.975601196289,-0.00118091407734901,0.999000012874603,-0.01500384516716,0.999000012874603,-0.000757082676887512,0.999000012874603,,,0.000599949996960124,6.9341594001041e-005,0.00011191134789941,,20,-1.18091407734901,-15.00384516716,-0.757082676887512,
,6056510.94,4417,5.00055003166199,-640.717630004883,179.975601196289,-0.00104549012668431,0.999000012874603,-0.0148914306163788,0.999000012874603,-0.000521646966040134,0.999000012874603,,,0.000574561261338578,5.91666764013857e-005,0.000167019516635164,,20,-1.04549012668431,-14.8914306163788,-0.521646966040134,
,6056536.61,4417,5.00005006790161,-600.855587768555,179.975601196289,-0.000937971452623606,0.999000012874603,-0.0147598493099213,0.999000012874603,-0.000477818296849728,0.999000012874603,,,0.000430392071885265,7.23212397669044e-005,0.000130997392104334,,20,-0.937971452623606,-14.7598493099213,-0.477818296849728,
,6056562.50,4417,5.00075006484985,-560.854409790039,179.975601196289,-0.000589510305225849,0.999000012874603,-0.0146017905235291,0.999000012874603,-0.000273844436742365,0.999000012874603,,,0.000630827701084041,6.52002312850634e-005,0.000129013221139034,,20,-0.589510305225849,-14.6017905235291,-0.273844436742365,
,6056590.42,4417,5.00089979171753,-520.328997802734,179.975601196289,-0.000482092249812558,0.999000012874603,-0.0144582800865173,0.999000012874603,-0.000145038253092207,0.999000012874603,,,0.000463930671143144,5.98951921657343e-005,0.000131103696245699,,20,-0.482092249812558,-14.4582800865173,-0.145038253092207,
,6056616.36,4417,5.00059986114502,-480.823355102539,179.975601196289,-2.05297632899601e-005,0.999000012874603,-0.014330252122879,0.999000012874603,4.58338897500653e-005,0.999000012874603,,,0.000491251294469922,6.78911767463748e-005,0.000156667824294125,,20,-0.0205297632899601,-14.330252122879,0.0458338897500653,
,6056642.25,4417,4.9980001449585,-440.885403442383,179.975601196289,-0.000371349978726357,0.999000012874603,-0.0141935143470764,0.999000012874603,0.000182285190396942,0.999000012874603,,,0.000446780636624596,7.71953676645528e-005,0.000131525133094851,,20,-0.371349978726357,-14.1935143470764,0.182285190396942,
,6056667.89,4417,5.00094985961914,-400.819883728027,179.975601196289,-0.000289818302541971,0.999000012874603,-0.0140699393749237,0.999000012874603,0.00027434548214078,0.999000012874603,,,0.000487621439861587,5.30567535641202e-005,0.000107951871539544,,20,-0.289818302541971,-14.0699393749237,0.274345482140779,
,6056694.45,4417,5.00110006332397,-360.789971923828,179.975601196289,-0.000140086529101245,0.999000012874603,-0.0139089584827423,0.999000012874603,0.000426562022417784,0.999000012874603,,,0.000565397233623687,7.34076230863239e-005,0.00013107558433128,,20,-0.140086529101245,-13.9089584827423,0.426562022417784,
,6056720.28,4417,5.00255012512207,-320.835932922363,179.975601196289,0.000216861954703927,0.999000012874603,-0.0137954186439514,0.999000012874603,0.000514891983568668,0.999000012874603,,,0.00049076467868647,4.06810995761565e-005,0.00013804091382616,,20,0.216861954703927,-13.7954186439514,0.514891983568668,
,6056745.91,4417,4.99994993209839,-280.812933349609,179.975601196289,7.25750885903837e-006,0.999000012874603,-0.0136747870445251,0.999000012874603,0.000685071474313736,0.999000012874603,,,0.000439826228386903,7.833373823387e-005,0.000109302671802378,,20,0.00725750885903835,-13.6747870445251,0.685071474313736,
,6056770.75,4417,5.00125002861023,-240.792216491699,179.975601196289,0.000671797882765531,0.999000012874603,-0.0134976464271545,0.999000012874603,0.000802433213591576,0.999000012874603,,,0.000607403884517184,7.12107958121808e-005,0.000145921400632962,,20,0.671797882765532,-13.4976464271545,0.802433213591576,
,6056795.98,4417,4.99885010719299,-200.77151184082,179.975601196289,0.000518657134473324,0.999000012874603,-0.0133954276561737,0.999000012874603,0.00100905162394047,0.999000012874603,,,0.000391345592846317,7.26674578275224e-005,0.000109436320371654,,20,0.518657134473324,-13.3954276561737,1.00905162394047,
,6056822.84,4417,4.99905014038086,-160.741603851318,179.975601196289,0.000759748673811555,0.999000012874603,-0.0132370234966278,0.999000012874603,0.0010458121150732,0.999000012874603,,,0.000689399270979861,6.21234637497039e-005,0.000141292783560494,,20,0.759748673811555,-13.2370234966278,1.0458121150732,
,6056849.58,4417,4.99989986419678,-120.759986495972,179.975601196289,0.000970481139421463,0.999000012874603,-0.0130953981399536,0.999000012874603,0.00121617563068867,0.999000012874603,,,0.000339924216519865,5.00628326785057e-005,0.000115868074960809,,20,0.970481139421463,-13.0953981399536,1.21617563068867,
,6056877.55,4417,4.99790000915527,-80.8347030639648,179.975601196289,0.00100190989375114,0.999000012874603,-0.012985103559494,0.999000012874603,0.00135618796944618,0.999000012874603,,,0.000604295557196824,6.88979394696501e-005,0.000156861672474221,,20,1.00190989375114,-12.985103559494,1.35618796944618,
,6056901.92,4417,4.99820017814636,-40.7875509262085,179.975601196289,0.00119528268203139,0.999000012874603,-0.0128214287281036,0.999000012874603,0.00144165396094322,0.999000012874603,,,0.000384360995055751,8.20462992866393e-005,0.000171338876035168,,20,1.19528268203139,-12.8214287281036,1.44165396094322,
,6056928.95,4417,5.00144982337952,-0.758795404434204,179.975601196289,0.00119001003801823,0.999000012874603,-0.0127089443206787,0.999000012874603,0.00170689079165459,0.999000012874603,,,0.000226948665538032,7.74448616054168e-005,0.000135819940924826,,20,1.19001003801823,-12.7089443206787,1.70689079165459,