File: data/r95.dat
[Header]
TITLE, default name
FILEOPENTIME,6068446.47,5/27/2021,7:03 PM
BYAPP, Resistivity, 2.1, 1.0
INFO, APPNAME, PPMS MultiVu Application, 1.5.11
INFO, , Sample1 Name
INFO, 1, Sample1 Cross Section
INFO, 1, Sample1 Length
INFO, Ohm-m, Sample1 Units
INFO, , Sample2 Name
INFO, 1, Sample2 Cross Section
INFO, 1, Sample2 Length
INFO, Ohm-m, Sample2 Units
INFO, , Sample3 Name
INFO, 1, Sample3 Cross Section
INFO, 1, Sample3 Length
INFO, Ohm-m, Sample3 Units
INFO, , Sample4 Name
INFO, 1, Sample4 Cross Section
INFO, 1, Sample4 Length
INFO, Ohm-m, Sample4 Units
FIELDGROUP, Resistivity,2,3,4,5,6,7,8,9,10,11,12,13,14,15,16,17,18,19,20,21,22,23,24,25,26,27,28,29,30,31,32,33,34,35,36,37,38,39,40,41
STARTUPGROUP, Resistivity
STARTUPAXIS, X, 2, LINEAR, AUTO
STARTUPAXIS, Y1, 7, LINEAR, AUTO
STARTUPAXIS, Y2, 9, LINEAR, AUTO
STARTUPAXIS, Y3, 11, LINEAR, AUTO
PLOT_APPEARANCE, ALL, HORZ_GRID_ON, VERT_GRID_ON, MARKERS_AND_LINES, ALL_LINES
DATATYPE, TIME, 2
DATATYPE, COMMENT, 1
[Data]
Comment,Time Stamp (sec),Status (code),Temperature (K),Magnetic Field (Oe),Sample Position (deg),Bridge 1 Resistivity (Ohm-m),Bridge 1 Excitation (uA),Bridge 2 Resistivity (Ohm-m),Bridge 2 Excitation (uA),Bridge 3 Resistivity (Ohm-m),Bridge 3 Excitation (uA),Bridge 4 Resistivity (Ohm-m),Bridge 4 Excitation (uA),Bridge 1 Std. Dev. (Ohm-m),Bridge 2 Std. Dev. (Ohm-m),Bridge 3 Std. Dev. (Ohm-m),Bridge 4 Std. Dev. (Ohm-m),Number of Readings,Bridge 1 Resistance (Ohms),Bridge 2 Resistance (Ohms),Bridge 3 Resistance (Ohms),Bridge 4 Resistance (Ohms),Signal 1 Vin (V),Signal 2 Vin (V),Digital Inputs (code),Drive 1 Iout (mA),Drive 1 Ipower (watts),Drive 2 Iout (mA),Drive 2 Ipower (watts),Pressure (),Map 20 (),Map 21 (),Map 22 (),Map 23 (),Map 24 (),Map 25 (),Map 26 (),Map 27 (),Map 28 (),Map 29 ()
,6068664.09,4417,4.99979996681213,-0.236836203187704,179.975601196289,0.125484980392456,0.999000012874603,0.0154549011230469,0.999000012874603,-0.405039436340332,0.999000012874603,,,0.000409000828857525,0.000310928951861759,0.00188470677129185,,20,125.484980392456,15.4549011230469,-405.039436340332,
,6068689.97,4417,5.00009989738464,49.5964754104614,179.975601196289,0.125248874664307,0.999000012874603,0.0153515295028687,0.999000012874603,-0.40492142791748,0.999000012874603,,,0.000409888105153297,0.000266725872209703,0.0016073100300226,,20,125.248874664307,15.3515295028687,-404.92142791748,
,6068716.55,4417,4.99994993209839,99.3654075622559,179.975601196289,0.124744263076782,0.999000012874603,0.0151652127742767,0.999000012874603,-0.404670071411133,0.999000012874603,,,0.0003574106774569,0.000209170863966349,0.001523318201085,,20,124.744263076782,15.1652127742767,-404.670071411133,
,6068743.38,4417,5.00014996528625,149.593063354492,179.975601196289,0.124492052841187,0.999000012874603,0.0149654758930206,0.999000012874603,-0.404600245666504,0.999000012874603,,,0.000336282470285741,0.000131852559295293,0.00172773609104675,,20,124.492052841187,14.9654758930206,-404.600245666504,
,6068770.42,4417,4.99969983100891,199.195281982422,179.975601196289,0.124687511444092,0.999000012874603,0.0147761086940765,0.999000012874603,-0.403973941040039,0.999000012874603,,,0.000357031299824462,0.000251797654917803,0.000900670608829354,,20,124.687511444092,14.7761086940765,-403.973941040039,
,6068797.58,4417,5.00014996528625,249.374655914307,179.975601196289,0.124134609222412,0.999000012874603,0.0147535762786865,0.999000012874603,-0.405336000061035,0.999000012874603,,,0.000392092809508488,0.000198445816329855,0.00139939151484307,,20,124.134609222412,14.7535762786865,-405.336000061035,
,6068824.84,4417,4.99994993209839,299.248205566406,179.975601196289,0.12396473197937,0.999000012874603,0.0145437100410461,0.999000012874603,-0.404639192199707,0.999000012874603,,,0.000509010622973564,0.000198809081196717,0.0017874840848656,,20,123.96473197937,14.5437100410461,-404.639192199707,
,6068851.81,4417,5.00014996528625,349.344805908203,179.975601196289,0.123618146896362,0.999000012874603,0.0143675530433655,0.999000012874603,-0.405088227844238,0.999000012874603,,,0.000573100564115009,0.000216762718100006,0.00183521497075873,,20,123.618146896362,14.3675530433655,-405.088227844238,
,6068878.42,4417,4.99950003623962,399.208010864258,179.975601196289,0.123232517623901,0.999000012874603,0.0143786943912506,0.999000012874603,-0.405114932250977,0.999000012874603,,,0.000535703396238609,0.000204077832104018,0.00133361669305203,,20,123.232517623901,14.3786943912506,-405.114932250977,
,6068906.28,4417,5,449.642604064941,179.975601196289,0.123083480072021,0.999000012874603,0.0139873406887054,0.999000012874603,-0.405565570068359,0.999000012874603,,,0.000379678704416776,0.000178341188784643,0.00189762099128475,,20,123.083480072021,13.9873406887054,-405.565570068359,
,6068933.13,4417,4.99965000152588,499.570198059082,179.975601196289,0.122444520950317,0.999000012874603,0.0140783044815063,0.999000012874603,-0.405036199951172,0.999000012874603,,,0.000393392872129616,0.000214891690651575,0.00164621213411445,,20,122.444520950317,14.0783044815063,-405.036199951172,
,6068961.58,4417,4.99994993209839,549.318420410156,179.975601196289,0.122496849060059,0.999000012874603,0.013785905456543,0.999000012874603,-0.404735784912109,0.999000012874603,,,0.000487580052005342,0.000269795170353006,0.00155471451586661,,20,122.496849060059,13.785905456543,-404.735784912109,
,6068987.94,4417,5.00005006790161,599.496636962891,179.975601196289,0.122089209365845,0.999000012874603,0.0137165175914764,0.999000012874603,-0.403868075561523,0.999000012874603,,,0.000359249312898062,0.000219154133403812,0.00113683073208881,,20,122.089209365845,13.7165175914764,-403.868075561523,
,6069015.05,4417,4.99980020523071,649.118408203125,179.975601196289,0.121866806030273,0.999000012874603,0.0135101557731628,0.999000012874603,-0.404164392089844,0.999000012874603,,,0.000478120231600268,0.000220786040694813,0.00120368706539799,,20,121.866806030273,13.5101557731628,-404.164392089844,
,6069043.14,4417,4.99990010261536,699.605899047852,179.975601196289,0.121536931610107,0.999000012874603,0.0133568405151367,0.999000012874603,-0.40443448638916,0.999000012874603,,,0.000365531078586292,0.000178206054294161,0.00122089186316519,,20,121.536931610107,13.3568405151367,-404.43448638916,
,6069071.58,4417,4.99985003471375,749.367944335938,179.975601196289,0.12126223449707,0.999000012874603,0.0131606038570404,0.999000012874603,-0.404456455993652,0.999000012874603,,,0.000530095456503175,0.000190982818900875,0.00180256910381771,,20,121.26223449707,13.1606038570404,-404.456455993652,
,6069099.06,4417,4.99994993209839,799.513952636719,179.975601196289,0.120948133850098,0.999000012874603,0.0130927981376648,0.999000012874603,-0.404418545532227,0.999000012874603,,,0.00033450824031882,0.000169062665310109,0.0012947117469197,,20,120.948133850098,13.0927981376648,-404.418545532227,
,6069126.88,4417,5.00025010108948,849.207009887695,179.975601196289,0.120564319992065,0.999000012874603,0.0127506235122681,0.999000012874603,-0.404401376342774,0.999000012874603,,,0.00030417900891988,0.000323928472751383,0.00142307800762987,,20,120.564319992065,12.7506235122681,-404.401376342773,
,6069155.09,4417,4.99995017051697,899.376022338867,179.975601196289,0.120495475769043,0.999000012874603,0.0122940165042877,0.999000012874603,-0.40373995513916,0.999000012874603,,,0.0003979116764172,0.000224568926325972,0.00114649437879413,,20,120.495475769043,12.2940165042877,-403.73995513916,
,6069182.20,4417,4.99990010261536,949.154162597656,179.975601196289,0.12012483215332,0.999000012874603,0.0121558257579803,0.999000012874603,-0.404221801757812,0.999000012874603,,,0.000370345232483079,0.000215408155269732,0.00157147200921266,,20,120.12483215332,12.1558257579803,-404.221801757813,
,6069209.73,4417,5.00255012512207,999.357659912109,179.975601196289,0.119940506362915,0.999000012874603,0.0120173442363739,0.999000012874603,-0.404457218933106,0.999000012874603,,,0.000476978026792015,0.000288785307436441,0.00144049807570755,,20,119.940506362915,12.0173442363739,-404.457218933105,
,6069236.73,4417,5.00064992904663,1049.25880126953,179.975601196289,0.119378481674194,0.999000012874603,0.0119079997062683,0.999000012874603,-0.40393108215332,0.999000012874603,,,0.000420867076644144,0.000293153871474064,0.0016632985497009,,20,119.378481674194,11.9079997062683,-403.93108215332,
,6069262.52,4417,5.00065016746521,1099.44508666992,179.975601196289,0.118925929260254,0.999000012874603,0.0116678759098053,0.999000012874603,-0.403592478942871,0.999000012874603,,,0.000325100541388133,0.000207335912916794,0.0016722442635814,,20,118.925929260254,11.6678759098053,-403.592478942871,
,6069289.63,4417,5.00034999847412,1149.20593261719,179.975601196289,0.118479492950439,0.999000012874603,0.0115453456401825,0.999000012874603,-0.403294427490234,0.999000012874603,,,0.000436349644177962,0.000218478899040853,0.00178415555802922,,20,118.479492950439,11.5453456401825,-403.294427490234,
,6069316.61,4417,5.00030016899109,1199.37154541016,179.975601196289,0.118305674743652,0.999000012874603,0.011403236246109,0.999000012874603,-0.402810609436035,0.999000012874603,,,0.000354000328551927,0.000235003858108495,0.00127415953970887,,20,118.305674743652,11.403236246109,-402.810609436035,
,6069344.41,4417,5.00049996376038,1249.57045288086,179.975601196289,0.117662999343872,0.999000012874603,0.0113640711307526,0.999000012874603,-0.40267562713623,0.999000012874603,,,0.000292018785909145,0.000187010153481266,0.00120090212496496,,20,117.662999343872,11.3640711307526,-402.67562713623,
,6069372.61,4417,5.00025010108948,1299.14851074219,179.975601196289,0.117157353591919,0.999000012874603,0.0112469449043274,0.999000012874603,-0.401790846252441,0.999000012874603,,,0.000513275402209567,0.000208708865728996,0.00101748102292388,,20,117.157353591919,11.2469449043274,-401.790846252441,
,6069400.48,4417,5.00020003318787,1349.63487548828,179.975601196289,0.116987036132813,0.999000012874603,0.0110636410713196,0.999000012874603,-0.401651556396484,0.999000012874603,,,0.000476245116279904,0.000221978994238047,0.00132293083753484,,20,116.987036132813,11.0636410713196,-401.651556396484,
,6069428.23,4417,4.99965000152588,1399.1405090332,179.975601196289,0.116333729934692,0.999000012874603,0.0110183158874512,0.999000012874603,-0.400829753112793,0.999000012874603,,,0.000497582363477497,0.000233005042759951,0.00103524328536899,,20,116.333729934692,11.0183158874512,-400.829753112793,
,6069455.33,4417,4.99994993209839,1449.57284545898,179.975601196289,0.116072466278076,0.999000012874603,0.0108971376895905,0.999000012874603,-0.40121611328125,0.999000012874603,,,0.000364342724533945,0.000279103774491668,0.00112527935668816,,20,116.072466278076,10.8971376895905,-401.21611328125,
,6069480.89,4417,5,1499.20490722656,179.975601196289,0.115647674179077,0.999000012874603,0.0106537332057953,0.999000012874603,-0.400128440856934,0.999000012874603,,,0.000433881780714825,0.000217414605864642,0.000734642837824564,,20,115.647674179077,10.6537332057953,-400.128440856934,
,6069506.69,4417,4.99985003471375,1475.3155456543,179.975601196289,0.115469132232666,0.999000012874603,0.0107367027282715,0.999000012874603,-0.400660624694824,0.999000012874603,,,0.000385679091950864,0.000258201442276821,0.00135281767347205,,20,115.469132232666,10.7367027282715,-400.660624694824,
,6069532.19,4417,5.00010013580322,1425.66042480469,179.975601196289,0.11577759552002,0.999000012874603,0.0108884121894836,0.999000012874603,-0.400852159118652,0.999000012874603,,,0.000402438493358592,0.000230831772554856,0.00126128168406974,,20,115.77759552002,10.8884121894836,-400.852159118652,
,6069569.56,4417,4.99965000152588,1350.40168457031,179.975601196289,0.11627131690979,0.999000012874603,0.011083130979538,0.999000012874603,-0.400459761047363,0.999000012874603,,,0.000543217334254743,0.000183894632261471,0.00102989517525738,,20,116.27131690979,11.083130979538,-400.459761047363,
,6069597.13,4417,5.00029993057251,1300.33615112305,179.975601196289,0.116543746948242,0.999000012874603,0.0111386199474335,0.999000012874603,-0.400496118164063,0.999000012874603,,,0.000463096275679056,0.000222006215431577,0.0012223983029302,,20,116.543746948242,11.1386199474335,-400.496118164063,
,6069622.98,4417,4.99935007095337,1250.42930908203,179.975601196289,0.116948303222656,0.999000012874603,0.0112865211963654,0.999000012874603,-0.399946900939941,0.999000012874603,,,0.000415348523065369,0.000236392736565987,0.00148840582931833,,20,116.948303222656,11.2865211963654,-399.946900939941,
,6069648.70,4417,4.9991500377655,1200.28323974609,179.975601196289,0.117421907424927,0.999000012874603,0.0113491792201996,0.999000012874603,-0.401471835327148,0.999000012874603,,,0.00033617640391269,0.000266544483135081,0.00105002161703034,,20,117.421907424927,11.3491792201996,-401.471835327148,
,6069676.69,4417,4.99965000152588,1150.70864257812,179.975601196289,0.117478820419312,0.999000012874603,0.011562687587738,0.999000012874603,-0.400772654724121,0.999000012874603,,,0.000381939205676457,0.000244653649890039,0.00133959533207368,,20,117.478820419312,11.562687587738,-400.772654724121,
,6069702.34,4417,5.00069999694824,1100.60973510742,179.975601196289,0.117593988800049,0.999000012874603,0.0117249344825745,0.999000012874603,-0.400678211975098,0.999000012874603,,,0.000485293287211847,0.000184938904534488,0.000913364783010116,,20,117.593988800049,11.7249344825745,-400.678211975098,
,6069731.44,4417,5.01749992370605,1050.73843994141,179.975601196289,0.117335412979126,0.999000012874603,0.0121147919654846,0.999000012874603,-0.403407008361816,0.999000012874603,,,0.00119183416431745,0.000383168536829558,0.00316965404404687,,20,117.335412979126,12.1147919654846,-403.407008361816,
,6069757.02,4421,4.99650001525879,1000.53840026855,179.975601196289,0.116965602111816,0.999000012874603,0.0120837594985962,0.999000012874603,-0.399626290893555,0.999000012874603,,,0.000344278234109088,0.000235009455092171,0.00100542314766702,,20,116.965602111816,12.0837594985962,-399.626290893555,
,6069786.05,4421,4.99784994125366,950.652200317383,179.975601196289,0.117183549499512,0.999000012874603,0.0121790154933929,0.999000012874603,-0.399439245605469,0.999000012874603,,,0.000502621922365028,0.000285665329052969,0.00135408831817348,,20,117.183549499512,12.1790154933929,-399.439245605469,
,6069813.19,4421,4.99775004386902,900.510754394531,179.975601196289,0.117657302093506,0.999000012874603,0.0122766119480133,0.999000012874603,-0.399356832885742,0.999000012874603,,,0.000437214256037036,0.000278517259119056,0.00103451107036513,,20,117.657302093506,12.2766119480133,-399.356832885742,
,6069841.92,4421,4.9967999458313,850.688958740234,179.975601196289,0.117966254425049,0.999000012874603,0.0123990532875061,0.999000012874603,-0.399238380432129,0.999000012874603,,,0.000422765859185532,0.000264998553798951,0.00121135075568179,,20,117.966254425049,12.3990532875061,-399.238380432129,
,6069867.75,4421,4.99744987487793,800.429113769531,179.975601196289,0.118311213684082,0.999000012874603,0.0125551064014435,0.999000012874603,-0.400736848449707,0.999000012874603,,,0.000380633931698823,0.000202846767067803,0.00144495997463288,,20,118.311213684082,12.5551064014435,-400.736848449707,
,6069897.00,4421,4.99829983711243,750.841830444336,179.975601196289,0.11871273651123,0.999000012874603,0.0126505240440369,0.999000012874603,-0.399867372131348,0.999000012874603,,,0.000494133725387682,0.000265202165144246,0.00153592712204407,,20,118.71273651123,12.6505240440369,-399.867372131348,
,6069922.70,4421,5.00319981575012,700.787789916992,179.975601196289,0.11911728515625,0.999000012874603,0.0128461625099182,0.999000012874603,-0.401632800292969,0.999000012874603,,,0.000386976246359744,0.000210068406346706,0.00182970949396688,,20,119.11728515625,12.8461625099182,-401.632800292969,
,6069950.53,4421,5.00135016441345,650.867095947266,179.975601196289,0.118996130752563,0.999000012874603,0.0129442196846008,0.999000012874603,-0.400937435913086,0.999000012874603,,,0.000372081184461404,0.000209106790527042,0.00120330726320259,,20,118.996130752563,12.9442196846008,-400.937435913086,
,6069977.14,4417,5.00110006332397,600.649780273438,179.975601196289,0.11932784538269,0.999000012874603,0.013098205280304,0.999000012874603,-0.399775746154785,0.999000012874603,,,0.00049012997781721,0.000186528857465417,0.00141952921003805,,20,119.32784538269,13.098205280304,-399.775746154785,
,6070002.55,4417,5.00095009803772,550.784292602539,179.975601196289,0.119333005142212,0.999000012874603,0.0132123308181763,0.999000012874603,-0.400110389709473,0.999000012874603,,,0.000464870597351627,0.0002160726234748,0.00125450308366683,,20,119.333005142212,13.2123308181763,-400.110389709473,
,6070028.36,4417,5.00049996376038,500.71872253418,179.975601196289,0.119349157714844,0.999000012874603,0.0132668105602264,0.999000012874603,-0.399209365844727,0.999000012874603,,,0.000399500612993457,0.000209624367490967,0.00108572174290977,,20,119.349157714844,13.2668105602264,-399.209365844727,
,6070056.20,4417,5.00355005264282,450.826786804199,179.975601196289,0.120763611602783,0.999000012874603,0.01336038813591,0.999000012874603,-0.400331539916992,0.999000012874603,,,0.000740209340764371,0.000168381789288679,0.00160528884466899,,20,120.763611602783,13.36038813591,-400.331539916992,
,6070081.81,4417,5.00040006637573,400.368034362793,179.975601196289,0.120647744750977,0.999000012874603,0.0135105090618134,0.999000012874603,-0.39879397277832,0.999000012874603,,,0.000487343588906175,0.00018051722757056,0.00157944212855543,,20,120.647744750977,13.5105090618134,-398.79397277832,
,6070109.39,4417,4.99995017051697,350.485292053223,179.975601196289,0.120469836044312,0.999000012874603,0.0136256766319275,0.999000012874603,-0.398201905822754,0.999000012874603,,,0.000262318563483924,0.000196132608616087,0.00145415336133392,,20,120.469836044312,13.6256766319275,-398.201905822754,
,6070137.19,4417,4.99985003471375,300.632441711426,179.975601196289,0.12073123664856,0.999000012874603,0.0137238781929016,0.999000012874603,-0.398322158813477,0.999000012874603,,,0.000417684195034392,0.00020239456676313,0.00107192987858569,,20,120.73123664856,13.7238781929016,-398.322158813477,
,6070164.64,4417,5.00009989738464,250.549634552002,179.975601196289,0.120891886520386,0.999000012874603,0.0137918819904327,0.999000012874603,-0.399270497131348,0.999000012874603,,,0.000350833467701494,0.00026007874984318,0.00182541444575486,,20,120.891886520386,13.7918819904327,-399.270497131348,
,6070192.73,4417,5.00020003318787,200.427750396729,179.975601196289,0.121039302825928,0.999000012874603,0.0140095921516418,0.999000012874603,-0.398395118713379,0.999000012874603,,,0.000503879061263468,0.000173130744230272,0.00161860993420778,,20,121.039302825928,14.0095921516418,-398.395118713379,
,6070219.61,4417,5.00014996528625,150.419689941406,179.975601196289,0.121000699996948,0.999000012874603,0.0142894111633301,0.999000012874603,-0.397559698486328,0.999000012874603,,,0.000446441461928679,0.000186336962400781,0.000988213788936491,,20,121.000699996948,14.2894111633301,-397.559698486328,
,6070247.61,4417,4.99994993209839,100.544989013672,179.975601196289,0.119950926971436,0.999000012874603,0.0143615918159485,0.999000012874603,-0.395779522705078,0.999000012874603,,,0.00109039566301769,0.00028624921685118,0.000999040180809249,,20,119.950926971436,14.3615918159485,-395.779522705078,
,6070275.73,4417,5,50.4828872680664,179.975601196289,0.11942396812439,0.999000012874603,0.0145851130008698,0.999000012874603,-0.395604081726074,0.999000012874603,,,0.000350586088498465,0.000208570492869245,0.00132205811547269,,20,119.42396812439,14.5851130008698,-395.604081726074,
,6070302.61,4417,5.00014996528625,0.651874193549156,179.975601196289,0.119594051361084,0.999000012874603,0.0146022070407867,0.999000012874603,-0.39607737121582,0.999000012874603,,,0.000471994202121301,0.00024708114986465,0.00146456516751783,,20,119.594051361084,14.6022070407867,-396.07737121582,
,6070327.91,4417,5.00069999694824,-49.3033056259155,179.975601196289,0.119636373901367,0.999000012874603,0.014832364654541,0.999000012874603,-0.395425375366211,0.999000012874603,,,0.000350031922231229,0.000258589492943817,0.00131429672264047,,20,119.636373901367,14.832364654541,-395.425375366211,
,6070354.92,4417,5.00034999847412,-99.1515644073486,179.975601196289,0.119803484725952,0.999000012874603,0.0149796129703522,0.999000012874603,-0.394057743835449,0.999000012874603,,,0.00040251412340344,0.00019867826675548,0.00102225269604596,,20,119.803484725952,14.9796129703522,-394.057743835449,
,6070383.80,4417,5.00045013427734,-149.527533721924,179.975601196289,0.119750694274902,0.999000012874603,0.0151467548847198,0.999000012874603,-0.393983192443848,0.999000012874603,,,0.000322589488204649,0.000241540480995486,0.00145856540774463,,20,119.750694274902,15.1467548847198,-393.983192443848,
,6070411.92,4417,5.00014996528625,-199.721848297119,179.975601196289,0.120166421890259,0.999000012874603,0.0151646099567413,0.999000012874603,-0.394087840270996,0.999000012874603,,,0.000555151553030952,0.000167464252068453,0.00156224073691042,,20,120.166421890259,15.1646099567413,-394.087840270996,
,6070439.00,4417,4.99974989891052,-249.622995758057,179.975601196289,0.119967735290527,0.999000012874603,0.0153624332904816,0.999000012874603,-0.39369157409668,0.999000012874603,,,0.000343837752191916,0.000221709646509949,0.00112472461662456,,20,119.967735290527,15.3624332904816,-393.69157409668,
,6070466.75,4417,5.00040006637573,-299.193022155762,179.975601196289,0.120216677093506,0.999000012874603,0.0155358433246613,0.999000012874603,-0.393678105163574,0.999000012874603,,,0.000464958065118257,0.000305804690650737,0.00110469523361282,,20,120.216677093506,15.5358433246613,-393.678105163574,
,6070494.36,4417,5.00104999542236,-349.603479003906,179.975601196289,0.120459637069702,0.999000012874603,0.0156066136360168,0.999000012874603,-0.393294361877441,0.999000012874603,,,0.00038177908230442,0.000241688646792047,0.00139599263604155,,20,120.459637069702,15.6066136360168,-393.294361877441,
,6070522.42,4417,4.99990010261536,-399.150524902344,179.975601196289,0.120351205825806,0.999000012874603,0.0156229703903198,0.999000012874603,-0.392678454589844,0.999000012874603,,,0.00043580840045858,0.000172999788962809,0.00112175103602919,,20,120.351205825806,15.6229703903198,-392.678454589844,
,6070549.53,4417,4.99994993209839,-449.665596008301,179.975601196289,0.12055736656189,0.999000012874603,0.015886615562439,0.999000012874603,-0.392228700256348,0.999000012874603,,,0.000322553406102091,0.000212809932511032,0.00121247778876159,,20,120.55736656189,15.886615562439,-392.228700256348,
,6070576.05,4417,4.99989986419678,-499.256323242187,179.975601196289,0.120435167694092,0.999000012874603,0.0160595496654511,0.999000012874603,-0.39208186340332,0.999000012874603,,,0.000388997750852477,0.000284518788446713,0.00141096891061175,,20,120.435167694092,16.0595496654511,-392.08186340332,
,6070601.53,4417,5.00014996528625,-549.309222412109,179.975601196289,0.120652606201172,0.999000012874603,0.016018200969696,0.999000012874603,-0.391948262023926,0.999000012874603,,,0.000339426240378142,0.000193684819640837,0.00168049990911502,,20,120.652606201172,16.018200969696,-391.948262023926,
,6070629.70,4417,4.99994993209839,-599.162088012695,179.975601196289,0.12061602897644,0.999000012874603,0.0163058554172516,0.999000012874603,-0.391167608642578,0.999000012874603,,,0.000486201284732409,0.000237909090924328,0.000926880326289013,,20,120.61602897644,16.3058554172516,-391.167608642578,
,6070655.28,4417,4.99995017051697,-649.36328125,179.975601196289,0.12076277885437,0.999000012874603,0.0164222425460815,0.999000012874603,-0.390670930480957,0.999000012874603,,,0.000372753328211605,0.000312862977951433,0.0011009069443761,,20,120.76277885437,16.4222425460815,-390.670930480957,
,6070682.33,4417,5.00009989738464,-699.231103515625,179.975601196289,0.120797957611084,0.999000012874603,0.0165102034568787,0.999000012874603,-0.390191947937012,0.999000012874603,,,0.000545744340584145,0.000169415529223469,0.00142709649632069,,20,120.797957611084,16.5102034568787,-390.191947937012,
,6070709.22,4417,5,-749.405871582031,179.975601196289,0.120953116607666,0.999000012874603,0.0166255466461182,0.999000012874603,-0.390043281555176,0.999000012874603,,,0.000316215713895844,0.000228776301533789,0.00129140367210071,,20,120.953116607666,16.6255466461182,-390.043281555176,
,6070734.59,4417,5.00014996528625,-799.218472290039,179.975601196289,0.121108951187134,0.999000012874603,0.0169007740974426,0.999000012874603,-0.390004621887207,0.999000012874603,,,0.000558035940172248,0.000214272018640846,0.000988821340713524,,20,121.108951187134,16.9007740974426,-390.004621887207,
,6070761.17,4417,4.99980020523071,-849.327734375,179.975601196289,0.121268279647827,0.999000012874603,0.0170935334205627,0.999000012874603,-0.389496415710449,0.999000012874603,,,0.000363642610522998,0.000187985994603105,0.000896831977603875,,20,121.268279647827,17.0935334205627,-389.496415710449,
,6070787.97,4417,5.00009989738464,-899.215106201172,179.975601196289,0.12109087562561,0.999000012874603,0.0176692888259888,0.999000012874603,-0.389521908569336,0.999000012874603,,,0.000484053399402513,0.000326054218731697,0.00162369157457493,,20,121.09087562561,17.6692888259888,-389.521908569336,
,6070816.00,4417,5.0008499622345,-949.640466308594,179.975601196289,0.121169859313965,0.999000012874603,0.0178150012016296,0.999000012874603,-0.388143159484863,0.999000012874603,,,0.000330267102738849,0.000228447328348589,0.000833929683770771,,20,121.169859313965,17.8150012016296,-388.143159484863,
,6070842.88,4417,4.99960017204285,-999.150723266602,179.975601196289,0.120917554092407,0.999000012874603,0.0179454517364502,0.999000012874603,-0.387954833984375,0.999000012874603,,,0.000498893747765966,0.000157040446743057,0.000891722812230818,,20,120.917554092407,17.9454517364502,-387.954833984375,
,6070869.91,4417,4.99930000305176,-1049.32777709961,179.975601196289,0.120792820739746,0.999000012874603,0.017987032699585,0.999000012874603,-0.386837199401856,0.999000012874603,,,0.000434518449754784,0.000198796621457234,0.00148885458456582,,20,120.792820739746,17.987032699585,-386.837199401855,
,6070897.44,4417,4.99979996681213,-1099.23124389648,179.975601196289,0.12116563949585,0.999000012874603,0.0180822428703308,0.999000012874603,-0.387485520935059,0.999000012874603,,,0.00049955460884676,0.000218019617286915,0.00210196274552901,,20,121.16563949585,18.0822428703308,-387.485520935059,
,6070924.13,4417,4.99899983406067,-1149.14847412109,179.975601196289,0.120885887527466,0.999000012874603,0.0181992893218994,0.999000012874603,-0.386049526977539,0.999000012874603,,,0.000434839519192244,0.000171016750201092,0.00122588935864481,,20,120.885887527466,18.1992893218994,-386.049526977539,
,6070951.70,4417,4.99965000152588,-1199.21864624023,179.975601196289,0.121284676361084,0.999000012874603,0.0184010230064392,0.999000012874603,-0.385648165893555,0.999000012874603,,,0.000658137558465968,0.000165737360044384,0.000998284782675983,,20,121.284676361084,18.4010230064392,-385.648165893555,
,6070978.42,4417,4.99924993515015,-1249.68657226563,179.975601196289,0.121371237945557,0.999000012874603,0.0187494996070862,0.999000012874603,-0.38607931060791,0.999000012874603,,,0.00045159409980951,0.000220597240794022,0.00146396050753418,,20,121.371237945557,18.7494996070862,-386.07931060791,
,6071003.94,4417,4.99930000305176,-1299.29455566406,179.975601196289,0.121054735565186,0.999000012874603,0.0186697604179382,0.999000012874603,-0.385450932312012,0.999000012874603,,,0.000596701926259911,0.000264975450947165,0.00131365577621929,,20,121.054735565186,18.6697604179382,-385.450932312012,
,6071030.92,4417,5.00110006332397,-1349.13359375,179.975601196289,0.121077178573608,0.999000012874603,0.0187053797721863,0.999000012874603,-0.384605131530762,0.999000012874603,,,0.00042126996168671,0.000172230603471503,0.00173147463064594,,20,121.077178573608,18.7053797721863,-384.605131530762,
,6071056.69,4417,5.00585007667542,-1399.2669921875,179.975601196289,0.121580527114868,0.999000012874603,0.0190711667060852,0.999000012874603,-0.385880421447754,0.999000012874603,,,0.00104205907579838,0.000298931372443559,0.0019258440836623,,20,121.580527114868,19.0711667060852,-385.880421447754,
,6071083.97,4421,4.98985004425049,-1449.69811401367,179.975601196289,0.120375889968872,0.999000012874603,0.01895962266922,0.999000012874603,-0.38189605255127,0.999000012874603,,,0.00066535399038127,0.000227186411419898,0.00175836429067151,,20,120.375889968872,18.95962266922,-381.89605255127,
,6071109.58,4421,4.99804997444153,-1499.31185302734,179.975601196289,0.121139328765869,0.999000012874603,0.0191712337493897,0.999000012874603,-0.382503964233399,0.999000012874603,,,0.000441172026178401,0.000230388863339781,0.00104308892000066,,20,121.139328765869,19.1712337493897,-382.503964233398,
,6071136.30,4421,4.99809980392456,-1475.71679077148,179.975601196289,0.121272509384155,0.999000012874603,0.0191468891143799,0.999000012874603,-0.382979783630371,0.999000012874603,,,0.000427023692765228,0.000214661348036808,0.00109350022848853,,20,121.272509384155,19.1468891143799,-382.979783630371,
,6071164.27,4421,4.99724984169006,-1425.53049316406,179.975601196289,0.121580525588989,0.999000012874603,0.0189171252250671,0.999000012874603,-0.383683825683594,0.999000012874603,,,0.000517920607123953,0.00020047931683839,0.00106675748674704,,20,121.580525588989,18.9171252250671,-383.683825683594,
,6071193.28,4421,4.9974000453949,-1375.45688476563,179.975601196289,0.121437658309937,0.999000012874603,0.0188322255134582,0.999000012874603,-0.384109373474121,0.999000012874603,,,0.000402189960631326,0.000277069876781113,0.000742336464072022,,20,121.437658309937,18.8322255134583,-384.109373474121,
,6071221.09,4421,4.9991500377655,-1325.57875976562,179.975601196289,0.121766796875,0.999000012874603,0.0187011987686157,0.999000012874603,-0.384992137145996,0.999000012874603,,,0.000435913223255678,0.000237872138722644,0.000994135573775444,,20,121.766796875,18.7011987686157,-384.992137145996,
,6071249.59,4421,4.99990010261536,-1275.34878540039,179.975601196289,0.121974016952515,0.999000012874603,0.0185733940124512,0.999000012874603,-0.385616902160645,0.999000012874603,,,0.000402694225555644,0.000301435010522096,0.00107625689684807,,20,121.974016952515,18.5733940124512,-385.616902160645,
,6071277.30,4421,5.00304985046387,-1225.48442382813,179.975601196289,0.121647425460815,0.999000012874603,0.0184008054733276,0.999000012874603,-0.386551063537598,0.999000012874603,,,0.000409043589657789,0.00025294811972382,0.001341913422071,,20,121.647425460815,18.4008054733276,-386.551063537598,
,6071306.31,4417,5.00059986114502,-1175.30048217773,179.975601196289,0.121309239959717,0.999000012874603,0.0183560451507568,0.999000012874603,-0.386425604248047,0.999000012874603,,,0.000387743159079175,0.000260916093447862,0.000999668956885643,,20,121.309239959717,18.3560451507568,-386.425604248047,
,6071334.36,4417,5.00150012969971,-1125.53037719727,179.975601196289,0.121332923126221,0.999000012874603,0.0182424054145813,0.999000012874603,-0.386658613586426,0.999000012874603,,,0.000532188760828195,0.000232846336509474,0.00146190346546109,,20,121.332923126221,18.2424054145813,-386.658613586426,
,6071362.55,4417,5.00804996490479,-1075.65913085938,179.975601196289,0.122721686935425,0.999000012874603,0.0179539326667786,0.999000012874603,-0.389017842102051,0.999000012874603,,,0.000458221070973986,0.00020886975181235,0.000788080130567277,,20,122.721686935425,17.9539326667786,-389.017842102051,
,6071390.45,4417,4.99899983406067,-1025.49013061523,179.975601196289,0.121965753936768,0.999000012874603,0.0176835883140564,0.999000012874603,-0.387356527709961,0.999000012874603,,,0.000552536078545445,0.000204853989264016,0.00155261652726413,,20,121.965753936768,17.6835883140564,-387.356527709961,
,6071419.16,4417,4.99994993209839,-975.828103637695,179.975601196289,0.122038763809204,0.999000012874603,0.0177321552276611,0.999000012874603,-0.387976985168457,0.999000012874603,,,0.000392598406172718,0.000260643713181623,0.00101721435850125,,20,122.038763809204,17.7321552276611,-387.976985168457,
,6071446.00,4417,5,-925.824649047852,179.975601196289,0.122056907653809,0.999000012874603,0.0175041296958923,0.999000012874603,-0.388033416748047,0.999000012874603,,,0.000404070590650516,0.000243615651716113,0.00114463609350886,,20,122.056907653809,17.5041296958923,-388.033416748047,
,6071475.02,4417,4.99994993209839,-875.395794677734,179.975601196289,0.12170690612793,0.999000012874603,0.017428239440918,0.999000012874603,-0.38816965637207,0.999000012874603,,,0.0004579466717775,0.000253538347443868,0.00102056037346283,,20,121.70690612793,17.428239440918,-388.16965637207,
,6071503.34,4417,5.0006000995636,-825.494653320313,179.975601196289,0.121616094207764,0.999000012874603,0.0173312209129333,0.999000012874603,-0.388358920288086,0.999000012874603,,,0.000450537011962175,0.000292470984817364,0.00161405786549255,,20,121.616094207764,17.3312209129334,-388.358920288086,
,6071533.59,4417,5.00064992904663,-775.616494750977,179.975601196289,0.119544632720947,0.999000012874603,0.017267875289917,0.999000012874603,-0.386942475891113,0.999000012874603,,,0.000508824746434195,0.000251702737577736,0.00111946075975722,,20,119.544632720947,17.267875289917,-386.942475891113,
,6071560.95,4417,5.00069999694824,-725.247439575195,179.975601196289,0.11949584236145,0.999000012874603,0.0171489957809448,0.999000012874603,-0.387439669799805,0.999000012874603,,,0.000346891655620937,0.000164008567776835,0.00131545211933234,,20,119.49584236145,17.1489957809448,-387.439669799805,
,6071589.14,4417,4.99974989891052,-675.648666381836,179.975601196289,0.119351617050171,0.999000012874603,0.017043531703949,0.999000012874603,-0.387937380981445,0.999000012874603,,,0.000358476939146709,0.000170381391809364,0.00118971552629262,,20,119.351617050171,17.043531703949,-387.937380981445,
,6071617.95,4417,4.99989986419678,-625.433660888672,179.975601196289,0.119180182266235,0.999000012874603,0.0169634023666382,0.999000012874603,-0.388595603942871,0.999000012874603,,,0.000512991329513447,0.000221495671339102,0.00167994185663616,,20,119.180182266235,16.9634023666382,-388.595603942871,
,6071646.20,4417,5.00025010108948,-575.857861328125,179.975601196289,0.11905850982666,0.999000012874603,0.0168051691055298,0.999000012874603,-0.388189370727539,0.999000012874603,,,0.000578701900067547,0.000209095597492733,0.00116281614801014,,20,119.05850982666,16.8051691055298,-388.189370727539,
,6071674.83,4417,4.99985003471375,-525.533633422852,179.975601196289,0.119018497085571,0.999000012874603,0.0166067280769348,0.999000012874603,-0.38891223449707,0.999000012874603,,,0.000400320933137059,0.000292496912328046,0.00112921164416917,,20,119.018497085571,16.6067280769348,-388.91223449707,
,6071703.28,4417,5.00025010108948,-475.642839050293,179.975601196289,0.118791452407837,0.999000012874603,0.0164666491985321,0.999000012874603,-0.38823910369873,0.999000012874603,,,0.000576779552411015,0.000207767845062287,0.00115779834535477,,20,118.791452407837,16.4666491985321,-388.23910369873,
,6071732.70,4417,5.00049996376038,-425.408279418945,179.975601196289,0.118635160827637,0.999000012874603,0.0164331148147583,0.999000012874603,-0.388603483581543,0.999000012874603,,,0.000472665569305268,0.000216629187484364,0.00119939011184489,,20,118.635160827637,16.4331148147583,-388.603483581543,
,6071760.56,4417,4.99985003471375,-375.839402770996,179.975601196289,0.118255537033081,0.999000012874603,0.0162965698242188,0.999000012874603,-0.388106541442871,0.999000012874603,,,0.000493447549441351,0.000197797270752583,0.00102023045268086,,20,118.255537033081,16.2965698242188,-388.106541442871,
,6071789.06,4417,4.99994993209839,-325.484127807617,179.975601196289,0.118354792404175,0.999000012874603,0.0160751328468323,0.999000012874603,-0.389094387817383,0.999000012874603,,,0.000425309477641333,0.000219029933799656,0.00139500019939416,,20,118.354792404175,16.0751328468323,-389.094387817383,
,6071817.92,4417,4.99994993209839,-275.840519714355,179.975601196289,0.118055428695679,0.999000012874603,0.0159832706928253,0.999000012874603,-0.38906163482666,0.999000012874603,,,0.000426457889113899,0.000243394636088574,0.00149551673309379,,20,118.055428695679,15.9832706928253,-389.06163482666,
,6071846.25,4417,4.99990010261536,-225.400165557861,179.975601196289,0.117878998565674,0.999000012874603,0.0158436867237091,0.999000012874603,-0.38928508605957,0.999000012874603,,,0.000448052736804604,0.000233786898146188,0.00122922001764398,,20,117.878998565674,15.8436867237091,-389.28508605957,
,6071874.36,4417,4.99989986419678,-175.831285095215,179.975601196289,0.117474514389038,0.999000012874603,0.0157211476802826,0.999000012874603,-0.389497494506836,0.999000012874603,,,0.000400957275836425,0.000185182009819719,0.00136456337050899,,20,117.474514389038,15.7211476802826,-389.497494506836,
,6071901.31,4417,4.99979996681213,-125.351851272583,179.975601196289,0.117299072265625,0.999000012874603,0.0156299965381622,0.999000012874603,-0.389650250244141,0.999000012874603,,,0.000407203129227165,0.00019304950841926,0.00126644728742536,,20,117.299072265625,15.6299965381622,-389.650250244141,
,6071928.70,4417,5,-75.8599937438965,179.975601196289,0.117194035720825,0.999000012874603,0.0155096790313721,0.999000012874603,-0.389083137512207,0.999000012874603,,,0.000451151101796221,0.000275297582521648,0.0011599163116031,,20,117.194035720825,15.5096790313721,-389.083137512207,
,6071956.16,4417,5,-25.3909032821655,179.975601196289,0.117071775054932,0.999000012874603,0.0152606008529663,0.999000012874603,-0.389504219055176,0.999000012874603,,,0.000542872226493238,0.000217174965385549,0.00115124910083949,,20,117.071775054932,15.2606008529663,-389.504219055176,
,6071969.47,4417,5.00010013580322,-0.864566907286644,179.975601196289,0.116874619293213,0.999000012874603,0.0153264788627625,0.999000012874603,-0.389842105102539,0.999000012874603,,,0.000448868345845375,0.000187918947922981,0.00123290338917302,,20,116.874619293213,15.3264788627625,-389.842105102539,