File: data/r96.dat
[Header]
TITLE, default name
FILEOPENTIME,6072128.27,5/27/2021,8:04 PM
BYAPP, Resistivity, 2.1, 1.0
INFO, APPNAME, PPMS MultiVu Application, 1.5.11
INFO, , Sample1 Name
INFO, 1, Sample1 Cross Section
INFO, 1, Sample1 Length
INFO, Ohm-m, Sample1 Units
INFO, , Sample2 Name
INFO, 1, Sample2 Cross Section
INFO, 1, Sample2 Length
INFO, Ohm-m, Sample2 Units
INFO, , Sample3 Name
INFO, 1, Sample3 Cross Section
INFO, 1, Sample3 Length
INFO, Ohm-m, Sample3 Units
INFO, , Sample4 Name
INFO, 1, Sample4 Cross Section
INFO, 1, Sample4 Length
INFO, Ohm-m, Sample4 Units
FIELDGROUP, Resistivity,2,3,4,5,6,7,8,9,10,11,12,13,14,15,16,17,18,19,20,21,22,23,24,25,26,27,28,29,30,31,32,33,34,35,36,37,38,39,40,41
STARTUPGROUP, Resistivity
STARTUPAXIS, X, 2, LINEAR, AUTO
STARTUPAXIS, Y1, 7, LINEAR, AUTO
STARTUPAXIS, Y2, 9, LINEAR, AUTO
STARTUPAXIS, Y3, 11, LINEAR, AUTO
PLOT_APPEARANCE, ALL, HORZ_GRID_ON, VERT_GRID_ON, MARKERS_AND_LINES, ALL_LINES
DATATYPE, TIME, 2
DATATYPE, COMMENT, 1
[Data]
Comment,Time Stamp (sec),Status (code),Temperature (K),Magnetic Field (Oe),Sample Position (deg),Bridge 1 Resistivity (Ohm-m),Bridge 1 Excitation (uA),Bridge 2 Resistivity (Ohm-m),Bridge 2 Excitation (uA),Bridge 3 Resistivity (Ohm-m),Bridge 3 Excitation (uA),Bridge 4 Resistivity (Ohm-m),Bridge 4 Excitation (uA),Bridge 1 Std. Dev. (Ohm-m),Bridge 2 Std. Dev. (Ohm-m),Bridge 3 Std. Dev. (Ohm-m),Bridge 4 Std. Dev. (Ohm-m),Number of Readings,Bridge 1 Resistance (Ohms),Bridge 2 Resistance (Ohms),Bridge 3 Resistance (Ohms),Bridge 4 Resistance (Ohms),Signal 1 Vin (V),Signal 2 Vin (V),Digital Inputs (code),Drive 1 Iout (mA),Drive 1 Ipower (watts),Drive 2 Iout (mA),Drive 2 Ipower (watts),Pressure (),Map 20 (),Map 21 (),Map 22 (),Map 23 (),Map 24 (),Map 25 (),Map 26 (),Map 27 (),Map 28 (),Map 29 ()
,6072242.52,4417,5.00014996528625,-0.257530602812767,179.975601196289,-0.0224534571647644,0.500999987125397,0.0117735272884369,0.500999987125397,-0.0822621631622315,0.500999987125397,,,0.000976474798960386,0.000494972358308561,0.000389663671080906,,20,-22.4534571647644,11.7735272884369,-82.2621631622314,
,6072269.27,4417,5.00005006790161,49.2826110839844,179.975601196289,-0.0228102481842041,0.500999987125397,0.0117847743988037,0.500999987125397,-0.0822646408081055,0.500999987125397,,,0.000781823366222983,0.000663330444664957,0.000451832571945121,,20,-22.8102481842041,11.7847743988037,-82.2646408081055,
,6072298.92,4417,5.00069999694824,99.1205219268799,179.975601196289,-0.0227892594337463,0.500999987125397,0.0114022922515869,0.500999987125397,-0.0830047687530518,0.500999987125397,,,0.00115253537971541,0.000469101632972658,0.000706868016792939,,20,-22.7892594337463,11.4022922515869,-83.0047687530518,
,6072328.00,4417,5.00034999847412,149.591915893555,179.975601196289,-0.0230355710029602,0.500999987125397,0.0112805241107941,0.500999987125397,-0.0828484268188477,0.500999987125397,,,0.000879803551337084,0.000582305010332294,0.000778093483309976,,20,-23.0355710029602,11.2805241107941,-82.8484268188477,
,6072356.00,4417,5.0002498626709,199.219425964355,179.975601196289,-0.022850790309906,0.500999987125397,0.0109949724674225,0.500999987125397,-0.0829895809173584,0.500999987125397,,,0.000913732085668875,0.000350317428561672,0.000357442039558365,,20,-22.850790309906,10.9949724674225,-82.9895809173584,
,6072383.84,4417,5.0008499622345,249.105623626709,179.975601196289,-0.0228992835044861,0.500999987125397,0.0111133327960968,0.500999987125397,-0.0836163967132569,0.500999987125397,,,0.00084384642136301,0.000507923702816493,0.000837124888327446,,20,-22.8992835044861,11.1133327960968,-83.6163967132568,
,6072409.31,4417,4.9997501373291,299.313732910156,179.975601196289,-0.0231080597877502,0.500999987125397,0.0108588393688202,0.500999987125397,-0.083219603729248,0.500999987125397,,,0.00117898308194651,0.000293825234251665,0.000295258903766662,,20,-23.1080597877502,10.8588393688202,-83.2196037292481,
,6072436.44,4417,5.0008499622345,349.66787109375,179.975601196289,-0.0231382730484009,0.500999987125397,0.0107211833953857,0.500999987125397,-0.0832938961029053,0.500999987125397,,,0.00100784227399053,0.000527797294398618,0.000331442453258466,,20,-23.1382730484009,10.7211833953857,-83.2938961029053,
,6072462.56,4417,5.00130009651184,399.295370483398,179.975601196289,-0.0231986573219299,0.500999987125397,0.0107851871013641,0.500999987125397,-0.0843331943511963,0.500999987125397,,,0.000890980398883664,0.000568612768895516,0.000718723589933293,,20,-23.1986573219299,10.7851871013641,-84.3331943511963,
,6072490.52,4417,4.99875020980835,449.674797058105,179.975601196289,-0.0229909008979797,0.500999987125397,0.0105670675754547,0.500999987125397,-0.0839032070159912,0.500999987125397,,,0.000874563158887766,0.000619798024402879,0.000279523209415725,,20,-22.9909008979797,10.5670675754547,-83.9032070159912,
,6072518.17,4417,5.0008499622345,499.54835357666,179.975601196289,-0.0232853772163391,0.500999987125397,0.0104624959468842,0.500999987125397,-0.0841548271179199,0.500999987125397,,,0.00104851611195748,0.000545996894236098,0.000245553883352716,,20,-23.2853772163391,10.4624959468842,-84.1548271179199,
,6072546.25,4417,4.99984979629517,549.316125488281,179.975601196289,-0.0232450657844543,0.500999987125397,0.0103588247299194,0.500999987125397,-0.0840322078704834,0.500999987125397,,,0.000851669223887073,0.000382661309895465,0.000260990054244814,,20,-23.2450657844543,10.3588247299194,-84.0322078704834,
,6072574.59,4417,5.00154995918274,599.510446166992,179.975601196289,-0.022949997138977,0.500999987125397,0.0100146098136902,0.500999987125397,-0.084773401260376,0.500999987125397,,,0.000864989645457221,0.000378265137738171,0.000713053592895047,,20,-22.9499971389771,10.0146098136902,-84.773401260376,
,6072601.23,4417,5.00160002708435,649.111520385742,179.975601196289,-0.0243271586418152,0.500999987125397,0.00995358061790467,0.500999987125397,-0.0837503658294678,0.500999987125397,,,0.00095919989495814,0.00082529484847948,0.00093767845988829,,20,-24.3271586418152,9.95358061790466,-83.7503658294678,
,6072629.50,4421,4.99724984169006,699.262155151367,179.975601196289,-0.0241510071754456,0.500999987125397,0.00972387232780457,0.500999987125397,-0.0844202331542969,0.500999987125397,,,0.000953485519727588,0.000409084910639918,0.000669982020856811,,20,-24.1510071754456,9.72387232780457,-84.4202331542969,
,6072656.66,4421,4.99779987335205,749.275958251953,179.975601196289,-0.0240216674804687,0.500999987125397,0.00970425267219543,0.500999987125397,-0.0840706962585449,0.500999987125397,,,0.000882392564460353,0.000610569511331035,0.000210335578802955,,20,-24.0216674804688,9.70425267219543,-84.0706962585449,
,6072684.88,4421,4.99819993972778,799.581787109375,179.975601196289,-0.0242064900398254,0.500999987125397,0.00948590245246887,0.500999987125397,-0.0841888862609863,0.500999987125397,,,0.00100532628385691,0.00040383742321727,0.000217821036499368,,20,-24.2064900398254,9.48590245246887,-84.1888862609863,
,6072712.17,4421,4.99775004386902,849.284051513672,179.975601196289,-0.0241042004585266,0.500999987125397,0.00914360313415527,0.500999987125397,-0.0842940330505371,0.500999987125397,,,0.00129886942071515,0.000637717483522422,0.000368328009773422,,20,-24.1042004585266,9.14360313415527,-84.2940330505371,
,6072738.98,4421,4.99799990653992,899.153015136719,179.975601196289,-0.0242814455032349,0.500999987125397,0.0088790559053421,0.500999987125397,-0.0844819927215576,0.500999987125397,,,0.000710145557305662,0.00044436783176177,0.000293860932865166,,20,-24.2814455032349,8.8790559053421,-84.4819927215576,
,6072766.67,4421,4.99904990196228,949.230029296875,179.975601196289,-0.0244627868652344,0.500999987125397,0.00867047543525696,0.500999987125397,-0.0845719013214111,0.500999987125397,,,0.000894838923039638,0.000480614559205099,0.000309856740323208,,20,-24.4627868652344,8.67047543525696,-84.5719013214111,
,6072794.66,4421,4.99909996986389,999.69912109375,179.975601196289,-0.0242247245788574,0.500999987125397,0.00855772399902344,0.500999987125397,-0.0846543407440186,0.500999987125397,,,0.000785417853637828,0.00059908402613086,0.000252719328485926,,20,-24.2247245788574,8.55772399902344,-84.6543407440186,
,6072820.13,4421,5.00244998931885,1049.33009033203,179.975601196289,-0.0243047280311584,0.500999987125397,0.00831028401851654,0.500999987125397,-0.0849335906982422,0.500999987125397,,,0.00108384233569938,0.00044395690194659,0.000461774189685782,,20,-24.3047280311584,8.31028401851654,-84.9335906982422,
,6072848.66,4417,5.00149989128113,1099.16337280273,179.975601196289,-0.0248406175613403,0.500999987125397,0.00813093461990356,0.500999987125397,-0.0855240539550781,0.500999987125397,,,0.000995840517811505,0.000426523324093613,0.000849331293287846,,20,-24.8406175613403,8.13093461990356,-85.5240539550781,
,6072875.08,4417,5.00045013427734,1149.26917724609,179.975601196289,-0.0250855719566345,0.500999987125397,0.00816807761192322,0.500999987125397,-0.0849907157897949,0.500999987125397,,,0.000770281370431928,0.000499435884139031,0.000505212122506915,,20,-25.0855719566345,8.16807761192322,-84.9907157897949,
,6072902.05,4417,5.00104999542236,1199.44971923828,179.975601196289,-0.0252063896179199,0.500999987125397,0.00803729937076569,0.500999987125397,-0.0848954906463623,0.500999987125397,,,0.00108698145960329,0.000442830712009691,0.000260560242256411,,20,-25.2063896179199,8.03729937076569,-84.8954906463623,
,6072929.88,4417,5,1249.58768310547,179.975601196289,-0.0250259520530701,0.500999987125397,0.00798799877166748,0.500999987125397,-0.0849196590423584,0.500999987125397,,,0.000922432016138538,0.000502810292554013,0.00029264106131284,,20,-25.0259520530701,7.98799877166748,-84.9196590423584,
,6072955.20,4417,5.00139999389648,1299.16920776367,179.975601196289,-0.0250488101959229,0.500999987125397,0.00755388286113739,0.500999987125397,-0.0850710960388184,0.500999987125397,,,0.000966468850699778,0.000485744999768882,0.000252900594708909,,20,-25.0488101959229,7.55388286113739,-85.0710960388184,
,6072983.38,4417,5.00045013427734,1349.64407348633,179.975601196289,-0.0249247121810913,0.500999987125397,0.00759494173526764,0.500999987125397,-0.0849080295562744,0.500999987125397,,,0.000724166877460586,0.000414263597088308,0.000188011239551441,,20,-24.9247121810913,7.59494173526764,-84.9080295562744,
,6073011.47,4417,5.00049996376038,1399.18419189453,179.975601196289,-0.0249174736976624,0.500999987125397,0.00801190936565399,0.500999987125397,-0.0855855762481689,0.500999987125397,,,0.00089018216565975,0.000381720743375221,0.000236494171759667,,20,-24.9174736976624,8.01190936565399,-85.5855762481689,
,6073039.55,4417,5.00014996528625,1449.60961303711,179.975601196289,-0.0249926643371582,0.500999987125397,0.00750766661167145,0.500999987125397,-0.0857424175262451,0.500999987125397,,,0.00101120798807587,0.000536845578807682,0.000563219991118598,,20,-24.9926643371582,7.50766661167145,-85.7424175262451,
,6073065.63,4417,5.00005006790161,1499.24170532227,179.975601196289,-0.0250606683731079,0.500999987125397,0.00721488797664642,0.500999987125397,-0.0856595558166504,0.500999987125397,,,0.000957295043719888,0.000477008768711191,0.000320243124715914,,20,-25.0606683731079,7.21488797664642,-85.6595558166504,
,6073092.39,4417,4.99990010261536,1475.35231323242,179.975601196289,-0.0251639675140381,0.500999987125397,0.0074553906917572,0.500999987125397,-0.0854886837005615,0.500999987125397,,,0.00105558898470616,0.000454591242652835,0.000230868166063576,,20,-25.1639675140381,7.4553906917572,-85.4886837005615,
,6073119.39,4417,5.00014996528625,1425.40863647461,179.975601196289,-0.0250271928787231,0.500999987125397,0.00743157885074616,0.500999987125397,-0.0856184104919434,0.500999987125397,,,0.00102840604048714,0.000576282772694881,0.000214232881644672,,20,-25.0271928787231,7.43157885074615,-85.6184104919434,
,6073145.59,4417,5.0002498626709,1375.83057250977,179.975601196289,-0.0250159214019775,0.500999987125397,0.00762179715633392,0.500999987125397,-0.0855484748840332,0.500999987125397,,,0.00112318836234596,0.00047280291884136,0.000337791850203996,,20,-25.0159214019775,7.62179715633392,-85.5484748840332,
,6073171.33,4417,4.99980020523071,1325.73743286133,179.975601196289,-0.0245198690414429,0.500999987125397,0.00795257530212402,0.500999987125397,-0.0857959201812744,0.500999987125397,,,0.00104665005459241,0.000558312170287829,0.000706616832082952,,20,-24.5198690414429,7.95257530212402,-85.7959201812744,
,6073198.34,4417,5.00069999694824,1275.86615600586,179.975601196289,-0.0246945484161377,0.500999987125397,0.0077222728729248,0.500999987125397,-0.0853534126281738,0.500999987125397,,,0.001087497079469,0.000500520484742861,0.000229504690697218,,20,-24.6945484161377,7.7222728729248,-85.3534126281738,
,6073224.00,4417,5.00055003166199,1225.69714355469,179.975601196289,-0.0247276641845703,0.500999987125397,0.00825531675815582,0.500999987125397,-0.0853907180786133,0.500999987125397,,,0.000964604153465546,0.00059821502160899,0.000635089559528064,,20,-24.7276641845703,8.25531675815582,-85.3907180786133,
,6073251.00,4417,5.00014996528625,1175.54078369141,179.975601196289,-0.0241937539100647,0.500999987125397,0.00824484040737152,0.500999987125397,-0.0858964366912842,0.500999987125397,,,0.00079256828584623,0.000430088821521348,0.000800345589413666,,20,-24.1937539100647,8.24484040737152,-85.8964366912842,
,6073276.88,4417,5.00025010108948,1125.4775390625,179.975601196289,-0.0244491582870483,0.500999987125397,0.00834541296958923,0.500999987125397,-0.0851662246704102,0.500999987125397,,,0.000779613014482566,0.000506745487677024,0.000445445205713759,,20,-24.4491582870483,8.34541296958923,-85.1662246704102,
,6073302.64,4417,5.00075006484985,1075.58096923828,179.975601196289,-0.024450110912323,0.500999987125397,0.0085101836681366,0.500999987125397,-0.0855700546264648,0.500999987125397,,,0.000929045860191626,0.000576388460183268,0.000752267773482249,,20,-24.450110912323,8.5101836681366,-85.5700546264648,
,6073329.25,4417,4.99965000152588,1025.6510559082,179.975601196289,-0.0242338377952576,0.500999987125397,0.00849919939041138,0.500999987125397,-0.0849287895202637,0.500999987125397,,,0.000950651522302934,0.000398700099532092,0.000299297826918823,,20,-24.2338377952576,8.49919939041138,-84.9287895202637,
,6073358.59,4417,4.99990010261536,975.48205871582,179.975601196289,-0.0236516858100891,0.500999987125397,0.00876422972679138,0.500999987125397,-0.0854950531005859,0.500999987125397,,,0.00108539994780602,0.000621394997821773,0.000709677304015276,,20,-23.6516858100891,8.76422972679138,-85.4950531005859,
,6073386.25,4417,4.99944996833801,925.386614990234,179.975601196289,-0.023695198059082,0.500999987125397,0.0087289960861206,0.500999987125397,-0.0848075336456299,0.500999987125397,,,0.000904650828777369,0.000509549987596388,0.000421935148873322,,20,-23.695198059082,8.72899608612061,-84.8075336456299,
,6073412.94,4417,4.99995017051697,875.5326171875,179.975601196289,-0.0237712348937988,0.500999987125397,0.00895464310646057,0.500999987125397,-0.0849927272796631,0.500999987125397,,,0.000954732456206884,0.000481824636578645,0.000458306419921578,,20,-23.7712348937988,8.95464310646057,-84.9927272796631,
,6073441.02,4417,4.99950003623962,825.679748535156,179.975601196289,-0.0234605555534363,0.500999987125397,0.00893711867332458,0.500999987125397,-0.0846538578033447,0.500999987125397,,,0.000725248818481038,0.000429201500490421,0.000236052818513088,,20,-23.4605555534363,8.93711867332459,-84.6538578033447,
,6073465.66,4417,4.99985003471375,775.660186767578,179.975601196289,-0.0240309439659119,0.500999987125397,0.00909601783752441,0.500999987125397,-0.0847322772979736,0.500999987125397,,,0.000776463575165808,0.00055217770954036,0.000252946860613456,,20,-24.0309439659119,9.09601783752441,-84.7322772979736,
,6073492.64,4417,5.00010013580322,725.791226196289,179.975601196289,-0.0238010149002075,0.500999987125397,0.00923031754493714,0.500999987125397,-0.0845739757537842,0.500999987125397,,,0.000882292471533817,0.000623688185055821,0.000309639242006433,,20,-23.8010149002075,9.23031754493713,-84.5739757537842,
,6073518.84,4417,4.99969983100891,675.708459472656,179.975601196289,-0.0231024458885193,0.500999987125397,0.0095119987487793,0.500999987125397,-0.0844984230041504,0.500999987125397,,,0.0010300937147656,0.000634034234651189,0.000231417602519768,,20,-23.1024458885193,9.5119987487793,-84.4984230041504,
,6073544.25,4417,5.00019979476929,625.834896850586,179.975601196289,-0.0234258873939514,0.500999987125397,0.00948209276199341,0.500999987125397,-0.0844487049102783,0.500999987125397,,,0.000851856406679259,0.000477552531695431,0.000397145320820104,,20,-23.4258873939514,9.48209276199341,-84.4487049102783,
,6073571.27,4417,4.99924993515015,575.596893310547,179.975601196289,-0.0232559885025024,0.500999987125397,0.00965848484039307,0.500999987125397,-0.0842960536956787,0.500999987125397,,,0.00107001779229865,0.000670351336766464,0.000272021418486085,,20,-23.2559885025024,9.65848484039307,-84.2960536956787,
,6073597.27,4417,5.00074982643127,525.763571166992,179.975601196289,-0.0231293643951416,0.500999987125397,0.00981924600601196,0.500999987125397,-0.0847177593231201,0.500999987125397,,,0.000644561050692645,0.000436069489354796,0.000695184912558656,,20,-23.1293643951416,9.81924600601196,-84.7177593231201,
,6073623.20,4417,5.00075006484985,475.66238861084,179.975601196289,-0.0231724146842957,0.500999987125397,0.00997411222457886,0.500999987125397,-0.0840068603515625,0.500999987125397,,,0.000816113172340428,0.000472435752031861,0.000270184936624997,,20,-23.1724146842957,9.97411222457886,-84.0068603515625,
,6073650.16,4417,5.00130009651184,425.764692687988,179.975601196289,-0.0231480020523071,0.500999987125397,0.0100440582275391,0.500999987125397,-0.0841883728027344,0.500999987125397,,,0.000934793458135284,0.000429819662553116,0.000309168348732822,,20,-23.1480020523071,10.0440582275391,-84.1883728027344,
,6073678.14,4417,4.99909996986389,375.328948974609,179.975601196289,-0.0228592329025269,0.500999987125397,0.0101785381793976,0.500999987125397,-0.0842325630187988,0.500999987125397,,,0.000736979006220596,0.000413584157730074,0.000781151532494077,,20,-22.8592329025269,10.1785381793976,-84.2325630187988,
,6073706.20,4417,5.00034999847412,325.449635314941,179.975601196289,-0.0231592568397522,0.500999987125397,0.0103094485759735,0.500999987125397,-0.0841985599517822,0.500999987125397,,,0.000870507758006679,0.000440306215632311,0.000821927167768087,,20,-23.1592568397522,10.3094485759735,-84.1985599517822,
,6073734.42,4417,4.99930000305176,275.679559326172,179.975601196289,-0.0229165738105774,0.500999987125397,0.0103824060916901,0.500999987125397,-0.0840246444702148,0.500999987125397,,,0.00101272435644082,0.000508789464415316,0.00062700008465866,,20,-22.9165738105774,10.3824060916901,-84.0246444702148,
,6073762.89,4417,4.99974989891052,225.471446228027,179.975601196289,-0.0223482953071594,0.500999987125397,0.0104810909748077,0.500999987125397,-0.0838481533050537,0.500999987125397,,,0.000815675288819864,0.000467883156555185,0.000690542741481748,,20,-22.3482953071594,10.4810909748077,-83.8481533050537,
,6073789.41,4417,5.00025010108948,175.853129577637,179.975601196289,-0.0227732533454895,0.500999987125397,0.0103408985614777,0.500999987125397,-0.0835313877105713,0.500999987125397,,,0.00097986410649484,0.000357374860239215,0.000295017466801083,,20,-22.7732533454895,10.3408985614777,-83.5313877105713,
,6073815.33,4417,4.99874997138977,125.387490081787,179.975601196289,-0.022475844669342,0.500999987125397,0.010760845708847,0.500999987125397,-0.0831997299194336,0.500999987125397,,,0.000926758180777894,0.000454474425214224,0.000241099762112512,,20,-22.475844669342,10.760845708847,-83.1997299194336,
,6073841.44,4417,4.99974989891052,75.8806884765625,179.975601196289,-0.0225651838302612,0.500999987125397,0.0110530539512634,0.500999987125397,-0.0834014572143555,0.500999987125397,,,0.00070630848814562,0.000569803683119885,0.000461051276141024,,20,-22.5651838302612,11.0530539512634,-83.4014572143555,
,6073869.67,4417,4.99974989891052,25.7116665840149,179.975601196289,-0.0223065410614014,0.500999987125397,0.0109436321735382,0.500999987125397,-0.0830430210113525,0.500999987125397,,,0.00112320474493532,0.000535397021052441,0.00025213032761107,,20,-22.3065410614014,10.9436321735382,-83.0430210113525,
,6073897.27,4417,5.00039982795715,-24.1607350349426,179.975601196289,-0.0224482090950012,0.500999987125397,0.011354687166214,0.500999987125397,-0.0832974220275879,0.500999987125397,,,0.0006075476307098,0.000414955998990151,0.000760985214318407,,20,-22.4482090950012,11.354687166214,-83.2974220275879,
,6073923.98,4417,4.99829983711243,-74.3113639831543,179.975601196289,-0.0222527635574341,0.500999987125397,0.0111160001754761,0.500999987125397,-0.082817569732666,0.500999987125397,,,0.000675287150058783,0.00034776677941432,0.00048223427334352,,20,-22.2527635574341,11.1160001754761,-82.817569732666,
,6073950.75,4417,5,-124.222853851318,179.975601196289,-0.0222120400428772,0.500999987125397,0.0114888024330139,0.500999987125397,-0.0827215476989746,0.500999987125397,,,0.000799996700541484,0.000528649953734487,0.000540716994815621,,20,-22.2120400428772,11.4888024330139,-82.7215476989746,
,6073978.91,4417,4.99685001373291,-174.59536819458,179.975601196289,-0.0219023092269897,0.500999987125397,0.011689955997467,0.500999987125397,-0.082437915802002,0.500999987125397,,,0.000765691804757195,0.000300701856423323,0.000439622254409066,,20,-21.9023092269897,11.689955997467,-82.437915802002,
,6074006.55,4417,5,-224.163112640381,179.975601196289,-0.0221721690177917,0.500999987125397,0.0118408520698547,0.500999987125397,-0.082234912109375,0.500999987125397,,,0.00087194711975646,0.000642152867275219,0.000340873084888758,,20,-22.1721690177917,11.8408520698547,-82.234912109375,
,6074034.75,4417,5.00180006027222,-274.632192993164,179.975601196289,-0.0218439758300781,0.500999987125397,0.0121197112560272,0.500999987125397,-0.0823472927093506,0.500999987125397,,,0.00102655183418391,0.000449287193106591,0.000711182094867763,,20,-21.8439758300781,12.1197112560272,-82.3472927093506,
,6074062.95,4417,4.99934983253479,-324.224076843262,179.975601196289,-0.0217809037208557,0.500999987125397,0.0119717538356781,0.500999987125397,-0.082026362991333,0.500999987125397,,,0.00103443618871275,0.000498422774003799,0.000286182084790522,,20,-21.7809037208557,11.9717538356781,-82.026362991333,
,6074090.81,4417,4.99959993362427,-374.556350708008,179.975601196289,-0.0218018574714661,0.500999987125397,0.0119243222236633,0.500999987125397,-0.0818307323455811,0.500999987125397,,,0.0011416728805303,0.00039520226013951,0.000325009587111999,,20,-21.8018574714661,11.9243222236633,-81.8307323455811,
,6074117.83,4417,5.00049996376038,-424.14363861084,179.975601196289,-0.0211698581695557,0.500999987125397,0.0121591584682465,0.500999987125397,-0.081732311630249,0.500999987125397,,,0.00100615637898755,0.000513223825560067,0.00025280386920493,,20,-21.1698581695557,12.1591584682465,-81.732311630249,
,6074145.84,4417,5.00169992446899,-474.695504760742,179.975601196289,-0.0218395888328552,0.500999987125397,0.0124427843570709,0.500999987125397,-0.0823384208679199,0.500999987125397,,,0.000851840215697058,0.000570469527199548,0.000937994884169403,,20,-21.8395888328552,12.4427843570709,-82.3384208679199,
,6074173.81,4417,5.00069999694824,-524.528805541992,179.975601196289,-0.0214305418968201,0.500999987125397,0.0127204410076141,0.500999987125397,-0.0819305038452149,0.500999987125397,,,0.00114918624732293,0.000541152384305323,0.000875258852513487,,20,-21.4305418968201,12.7204410076141,-81.9305038452148,
,6074201.66,4417,5.00025010108948,-574.655307006836,179.975601196289,-0.0217171733856201,0.500999987125397,0.0123998264789581,0.500999987125397,-0.0813515865325928,0.500999987125397,,,0.00103820750063919,0.000357019668407005,0.00024266110843967,,20,-21.7171733856201,12.3998264789581,-81.3515865325928,
,6074228.58,4417,5.00110006332397,-624.490893554688,179.975601196289,-0.0212826700210571,0.500999987125397,0.0125998389720917,0.500999987125397,-0.0814877853393555,0.500999987125397,,,0.000906812498144867,0.000521087071356938,0.000490873858168225,,20,-21.2826700210571,12.5998389720917,-81.4877853393555,
,6074256.61,4417,4.99849987030029,-674.680627441406,179.975601196289,-0.0212034502029419,0.500999987125397,0.0127713314533234,0.500999987125397,-0.0811062618255615,0.500999987125397,,,0.000733622541303884,0.000457004955612354,0.000265271230030496,,20,-21.2034502029419,12.7713314533234,-81.1062618255615,
,6074282.63,4417,4.99960017204285,-724.251797485352,179.975601196289,-0.021188210773468,0.500999987125397,0.0129816341400146,0.500999987125397,-0.0816099197387695,0.500999987125397,,,0.00073269293990673,0.000493804460870732,0.000643246271323772,,20,-21.188210773468,12.9816341400146,-81.6099197387695,
,6074309.28,4417,4.99985003471375,-774.32770690918,179.975601196289,-0.0210097434043884,0.500999987125397,0.0132506645679474,0.500999987125397,-0.0807034523010254,0.500999987125397,,,0.000907934824908085,0.000665185928028115,0.000292762310874909,,20,-21.0097434043884,13.2506645679474,-80.7034523010254,
,6074335.78,4417,5.00069999694824,-824.196661376953,179.975601196289,-0.0209453607559204,0.500999987125397,0.0135508635520935,0.500999987125397,-0.0807960266113281,0.500999987125397,,,0.00090087757856689,0.000610530915697897,0.00025883303075142,,20,-20.9453607559204,13.5508635520935,-80.7960266113281,
,6074363.78,4417,5.00055003166199,-874.275991821289,179.975601196289,-0.0209916923522949,0.500999987125397,0.013845175075531,0.500999987125397,-0.080646017074585,0.500999987125397,,,0.000990021974074953,0.000538877899768741,0.000198967881528842,,20,-20.9916923522949,13.845175075531,-80.646017074585,
,6074391.30,4417,5.00034999847412,-924.548480224609,179.975601196289,-0.0207853832244873,0.500999987125397,0.0144063806533814,0.500999987125397,-0.0807542205810547,0.500999987125397,,,0.000937744171605721,0.000494504509346376,0.000563346498751803,,20,-20.7853832244873,14.4063806533813,-80.7542205810547,
,6074419.38,4417,5.00339984893799,-974.29443359375,179.975601196289,-0.0206238955497742,0.500999987125397,0.0143342617034912,0.500999987125397,-0.0804116123199463,0.500999987125397,,,0.000929051324899517,0.000427319552979024,0.000501234469576697,,20,-20.6238955497742,14.3342617034912,-80.4116123199463,
,6074447.28,4421,4.99055004119873,-1024.46688232422,179.975601196289,-0.0210856460571289,0.500999987125397,0.0144597951889038,0.500999987125397,-0.0798629962921143,0.500999987125397,,,0.000925850449656326,0.00048960768059631,0.000726344928576855,,20,-21.0856460571289,14.4597951889038,-79.8629962921143,
,6074474.17,4421,4.99825000762939,-1074.0932434082,179.975601196289,-0.0210749619483948,0.500999987125397,0.0143778267860413,0.500999987125397,-0.0793375755310059,0.500999987125397,,,0.00103276866451714,0.000453750255253228,0.000335807410103999,,20,-21.0749619483948,14.3778267860413,-79.3375755310059,
,6074503.33,4421,4.99839997291565,-1124.59110107422,179.975601196289,-0.0208743475914001,0.500999987125397,0.014571967792511,0.500999987125397,-0.0794256404876709,0.500999987125397,,,0.00104094350849542,0.000540268368028953,0.000278627564364231,,20,-20.8743475914001,14.571967792511,-79.4256404876709,
,6074531.19,4421,4.99870014190674,-1174.64286499023,179.975601196289,-0.020898347568512,0.500999987125397,0.0148580587863922,0.500999987125397,-0.0793900257110596,0.500999987125397,,,0.00115558143751833,0.00042352446725529,0.00055533586595645,,20,-20.898347568512,14.8580587863922,-79.3900257110596,
,6074557.89,4421,4.99790000915527,-1224.57158813477,179.975601196289,-0.0203632503509521,0.500999987125397,0.0147855143070221,0.500999987125397,-0.0799058944702149,0.500999987125397,,,0.000685123534030797,0.000450048245121387,0.000872177743612297,,20,-20.3632503509522,14.7855143070221,-79.9058944702148,
,6074587.41,4421,4.99830007553101,-1274.69232177734,179.975601196289,-0.0201737190246582,0.500999987125397,0.0148725653171539,0.500999987125397,-0.079178625869751,0.500999987125397,,,0.000664488116850131,0.000469965584885363,0.000282312235508454,,20,-20.1737190246582,14.8725653171539,-79.178625869751,
,6074612.77,4421,4.99865007400513,-1324.31065673828,179.975601196289,-0.0204300966262817,0.500999987125397,0.0148229068279266,0.500999987125397,-0.0797613460540772,0.500999987125397,,,0.00101857791139255,0.000437591469512748,0.000823562045787211,,20,-20.4300966262817,14.8229068279266,-79.7613460540772,
,6074639.89,4421,4.99905014038086,-1374.20491333008,179.975601196289,-0.020312371635437,0.500999987125397,0.0153509561538696,0.500999987125397,-0.0790022277832031,0.500999987125397,,,0.00093552093192116,0.000399474140026731,0.000560279126021371,,20,-20.312371635437,15.3509561538696,-79.0022277832031,
,6074666.72,4421,5.00069999694824,-1424.57855834961,179.975601196289,-0.0206740735054016,0.500999987125397,0.0151945771217346,0.500999987125397,-0.0788315944671631,0.500999987125397,,,0.00067678214817924,0.00050707450647015,0.000251303542536357,,20,-20.6740735054016,15.1945771217346,-78.8315944671631,
,6074693.61,4417,5.00224995613098,-1474.15551757813,179.975601196289,-0.0203376648902893,0.500999987125397,0.0154944114685059,0.500999987125397,-0.0787134918212891,0.500999987125397,,,0.000841256102441116,0.000517200584011163,0.000466308724094023,,20,-20.3376648902893,15.4944114685059,-78.7134918212891,
,6074717.86,4417,5.00449991226196,-1499.22216796875,179.975601196289,-0.0203749390602112,0.500999987125397,0.0156815966129303,0.500999987125397,-0.0788793083190918,0.500999987125397,,,0.00126575881782459,0.000631281480602715,0.000747943488071305,,20,-20.3749390602112,15.6815966129303,-78.8793083190918,
,6074745.81,4417,4.9993999004364,-1450.5764831543,179.975601196289,-0.0207148826599121,0.500999987125397,0.015259437084198,0.500999987125397,-0.0788429954528808,0.500999987125397,,,0.000993651410471819,0.000430929682215686,0.000410235617914098,,20,-20.7148826599121,15.259437084198,-78.8429954528809,
,6074772.77,4417,5.00049996376038,-1400.3753112793,179.975601196289,-0.0201369557380676,0.500999987125397,0.0151506713867188,0.500999987125397,-0.0788679473876953,0.500999987125397,,,0.000915454445835867,0.000468174034066981,0.000292588503459376,,20,-20.1369557380676,15.1506713867188,-78.8679473876953,
,6074799.52,4417,5.00069999694824,-1350.76730957031,179.975601196289,-0.0205632632255554,0.500999987125397,0.0149551872253418,0.500999987125397,-0.0789942306518555,0.500999987125397,,,0.000986623892490956,0.000490849637174422,0.000216368169059677,,20,-20.5632632255554,14.9551872253418,-78.9942306518555,
,6074825.03,4417,5.00069999694824,-1300.44769897461,179.975601196289,-0.0205198328018189,0.500999987125397,0.0150300479412079,0.500999987125397,-0.079661882019043,0.500999987125397,,,0.000805529457445041,0.000380161392834637,0.000755142823699247,,20,-20.5198328018188,15.0300479412079,-79.661882019043,
,6074852.11,4417,4.99994993209839,-1250.84202880859,179.975601196289,-0.0204174337387085,0.500999987125397,0.0151093008518219,0.500999987125397,-0.0806115737915039,0.500999987125397,,,0.000786780156695159,0.000472763424580406,0.000865113084509071,,20,-20.4174337387085,15.1093008518219,-80.6115737915039,
,6074879.84,4417,5.00040006637573,-1200.36947631836,179.975601196289,-0.0203416193962097,0.500999987125397,0.0149079551696777,0.500999987125397,-0.0803393692016602,0.500999987125397,,,0.00116703260485201,0.000542619307417981,0.000764801780714375,,20,-20.3416193962097,14.9079551696777,-80.3393692016602,
,6074904.05,4417,4.99954986572266,-1150.88334350586,179.975601196289,-0.0203800974845886,0.500999987125397,0.0146669881343842,0.500999987125397,-0.0803506080627441,0.500999987125397,,,0.00104174857183546,0.000553058245540484,0.000706989733431231,,20,-20.3800974845886,14.6669881343842,-80.3506080627441,
,6074932.61,4417,4.99900007247925,-1100.38438720703,179.975601196289,-0.02006293592453,0.500999987125397,0.0147572793960571,0.500999987125397,-0.0805515724182129,0.500999987125397,,,0.000992894637098667,0.00038302833302918,0.000695722021931546,,20,-20.06293592453,14.7572793960571,-80.5515724182129,
,6074959.33,4417,4.99985003471375,-1050.81435546875,179.975601196289,-0.0202771117210388,0.500999987125397,0.014458464050293,0.500999987125397,-0.0810017543792725,0.500999987125397,,,0.000740357260239177,0.000439678964564524,0.000808369886867729,,20,-20.2771117210388,14.458464050293,-81.0017543792725,
,6074988.14,4417,5.00049996376038,-1000.31534423828,179.975601196289,-0.020274175453186,0.500999987125397,0.0146458569526672,0.500999987125397,-0.0805408836364746,0.500999987125397,,,0.00113262488064117,0.000494668040251172,0.00029440428000056,,20,-20.274175453186,14.6458569526672,-80.5408836364746,
,6075014.83,4417,5.00080013275146,-950.835012817383,179.975601196289,-0.0202086507797241,0.500999987125397,0.0143433738231659,0.500999987125397,-0.0812264213562012,0.500999987125397,,,0.000662794850800653,0.000404234376290669,0.000868350809924307,,20,-20.2086507797241,14.3433738231659,-81.2264213562012,
,6075040.52,4417,4.99954986572266,-900.364770507813,179.975601196289,-0.0203688631057739,0.500999987125397,0.0140889922142029,0.500999987125397,-0.0810169456481934,0.500999987125397,,,0.000859490121404477,0.000380761682366911,0.000684414224872928,,20,-20.3688631057739,14.0889922142029,-81.0169456481934,
,6075067.41,4417,4.99970006942749,-850.80622253418,179.975601196289,-0.0206001177787781,0.500999987125397,0.0136941072940826,0.500999987125397,-0.0809194145202637,0.500999987125397,,,0.000748350146456382,0.000477197559060525,0.000264008144351682,,20,-20.6001177787781,13.6941072940826,-80.9194145202637,
,6075094.05,4417,5.00034999847412,-800.656759643555,179.975601196289,-0.0210694121360779,0.500999987125397,0.0140695139408112,0.500999987125397,-0.0812228614807129,0.500999987125397,,,0.00101122064420029,0.000453436061122352,0.000646084035827331,,20,-21.0694121360779,14.0695139408112,-81.2228614807129,
,6075122.31,4417,4.99905014038086,-750.530252075195,179.975601196289,-0.0211707500457764,0.500999987125397,0.0136597833633423,0.500999987125397,-0.0810659038543701,0.500999987125397,,,0.000807100083872047,0.000506936572755641,0.000250308628211037,,20,-21.1707500457764,13.6597833633423,-81.0659038543701,
,6075149.20,4417,4.99990010261536,-700.67395324707,179.975601196289,-0.0212486325263977,0.500999987125397,0.0138624837875366,0.500999987125397,-0.0812386894226074,0.500999987125397,,,0.00118566698929007,0.000558915757454599,0.000208975853574796,,20,-21.2486325263977,13.8624837875366,-81.2386894226074,
,6075174.92,4417,5,-650.816510009766,179.975601196289,-0.0213583597183227,0.500999987125397,0.0133231860160828,0.500999987125397,-0.0812127826690674,0.500999987125397,,,0.000788941440359975,0.000333674815701689,0.000241563674766106,,20,-21.3583597183228,13.3231860160828,-81.2127826690674,
,6075201.81,4417,4.99955010414124,-600.675082397461,179.975601196289,-0.0212607290267944,0.500999987125397,0.0131713827133179,0.500999987125397,-0.0817245197296143,0.500999987125397,,,0.000944767581852482,0.000487416432945565,0.000554013131913285,,20,-21.2607290267944,13.1713827133179,-81.7245197296143,
,6075229.23,4417,5.00059986114502,-550.447436523438,179.975601196289,-0.0216061102867127,0.500999987125397,0.0135267954349518,0.500999987125397,-0.0816539211273193,0.500999987125397,,,0.000696523207374335,0.000560264434015687,0.000293490001995917,,20,-21.6061102867126,13.5267954349518,-81.6539211273193,
,6075256.77,4417,5.00125002861023,-500.318640136719,179.975601196289,-0.0207255307197571,0.500999987125397,0.0131906018733978,0.500999987125397,-0.0817318248748779,0.500999987125397,,,0.000551709828193933,0.000472439875747319,0.000443846768970992,,20,-20.7255307197571,13.1906018733978,-81.7318248748779,
,6075283.63,4417,4.99829983711243,-450.485331726074,179.975601196289,-0.0213641315460205,0.500999987125397,0.0128689189910889,0.500999987125397,-0.0817836112976074,0.500999987125397,,,0.000802002263387188,0.000548434877693887,0.000241927782032013,,20,-21.3641315460205,12.8689189910889,-81.7836112976074,
,6075311.91,4417,5.00009989738464,-400.833680725098,179.975601196289,-0.0215292814254761,0.500999987125397,0.0127965350627899,0.500999987125397,-0.0821796268463135,0.500999987125397,,,0.000787089637069561,0.000492611956921378,0.000369205741619053,,20,-21.5292814254761,12.7965350627899,-82.1796268463135,
,6075338.88,4417,5.00059986114502,-350.379516601563,179.975601196289,-0.0214208966255188,0.500999987125397,0.0126840225219727,0.500999987125397,-0.0824746257781983,0.500999987125397,,,0.000874887456561586,0.000507983408271174,0.00060430951242265,,20,-21.4208966255188,12.6840225219727,-82.4746257781982,
,6075367.80,4417,5.00124979019165,-300.47262878418,179.975601196289,-0.0216237790107727,0.500999987125397,0.012611442232132,0.500999987125397,-0.0822806949615479,0.500999987125397,,,0.00110377621948882,0.000470913412980147,0.000444544011595325,,20,-21.6237790107727,12.611442232132,-82.2806949615479,
,6075394.58,4417,5.00049996376038,-250.717498779297,179.975601196289,-0.0217336055755615,0.500999987125397,0.0126061615943909,0.500999987125397,-0.0822239433288574,0.500999987125397,,,0.000770292375171197,0.000498956227162458,0.000292752499273792,,20,-21.7336055755615,12.6061615943909,-82.2239433288574,
,6075422.73,4417,5.00020003318787,-200.862342071533,179.975601196289,-0.0222669176101685,0.500999987125397,0.012261794424057,0.500999987125397,-0.0824024116516113,0.500999987125397,,,0.000978969512005034,0.000389459087330116,0.00032565987503716,,20,-22.2669176101685,12.261794424057,-82.4024116516113,
,6075449.56,4417,5.0008499622345,-150.388642883301,179.975601196289,-0.0218660283088684,0.500999987125397,0.012123474407196,0.500999987125397,-0.082831421661377,0.500999987125397,,,0.00106557324977114,0.000374874549672046,0.000669283308878826,,20,-21.8660283088684,12.123474407196,-82.831421661377,
,6075476.89,4417,5.00174999237061,-100.876096725464,179.975601196289,-0.0223020568847656,0.500999987125397,0.0121072825908661,0.500999987125397,-0.0824066307067871,0.500999987125397,,,0.000772328441507163,0.00049882268093706,0.000265890798988621,,20,-22.3020568847656,12.1072825908661,-82.4066307067871,
,6075513.81,4417,5.00045013427734,-25.3012273788452,179.975601196289,-0.022516099357605,0.500999987125397,0.0118185567378998,0.500999987125397,-0.082914667892456,0.500999987125397,,,0.000802859559008983,0.000395647060732252,0.000487450424624343,,20,-22.516099357605,11.8185567378998,-82.9146678924561,
,6075527.20,4417,5.00055003166199,-0.802483609318733,179.975601196289,-0.0220998860359192,0.500999987125397,0.0118928464412689,0.500999987125397,-0.0832714504241943,0.500999987125397,,,0.00100649760254782,0.000583923211209724,0.000685788849226766,,20,-22.0998860359192,11.8928464412689,-83.2714504241943,