File: data/r98.dat
[Header]
TITLE, default name
FILEOPENTIME,6077336.17,5/27/2021,9:31 PM
BYAPP, Resistivity, 2.1, 1.0
INFO, APPNAME, PPMS MultiVu Application, 1.5.11
INFO, , Sample1 Name
INFO, 1, Sample1 Cross Section
INFO, 1, Sample1 Length
INFO, Ohm-m, Sample1 Units
INFO, , Sample2 Name
INFO, 1, Sample2 Cross Section
INFO, 1, Sample2 Length
INFO, Ohm-m, Sample2 Units
INFO, , Sample3 Name
INFO, 1, Sample3 Cross Section
INFO, 1, Sample3 Length
INFO, Ohm-m, Sample3 Units
INFO, , Sample4 Name
INFO, 1, Sample4 Cross Section
INFO, 1, Sample4 Length
INFO, Ohm-m, Sample4 Units
FIELDGROUP, Resistivity,2,3,4,5,6,7,8,9,10,11,12,13,14,15,16,17,18,19,20,21,22,23,24,25,26,27,28,29,30,31,32,33,34,35,36,37,38,39,40,41
STARTUPGROUP, Resistivity
STARTUPAXIS, X, 2, LINEAR, AUTO
STARTUPAXIS, Y1, 7, LINEAR, AUTO
STARTUPAXIS, Y2, 9, LINEAR, AUTO
STARTUPAXIS, Y3, 11, LINEAR, AUTO
PLOT_APPEARANCE, ALL, HORZ_GRID_ON, VERT_GRID_ON, MARKERS_AND_LINES, ALL_LINES
DATATYPE, TIME, 2
DATATYPE, COMMENT, 1
[Data]
Comment,Time Stamp (sec),Status (code),Temperature (K),Magnetic Field (Oe),Sample Position (deg),Bridge 1 Resistivity (Ohm-m),Bridge 1 Excitation (uA),Bridge 2 Resistivity (Ohm-m),Bridge 2 Excitation (uA),Bridge 3 Resistivity (Ohm-m),Bridge 3 Excitation (uA),Bridge 4 Resistivity (Ohm-m),Bridge 4 Excitation (uA),Bridge 1 Std. Dev. (Ohm-m),Bridge 2 Std. Dev. (Ohm-m),Bridge 3 Std. Dev. (Ohm-m),Bridge 4 Std. Dev. (Ohm-m),Number of Readings,Bridge 1 Resistance (Ohms),Bridge 2 Resistance (Ohms),Bridge 3 Resistance (Ohms),Bridge 4 Resistance (Ohms),Signal 1 Vin (V),Signal 2 Vin (V),Digital Inputs (code),Drive 1 Iout (mA),Drive 1 Ipower (watts),Drive 2 Iout (mA),Drive 2 Ipower (watts),Pressure (),Map 20 (),Map 21 (),Map 22 (),Map 23 (),Map 24 (),Map 25 (),Map 26 (),Map 27 (),Map 28 (),Map 29 ()
,6077357.20,4417,5.00049996376038,0.601287895441055,179.975601196289,0.0015514416962862,0.75,0.00801605751514435,0.75,-0.150292179107666,0.75,,,0.000667760207875029,0.000405475221225734,0.000702119429537936,,20,1.5514416962862,8.01605751514435,-150.292179107666,
,6077384.75,4417,4.99954986572266,49.3240001678467,179.975601196289,0.00203962998092175,0.75,0.00774601495265961,0.75,-0.150500146484375,0.75,,,0.00057783064134614,0.000346569389777508,0.000481044898077439,,20,2.03962998092175,7.74601495265961,-150.500146484375,
,6077411.91,4417,5.00154995918274,99.1251220703125,179.975601196289,0.00207334660887718,0.75,0.00797577676773071,0.75,-0.15101654586792,0.75,,,0.000577459883743688,0.000340696053096612,0.000458559715542924,,20,2.07334660887718,7.97577676773071,-151.01654586792,
,6077439.64,4417,5.00119996070862,149.324031066895,179.975601196289,0.00208801049888134,0.75,0.00782148518562317,0.75,-0.15120834274292,0.75,,,0.000528542055965645,0.000349732433851404,0.000501526267479055,,20,2.08801049888134,7.82148518562317,-151.20834274292,
,6077464.91,4417,4.99979996681213,199.213677978516,179.975601196289,0.00196042757928371,0.75,0.00769555580615997,0.75,-0.151276139068603,0.75,,,0.000659774487060864,0.000364493783670987,0.00038459443774399,,20,1.96042757928371,7.69555580615997,-151.276139068604,
,6077490.31,4417,4.99909996986389,249.381550598145,179.975601196289,0.00204286693930626,0.75,0.007532022356987,0.75,-0.151300375366211,0.75,,,0.000644881675904945,0.000264342258763274,0.000445555091989705,,20,2.04286693930626,7.532022356987,-151.300375366211,
,6077516.05,4417,5.00115013122559,299.282696533203,179.975601196289,0.00178909862339497,0.75,0.00733435020446777,0.75,-0.151514196777344,0.75,,,0.000499797997582757,0.00028908034220183,0.0003189747628777,,20,1.78909862339497,7.33435020446777,-151.514196777344,
,6077541.88,4417,4.9991500377655,349.352851867676,179.975601196289,0.00160591731667519,0.75,0.00723394203186035,0.75,-0.152154082489014,0.75,,,0.000494547954571886,0.000393681396338543,0.00070819813367794,,20,1.60591731667519,7.23394203186035,-152.154082489014,
,6077567.91,4417,4.99819993972778,399.201104736328,179.975601196289,0.00152183723449707,0.75,0.00718993053436279,0.75,-0.151907439422607,0.75,,,0.000433247665736425,0.000417492256804248,0.000508144630010846,,20,1.52183723449707,7.18993053436279,-151.907439422607,
,6077595.59,4417,5.00075006484985,449.324133300781,179.975601196289,0.00138901158869267,0.75,0.00703323299884796,0.75,-0.151947058105469,0.75,,,0.0003528199130378,0.000397239341284521,0.000748791466300309,,20,1.38901158869267,7.03323299884796,-151.947058105469,
,6077622.45,4417,5.0023500919342,499.237939453125,179.975601196289,0.00165318366587162,0.75,0.0068455055475235,0.75,-0.152657649993896,0.75,,,0.000574249525856701,0.000378797682435051,0.000627219253656176,,20,1.65318366587162,6.8455055475235,-152.657649993896,
,6077650.56,4417,4.99884986877441,549.340267944336,179.975601196289,0.00114210476130247,0.75,0.00671512837409973,0.75,-0.151756455993652,0.75,,,0.000466696988861512,0.000366671043178143,0.000348101815589642,,20,1.14210476130247,6.71512837409973,-151.756455993652,
,6077678.98,4417,4.99990010261536,599.233383178711,179.975601196289,0.00109773805290461,0.75,0.00658528337478638,0.75,-0.152273561096191,0.75,,,0.000377923440783283,0.00030496712036996,0.000322049661158571,,20,1.09773805290461,6.58528337478638,-152.273561096191,
,6077707.59,4417,4.99834990501404,649.674859619141,179.975601196289,0.00107840360105038,0.75,0.00650909039974213,0.75,-0.152291245269775,0.75,,,0.000455098842216461,0.000420184915148661,0.000766184769832912,,20,1.07840360105038,6.50909039974213,-152.291245269775,
,6077732.88,4417,4.99955010414124,699.289752197266,179.975601196289,0.000838470965623856,0.75,0.00638570938110352,0.75,-0.152729039001465,0.75,,,0.000694203726116942,0.000363913971646253,0.000566020702701817,,20,0.838470965623856,6.38570938110352,-152.729039001465,
,6077761.34,4417,5.00030016899109,749.662255859375,179.975601196289,0.000844576332718134,0.75,0.00626360204219818,0.75,-0.152376961517334,0.75,,,0.000383807678537562,0.000391435385864661,0.000315859242074213,,20,0.844576332718134,6.26360204219818,-152.376961517334,
,6077789.27,4417,4.99954986572266,799.553045654297,179.975601196289,0.000591472851857543,0.75,0.00622343909740448,0.75,-0.152608642578125,0.75,,,0.000588613948268254,0.000378939710135002,0.000457074666803591,,20,0.591472851857543,6.22343909740448,-152.608642578125,
,6077815.92,4417,5.00160002708435,849.538116455078,179.975601196289,0.00074754536151886,0.75,0.00615780470371246,0.75,-0.152530921173096,0.75,,,0.000511267751019683,0.000445691828757065,0.000401089815140741,,20,0.74754536151886,6.15780470371246,-152.530921173096,
,6077843.19,4417,5.0014500617981,899.38752746582,179.975601196289,0.000225912222638726,0.75,0.00583606567382813,0.75,-0.152513010406494,0.75,,,0.000423797061281841,0.000446250241887894,0.00065678076251741,,20,0.225912222638726,5.83606567382813,-152.513010406494,
,6077869.02,4417,5.00250005722046,949.254165649414,179.975601196289,0.000118934647971764,0.75,0.00589737749099731,0.75,-0.152227184295654,0.75,,,0.000586801896057002,0.000307649878545204,0.000550367365097834,,20,0.118934647971764,5.89737749099731,-152.227184295654,
,6077895.08,4417,4.99889993667603,999.459997558594,179.975601196289,0.000265219440730289,0.75,0.00569011526107788,0.75,-0.15190345916748,0.75,,,0.000649912763392734,0.000350285900889825,0.000523780800837481,,20,0.265219440730289,5.69011526107788,-151.90345916748,
,6077920.77,4417,4.99810004234314,1049.38874511719,179.975601196289,0.00010430193785578,0.75,0.00557252216339111,0.75,-0.152565882110596,0.75,,,0.000701810242948273,0.000369336889729654,0.000345019795943221,,20,0.10430193785578,5.57252216339111,-152.565882110596,
,6077946.53,4417,5.00095009803772,1099.55661621094,179.975601196289,-0.000419497326202691,0.75,0.00526330497264862,0.75,-0.151731086730957,0.75,,,0.000449078768194804,0.000388646534956139,0.000311994515950951,,20,-0.419497326202691,5.26330497264862,-151.731086730957,
,6077972.41,4417,4.9993999004364,1149.37266845703,179.975601196289,-0.000375096303224563,0.75,0.00540232834815979,0.75,-0.15193983001709,0.75,,,0.000617958292895935,0.000367431422431475,0.000369342371399824,,20,-0.375096303224564,5.40232834815979,-151.93983001709,
,6077998.55,4417,4.99870014190674,1199.55202636719,179.975601196289,-0.000768127070367336,0.75,0.00513000509738922,0.75,-0.152286182403564,0.75,,,0.000516017860014187,0.000353887092860658,0.00060680847335144,,20,-0.768127070367336,5.13000509738922,-152.286182403564,
,6078025.33,4417,5.00390005111694,1249.13584594727,179.975601196289,-0.000543016472924501,0.75,0.0049306503534317,0.75,-0.152504303741455,0.75,,,0.000555131963464844,0.000450172881162485,0.000265505045105991,,20,-0.543016472924501,4.9306503534317,-152.504303741455,
,6078051.06,4417,4.99935007095337,1299.59233398438,179.975601196289,-0.00100182654112577,0.75,0.00509550149440765,0.75,-0.151870083618164,0.75,,,0.000541874975296187,0.000468998095205458,0.000637127730630082,,20,-1.00182654112577,5.09550149440765,-151.870083618164,
,6078076.41,4417,4.99955010414124,1349.19111328125,179.975601196289,-0.00135506248623133,0.75,0.00493244595527649,0.75,-0.152006523895264,0.75,,,0.000631142808340292,0.000358614918851588,0.0006268925183017,,20,-1.35506248623133,4.93244595527649,-152.006523895264,
,6078102.56,4417,4.9993999004364,1399.59348754883,179.975601196289,-0.000831517562270165,0.75,0.00477438883781433,0.75,-0.15229783706665,0.75,,,0.000967867195040859,0.000406361169614022,0.00106024784069972,,20,-0.831517562270164,4.77438883781433,-152.29783706665,
,6078129.11,4417,5.00119996070862,1449.16810913086,179.975601196289,-0.00129618539661169,0.75,0.00446414395570755,0.75,-0.152345664215088,0.75,,,0.000464292499706612,0.000257337408092855,0.000532214289662149,,20,-1.29618539661169,4.46414395570755,-152.345664215088,
,6078155.67,4417,4.99990010261536,1499.38085327148,179.975601196289,-0.00146535423398018,0.75,0.0044068746805191,0.75,-0.151985468292236,0.75,,,0.000533965616310233,0.000349103635862855,0.000425184377167222,,20,-1.46535423398018,4.4068746805191,-151.985468292236,
,6078180.22,4417,4.99905014038086,1475.49606323242,179.975601196289,-0.00140226255729795,0.75,0.00458292070627212,0.75,-0.152126789855957,0.75,,,0.000640175429743343,0.00035998561946807,0.000353255142136328,,20,-1.40226255729795,4.58292070627212,-152.126789855957,
,6078207.39,4417,5.00014996528625,1425.59946289063,179.975601196289,-0.000973326318711042,0.75,0.00452395776510239,0.75,-0.152260444641113,0.75,,,0.00061096999735677,0.000345363430689812,0.000408881736731517,,20,-0.973326318711042,4.52395776510239,-152.260444641113,
,6078232.88,4417,5.00055003166199,1375.71326293945,179.975601196289,-0.00100207331702113,0.75,0.0047529158115387,0.75,-0.152599047088623,0.75,,,0.000539567027985339,0.000341511634916744,0.000701343920491645,,20,-1.00207331702113,4.7529158115387,-152.599047088623,
,6078259.86,4417,4.9965500831604,1325.55692749023,179.975601196289,-0.00204843386262655,0.75,0.00478921287059784,0.75,-0.150950205993652,0.75,,,0.000763356059260151,0.000418777603208345,0.00136415207444252,,20,-2.04843386262655,4.78921287059784,-150.950205993652,
,6078285.86,4421,4.99664998054504,1275.7029296875,179.975601196289,-0.00222462480664253,0.75,0.00479447395801544,0.75,-0.150404556274414,0.75,,,0.000832710187712001,0.000353827116282925,0.000707921392739634,,20,-2.22462480664253,4.79447395801544,-150.404556274414,
,6078311.34,4421,4.99869990348816,1225.84201660156,179.975601196289,-0.00198739423155785,0.75,0.00473863266706467,0.75,-0.150289693450928,0.75,,,0.000551692504234264,0.000400890904625769,0.000481469390051573,,20,-1.98739423155785,4.73863266706467,-150.289693450928,
,6078336.89,4421,4.99810004234314,1175.69596557617,179.975601196289,-0.0017409566372633,0.75,0.0050062520980835,0.75,-0.150420588684082,0.75,,,0.000583475836350685,0.000355142066852624,0.000363491890383802,,20,-1.7409566372633,5.0062520980835,-150.420588684082,
,6078362.22,4421,4.99809980392456,1125.60626831055,179.975601196289,-0.001519632409513,0.75,0.00518407459259033,0.75,-0.150872136688232,0.75,,,0.000435894345571207,0.000365141959741589,0.000669069968152887,,20,-1.519632409513,5.18407459259033,-150.872136688232,
,6078387.33,4421,4.99815011024475,1075.68441772461,179.975601196289,-0.001446760815382,0.75,0.00527354109287262,0.75,-0.150565140533447,0.75,,,0.000433042548090981,0.000252703650220268,0.000605103950556076,,20,-1.446760815382,5.27354109287262,-150.565140533447,
,6078415.27,4421,4.99779987335205,1025.78675537109,179.975601196289,-0.0012086443990469,0.75,0.00533345184326172,0.75,-0.151331256866455,0.75,,,0.000667391378503276,0.000439286615164934,0.000776330599495803,,20,-1.2086443990469,5.33345184326172,-151.331256866455,
,6078440.64,4421,4.99835014343262,975.57633972168,179.975601196289,-0.000915699510276318,0.75,0.00553540778160095,0.75,-0.151046823120117,0.75,,,0.00050443967498855,0.000461894704344845,0.000550349167811425,,20,-0.915699510276318,5.53540778160095,-151.046823120117,
,6078466.38,4421,4.99944996833801,925.836154174805,179.975601196289,-0.000689027096936479,0.75,0.00570441164970398,0.75,-0.151135935974121,0.75,,,0.000458477113497119,0.000422291797449005,0.00057594381320698,,20,-0.689027096936479,5.70441164970398,-151.135935974121,
,6078491.17,4421,4.99904990196228,875.642977905273,179.975601196289,-0.00062937159575522,0.75,0.00581138443946838,0.75,-0.150979356384277,0.75,,,0.000475861205006495,0.000408198259621335,0.000583975817044729,,20,-0.62937159575522,5.81138443946838,-150.979356384277,
,6078517.84,4417,5.00025010108948,825.765975952148,179.975601196289,-0.000665654053911567,0.75,0.00597511343955994,0.75,-0.151104616546631,0.75,,,0.000555994029719649,0.000469085740573839,0.00045515467364716,,20,-0.665654053911567,5.97511343955994,-151.104616546631,
,6078543.77,4417,5.00174999237061,775.51994934082,179.975601196289,-0.000175794757623226,0.75,0.00617507672309875,0.75,-0.15122673034668,0.75,,,0.000360192866808695,0.000405724930497995,0.000684028850006732,,20,-0.175794757623225,6.17507672309875,-151.22673034668,
,6078570.55,4417,5.01075005531311,725.629132080078,179.975601196289,-7.88623904809356e-006,0.75,0.00602775392532349,0.75,-0.152020390319824,0.75,,,0.000571921899523013,0.000344169221606107,0.000577432375638082,,20,-0.00788623904809356,6.02775392532349,-152.020390319824,
,6078595.91,4417,5.00014996528625,675.502627563477,179.975601196289,-9.14548803120852e-005,0.75,0.00645004909038544,0.75,-0.1509794090271,0.75,,,0.00055645683116255,0.000299818336911097,0.000632002222146615,,20,-0.0914548803120852,6.45004909038544,-150.9794090271,
,6078621.84,4417,5.00034999847412,625.652096557617,179.975601196289,-8.02599757909775e-005,0.75,0.00631557729244232,0.75,-0.151009613800049,0.75,,,0.000609440409851336,0.000336448721994618,0.000682447469584914,,20,-0.0802599757909775,6.31557729244232,-151.009613800049,
,6078648.81,4417,5.0002498626709,575.748641967773,179.975601196289,0.000209745457977988,0.75,0.00667013466358185,0.75,-0.150829882049561,0.75,,,0.000466976766384749,0.000414165702485717,0.000374112707238611,,20,0.209745457977988,6.67013466358185,-150.829882049561,
,6078674.45,4417,5.00040006637573,525.542840576172,179.975601196289,0.00149098624587059,0.75,0.00683714241981506,0.75,-0.152275585174561,0.75,,,0.000508757966204408,0.000390578763978733,0.000540395988388289,,20,1.49098624587059,6.83714241981506,-152.275585174561,
,6078701.56,4417,4.99994993209839,475.478436279297,179.975601196289,0.00137363535761833,0.75,0.00687046627998352,0.75,-0.152438796234131,0.75,,,0.000402250073615378,0.000348412728019811,0.000565774195220452,,20,1.37363535761833,6.87046627998352,-152.438796234131,
,6078727.70,4417,5.00025010108948,425.627883911133,179.975601196289,0.00169519752860069,0.75,0.00709891786575318,0.75,-0.152346829223633,0.75,,,0.000534447665058933,0.000280422131204257,0.000666811601466881,,20,1.69519752860069,7.09891786575317,-152.346829223633,
,6078755.41,4417,5.0002498626709,375.73363494873,179.975601196289,0.00186304745078087,0.75,0.00722921433448791,0.75,-0.152080609130859,0.75,,,0.000527296875543247,0.000374049305652653,0.000476497708377114,,20,1.86304745078087,7.22921433448792,-152.080609130859,
,6078781.73,4417,5.00215005874634,325.569203186035,179.975601196289,0.00209479949474335,0.75,0.00730298824310303,0.75,-0.152125385284424,0.75,,,0.000514209729687161,0.00031614100311563,0.000392838104941851,,20,2.09479949474335,7.30298824310303,-152.125385284424,
,6078807.45,4417,5.00244998931885,275.765798950195,179.975601196289,0.00201971865296364,0.75,0.00737711391448975,0.75,-0.152355277252197,0.75,,,0.000404002305772045,0.000320499280251509,0.000727609213854884,,20,2.01971865296364,7.37711391448975,-152.355277252197,
,6078832.86,4417,5.0046501159668,225.592176055908,179.975601196289,0.00222872074246407,0.75,0.00772668144702912,0.75,-0.152327549743652,0.75,,,0.00069982339304419,0.000414429406449785,0.000771376645087526,,20,2.22872074246407,7.72668144702911,-152.327549743652,
,6078859.53,4417,5.00030016899109,175.666876983643,179.975601196289,0.00212530485391617,0.75,0.00779041006565094,0.75,-0.151526298522949,0.75,,,0.000539245429130266,0.000411029013176279,0.000351650027959612,,20,2.12530485391617,7.79041006565094,-151.526298522949,
,6078884.05,4417,5.00165009498596,125.507057189941,179.975601196289,0.00216430112123489,0.75,0.00791067020893097,0.75,-0.151638072967529,0.75,,,0.000522491503464289,0.000334767050405631,0.000364204066053006,,20,2.16430112123489,7.91067020893097,-151.638072967529,
,6078910.06,4417,5.00025010108948,75.7070861816406,179.975601196289,0.00236909250617027,0.75,0.0079442507982254,0.75,-0.151600425720215,0.75,,,0.00065357521140205,0.000450177946289482,0.000684709559050291,,20,2.36909250617027,7.9442507982254,-151.600425720215,
,6078934.52,4417,4.99950003623962,25.5748538970947,179.975601196289,0.00256486891508102,0.75,0.00814133460521698,0.75,-0.151200065612793,0.75,,,0.000683147760936785,0.000375923696780227,0.000573599792761317,,20,2.56486891508102,8.14133460521698,-151.200065612793,
,6078962.47,4417,5.0023500919342,-24.626359462738,179.975601196289,0.00272997505068779,0.75,0.00819870195388794,0.75,-0.15148690032959,0.75,,,0.000688903474380064,0.000305345589320976,0.000752968049161188,,20,2.72997505068779,8.19870195388794,-151.48690032959,
,6078989.09,4417,4.99590015411377,-74.5631454467773,179.975601196289,0.00242054868340492,0.75,0.00850111339092255,0.75,-0.150802536773682,0.75,,,0.000599917039429199,0.000387195565723649,0.000497117936938547,,20,2.42054868340492,8.50111339092255,-150.802536773682,
,6079015.52,4417,4.99904990196228,-124.644791412354,179.975601196289,0.00255398477911949,0.75,0.00853978328704834,0.75,-0.150856699371338,0.75,,,0.000607938389346261,0.000384208165517274,0.000650447265887107,,20,2.55398477911949,8.53978328704834,-150.856699371338,
,6079042.80,4417,5.002849817276,-174.204473876953,179.975601196289,0.00279985991716385,0.75,0.00865600771903992,0.75,-0.151187982177734,0.75,,,0.000626748835732717,0.000450781573376733,0.000772478357312821,,20,2.79985991716385,8.65600771903992,-151.187982177734,
,6079069.56,4417,4.99990010261536,-224.365445709229,179.975601196289,0.0031366029381752,0.75,0.00875397024154663,0.75,-0.150351005554199,0.75,,,0.000758096722143694,0.000356905826614758,0.000803675900794624,,20,3.1366029381752,8.75397024154663,-150.351005554199,
,6079096.23,4417,5.00044989585876,-274.249342346191,179.975601196289,0.00326481965780258,0.75,0.00890966205596924,0.75,-0.150063536834717,0.75,,,0.000555825101954406,0.000371365309164091,0.000476396101360358,,20,3.26481965780258,8.90966205596924,-150.063536834717,
,6079122.86,4417,5.00410008430481,-324.19532623291,179.975601196289,0.0032371107339859,0.75,0.00892523665428162,0.75,-0.150456644439697,0.75,,,0.000488742050291375,0.00034142429395421,0.000543823523636054,,20,3.2371107339859,8.92523665428162,-150.456644439697,
,6079150.13,4417,4.99790000915527,-374.191893005371,179.975601196289,0.00291745727062225,0.75,0.00898120450973511,0.75,-0.150023654937744,0.75,,,0.000601713179169208,0.000388846938776844,0.000791688400854429,,20,2.91745727062225,8.98120450973511,-150.023654937744,
,6079178.17,4417,5.00025010108948,-424.644897460938,179.975601196289,0.00332520121335983,0.75,0.00938413414955139,0.75,-0.149494900512695,0.75,,,0.000463840808842543,0.000350196686656004,0.000476273706281707,,20,3.32520121335983,9.38413414955139,-149.494900512695,
,6079206.13,4417,5.00040006637573,-474.308052062988,179.975601196289,0.00347987352609635,0.75,0.0094557466506958,0.75,-0.149255644989014,0.75,,,0.000680009176505434,0.000282447049235504,0.000344840341991338,,20,3.47987352609634,9.4557466506958,-149.255644989014,
,6079233.73,4417,4.99994993209839,-524.150549316406,179.975601196289,0.00353837978839874,0.75,0.00956486992835999,0.75,-0.14912507019043,0.75,,,0.000536099536862209,0.000371022993877786,0.000377875323572606,,20,3.53837978839874,9.56486992835999,-149.12507019043,
,6079261.06,4417,4.99979996681213,-574.256353759766,179.975601196289,0.00342822676897049,0.75,0.00973976621627808,0.75,-0.148820935821533,0.75,,,0.000680673904355393,0.000352701220047276,0.000472848395397859,,20,3.42822676897049,9.73976621627808,-148.820935821533,
,6079287.61,4417,5.00294995307922,-624.133355712891,179.975601196289,0.00351566134691238,0.75,0.00981649537086487,0.75,-0.148841027069092,0.75,,,0.000621891462732671,0.000325283162546731,0.00055676026953266,,20,3.51566134691238,9.81649537086487,-148.841027069092,
,6079314.22,4417,4.99934983253479,-674.318469238281,179.975601196289,0.00360245636701584,0.75,0.00992039728164673,0.75,-0.14823902053833,0.75,,,0.000539759724047902,0.000366806898602274,0.000268023637259486,,20,3.60245636701584,9.92039728164673,-148.23902053833,
,6079340.09,4417,4.99855017662048,-724.19778137207,179.975601196289,0.00334233055114746,0.75,0.0102633306980133,0.75,-0.148051528930664,0.75,,,0.000445737440927855,0.000379852586400397,0.000610301213951467,,20,3.34233055114746,10.2633306980133,-148.051528930664,
,6079366.14,4417,4.99954986572266,-774.31044921875,179.975601196289,0.00391607911586761,0.75,0.0102614067077637,0.75,-0.148217622375488,0.75,,,0.000518844061652493,0.000383711810127271,0.000519452994085176,,20,3.91607911586761,10.2614067077637,-148.217622375488,
,6079393.83,4417,5.00055003166199,-824.159869384766,179.975601196289,0.0038224604845047,0.75,0.0104898565769196,0.75,-0.147864644622803,0.75,,,0.000672847713547779,0.000342275363715037,0.000662864803808074,,20,3.8224604845047,10.4898565769196,-147.864644622803,
,6079420.98,4417,4.99850010871887,-874.602481079102,179.975601196289,0.00383213231563568,0.75,0.0106463241100311,0.75,-0.147596176147461,0.75,,,0.000530966612276488,0.00030350595472138,0.00058529338687167,,20,3.83213231563568,10.6463241100311,-147.596176147461,
,6079447.80,4417,5.00020003318787,-924.177145385742,179.975601196289,0.00403717756271362,0.75,0.0112809212684631,0.75,-0.146731600189209,0.75,,,0.000679368647659537,0.000466942497747983,0.00045324538592088,,20,4.03717756271362,11.2809212684631,-146.731600189209,
,6079475.50,4417,5.00244998931885,-974.594491577148,179.975601196289,0.00389287078380585,0.75,0.0113627716064453,0.75,-0.147254790496826,0.75,,,0.000609602573059533,0.000403457498554454,0.000347229052502468,,20,3.89287078380585,11.3627716064453,-147.254790496826,
,6079514.31,4417,5.00059986114502,-1049.22319946289,179.975601196289,0.00375282211303711,0.75,0.0115711274623871,0.75,-0.147019981384277,0.75,,,0.000571053439965271,0.000423339647875352,0.000538758663166765,,20,3.75282211303711,11.5711274623871,-147.019981384277,
,6079541.59,4417,5.00239992141724,-1099.68076171875,179.975601196289,0.00393823901414871,0.75,0.0115122450828552,0.75,-0.146924983215332,0.75,,,0.000552820275215254,0.000358964983363806,0.000459408548191423,,20,3.93823901414871,11.5122450828552,-146.924983215332,
,6079567.81,4417,5.0014500617981,-1149.27953491211,179.975601196289,0.0039673668384552,0.75,0.0118208223819733,0.75,-0.146595161437988,0.75,,,0.000618237128310518,0.00034915335255364,0.000553491003800802,,20,3.9673668384552,11.8208223819733,-146.595161437988,
,6079596.58,4417,4.99875020980835,-1199.63941040039,179.975601196289,0.00394520769119263,0.75,0.0119958937168121,0.75,-0.145484367370605,0.75,,,0.00060033381595369,0.000451143610436501,0.000643232265542243,,20,3.94520769119263,11.9958937168121,-145.484367370605,
,6079622.58,4417,4.99994993209839,-1249.23707275391,179.975601196289,0.00421334348917008,0.75,0.012072594833374,0.75,-0.145948264312744,0.75,,,0.000450996938889079,0.000369696164914865,0.000641378554847776,,20,4.21334348917007,12.072594833374,-145.948264312744,
,6079647.94,4417,4.99900007247925,-1299.13013305664,179.975601196289,0.00398540009260178,0.75,0.0122118738651276,0.75,-0.145371044158936,0.75,,,0.000459923518719477,0.000309091200866287,0.00040362082360922,,20,3.98540009260178,12.2118738651276,-145.371044158936,
,6079673.77,4417,5.00154995918274,-1349.52678222656,179.975601196289,0.00413332977294922,0.75,0.0123300298690796,0.75,-0.145582118988037,0.75,,,0.000600165972905834,0.000455332790026821,0.000510447716931716,,20,4.13332977294922,12.3300298690796,-145.582118988037,
,6079700.75,4417,4.99834990501404,-1399.15545654297,179.975601196289,0.00429054770469666,0.75,0.012283475112915,0.75,-0.145042672729492,0.75,,,0.000551397990806432,0.000375447143361689,0.000374718866018158,,20,4.29054770469665,12.283475112915,-145.042672729492,
,6079728.91,4417,4.99650001525879,-1449.66592407227,179.975601196289,0.00434988367557526,0.75,0.0125699766635895,0.75,-0.144822110748291,0.75,,,0.000662530700162875,0.000285469614646548,0.000476210762494122,,20,4.34988367557526,12.5699766635895,-144.822110748291,
,6079754.53,4417,4.99899983406067,-1499.23598632812,179.975601196289,0.0046494412779808,0.75,0.012743096780777,0.75,-0.144900463867188,0.75,,,0.00076169964735347,0.000352190916715681,0.000602892329998719,,20,4.6494412779808,12.743096780777,-144.900463867188,
,6079780.48,4417,4.99745011329651,-1475.90532226563,179.975601196289,0.00419531316757202,0.75,0.0126599696159363,0.75,-0.144567477416992,0.75,,,0.000607664938635952,0.000363677862925131,0.000433534748788942,,20,4.19531316757202,12.6599696159363,-144.567477416992,
,6079809.22,4417,5.0040500164032,-1425.44313354492,179.975601196289,0.00463211824893951,0.75,0.0126129061222076,0.75,-0.145188466644287,0.75,,,0.000590341473069282,0.000436677695574609,0.000740147991926552,,20,4.63211824893951,12.6129061222076,-145.188466644287,
,6079837.03,4417,5.00230002403259,-1375.33848876953,179.975601196289,0.00411041823625565,0.75,0.0124696469306946,0.75,-0.145117037963867,0.75,,,0.000631662435766633,0.000446191481594041,0.000310414800949814,,20,4.11041823625565,12.4696469306946,-145.117037963867,
,6079865.22,4417,5.00114989280701,-1325.80524902344,179.975601196289,0.00442930485010147,0.75,0.0123789543628693,0.75,-0.146023961639404,0.75,,,0.000589732388150151,0.000442009125827776,0.000797295652310374,,20,4.42930485010147,12.3789543628693,-146.023961639404,
,6079893.34,4417,4.99989986419678,-1275.29130859375,179.975601196289,0.0041502750992775,0.75,0.0121884066104889,0.75,-0.145542636871338,0.75,,,0.000571692248794432,0.000381223348344517,0.000648482737102377,,20,4.1502750992775,12.1884066104889,-145.542636871338,
,6079920.36,4417,4.9985499382019,-1225.43500976563,179.975601196289,0.00420824884176254,0.75,0.0121116414546967,0.75,-0.145963460540771,0.75,,,0.000680137113291049,0.000418345659142168,0.000455115167930155,,20,4.20824884176254,12.1116414546967,-145.963460540771,
,6079949.70,4417,4.99889993667603,-1175.88564453125,179.975601196289,0.00403566944599152,0.75,0.0120397080898285,0.75,-0.146197403717041,0.75,,,0.000689493011637012,0.000380900030173654,0.000575707512497342,,20,4.03566944599152,12.0397080898285,-146.197403717041,
,6079977.95,4417,5.00014996528625,-1125.47752075195,179.975601196289,0.00377867525815964,0.75,0.0118319712638855,0.75,-0.146479853820801,0.75,,,0.000465148368675365,0.0004155600318199,0.000703746131651412,,20,3.77867525815964,11.8319712638855,-146.479853820801,
,6080004.78,4417,5.00069999694824,-1075.68903198242,179.975601196289,0.00388971920013428,0.75,0.0116452442646027,0.75,-0.146840841674805,0.75,,,0.000634722562142351,0.000309332168781575,0.000337845249873628,,20,3.88971920013428,11.6452442646027,-146.840841674805,
,6080031.64,4417,5.00034999847412,-1025.42803955078,179.975601196289,0.00417350891828537,0.75,0.0115446301460266,0.75,-0.146862609100342,0.75,,,0.000590986368543941,0.000307776924724819,0.000307351603007989,,20,4.17350891828537,11.5446301460266,-146.862609100342,
,6080059.44,4417,5.00074982643127,-975.826953125,179.975601196289,0.00377371187210083,0.75,0.0114195901870728,0.75,-0.147110143280029,0.75,,,0.000608491790632001,0.00044351127639466,0.000213254264195755,,20,3.77371187210083,11.4195901870728,-147.110143280029,
,6080087.42,4417,5.00294995307922,-925.74533996582,179.975601196289,0.00372720756530762,0.75,0.011240388917923,0.75,-0.14741155090332,0.75,,,0.000763104420579639,0.000418997313585486,0.000927632629394339,,20,3.72720756530762,11.240388917923,-147.41155090332,
,6080113.28,4421,4.99079990386963,-875.866015625,179.975601196289,0.00200237871110439,0.75,0.0109633477687836,0.75,-0.14479976348877,0.75,,,0.000643059890484971,0.000432970067212447,0.000907084278913875,,20,2.00237871110439,10.9633477687836,-144.79976348877,
,6080142.34,4421,4.99780011177063,-825.427978515625,179.975601196289,0.00295941460132599,0.75,0.0108035296440125,0.75,-0.146759156036377,0.75,,,0.00073016856524201,0.000320276200926048,0.000749600086445721,,20,2.95941460132599,10.8035296440125,-146.759156036377,
,6080170.44,4421,4.99860000610352,-775.538330078125,179.975601196289,0.00315186688899994,0.75,0.0107470531463623,0.75,-0.147604777526855,0.75,,,0.000603842729286576,0.000498966740673009,0.000970397617989888,,20,3.15186688899994,10.7470531463623,-147.604777526855,
,6080195.95,4421,4.99845004081726,-725.421047973633,179.975601196289,0.00302482372522354,0.75,0.0107250249862671,0.75,-0.147236232757568,0.75,,,0.000536139389029456,0.00036745965980781,0.000376477420250378,,20,3.02482372522354,10.7250249862671,-147.236232757568,
,6080222.58,4421,4.99835014343262,-675.726831054688,179.975601196289,0.00294723719954491,0.75,0.0107562075614929,0.75,-0.147887321472168,0.75,,,0.00076227447909908,0.000421498693248184,0.000549293321223043,,20,2.94723719954491,10.7562075614929,-147.887321472168,
,6080250.83,4421,4.99804997444153,-625.380770874023,179.975601196289,0.00305407820940018,0.75,0.0105580181121826,0.75,-0.148434050750732,0.75,,,0.000542931235613013,0.00036582862928664,0.000574136136710832,,20,3.05407820940018,10.5580181121826,-148.434050750732,
,6080279.06,4421,4.99885010719299,-575.826815795898,179.975601196289,0.0032064065694809,0.75,0.0104377387046814,0.75,-0.148491937255859,0.75,,,0.000723740361468196,0.000415863516371725,0.000560093052751423,,20,3.2064065694809,10.4377387046814,-148.491937255859,
,6080306.05,4421,4.99880003929138,-525.441659545898,179.975601196289,0.00310274024009705,0.75,0.0103371250152588,0.75,-0.149246478271484,0.75,,,0.000450419698963255,0.000396937837199213,0.000517612758614892,,20,3.10274024009705,10.3371250152588,-149.246478271484,
,6080330.52,4421,4.99909996986389,-475.658938598633,179.975601196289,0.00287691996097565,0.75,0.0101307826042175,0.75,-0.148777898406982,0.75,,,0.000570959138253236,0.000360761015690042,0.000443996147091945,,20,2.87691996097565,10.1307826042175,-148.777898406982,
,6080358.88,4417,4.99989986419678,-425.342753601074,179.975601196289,0.00290871896743774,0.75,0.00994609413146973,0.75,-0.149337944793701,0.75,,,0.000609342238125876,0.000412495684590838,0.000324516238661599,,20,2.90871896743774,9.94609413146973,-149.337944793701,
,6080384.88,4417,5.00170016288757,-375.743984985352,179.975601196289,0.00303389939665794,0.75,0.00996180324554443,0.75,-0.149128012084961,0.75,,,0.00076144304167203,0.000336442693646325,0.000404681980821584,,20,3.03389939665794,9.96180324554443,-149.128012084961,
,6080412.70,4417,5.00709986686707,-325.369166564941,179.975601196289,0.00322851058244705,0.75,0.00996154890060425,0.75,-0.150241107940674,0.75,,,0.000633500018332891,0.000391629628322805,0.000593997178851454,,20,3.22851058244705,9.96154890060425,-150.241107940674,
,6080438.81,4417,5,-275.811779785156,179.975601196289,0.00309158056974411,0.75,0.00960810351371765,0.75,-0.149782139587402,0.75,,,0.000696201537232602,0.000310863169327442,0.000465973391226712,,20,3.09158056974411,9.60810351371765,-149.782139587402,
,6080465.50,4417,5.00095009803772,-225.405917358398,179.975601196289,0.00292825080752373,0.75,0.00947315397262573,0.75,-0.15017445526123,0.75,,,0.000614598161301653,0.000362291254798942,0.000820728174604408,,20,2.92825080752373,9.47315397262573,-150.17445526123,
,6080491.52,4417,5.00094985961914,-175.746208190918,179.975601196289,0.00263416644334793,0.75,0.00933221750259399,0.75,-0.150150287628174,0.75,,,0.000590962471821873,0.000334430802173055,0.000443455425592634,,20,2.63416644334793,9.33221750259399,-150.150287628174,
,6080518.25,4417,4.99974989891052,-125.863461303711,179.975601196289,0.00131138959527016,0.75,0.00914245848655701,0.75,-0.14901392364502,0.75,,,0.000411015176047481,0.00037228861378199,0.000672833946181506,,20,1.31138959527016,9.14245848655701,-149.01392364502,
,6080543.95,4417,5.00034999847412,-75.7841148376465,179.975601196289,0.00121510228514671,0.75,0.00917565650939942,0.75,-0.14875177230835,0.75,,,0.00062031816780942,0.000420451898542334,0.000688364098331377,,20,1.21510228514671,9.17565650939941,-148.75177230835,
,6080570.94,4417,5.00020003318787,-25.8783717155457,179.975601196289,0.00164827755391598,0.75,0.00894862837791443,0.75,-0.148883934783936,0.75,,,0.000637442402266346,0.000383450001987674,0.000619443991406617,,20,1.64827755391598,8.94862837791443,-148.883934783936,
,6080583.92,4417,4.99919986724854,-0.808232101798058,179.975601196289,0.00119963771700859,0.75,0.00877283582687378,0.75,-0.14860383682251,0.75,,,0.000556772337018994,0.000280611742806536,0.000471625263590273,,20,1.19963771700859,8.77283582687378,-148.60383682251,