File: data/r99.dat
[Header]
TITLE, default name
FILEOPENTIME,6080857.80,5/27/2021,10:30 PM
BYAPP, Resistivity, 2.1, 1.0
INFO, APPNAME, PPMS MultiVu Application, 1.5.11
INFO, , Sample1 Name
INFO, 1, Sample1 Cross Section
INFO, 1, Sample1 Length
INFO, Ohm-m, Sample1 Units
INFO, , Sample2 Name
INFO, 1, Sample2 Cross Section
INFO, 1, Sample2 Length
INFO, Ohm-m, Sample2 Units
INFO, , Sample3 Name
INFO, 1, Sample3 Cross Section
INFO, 1, Sample3 Length
INFO, Ohm-m, Sample3 Units
INFO, , Sample4 Name
INFO, 1, Sample4 Cross Section
INFO, 1, Sample4 Length
INFO, Ohm-m, Sample4 Units
FIELDGROUP, Resistivity,2,3,4,5,6,7,8,9,10,11,12,13,14,15,16,17,18,19,20,21,22,23,24,25,26,27,28,29,30,31,32,33,34,35,36,37,38,39,40,41
STARTUPGROUP, Resistivity
STARTUPAXIS, X, 2, LINEAR, AUTO
STARTUPAXIS, Y1, 7, LINEAR, AUTO
STARTUPAXIS, Y2, 9, LINEAR, AUTO
STARTUPAXIS, Y3, 11, LINEAR, AUTO
PLOT_APPEARANCE, ALL, HORZ_GRID_ON, VERT_GRID_ON, MARKERS_AND_LINES, ALL_LINES
DATATYPE, TIME, 2
DATATYPE, COMMENT, 1
[Data]
Comment,Time Stamp (sec),Status (code),Temperature (K),Magnetic Field (Oe),Sample Position (deg),Bridge 1 Resistivity (Ohm-m),Bridge 1 Excitation (uA),Bridge 2 Resistivity (Ohm-m),Bridge 2 Excitation (uA),Bridge 3 Resistivity (Ohm-m),Bridge 3 Excitation (uA),Bridge 4 Resistivity (Ohm-m),Bridge 4 Excitation (uA),Bridge 1 Std. Dev. (Ohm-m),Bridge 2 Std. Dev. (Ohm-m),Bridge 3 Std. Dev. (Ohm-m),Bridge 4 Std. Dev. (Ohm-m),Number of Readings,Bridge 1 Resistance (Ohms),Bridge 2 Resistance (Ohms),Bridge 3 Resistance (Ohms),Bridge 4 Resistance (Ohms),Signal 1 Vin (V),Signal 2 Vin (V),Digital Inputs (code),Drive 1 Iout (mA),Drive 1 Ipower (watts),Drive 2 Iout (mA),Drive 2 Ipower (watts),Pressure (),Map 20 (),Map 21 (),Map 22 (),Map 23 (),Map 24 (),Map 25 (),Map 26 (),Map 27 (),Map 28 (),Map 29 ()
,6080893.92,4417,4.99954986572266,-0.235686503350735,179.975601196289,0.596654119873047,4.98624997138977,0.263866809082031,4.99599997997284,-0.251415059661865,5.08439996242523,,,0.00452685245252797,0.00625654801626341,0.00809584415221539,,20,596.654119873047,263.866809082031,-251.415059661865,
,6080924.06,4417,5.00025010108948,49.6332656860352,179.975601196289,0.592559957885742,5.17799997329712,0.26664095916748,5.17799997329712,-0.248797382354736,5.17799997329712,,,0.000700838073960129,0.000266692390914565,0.000716690987188671,,20,592.559957885742,266.64095916748,-248.797382354736,
,6080950.41,4417,5.00049996376038,99.1803062438965,179.975601196289,0.592654251098633,5.17799997329712,0.266595648193359,5.17799997329712,-0.251100556945801,5.17799997329712,,,0.000620601038900282,0.000317615634984082,0.00067978694925387,,20,592.654251098633,266.595648193359,-251.100556945801,
,6080976.28,4417,5.00045013427734,149.296437835693,179.975601196289,0.592217269897461,5.17799997329712,0.266396649169922,5.17799997329712,-0.253499436950684,5.17799997329712,,,0.000775157409207094,0.000345866753298668,0.000651344267048309,,20,592.217269897461,266.396649169922,-253.499436950684,
,6081001.44,4417,4.99795007705688,199.20678024292,179.975601196289,0.591758963012695,5.17799997329712,0.266465209960938,5.17799997329712,-0.256364010620117,5.17799997329712,,,0.000639437471941111,0.000296043523679251,0.000717860880662382,,20,591.758963012695,266.465209960938,-256.364010620117,
,6081029.41,4417,4.99895000457764,249.468930053711,179.975601196289,0.591584393310547,5.17799997329712,0.266406359863281,5.17799997329712,-0.259671714782715,5.17799997329712,,,0.000587828648584865,0.000376727220784888,0.000601057627440081,,20,591.584393310547,266.406359863281,-259.671714782715,
,6081055.95,4417,5.00150012969971,299.241311645508,179.975601196289,0.59098083190918,5.17799997329712,0.26618345489502,5.17799997329712,-0.261946687316895,5.17799997329712,,,0.000670535495088358,0.000382361215089947,0.000578613985473545,,20,590.98083190918,266.18345489502,-261.946687316895,
,6081083.94,4417,4.99799990653992,349.634526062012,179.975601196289,0.590152828979492,5.17799997329712,0.265747766113281,5.17799997329712,-0.265202793884277,5.17799997329712,,,0.00076342590702987,0.000348596491693247,0.000771639871699203,,20,590.152828979492,265.747766113281,-265.202793884277,
,6081111.36,4417,5.00180006027222,399.20915222168,179.975601196289,0.589971517944336,5.17799997329712,0.266033961486816,5.17799997329712,-0.267427847290039,5.17799997329712,,,0.000678138201622298,0.00031959583015295,0.000566240978810625,,20,589.971517944336,266.033961486816,-267.427847290039,
,6081140.39,4417,4.99785017967224,449.389669799805,179.975601196289,0.58943108215332,5.17799997329712,0.265141212463379,5.17799997329712,-0.269742868041992,5.17799997329712,,,0.00064896769779641,0.000314107646756992,0.000754671016891263,,20,589.43108215332,265.141212463379,-269.742868041992,
,6081169.98,4417,5.00005006790161,499.569047546387,179.975601196289,0.588778890991211,5.17799997329712,0.265104699707031,5.17799997329712,-0.27209755859375,5.17799997329712,,,0.000683270791106864,0.000414356242520341,0.000810269283939648,,20,588.778890991211,265.104699707031,-272.09755859375,
,6081198.20,4417,4.99720001220703,549.644927978516,179.975601196289,0.588141128540039,5.17799997329712,0.265440258789063,5.17799997329712,-0.274263383483887,5.17799997329712,,,0.000608781014639766,0.000348445868829807,0.000626561161603602,,20,588.141128540039,265.440258789063,-274.263383483887,
,6081227.23,4417,4.99940013885498,599.527691650391,179.975601196289,0.586951336669922,5.17799997329712,0.26502737121582,5.17799997329712,-0.276790357971192,5.17799997329712,,,0.000706258330276646,0.000298911121012174,0.000860411867512556,,20,586.951336669922,265.02737121582,-276.790357971191,
,6081254.20,4417,5.00095009803772,649.44147644043,179.975601196289,0.587241744995117,5.17799997329712,0.264182069396973,5.17799997329712,-0.279661926269531,5.17799997329712,,,0.000687187482234153,0.000311752520094634,0.000744406166505667,,20,587.241744995117,264.182069396973,-279.661926269531,
,6081282.80,4417,5.0019998550415,699.335733032227,179.975601196289,0.5870109375,5.17799997329712,0.264196336364746,5.17799997329712,-0.282365531921387,5.17799997329712,,,0.000480795057089023,0.000447057741153902,0.000895809497963443,,20,587.0109375,264.196336364746,-282.365531921387,
,6081311.30,4417,4.99869990348816,749.132269287109,179.975601196289,0.586163238525391,5.17799997329712,0.263284368896484,5.17799997329712,-0.284111723327637,5.17799997329712,,,0.000409492583422435,0.000337257663610285,0.000842367838263004,,20,586.163238525391,263.284368896484,-284.111723327637,
,6081340.61,4417,5.00005006790161,799.303558349609,179.975601196289,0.584843884277344,5.17799997329712,0.263312426757813,5.17799997329712,-0.286508531188965,5.17799997329712,,,0.000594320711966919,0.000400241117415537,0.00070229716831637,,20,584.843884277344,263.312426757812,-286.508531188965,
,6081365.91,4417,4.99930000305176,849.274844360352,179.975601196289,0.584383630371094,5.17799997329712,0.262960696411133,5.17799997329712,-0.288592509460449,5.17799997329712,,,0.000707488709455203,0.000448952410193684,0.00073182322699988,,20,584.383630371094,262.960696411133,-288.592509460449,
,6081392.92,4417,4.99889993667603,899.127709960938,179.975601196289,0.583011218261719,5.17799997329712,0.262005740356445,5.17799997329712,-0.291277238464355,5.17799997329712,,,0.000555524978624263,0.000429078015570762,0.000757387837681347,,20,583.011218261719,262.005740356445,-291.277238464355,
,6081420.23,4417,5.00020003318787,949.193246459961,179.975601196289,0.58206262512207,5.17799997329712,0.261722978210449,5.17799997329712,-0.293203364562988,5.17799997329712,,,0.000586298979846842,0.000387182556293591,0.000644862850674643,,20,582.06262512207,261.722978210449,-293.203364562988,
,6081448.13,4417,4.9991500377655,999.68762512207,179.975601196289,0.581132827758789,5.17799997329712,0.261464674377441,5.17799997329712,-0.295770040893555,5.17799997329712,,,0.000499726194027397,0.000361095841107766,0.000826294091668927,,20,581.132827758789,261.464674377441,-295.770040893555,
,6081475.91,4417,5.00090003013611,1049.30592651367,179.975601196289,0.580536434936523,5.17799997329712,0.260793783569336,5.17799997329712,-0.298137272644043,5.17799997329712,,,0.000560801274000603,0.000315600941395131,0.000822778096058768,,20,580.536434936523,260.793783569336,-298.137272644043,
,6081503.45,4417,5.00029993057251,1099.16223144531,179.975601196289,0.579071520996094,5.17799997329712,0.260076080322266,5.17799997329712,-0.300581773376465,5.17799997329712,,,0.000592463453247243,0.000388476058011257,0.00053753056748848,,20,579.071520996094,260.076080322266,-300.581773376465,
,6081529.34,4417,4.9991500377655,1149.25308837891,179.975601196289,0.578372766113281,5.17799997329712,0.26008317565918,5.17799997329712,-0.302650038146973,5.17799997329712,,,0.00048664300414121,0.000363787937563676,0.000697771859148058,,20,578.372766113281,260.08317565918,-302.650038146973,
,6081555.02,4417,4.99865007400513,1199.12092285156,179.975601196289,0.576743524169922,5.17799997329712,0.258966148376465,5.17799997329712,-0.305291467285156,5.17799997329712,,,0.000558752449779576,0.000328268928164977,0.000802945537393082,,20,576.743524169922,258.966148376465,-305.291467285156,
,6081583.38,4417,5.00099992752075,1249.29452514648,179.975601196289,0.576027255249023,5.17799997329712,0.25876651763916,5.17799997329712,-0.308556887817383,5.17799997329712,,,0.000495866378595846,0.000377855583823621,0.000780400420240694,,20,576.027255249023,258.76651763916,-308.556887817383,
,6081610.25,4417,4.99889993667603,1299.49000244141,179.975601196289,0.574866598510742,5.17799997329712,0.258053800964355,5.17799997329712,-0.310048406982422,5.17799997329712,,,0.000543994907271816,0.000314370405447301,0.000538211371063111,,20,574.866598510742,258.053800964355,-310.048406982422,
,6081639.41,4417,5,1349.36583251953,179.975601196289,0.574179049682617,5.17799997329712,0.257630569458008,5.17799997329712,-0.312907803344727,5.17799997329712,,,0.000401594543430361,0.000322234858031002,0.000565332721046258,,20,574.179049682617,257.630569458008,-312.907803344727,
,6081665.97,4417,4.99960017204285,1399.17270507813,179.975601196289,0.572822180175781,5.17799997329712,0.256902714538574,5.17799997329712,-0.315094018554687,5.17799997329712,,,0.000560469915301113,0.00032438080949102,0.000682992132446198,,20,572.822180175781,256.902714538574,-315.094018554688,
,6081695.52,4417,4.99830007553101,1449.63260498047,179.975601196289,0.571581317138672,5.17799997329712,0.256315981292725,5.17799997329712,-0.317635182189941,5.17799997329712,,,0.000579664019517723,0.000440153014204018,0.000574386004360297,,20,571.581317138672,256.315981292725,-317.635182189941,
,6081723.38,4417,4.99790000915527,1499.25897827148,179.975601196289,0.570419860839844,5.17799997329712,0.255506803131104,5.17799997329712,-0.319304768371582,5.17799997329712,,,0.000920933208017066,0.000374702875155704,0.000471327520321632,,20,570.419860839844,255.506803131104,-319.304768371582,
,6081749.03,4417,5.00169992446899,1475.34311523438,179.975601196289,0.570489575195313,5.17799997329712,0.256066968536377,5.17799997329712,-0.319677438354492,5.17799997329712,,,0.000466187724742588,0.000290606543521791,0.000563639956469211,,20,570.489575195312,256.066968536377,-319.677438354492,
,6081774.61,4417,4.99889993667603,1425.7397277832,179.975601196289,0.571496786499023,5.17799997329712,0.256976959228516,5.17799997329712,-0.318397421264648,5.17799997329712,,,0.000613317785912432,0.000229799715732888,0.000525460774507459,,20,571.496786499023,256.976959228516,-318.397421264648,
,6081801.75,4417,5.00064992904663,1375.85472412109,179.975601196289,0.572267446899414,5.17799997329712,0.25839584197998,5.17799997329712,-0.317398109436035,5.17799997329712,,,0.000519712096690523,0.000331966717113463,0.000578677673538689,,20,572.267446899414,258.39584197998,-317.398109436035,
,6081828.23,4417,5.00090003013611,1325.74892578125,179.975601196289,0.573886727905274,5.17799997329712,0.259160391235352,5.17799997329712,-0.315841038513184,5.17799997329712,,,0.000563274372724906,0.000249830574643471,0.000448107205028889,,20,573.886727905273,259.160391235352,-315.841038513184,
,6081854.11,4417,5.0006000995636,1275.75465087891,179.975601196289,0.574571420288086,5.17799997329712,0.260369273376465,5.17799997329712,-0.31545152130127,5.17799997329712,,,0.000677040424503953,0.000376164555741147,0.000524520023450074,,20,574.571420288086,260.369273376465,-315.45152130127,
,6081881.88,4417,5,1225.43041381836,179.975601196289,0.576149084472656,5.17799997329712,0.261301495361328,5.17799997329712,-0.313881016540527,5.17799997329712,,,0.000674151915735318,0.000295182995328771,0.000520797569849852,,20,576.149084472656,261.301495361328,-313.881016540527,
,6081910.84,4417,5.00079989433289,1175.55227661133,179.975601196289,0.577129837036133,5.17799997329712,0.262236430358887,5.17799997329712,-0.312585433959961,5.17799997329712,,,0.00072754100303828,0.000288608900277737,0.000472339087201448,,20,577.129837036133,262.236430358887,-312.585433959961,
,6081940.13,4417,4.98965001106262,1125.45224609375,179.975601196289,0.578452563476562,5.17799997329712,0.263348616027832,5.17799997329712,-0.311866990661621,5.17799997329712,,,0.000587324989578004,0.000284080618096182,0.000736323117343104,,20,578.452563476563,263.348616027832,-311.866990661621,
,6081965.63,4421,4.99475002288818,1075.59362792969,179.975601196289,0.579680859375,5.17799997329712,0.264517059326172,5.17799997329712,-0.310133433532715,5.17799997329712,,,0.000652525417214499,0.000311902955573571,0.000719070181909263,,20,579.680859375,264.517059326172,-310.133433532715,
,6081992.98,4421,4.99810004234314,1025.37399291992,179.975601196289,0.580483889770508,5.17799997329712,0.265272805786133,5.17799997329712,-0.309259257507324,5.17799997329712,,,0.000519319051215309,0.000547675393825048,0.000614275523078063,,20,580.483889770508,265.272805786133,-309.259257507324,
,6082017.36,4421,4.99784994125366,975.479766845703,179.975601196289,0.581707455444336,5.17799997329712,0.266390895080566,5.17799997329712,-0.308534469604492,5.17799997329712,,,0.000450465443685433,0.000313270101649238,0.000682936075641985,,20,581.707455444336,266.390895080566,-308.534469604492,
,6082045.17,4421,4.99830007553101,925.434915161133,179.975601196289,0.583199337768555,5.17799997329712,0.267318476867676,5.17799997329712,-0.307035733032227,5.17799997329712,,,0.000632771527558436,0.0002364267907575,0.000692244316052615,,20,583.199337768555,267.318476867676,-307.035733032227,
,6082071.95,4421,4.9980001449585,875.494686889648,179.975601196289,0.584300689697266,5.17799997329712,0.268403327941895,5.17799997329712,-0.305674070739746,5.17799997329712,,,0.000471250494182044,0.000285771692561073,0.000760580623053394,,20,584.300689697266,268.403327941895,-305.674070739746,
,6082100.22,4421,4.9980001449585,825.256674194336,179.975601196289,0.585170053100586,5.17799997329712,0.269539141845703,5.17799997329712,-0.305154533386231,5.17799997329712,,,0.000421475735424048,0.000298180647758968,0.000608591833932203,,20,585.170053100586,269.539141845703,-305.15453338623,
,6082125.00,4421,4.9985499382019,775.686639404297,179.975601196289,0.586617993164062,5.17799997329712,0.270444868469238,5.17799997329712,-0.303718969726562,5.17799997329712,,,0.000510305013788888,0.000265109744441946,0.000863506622434964,,20,586.617993164062,270.444868469238,-303.718969726562,
,6082153.11,4421,4.99899983406067,725.798135375977,179.975601196289,0.587562808227539,5.17799997329712,0.271416593933105,5.17799997329712,-0.30325064239502,5.17799997329712,,,0.000546680808191531,0.00032937250071022,0.000541071522678095,,20,587.562808227539,271.416593933105,-303.25064239502,
,6082178.80,4421,4.99935007095337,675.714196777344,179.975601196289,0.588835336303711,5.17799997329712,0.272407078552246,5.17799997329712,-0.301875703430176,5.17799997329712,,,0.000438916936638912,0.00039568900803104,0.000592764497963299,,20,588.835336303711,272.407078552246,-301.875703430176,
,6082205.41,4417,5.00005006790161,625.833746337891,179.975601196289,0.589843685913086,5.17799997329712,0.273447857666016,5.17799997329712,-0.301103187561035,5.17799997329712,,,0.000503448932248216,0.000283841477071849,0.000741406393966616,,20,589.843685913086,273.447857666016,-301.103187561035,
,6082231.19,4417,5.00169992446899,575.614144897461,179.975601196289,0.591200271606445,5.17799997329712,0.273887214660645,5.17799997329712,-0.300120310974121,5.17799997329712,,,0.000620082988852675,0.000356303691669891,0.000770685001951404,,20,591.200271606445,273.887214660645,-300.120310974121,
,6082257.47,4417,5.00869989395142,525.746331787109,179.975601196289,0.592213192749023,5.17799997329712,0.274512551879883,5.17799997329712,-0.299458918762207,5.17799997329712,,,0.000449300532491336,0.000366746609878818,0.000660312317106505,,20,592.213192749023,274.512551879883,-299.458918762207,
,6082284.91,4417,4.99995017051697,475.672738647461,179.975601196289,0.593296710205078,5.17799997329712,0.275487347412109,5.17799997329712,-0.298018330383301,5.17799997329712,,,0.000486573266371762,0.000317908552686419,0.000690322008240729,,20,593.296710205078,275.487347412109,-298.018330383301,
,6082310.89,4417,5.00030016899109,425.793428039551,179.975601196289,0.594429901123047,5.17799997329712,0.276433595275879,5.17799997329712,-0.296516482543945,5.17799997329712,,,0.000489371710557553,0.000388844957933683,0.000675710143903661,,20,594.429901123047,276.433595275879,-296.516482543945,
,6082338.89,4417,5.00029993057251,375.361141967773,179.975601196289,0.595640240478516,5.17799997329712,0.277261212158203,5.17799997329712,-0.295398931884766,5.17799997329712,,,0.000481373967667954,0.000323822523709657,0.000601306836915874,,20,595.640240478516,277.261212158203,-295.398931884766,
,6082364.84,4417,4.99985003471375,325.449638366699,179.975601196289,0.596535726928711,5.17799997329712,0.277963182067871,5.17799997329712,-0.294779051208496,5.17799997329712,,,0.000406618891930453,0.00031079736623325,0.000824950236048524,,20,596.535726928711,277.963182067871,-294.779051208496,
,6082394.97,4417,4.99944996833801,275.656567382813,179.975601196289,0.597584039306641,5.17799997329712,0.279166482543945,5.17799997329712,-0.293353981018066,5.17799997329712,,,0.000447237519420492,0.000360674041044084,0.000807591158967293,,20,597.584039306641,279.166482543945,-293.353981018066,
,6082420.94,4417,5.00010013580322,225.218524932861,179.975601196289,0.599000973510742,5.17799997329712,0.279903941345215,5.17799997329712,-0.292359176635742,5.17799997329712,,,0.000776732983892704,0.000357033145449817,0.000533637853359733,,20,599.000973510742,279.903941345215,-292.359176635742,
,6082448.17,4417,5.00014996528625,175.871524047852,179.975601196289,0.600146029663086,5.17799997329712,0.280577386474609,5.17799997329712,-0.292012870788574,5.17799997329712,,,0.00051538687575561,0.000305080698639101,0.000863557888145843,,20,600.146029663086,280.577386474609,-292.012870788574,
,6082475.91,4417,5.00004982948303,125.411631393433,179.975601196289,0.601557275390625,5.17799997329712,0.281512417602539,5.17799997329712,-0.291127345275879,5.17799997329712,,,0.000445561398281005,0.000429455957211084,0.000615287348817465,,20,601.557275390625,281.512417602539,-291.127345275879,
,6082501.27,4417,5.00164985656738,75.6128105163574,179.975601196289,0.603151528930664,5.17799997329712,0.282209283447266,5.17799997329712,-0.290831433105469,5.17799997329712,,,0.000516172515389289,0.00032627168490405,0.000821616699598518,,20,603.151528930664,282.209283447266,-290.831433105469,
,6082527.28,4417,4.99860000610352,25.7542057991028,179.975601196289,0.60446145324707,5.17799997329712,0.282798756408691,5.17799997329712,-0.289339549255371,5.17799997329712,,,0.000567620258893533,0.000413291240742433,0.000564393680619847,,20,604.46145324707,282.798756408691,-289.339549255371,
,6082556.25,4417,5.00075006484985,-24.1227949142456,179.975601196289,0.605553924560547,5.17799997329712,0.283780813598633,5.17799997329712,-0.288903944396973,5.17799997329712,,,0.000433389109091995,0.000245296123901723,0.000877468569369886,,20,605.553924560547,283.780813598633,-288.903944396973,
,6082583.39,4417,4.99974989891052,-74.604532623291,179.975601196289,0.606166070556641,5.17799997329712,0.284930224609375,5.17799997329712,-0.288271002197266,5.17799997329712,,,0.000285041461775451,0.000405670033251518,0.000618658209367283,,20,606.166070556641,284.930224609375,-288.271002197266,
,6082609.94,4417,5.00244998931885,-124.388409042358,179.975601196289,0.608052056884766,5.17799997329712,0.286098175048828,5.17799997329712,-0.287438912963867,5.17799997329712,,,0.000595040305126939,0.000366197419885513,0.000893698278720661,,20,608.052056884766,286.098175048828,-287.438912963867,
,6082637.58,4417,5.0040500164032,-174.594219207764,179.975601196289,0.609481411743164,5.17799997329712,0.287062712097168,5.17799997329712,-0.286535740661621,5.17799997329712,,,0.000472255921907496,0.000337257691303506,0.000648268542557628,,20,609.481411743164,287.062712097168,-286.535740661621,
,6082664.78,4417,4.9976499080658,-224.134368896484,179.975601196289,0.610362963867188,5.17799997329712,0.287971047973633,5.17799997329712,-0.285839521789551,5.17799997329712,,,0.000574578000643582,0.000327088119169455,0.000513503802817232,,20,610.362963867188,287.971047973633,-285.839521789551,
,6082692.09,4417,4.99965000152588,-274.618391418457,179.975601196289,0.61163620300293,5.17799997329712,0.288912226867676,5.17799997329712,-0.285814286804199,5.17799997329712,,,0.000415697537385782,0.000361877157972874,0.000512559309962098,,20,611.63620300293,288.912226867676,-285.814286804199,
,6082718.78,4417,4.99950003623962,-324.535636901855,179.975601196289,0.612806478881836,5.17799997329712,0.290085949707031,5.17799997329712,-0.285299560546875,5.17799997329712,,,0.000512867742926582,0.000360693886508883,0.000553047802017535,,20,612.806478881836,290.085949707031,-285.299560546875,
,6082745.66,4417,5.00200009346008,-374.572453308105,179.975601196289,0.614218334960938,5.17799997329712,0.291202464294434,5.17799997329712,-0.284854089355469,5.17799997329712,,,0.00048230172606444,0.000345111293726029,0.000804194808986815,,20,614.218334960937,291.202464294434,-284.854089355469,
,6082772.58,4417,4.99900007247925,-424.153982543945,179.975601196289,0.615677380371094,5.17799997329712,0.292149458312988,5.17799997329712,-0.284084585571289,5.17799997329712,,,0.000738875931349105,0.000343403079752069,0.000877324171932601,,20,615.677380371094,292.149458312988,-284.084585571289,
,6082799.61,4417,5.00304985046387,-474.509248352051,179.975601196289,0.616587213134766,5.17799997329712,0.293361515808105,5.17799997329712,-0.284141181945801,5.17799997329712,,,0.000553926406416785,0.000319822316861928,0.000702110639454127,,20,616.587213134766,293.361515808105,-284.141181945801,
,6082825.91,4417,5,-524.218395996094,179.975601196289,0.61820407409668,5.17799997329712,0.294346028137207,5.17799997329712,-0.284403660583496,5.17799997329712,,,0.000533322050206618,0.000418692483936531,0.000863691257661472,,20,618.20407409668,294.346028137207,-284.403660583496,
,6082853.81,4417,4.99950003623962,-574.608166503906,179.975601196289,0.619796438598633,5.17799997329712,0.295562532043457,5.17799997329712,-0.283920150756836,5.17799997329712,,,0.000481703963691712,0.000386839894784815,0.000622460343201606,,20,619.796438598633,295.562532043457,-283.920150756836,
,6082880.91,4417,5.00104999542236,-624.165533447266,179.975601196289,0.620922528076172,5.17799997329712,0.296183148193359,5.17799997329712,-0.283469096374512,5.17799997329712,,,0.000477062544313282,0.000420143182364826,0.000701300644862018,,20,620.922528076172,296.183148193359,-283.469096374512,
,6082910.44,4417,5.0032000541687,-674.673724365234,179.975601196289,0.622615258789063,5.17799997329712,0.297409828186035,5.17799997329712,-0.283130563354492,5.17799997329712,,,0.000443662144452942,0.000363590344151295,0.000835836545282681,,20,622.615258789063,297.409828186035,-283.130563354492,
,6082937.47,4417,4.99775004386902,-724.238009643555,179.975601196289,0.623677438354492,5.17799997329712,0.298591351318359,5.17799997329712,-0.283307278442383,5.17799997329712,,,0.000657597458258509,0.000323109627941577,0.000656200955108283,,20,623.677438354492,298.591351318359,-283.307278442383,
,6082967.64,4417,4.99644994735718,-774.646179199219,179.975601196289,0.625158596801758,5.17799997329712,0.299423281860352,5.17799997329712,-0.283640869140625,5.17799997329712,,,0.000542581804103584,0.00039638121443114,0.000427316141950791,,20,625.158596801758,299.423281860352,-283.640869140625,
,6082993.58,4417,5.00209999084473,-824.211611938477,179.975601196289,0.626278607177734,5.17799997329712,0.300260136413574,5.17799997329712,-0.28298277130127,5.17799997329712,,,0.000349943704991545,0.000349356626899766,0.000686237594022948,,20,626.278607177734,300.260136413574,-282.98277130127,
,6083020.06,4417,5.00029993057251,-874.247250366211,179.975601196289,0.63175412902832,5.17799997329712,0.299346339416504,5.17799997329712,-0.284028948974609,5.17799997329712,,,0.000511579012288443,0.000485794346591065,0.000514796713778403,,20,631.75412902832,299.346339416504,-284.028948974609,
,6083047.31,4417,4.99924993515015,-924.541589355469,179.975601196289,0.633069604492187,5.17799997329712,0.300220159912109,5.17799997329712,-0.284550314331055,5.17799997329712,,,0.00048952385943493,0.000316678948793592,0.000633663670728133,,20,633.069604492188,300.220159912109,-284.550314331055,
,6083076.14,4417,5.0010998249054,-974.612899780273,179.975601196289,0.634148809814453,5.17799997329712,0.301104153442383,5.17799997329712,-0.284580485534668,5.17799997329712,,,0.000676809500808253,0.000411915393541488,0.000635044874350884,,20,634.148809814453,301.104153442383,-284.580485534668,
,6083102.88,4417,4.99950003623962,-1024.27144165039,179.975601196289,0.635661578369141,5.17799997329712,0.30224697265625,5.17799997329712,-0.285071116638184,5.17799997329712,,,0.000541665122224101,0.000304687959611735,0.00078306438394217,,20,635.661578369141,302.24697265625,-285.071116638184,
,6083131.38,4417,4.99930000305176,-1074.17030029297,179.975601196289,0.63700729675293,5.17799997329712,0.302970222473145,5.17799997329712,-0.285024540710449,5.17799997329712,,,0.000654421072713113,0.000418586856199391,0.000882113266957408,,20,637.00729675293,302.970222473145,-285.024540710449,
,6083159.38,4417,5.00290012359619,-1124.26690063477,179.975601196289,0.638588568115234,5.17799997329712,0.30393108215332,5.17799997329712,-0.28518116607666,5.17799997329712,,,0.00066423354804426,0.000407651541973225,0.000618635252179347,,20,638.588568115234,303.93108215332,-285.18116607666,
,6083186.19,4417,5.00104999542236,-1174.49915161133,179.975601196289,0.639336352539063,5.17799997329712,0.304990908813477,5.17799997329712,-0.285503973388672,5.17799997329712,,,0.000492226119829803,0.00035455611662483,0.000802911596485646,,20,639.336352539063,304.990908813477,-285.503973388672,
,6083211.66,4417,5.00069999694824,-1224.26349487305,179.975601196289,0.640703021240234,5.17799997329712,0.306037196350098,5.17799997329712,-0.285619857788086,5.17799997329712,,,0.000481888474908325,0.000341779202205154,0.000735344070816262,,20,640.703021240234,306.037196350098,-285.619857788086,
,6083238.00,4417,5.00069999694824,-1274.38991699219,179.975601196289,0.642170257568359,5.17799997329712,0.307023655700684,5.17799997329712,-0.286094364929199,5.17799997329712,,,0.000482676849012767,0.000294956685816798,0.000736462596691925,,20,642.170257568359,307.023655700684,-286.094364929199,
,6083265.86,4417,4.99950003623962,-1324.29339599609,179.975601196289,0.643413009643555,5.17799997329712,0.307972145080566,5.17799997329712,-0.286288768005371,5.17799997329712,,,0.000488683123400873,0.000299713145531403,0.000664428444061217,,20,643.413009643555,307.972145080566,-286.288768005371,
,6083292.56,4417,5.00049996376038,-1374.48084106445,179.975601196289,0.64390539855957,5.17799997329712,0.309231526184082,5.17799997329712,-0.286075216674805,5.17799997329712,,,0.000663872419429504,0.000375314903711849,0.000691543731192175,,20,643.90539855957,309.231526184082,-286.075216674805,
,6083319.17,4417,4.99834990501404,-1424.25551147461,179.975601196289,0.645760205078125,5.17799997329712,0.310006440734863,5.17799997329712,-0.287061972045898,5.17799997329712,,,0.000494296610827982,0.000382866745076599,0.000669397618954301,,20,645.760205078125,310.006440734863,-287.061972045898,
,6083344.66,4417,4.99815011024475,-1474.45094604492,179.975601196289,0.647420904541016,5.17799997329712,0.310715879821777,5.17799997329712,-0.286994486999512,5.17799997329712,,,0.000481953638051742,0.000324560473537869,0.00049811011186589,,20,647.420904541016,310.715879821777,-286.994486999512,
,6083369.45,4417,4.9991500377655,-1499.23713378906,179.975601196289,0.647823397827148,5.17799997329712,0.31139141998291,5.17799997329712,-0.286749839782715,5.17799997329712,,,0.000462719798745493,0.000411165609521072,0.000809663823081497,,20,647.823397827148,311.39141998291,-286.749839782715,
,6083396.30,4417,5.00069999694824,-1450.53969726562,179.975601196289,0.647307119750977,5.17799997329712,0.31114476776123,5.17799997329712,-0.28749663848877,5.17799997329712,,,0.000586693527235643,0.000379972005040769,0.000541659469213209,,20,647.307119750977,311.14476776123,-287.49663848877,
,6083423.14,4417,5.00020003318787,-1400.37759399414,179.975601196289,0.645969305419922,5.17799997329712,0.309750601196289,5.17799997329712,-0.288735952758789,5.17799997329712,,,0.000672804100123052,0.000306448613318608,0.000528380555346004,,20,645.969305419922,309.750601196289,-288.735952758789,
,6083450.92,4417,4.99989986419678,-1350.60522460938,179.975601196289,0.64423874206543,5.17799997329712,0.309496188354492,5.17799997329712,-0.288542059326172,5.17799997329712,,,0.000457898060428298,0.000355850059741689,0.000821604458435851,,20,644.23874206543,309.496188354492,-288.542059326172,
,6083478.17,4417,5.00184988975525,-1300.69372558594,179.975601196289,0.642845370483398,5.17799997329712,0.308544653320313,5.17799997329712,-0.289796841430664,5.17799997329712,,,0.000353964191644896,0.000307054298112175,0.000573829853119665,,20,642.845370483398,308.544653320312,-289.796841430664,
,6083504.78,4417,4.99994993209839,-1250.51892089844,179.975601196289,0.641762365722656,5.17799997329712,0.308161531066895,5.17799997329712,-0.290370291137695,5.17799997329712,,,0.00047163064725912,0.000304862369648864,0.000663383008898128,,20,641.762365722656,308.161531066895,-290.370291137695,
,6083532.05,4417,5.00349998474121,-1200.63160400391,179.975601196289,0.640877597045898,5.17799997329712,0.307261274719238,5.17799997329712,-0.291103172302246,5.17799997329712,,,0.000575782386073096,0.000320697183215724,0.000856790848405039,,20,640.877597045898,307.261274719238,-291.103172302246,
,6083559.53,4417,4.99820017814636,-1150.52007446289,179.975601196289,0.639279476928711,5.17799997329712,0.306392735290527,5.17799997329712,-0.291269421386719,5.17799997329712,,,0.000565125078216382,0.000294056297119291,0.000699589097280768,,20,639.279476928711,306.392735290527,-291.269421386719,
,6083585.97,4417,5.00025010108948,-1100.37517089844,179.975601196289,0.637952780151367,5.17799997329712,0.305635232543945,5.17799997329712,-0.292076298522949,5.17799997329712,,,0.000328413308485168,0.000362485058089569,0.000584882524715318,,20,637.952780151367,305.635232543945,-292.076298522949,
,6083614.78,4417,5.00094985961914,-1050.47058105469,179.975601196289,0.636871298217773,5.17799997329712,0.305083854675293,5.17799997329712,-0.293484861755371,5.17799997329712,,,0.000365377371813633,0.000372462995774913,0.000618326831520199,,20,636.871298217773,305.083854675293,-293.484861755371,
,6083644.03,4417,4.99785017967224,-1000.62117919922,179.975601196289,0.635950973510742,5.17799997329712,0.304083972167969,5.17799997329712,-0.293563980102539,5.17799997329712,,,0.000599868564183187,0.000444061189275403,0.000532637802917678,,20,635.950973510742,304.083972167969,-293.563980102539,
,6083671.09,4417,5.00189995765686,-950.544122314453,179.975601196289,0.634635858154297,5.17799997329712,0.303385934448242,5.17799997329712,-0.294164387512207,5.17799997329712,,,0.000535191831530184,0.000348711020779183,0.000680519808469545,,20,634.635858154297,303.385934448242,-294.164387512207,
,6083698.97,4417,4.99930000305176,-900.611956787109,179.975601196289,0.633320254516602,5.17799997329712,0.30290179901123,5.17799997329712,-0.29499803314209,5.17799997329712,,,0.000603024745284825,0.00035136370325378,0.000520867417543505,,20,633.320254516602,302.90179901123,-294.99803314209,
,6083724.92,4417,5.00014996528625,-850.76369934082,179.975601196289,0.632212377929688,5.17799997329712,0.30214326171875,5.17799997329712,-0.295460879516602,5.17799997329712,,,0.000706057251594134,0.000351083428918741,0.000559657552246789,,20,632.212377929687,302.14326171875,-295.460879516602,
,6083752.98,4417,5.00170016288757,-800.614218139648,179.975601196289,0.63083854675293,5.17799997329712,0.301628988647461,5.17799997329712,-0.296317077636719,5.17799997329712,,,0.000570217361224672,0.000238649050370917,0.000881627174109273,,20,630.83854675293,301.628988647461,-296.317077636719,
,6083781.09,4421,5.00999999046326,-750.741809082031,179.975601196289,0.629343139648438,5.17799997329712,0.300615231323242,5.17799997329712,-0.29501629486084,5.17799997329712,,,0.000502717207151368,0.000335518263347812,0.00208649072422689,,20,629.343139648438,300.615231323242,-295.01629486084,
,6083808.84,4421,4.99769997596741,-700.659014892578,179.975601196289,0.628725708007813,5.17799997329712,0.300247340393067,5.17799997329712,-0.297140721130371,5.17799997329712,,,0.000573285368576438,0.000370967007216389,0.000820831255111968,,20,628.725708007813,300.247340393066,-297.140721130371,
,6083837.03,4421,4.99749994277954,-650.480810546875,179.975601196289,0.627291500854492,5.17799997329712,0.299681448364258,5.17799997329712,-0.298140878295898,5.17799997329712,,,0.000609465353276833,0.0004090570296388,0.00077373270287655,,20,627.291500854492,299.681448364258,-298.140878295898,
,6083865.23,4421,4.9993999004364,-600.587698364258,179.975601196289,0.625568603515625,5.17799997329712,0.298560008239746,5.17799997329712,-0.298823568725586,5.17799997329712,,,0.000287053007303936,0.000293043514963938,0.000857710359235114,,20,625.568603515625,298.560008239746,-298.823568725586,
,6083891.28,4421,4.99810004234314,-550.408340454102,179.975601196289,0.625185595703125,5.17799997329712,0.298422241210938,5.17799997329712,-0.299500448608398,5.17799997329712,,,0.000439514776599577,0.000367059664828109,0.000787148083456697,,20,625.185595703125,298.422241210938,-299.500448608398,
,6083917.80,4421,4.99804997444153,-500.646301269531,179.975601196289,0.623765832519531,5.17799997329712,0.297538595581055,5.17799997329712,-0.301257208251953,5.17799997329712,,,0.000383233151892296,0.000318685585159856,0.000761309738985103,,20,623.765832519531,297.538595581055,-301.257208251953,
,6083945.25,4421,4.99804997444153,-450.479582214355,179.975601196289,0.622751165771484,5.17799997329712,0.296878469848633,5.17799997329712,-0.30215735168457,5.17799997329712,,,0.000640682446097123,0.000283721260373401,0.000594376205819949,,20,622.751165771484,296.878469848633,-302.15735168457,
,6083972.50,4421,4.99885010719299,-400.542797851563,179.975601196289,0.621047476196289,5.17799997329712,0.295945082092285,5.17799997329712,-0.302792816162109,5.17799997329712,,,0.000495288546030882,0.000312306841149756,0.000585498416987396,,20,621.047476196289,295.945082092285,-302.792816162109,
,6084000.23,4421,4.99895000457764,-350.689926147461,179.975601196289,0.620130432128906,5.17799997329712,0.294917744445801,5.17799997329712,-0.303064376831055,5.17799997329712,,,0.000489863456729645,0.000258719252481837,0.000877819687411583,,20,620.130432128906,294.917744445801,-303.064376831055,
,6084026.03,4417,4.99950003623962,-300.883074951172,179.975601196289,0.619058856201172,5.17799997329712,0.294377655029297,5.17799997329712,-0.304605506896973,5.17799997329712,,,0.000488289213811725,0.000300593640041705,0.00054240252945443,,20,619.058856201172,294.377655029297,-304.605506896973,
,6084054.28,4417,5.00184988975525,-250.724396514893,179.975601196289,0.617842684936524,5.17799997329712,0.293565074157715,5.17799997329712,-0.305897305297852,5.17799997329712,,,0.00054899798824002,0.000199421253538631,0.000589635996573665,,20,617.842684936523,293.565074157715,-305.897305297852,
,6084081.75,4417,5.00904989242554,-200.804856109619,179.975601196289,0.616544177246094,5.17799997329712,0.293017611694336,5.17799997329712,-0.306902270507812,5.17799997329712,,,0.000450401499751465,0.00033015659910618,0.000458437665271743,,20,616.544177246094,293.017611694336,-306.902270507812,
,6084109.47,4417,5.00049996376038,-150.635832977295,179.975601196289,0.615604940795898,5.17799997329712,0.292019784545898,5.17799997329712,-0.307600891113281,5.17799997329712,,,0.000556070652139707,0.000289697759343916,0.000564934622211393,,20,615.604940795898,292.019784545898,-307.600891113281,
,6084137.91,4417,5.00049996376038,-100.620869445801,179.975601196289,0.614204925537109,5.17799997329712,0.291411608886719,5.17799997329712,-0.308170246887207,5.17799997329712,,,0.000466408424146197,0.000299681471407367,0.000561738025558851,,20,614.204925537109,291.411608886719,-308.170246887207,
,6084166.45,4417,5.00044989585876,-50.3518220901489,179.975601196289,0.61260749206543,5.17799997329712,0.290831289672852,5.17799997329712,-0.309969018554688,5.17799997329712,,,0.000566821654448795,0.000326217886145733,0.000565433825059233,,20,612.60749206543,290.831289672852,-309.969018554688,
,6084192.16,4417,5.00115013122559,-0.736951300501823,179.975601196289,0.611625091552734,5.17799997329712,0.290028024291992,5.17799997329712,-0.310631782531738,5.17799997329712,,,0.000618717016487292,0.000286736951021389,0.000541194214746184,,20,611.625091552734,290.028024291992,-310.631782531738,